Workbook

Sheet 설문지 응답 시트1
A1: 타임스탬프 | B1: 이메일 주소 | C1: 이름 | D1: 소속 팀 | E1: 작성 날짜 | F1: 오늘의 작업량 | G1: 자유로운 한마디
A2: 46042.746 | B2: rladudeh6055@gmail.com | C2: 김영도 | D2: 10팀 | E2: 20일 (화) | F2: 0.25 | G2: 팀에 한번도 유니티나 코딩 메이플 스토리 월드를 한번도 사용해 본 적이 없어서 그런 면에서는 조금 어려움이 있었다고 생각합니다. 다른 면에서는 수월하게 진행이 되어서 문제는 없었습니다.
A3: 46042.746 | B3: zeno9758@gmail.com | C3: 신석균 | D3: 10팀 | E3: 20일 (화) | F3: 0.25 | G3: 프로그램을 처음 만졌는데 간단한 ui 추가도 매우 힘들었다.
A4: 46042.747 | B4: cayde05130@gmail.com | C4: 임동균 | D4: 10팀 | E4: 20일 (화) | F4: 0.5 | G4: AI 이미지 활용을 위해, Stable Diffusion을 설치하고, 사용법을 알아보고, 테스트를 여러 차례 진행했다. (샘플 출력 등) 또 이전에 배운 Gems를 활용해서 프롬프트를 출력하는 봇을 만들어서 더 작업 효율을 높이기 위한 시도를 했다.
A5: 46042.748 | B5: yundonghyun0618@gmail.com | C5: 윤동현 | D5: 10팀 | E5: 20일 (화) | F5: 0.75 | G5: 저희는 시나리오 작성을 해본 경험이 있는 분이 계셔서 시나리오 부분은 믿고 맡길 수 있었던 거 같아요. 하지만 메이플 월드 엔진이나, 아트, 사운드 등등은 다들 손을 대본 적이 없는 경험이 있어서 꽤나 골머리를 앓고 있는 것 같습니다. 저는 게임 내 삽입될 BGM이나 상황에 맞는 효과음, 대사 데이터 테이블, UI 등을 맡게 될 것 같습니다. 정말 1도 몰라서 처음부터 시작하면서 우여곡절이 참 많은 거 같습니다.
A6: 46042.755 | B6: cocohyeonmin@gmail.com | C6: 권현민 | D6: 10팀 | E6: 20일 (화) | F6: 0.5 | G6: 팀장님이 팀원과 소통을 잘 하시고 관리를 열심히 하십니다
A7: 46042.746 | B7: ownerjeong@gmail.com | C7: 정우경 | D7: 11팀 | E7: 20일 (화) | F7: 0.25 | G7: 시작이 반, 잘되고 있고 팀에 적극적으로 기여하는 기분이다. 좋은 결과가 있기를 바랍니다.
A8: 46042.746 | B8: dbgocks99@gmail.com | C8: 유해찬 | D8: 11팀 | E8: 20일 (화) | F8: 0.5 | G8: 팀 내 이슈: 아무래도 스토리와 전투부분에 소통 오류가 있는것 같군요.. 저는 UI 와 사운드를 맡게 되어서 여유롭게 작업중 입니다. 빠르게 Ui 를 마무리하고 연출쪽 작업을 노려보려합니다.
A9: 46042.748 | B9: gg.ikane13@gmail.com | C9: 박기은 | D9: 11팀 | E9: 20일 (화) | F9: 0.25 | G9: 어려워요.. 어렵습니다.. 모든게 어려워요...... 팀원분들이랑 조율하는 부분이 어렵습니다... 의견통합은 좋은데, 스토리, 이미지 제작, 전투 담당 셋이서 작업물을 합치는 방식이.. 정말 어려운 것 같습니다. 알고보니 셋이 다른 생각을 하고 있었다거나...ㅠㅠ 조별과제랑은 차원이 다르네요..
A10: 46042.753 | B10: tarentella92@gmail.com | C10: 한지우 | D10: 11팀 | E10: 20일 (화) | F10: 아직 가늠이 잘 안되는것 같아요 ㅠㅠ | G10: 정신이 없었지만 아이템 이미지를 어떻게 구현해야 할지 고민이 많았고 개그 장르라서 자신없는 장르이다보니 팀원분들과 협업하는게 중요해 보입니다 :)
A11: 46042.771 | B11: sznemo5565@gmail.com | C11: 이준혁 | D11: 11팀 | E11: 20일 (화) | F11: 0.15 | G11: 했던 말 또 하고 했던 말 또 하고 했던 말 또 하고 했던 말 또 하고 했던 말 또 하고 했던 말 또 하고 했던 말 또 하고 했던 말 또 하고 했던 말 또 하고 했던 말 또 하고 했던 말 또 하고 했던 말 또 하고 했던 말 또 하고 했던 말 또 하고 했던 말 또 하고 했던 말 또 하고 했던 말 또 하고 했던 말 또 하고 했던 말 또 하고 했던 말 또 하고 했던 말 또 하고 했던 말 또 하고 했던 말 또 하고 했던 말 또 하고 했던 말 또 하고 했던 말 또 하고 했던 말 또 하고 했던 말 또 하고 했던 말 또 하고 했던 말 또 하고 했던 말 또 하고 했던 말 또 하고 했던 말 또 하고 했던 말 또 하고 했던 말 또 하고 했던 말 또 하고 했던 말 또 하고 했던 말 또 하고 했던 말 또 하고 했던 말 또 하고 했던 말 또 하고 했던 말 또 하고 했던 말 또 하고 했던 말 또 하고 했던 말 또 하고 했던 말 또 하고 했던 말 또 하고 했던 말 또 하고 했던 말 또 하고 했던 말 또 하고 했던 말 또 하고
A12: 46042.791 | B12: slajswj123@gmail.com | C12: 임소영 | D12: 11팀 | E12: 20일 (화) | F12: 0.5 | G12: 비주얼노벨에 용사RPG를 사용하다보니 비주얼노벨에서 너무 벗어나게될까봐 많은 부분을 고민하는 시간을 가졌습니다. 신중하게 작업하고싶어 회의 시간이 길어지면서 잘할 수 있을까 하는 걱정이 앞서게 되었었는데 하루만에 뭔가 틀이 만들어지고 있다는게 느껴져서 기
A13: 46042.746 | B13: duddn04066@gmail.com | C13: 이영우 | D13: 12팀 | E13: 20일 (화) | F13: 0.5 | G13: 메이플 월드에 대한 툴에 대한 적응이 너무 어려웠습니다. 배가 아프지만 않았다면 더 많이 진행되었을 것 같은 아쉬움이 있습니다.
A14: 46042.747 | B14: eogks3681@gmail.com | C14: 김재환 | D14: 12팀 | E14: 20일 (화) | F14: 개인적으로 10%정도? | G14: 내 생각을 제대로 언어화해서 말로 전달하지 못하는 점이 힘드네요
A15: 46042.752 | B15: changyu0306@naver.com | C15: 이찬규 | D15: 12팀 | E15: 20일 (화) | F15: 0.25 | G15: 우리는 네모난 바퀴로 달리는 자동차.
A16: 46042.786 | B16: baoo88000@gmail.com | C16: 김태훈 | D16: 12팀 | E16: 20일 (화) | F16: 0.25 | G16: 팀내 소통이 잘 안되는거 같고 코드가 너무 어렵습니다
A17: 46042.746 | B17: overman623@naver.com | C17: 김범진 | D17: 13팀 | E17: 20일 (화) | F17: 0.5 | G17: 이미지생성에 어려움이 있지만 팀원들의 응원이 있어서 좋았습니다.
A18: 46042.751 | B18: gimyungyu9@gmail.com | C18: 김윤규 | D18: 13팀 | E18: 20일 (화) | F18: 0.5 | G18: 시나리오 담당으로 작업중인데 처음에는 되게 재밌고 아이디어가 계속 나올 줄 알았는데 하다보니깐 욕심 때문인지, 퀄리티가 실제로 떨어진건지 되게 별로인 것 처럼 보이고 머리가 생각보다 지끈거리네요 ㅋㅋㅋㅋ. 그치만 완벽하게 완성시켜서 팀원분이랑 잘 완성시키고 싶습니다.
A19: 46042.753 | B19: ceandgou10@gmail.com | C19: 윤유나 | D19: 13팀 | E19: 20일 (화) | F19: 0.25 | G19: 코드..코드가 너무 어려워요...
A20: 46042.754 | B20: sodgh3215@naver.com | C20: 이승진 | D20: 13팀 | E20: 20일 (화) | F20: 0.25 | G20: 오늘은 메이플스토리 월드를 활용하여 비주얼 노벨을 개발하는 프로젝트가 본격적으로 시작되었습니다. 평소 해보지못한 영역에 도전해보고싶어 패기롭게 사운드를 담당하게 되었는데 사운드를 A.I로 뽑는거까진 어떻게 되지만 그걸 게임에 적용하는데서 막혀버렸습니다... 윤석 강사님께 조언을 구하긴 했는데 아직 답장이 오지 않는걸보니 코딩의 ㅋ자도 모르는 초보에게 알려주긴 막막한 내용이었나 싶네요. 열심히 음악을 뽑고있긴 하지만 이걸 제대로 써먹을수 있을지 모르겠습니다. 팀에 민폐끼치고 싶진 않은데 이 난관을 돌파할수 있을지 모르겠네요. 몇시간전에 팀원분들에게 미리 이야기해두긴 했으나 아직은 대수롭지않은 문제로 여기고 있어서 내일까지 조언을 받을수 없다면 팀원들에게 진지하게 다시 상의해봐야겠습니다.
A21: 46042.76 | B21: hyunsu112913@gmail.com | C21: 박현수 | D21: 13팀 | E21: 20일 (화) | F21: 0.25 | G21: 코드를 모르니 뭐가 되고안되고의 파악이 힘들어서 애로사항이 있습니다. UI를 따로 제작하여야하는데 래퍼런스 사이트를 찾는게 힘드네요
A22: 46042.747 | B22: reals2006n@gmail.com | C22: 오종호 | D22: 14팀 | E22: 20일 (화) | F22: 0.5 | G22: 다들 본인이 맡은 일을 너무 잘한다. 다들 성격도 좋다. 실력도 좋다. 그렇다고 예스맨이 아닌 서로서로 피드백도 충분히 해주고 있다. 이대로만 가즈아
A23: 46042.75 | B23: dpfspr0632@gmail.com | C23: 장윤우 | D23: 14팀 | E23: 20일 (화) | F23: 써도 써도 끝이 없는 이기분... | G23: 팀원들이 하나같이 제 역할 이상의 것들을 해줘서 너무 편하게 작업을 진행했습니다. 정말 저만 잘하면 될 것 같네요. 화이팅! ai는 신이야!
A24: 46042.759 | B24: papalagioj@gmail.com | C24: 김서현 | D24: 14팀 | E24: 20일 (화) | F24: 1 | G24: 너무 잘 진행되고 있습니다! 다른 분들 모두 적극적으로 본인의 작업 내용을 공유해 주시고, 본인의 작업을 적극적으로 진행해주셔서 매우 순조롭습니다! 제가 팀장으로써 할 일이 별로 없습니다... ^_^) b
A25: 46042.746 | B25: monkey609s@gmail.com | C25: 이원홍 | D25: 15팀 | E25: 20일 (화) | F25: 약 35%정도 | G25: 어제보다 확실한 방향성이 정해진것같아 좋습니다.
A26: 46042.746 | B26: dlehalssla@gmail.com | C26: 이도민 | D26: 15팀 | E26: 20일 (화) | F26: 0.25 | G26: 핵심 콘텐츠 큰 틀 구성 완료
A27: 46042.746 | B27: cjsdudgus1@gmail.com | C27: 천영현 | D27: 15팀 | E27: 20일 (화) | F27: 0.25 | G27: 재밌게 자유롭게 대화하면서 했습니다!
A28: 46042.747 | B28: gustlrdn3@gmail.com | C28: 김현우B | D28: 15팀 | E28: 20일 (화) | F28: 0.25 | G28: 다들 적극적으로 참여해주고 서로의 의견을 존중하면서 진행해서 좋았습니다.
A29: 46042.747 | B29: cjh1654@gmail.com | C29: 최선동 | D29: 15팀 | E29: 20일 (화) | F29: 0.5 | G29: 팀이 재밌어요~ㅎㅎ
A30: 46042.748 | B30: jsh001012@gmail.com | C30: 정석현 | D30: 1팀 | E30: 20일 (화) | F30: 0.25 | G30: 메이플월드에 적용이 가능한 사운드 포맷, 스토리에 맞는 사운드 레퍼런스 방향성 잡기를 완료하였다. 지금은 AMB와 SFX를 분리시키는 코딩 작업을 시도중인데 쉽지 않다... 첫날이라 다들 방향성이 모호하고 처음 해보는 작업들도 있다보니 우왕좌왕 했던것 같지만 차차 방향성이 잡혀가고 있다는 느낌이 들어서 뿌듯함도 느껴졌다.
A31: 46042.749 | B31: leedogun3@gmail.com | C31: 이도건 | D31: 1팀 | E31: 20일 (화) | F31: 0.5 | G31: 시나리오 기획을 지망하고 어제 밤을 새서 시나리오를 썼지만 아쉽게도 다른 팀원분의 시나리오가 채택되어 약간은 아쉬웠습니다. 그래도 팀을 위한 좋은 방향이라 생각하면서 열심히 참여하려고 하고 있습니다. UI 및 연출 담당을 새로 맡게 되었는데 처음 접하는 부분이어서 솔직히 좀 막막했습니다. 하지만 팀원분들이 서로 잘 소통해주고 도와주셔서 방향을 알게 되었습니다. 역시 생각만 하는 것과 실제로 만드는 것은 천차만별인 것 같습니다. 남은 시간도 화이팅 해보겠습니다.
A32: 46042.751 | B32: jeungha89@gmail.com | C32: 승정하 | D32: 1팀 | E32: 20일 (화) | F32: 1 | G32: 팀원분들이 항상 생산적인 방향을 중심으로 소통하시는 것 같아서 원할하게 첫날이 진행된 것 같습니다. 1조 팀원분들 칭찬드립니다!
A33: 46042.754 | B33: sujin3752@gmail.com | C33: 정수진 | D33: 1팀 | E33: 20일 (화) | F33: 0.25 | G33: 처음쓰는 엔진인 만큼 스크립트에 대해 공부를 했습니다!
A34: 46042.746 | B34: yee8190@gmail.com | C34: 예인해 | D34: 2팀 | E34: 20일 (화) | F34: 0.1 | G34: 검열이 너무 싫습니다...
A35: 46042.746 | B35: viliv8177@gmail.com | C35: 권수빈 | D35: 2팀 | E35: 20일 (화) | F35: 0.25 | G35: 팀 내적이나 외적으로 심의를 다루는 게 가장 어렵습니다
A36: 46042.747 | B36: 0wjstjf10@gmail.com | C36: 조준현 | D36: 2팀 | E36: 20일 (화) | F36: 0.25 | G36: 팀장이지만 짬통이된듯한 이 상황...사실 팀장인지도 모르겠는 이 상황..ㅠ
A37: 46042.747 | B37: khal0429@gmail.com | C37: 김경민 | D37: 2팀 | E37: 20일 (화) | F37: 0.1 | G37: 팀원들과 방식을 맞춰가며 작업을 하는게 힘들었습니다.
... A50: 46042.748 | B50: areagate34@gmail.com | C50: 김태환 | D50: 5팀 | E50: 20일 (화) | F50: 0.25 | G50: 진행이 순서대로 이루어져야 하기 때문에 분업이 어려웠음. 카테고리별로 업무를 나누면 대기를 해야하는 상황 발생. 서로 시간에 쫓기는 작업이 어려웠음.
A51: 46042.758 | B51: wlgns30617@gmail.com | C51: 김민수 | D51: 5팀 | E51: 20일 (화) | F51: 혹시 퍼센트의 의미를 알 수 있을까요? 오늘 원하는 작업은 전부하긴했습니다 | G51: 부족한 기능을 추가하는 점이 어려웠습니다. 팀원들과 소통을 통해 작업을 하는 점이 저희 팀의 장점이라고 생각하고 정헌님의 팀을 이끄는 리더십이 배울 점이라고 생각합니다
A52: 46042.747 | B52: power122926@gmail.com | C52: 이균호 | D52: 6팀 | E52: 20일 (화) | F52: 0%. 수업 종료 직전에 내용이 엎어짐. 아주 기초적인 부분을 의논중임 | G52: 각자 역할에 맞춰 열심히 해줘서 일이 어느정도 진행되는 것을 보니 기분이 묘하다. 하지만 결과적으로 검열 때문에 게임 스토리와 스타일을 처음부터 갈아엎는 걸로 진행하게 되었다. 오늘 열심히 작업한 것이 아쉽지만 내일 더욱 노력해서 시간 내로 게임을 완성할 수 있도록 해야겠다.
...

Sheet 종합
B2: 데일리 체크인 종합 시트
B4: - 데일리 체크인 작성이 결국 개인 성실성과 과정 신뢰도, 과정 운영의 지시를 따르는 지표가 될 것으로 보입니다. - 작성의 판단 기준은 당일 오후 5:00 ~ 다음날 오전 9:00 까지 작성된 데이터를 기준으로 판단합니다.
B6: 팀 | C6: 이름 | D6: 미작성 횟수 | E6: 응답 비율 | F6: 46042 | G6: 46043 | H6: 46044 | I6: 46045
B7: 1 | C7: 강유민 | D7: =COUNTIFS(F7:I7, "X", F$6:I$6, "<"&TODAY()) -> 0 | E7: =COUNTIFS(F7:I7, "O", F$6:I$6, "<"&TODAY())/COUNTIF(F$6:I$6,"<"&TODAY()) -> 1 | F7: =IF(COUNTIFS('설문지 응답 시트1'!$C:$C, $C7, '설문지 응답 시트1'!$A:$A, ">="&(F$6 + TIME(17,0,0)), '설문지 응답 시트1'!$A:$A, "<"&(F$6 + 1 + TIME(9,0,0)))>0, "O", "X") -> O | G7: =IF(COUNTIFS('설문지 응답 시트1'!$C:$C, $C7, '설문지 응답 시트1'!$A:$A, ">="&(G$6 + TIME(17,0,0)), '설문지 응답 시트1'!$A:$A, "<"&(G$6 + 1 + TIME(9,0,0)))>0, "O", "X") -> O | H7: =IF(COUNTIFS('설문지 응답 시트1'!$C:$C, $C7, '설문지 응답 시트1'!$A:$A, ">="&(H$6 + TIME(17,0,0)), '설문지 응답 시트1'!$A:$A, "<"&(H$6 + 1 + TIME(9,0,0)))>0, "O", "X") -> O | I7: =IF(COUNTIFS('설문지 응답 시트1'!$C:$C, $C7, '설문지 응답 시트1'!$A:$A, ">="&(I$6 + TIME(17,0,0)), '설문지 응답 시트1'!$A:$A, "<"&(I$6 + 1 + TIME(9,0,0)))>0, "O", "X") -> O
B8: 1 | C8: 이유송 | D8: =COUNTIFS(F8:I8, "X", F$6:I$6, "<"&TODAY()) -> 0 | E8: =COUNTIFS(F8:I8, "O", F$6:I$6, "<"&TODAY())/COUNTIF(F$6:I$6,"<"&TODAY()) -> 1 | F8: =IF(COUNTIFS('설문지 응답 시트1'!$C:$C, $C8, '설문지 응답 시트1'!$A:$A, ">="&(F$6 + TIME(17,0,0)), '설문지 응답 시트1'!$A:$A, "<"&(F$6 + 1 + TIME(9,0,0)))>0, "O", "X") -> O | G8: =IF(COUNTIFS('설문지 응답 시트1'!$C:$C, $C8, '설문지 응답 시트1'!$A:$A, ">="&(G$6 + TIME(17,0,0)), '설문지 응답 시트1'!$A:$A, "<"&(G$6 + 1 + TIME(9,0,0)))>0, "O", "X") -> O | H8: =IF(COUNTIFS('설문지 응답 시트1'!$C:$C, $C8, '설문지 응답 시트1'!$A:$A, ">="&(H$6 + TIME(17,0,0)), '설문지 응답 시트1'!$A:$A, "<"&(H$6 + 1 + TIME(9,0,0)))>0, "O", "X") -> O | I8: =IF(COUNTIFS('설문지 응답 시트1'!$C:$C, $C8, '설문지 응답 시트1'!$A:$A, ">="&(I$6 + TIME(17,0,0)), '설문지 응답 시트1'!$A:$A, "<"&(I$6 + 1 + TIME(9,0,0)))>0, "O", "X") -> O
B9: 1 | C9: 이동현 | D9: =COUNTIFS(F9:I9, "X", F$6:I$6, "<"&TODAY()) -> 1 | E9: =COUNTIFS(F9:I9, "O", F$6:I$6, "<"&TODAY())/COUNTIF(F$6:I$6,"<"&TODAY()) -> 0.75 | F9: =IF(COUNTIFS('설문지 응답 시트1'!$C:$C, $C9, '설문지 응답 시트1'!$A:$A, ">="&(F$6 + TIME(17,0,0)), '설문지 응답 시트1'!$A:$A, "<"&(F$6 + 1 + TIME(9,0,0)))>0, "O", "X") -> O | G9: =IF(COUNTIFS('설문지 응답 시트1'!$C:$C, $C9, '설문지 응답 시트1'!$A:$A, ">="&(G$6 + TIME(17,0,0)), '설문지 응답 시트1'!$A:$A, "<"&(G$6 + 1 + TIME(9,0,0)))>0, "O", "X") -> O | H9: =IF(COUNTIFS('설문지 응답 시트1'!$C:$C, $C9, '설문지 응답 시트1'!$A:$A, ">="&(H$6 + TIME(17,0,0)), '설문지 응답 시트1'!$A:$A, "<"&(H$6 + 1 + TIME(9,0,0)))>0, "O", "X") -> X | I9: =IF(COUNTIFS('설문지 응답 시트1'!$C:$C, $C9, '설문지 응답 시트1'!$A:$A, ">="&(I$6 + TIME(17,0,0)), '설문지 응답 시트1'!$A:$A, "<"&(I$6 + 1 + TIME(9,0,0)))>0, "O", "X") -> O
B10: 1 | C10: 정우경 | D10: =COUNTIFS(F10:I10, "X", F$6:I$6, "<"&TODAY()) -> 0 | E10: =COUNTIFS(F10:I10, "O", F$6:I$6, "<"&TODAY())/COUNTIF(F$6:I$6,"<"&TODAY()) -> 1 | F10: =IF(COUNTIFS('설문지 응답 시트1'!$C:$C, $C10, '설문지 응답 시트1'!$A:$A, ">="&(F$6 + TIME(17,0,0)), '설문지 응답 시트1'!$A:$A, "<"&(F$6 + 1 + TIME(9,0,0)))>0, "O", "X") -> O | G10: =IF(COUNTIFS('설문지 응답 시트1'!$C:$C, $C10, '설문지 응답 시트1'!$A:$A, ">="&(G$6 + TIME(17,0,0)), '설문지 응답 시트1'!$A:$A, "<"&(G$6 + 1 + TIME(9,0,0)))>0, "O", "X") -> O | H10: =IF(COUNTIFS('설문지 응답 시트1'!$C:$C, $C10, '설문지 응답 시트1'!$A:$A, ">="&(H$6 + TIME(17,0,0)), '설문지 응답 시트1'!$A:$A, "<"&(H$6 + 1 + TIME(9,0,0)))>0, "O", "X") -> O | I10: =IF(COUNTIFS('설문지 응답 시트1'!$C:$C, $C10, '설문지 응답 시트1'!$A:$A, ">="&(I$6 + TIME(17,0,0)), '설문지 응답 시트1'!$A:$A, "<"&(I$6 + 1 + TIME(9,0,0)))>0, "O", "X") -> O
B11: 1 | C11: 김현우A | D11: =COUNTIFS(F11:I11, "X", F$6:I$6, "<"&TODAY()) -> 4 | E11: =COUNTIFS(F11:I11, "O", F$6:I$6, "<"&TODAY())/COUNTIF(F$6:I$6,"<"&TODAY()) -> 0 | F11: =IF(COUNTIFS('설문지 응답 시트1'!$C:$C, $C11, '설문지 응답 시트1'!$A:$A, ">="&(F$6 + TIME(17,0,0)), '설문지 응답 시트1'!$A:$A, "<"&(F$6 + 1 + TIME(9,0,0)))>0, "O", "X") -> X | G11: =IF(COUNTIFS('설문지 응답 시트1'!$C:$C, $C11, '설문지 응답 시트1'!$A:$A, ">="&(G$6 + TIME(17,0,0)), '설문지 응답 시트1'!$A:$A, "<"&(G$6 + 1 + TIME(9,0,0)))>0, "O", "X") -> X | H11: =IF(COUNTIFS('설문지 응답 시트1'!$C:$C, $C11, '설문지 응답 시트1'!$A:$A, ">="&(H$6 + TIME(17,0,0)), '설문지 응답 시트1'!$A:$A, "<"&(H$6 + 1 + TIME(9,0,0)))>0, "O", "X") -> X | I11: =IF(COUNTIFS('설문지 응답 시트1'!$C:$C, $C11, '설문지 응답 시트1'!$A:$A, ">="&(I$6 + TIME(17,0,0)), '설문지 응답 시트1'!$A:$A, "<"&(I$6 + 1 + TIME(9,0,0)))>0, "O", "X") -> X
B12: 1 | C12: 정석현 | D12: =COUNTIFS(F12:I12, "X", F$6:I$6, "<"&TODAY()) -> 0 | E12: =COUNTIFS(F12:I12, "O", F$6:I$6, "<"&TODAY())/COUNTIF(F$6:I$6,"<"&TODAY()) -> 1 | F12: =IF(COUNTIFS('설문지 응답 시트1'!$C:$C, $C12, '설문지 응답 시트1'!$A:$A, ">="&(F$6 + TIME(17,0,0)), '설문지 응답 시트1'!$A:$A, "<"&(F$6 + 1 + TIME(9,0,0)))>0, "O", "X") -> O | G12: =IF(COUNTIFS('설문지 응답 시트1'!$C:$C, $C12, '설문지 응답 시트1'!$A:$A, ">="&(G$6 + TIME(17,0,0)), '설문지 응답 시트1'!$A:$A, "<"&(G$6 + 1 + TIME(9,0,0)))>0, "O", "X") -> O | H12: =IF(COUNTIFS('설문지 응답 시트1'!$C:$C, $C12, '설문지 응답 시트1'!$A:$A, ">="&(H$6 + TIME(17,0,0)), '설문지 응답 시트1'!$A:$A, "<"&(H$6 + 1 + TIME(9,0,0)))>0, "O", "X") -> O | I12: =IF(COUNTIFS('설문지 응답 시트1'!$C:$C, $C12, '설문지 응답 시트1'!$A:$A, ">="&(I$6 + TIME(17,0,0)), '설문지 응답 시트1'!$A:$A, "<"&(I$6 + 1 + TIME(9,0,0)))>0, "O", "X") -> O
B13: 1 | C13: 임소영 | D13: =COUNTIFS(F13:I13, "X", F$6:I$6, "<"&TODAY()) -> 0 | E13: =COUNTIFS(F13:I13, "O", F$6:I$6, "<"&TODAY())/COUNTIF(F$6:I$6,"<"&TODAY()) -> 1 | F13: =IF(COUNTIFS('설문지 응답 시트1'!$C:$C, $C13, '설문지 응답 시트1'!$A:$A, ">="&(F$6 + TIME(17,0,0)), '설문지 응답 시트1'!$A:$A, "<"&(F$6 + 1 + TIME(9,0,0)))>0, "O", "X") -> O | G13: =IF(COUNTIFS('설문지 응답 시트1'!$C:$C, $C13, '설문지 응답 시트1'!$A:$A, ">="&(G$6 + TIME(17,0,0)), '설문지 응답 시트1'!$A:$A, "<"&(G$6 + 1 + TIME(9,0,0)))>0, "O", "X") -> O | H13: =IF(COUNTIFS('설문지 응답 시트1'!$C:$C, $C13, '설문지 응답 시트1'!$A:$A, ">="&(H$6 + TIME(17,0,0)), '설문지 응답 시트1'!$A:$A, "<"&(H$6 + 1 + TIME(9,0,0)))>0, "O", "X") -> O | I13: =IF(COUNTIFS('설문지 응답 시트1'!$C:$C, $C13, '설문지 응답 시트1'!$A:$A, ">="&(I$6 + TIME(17,0,0)), '설문지 응답 시트1'!$A:$A, "<"&(I$6 + 1 + TIME(9,0,0)))>0, "O", "X") -> O
B14: 1 | C14: 박현수 | D14: =COUNTIFS(F14:I14, "X", F$6:I$6, "<"&TODAY()) -> 0 | E14: =COUNTIFS(F14:I14, "O", F$6:I$6, "<"&TODAY())/COUNTIF(F$6:I$6,"<"&TODAY()) -> 1 | F14: =IF(COUNTIFS('설문지 응답 시트1'!$C:$C, $C14, '설문지 응답 시트1'!$A:$A, ">="&(F$6 + TIME(17,0,0)), '설문지 응답 시트1'!$A:$A, "<"&(F$6 + 1 + TIME(9,0,0)))>0, "O", "X") -> O | G14: =IF(COUNTIFS('설문지 응답 시트1'!$C:$C, $C14, '설문지 응답 시트1'!$A:$A, ">="&(G$6 + TIME(17,0,0)), '설문지 응답 시트1'!$A:$A, "<"&(G$6 + 1 + TIME(9,0,0)))>0, "O", "X") -> O | H14: =IF(COUNTIFS('설문지 응답 시트1'!$C:$C, $C14, '설문지 응답 시트1'!$A:$A, ">="&(H$6 + TIME(17,0,0)), '설문지 응답 시트1'!$A:$A, "<"&(H$6 + 1 + TIME(9,0,0)))>0, "O", "X") -> O | I14: =IF(COUNTIFS('설문지 응답 시트1'!$C:$C, $C14, '설문지 응답 시트1'!$A:$A, ">="&(I$6 + TIME(17,0,0)), '설문지 응답 시트1'!$A:$A, "<"&(I$6 + 1 + TIME(9,0,0)))>0, "O", "X") -> O
B15: 2 | C15: 김서현 | D15: =COUNTIFS(F15:I15, "X", F$6:I$6, "<"&TODAY()) -> 0 | E15: =COUNTIFS(F15:I15, "O", F$6:I$6, "<"&TODAY())/COUNTIF(F$6:I$6,"<"&TODAY()) -> 1 | F15: =IF(COUNTIFS('설문지 응답 시트1'!$C:$C, $C15, '설문지 응답 시트1'!$A:$A, ">="&(F$6 + TIME(17,0,0)), '설문지 응답 시트1'!$A:$A, "<"&(F$6 + 1 + TIME(9,0,0)))>0, "O", "X") -> O | G15: =IF(COUNTIFS('설문지 응답 시트1'!$C:$C, $C15, '설문지 응답 시트1'!$A:$A, ">="&(G$6 + TIME(17,0,0)), '설문지 응답 시트1'!$A:$A, "<"&(G$6 + 1 + TIME(9,0,0)))>0, "O", "X") -> O | H15: =IF(COUNTIFS('설문지 응답 시트1'!$C:$C, $C15, '설문지 응답 시트1'!$A:$A, ">="&(H$6 + TIME(17,0,0)), '설문지 응답 시트1'!$A:$A, "<"&(H$6 + 1 + TIME(9,0,0)))>0, "O", "X") -> O | I15: =IF(COUNTIFS('설문지 응답 시트1'!$C:$C, $C15, '설문지 응답 시트1'!$A:$A, ">="&(I$6 + TIME(17,0,0)), '설문지 응답 시트1'!$A:$A, "<"&(I$6 + 1 + TIME(9,0,0)))>0, "O", "X") -> O
B16: 2 | C16: 김태환 | D16: =COUNTIFS(F16:I16, "X", F$6:I$6, "<"&TODAY()) -> 0 | E16: =COUNTIFS(F16:I16, "O", F$6:I$6, "<"&TODAY())/COUNTIF(F$6:I$6,"<"&TODAY()) -> 1 | F16: =IF(COUNTIFS('설문지 응답 시트1'!$C:$C, $C16, '설문지 응답 시트1'!$A:$A, ">="&(F$6 + TIME(17,0,0)), '설문지 응답 시트1'!$A:$A, "<"&(F$6 + 1 + TIME(9,0,0)))>0, "O", "X") -> O | G16: =IF(COUNTIFS('설문지 응답 시트1'!$C:$C, $C16, '설문지 응답 시트1'!$A:$A, ">="&(G$6 + TIME(17,0,0)), '설문지 응답 시트1'!$A:$A, "<"&(G$6 + 1 + TIME(9,0,0)))>0, "O", "X") -> O | H16: =IF(COUNTIFS('설문지 응답 시트1'!$C:$C, $C16, '설문지 응답 시트1'!$A:$A, ">="&(H$6 + TIME(17,0,0)), '설문지 응답 시트1'!$A:$A, "<"&(H$6 + 1 + TIME(9,0,0)))>0, "O", "X") -> O | I16: =IF(COUNTIFS('설문지 응답 시트1'!$C:$C, $C16, '설문지 응답 시트1'!$A:$A, ">="&(I$6 + TIME(17,0,0)), '설문지 응답 시트1'!$A:$A, "<"&(I$6 + 1 + TIME(9,0,0)))>0, "O", "X") -> O
B17: 2 | C17: 장윤우 | D17: =COUNTIFS(F17:I17, "X", F$6:I$6, "<"&TODAY()) -> 0 | E17: =COUNTIFS(F17:I17, "O", F$6:I$6, "<"&TODAY())/COUNTIF(F$6:I$6,"<"&TODAY()) -> 1 | F17: =IF(COUNTIFS('설문지 응답 시트1'!$C:$C, $C17, '설문지 응답 시트1'!$A:$A, ">="&(F$6 + TIME(17,0,0)), '설문지 응답 시트1'!$A:$A, "<"&(F$6 + 1 + TIME(9,0,0)))>0, "O", "X") -> O | G17: =IF(COUNTIFS('설문지 응답 시트1'!$C:$C, $C17, '설문지 응답 시트1'!$A:$A, ">="&(G$6 + TIME(17,0,0)), '설문지 응답 시트1'!$A:$A, "<"&(G$6 + 1 + TIME(9,0,0)))>0, "O", "X") -> O | H17: =IF(COUNTIFS('설문지 응답 시트1'!$C:$C, $C17, '설문지 응답 시트1'!$A:$A, ">="&(H$6 + TIME(17,0,0)), '설문지 응답 시트1'!$A:$A, "<"&(H$6 + 1 + TIME(9,0,0)))>0, "O", "X") -> O | I17: =IF(COUNTIFS('설문지 응답 시트1'!$C:$C, $C17, '설문지 응답 시트1'!$A:$A, ">="&(I$6 + TIME(17,0,0)), '설문지 응답 시트1'!$A:$A, "<"&(I$6 + 1 + TIME(9,0,0)))>0, "O", "X") -> O
B18: 2 | C18: 유해찬 | D18: =COUNTIFS(F18:I18, "X", F$6:I$6, "<"&TODAY()) -> 0 | E18: =COUNTIFS(F18:I18, "O", F$6:I$6, "<"&TODAY())/COUNTIF(F$6:I$6,"<"&TODAY()) -> 1 | F18: =IF(COUNTIFS('설문지 응답 시트1'!$C:$C, $C18, '설문지 응답 시트1'!$A:$A, ">="&(F$6 + TIME(17,0,0)), '설문지 응답 시트1'!$A:$A, "<"&(F$6 + 1 + TIME(9,0,0)))>0, "O", "X") -> O | G18: =IF(COUNTIFS('설문지 응답 시트1'!$C:$C, $C18, '설문지 응답 시트1'!$A:$A, ">="&(G$6 + TIME(17,0,0)), '설문지 응답 시트1'!$A:$A, "<"&(G$6 + 1 + TIME(9,0,0)))>0, "O", "X") -> O | H18: =IF(COUNTIFS('설문지 응답 시트1'!$C:$C, $C18, '설문지 응답 시트1'!$A:$A, ">="&(H$6 + TIME(17,0,0)), '설문지 응답 시트1'!$A:$A, "<"&(H$6 + 1 + TIME(9,0,0)))>0, "O", "X") -> O | I18: =IF(COUNTIFS('설문지 응답 시트1'!$C:$C, $C18, '설문지 응답 시트1'!$A:$A, ">="&(I$6 + TIME(17,0,0)), '설문지 응답 시트1'!$A:$A, "<"&(I$6 + 1 + TIME(9,0,0)))>0, "O", "X") -> O
... B80: 10 | C80: 정재용 | D80: =COUNTIFS(F80:I80, "X", F$6:I$6, "<"&TODAY()) -> 1 | E80: =COUNTIFS(F80:I80, "O", F$6:I$6, "<"&TODAY())/COUNTIF(F$6:I$6,"<"&TODAY()) -> 0.75 | F80: =IF(COUNTIFS('설문지 응답 시트1'!$C:$C, $C80, '설문지 응답 시트1'!$A:$A, ">="&(F$6 + TIME(17,0,0)), '설문지 응답 시트1'!$A:$A, "<"&(F$6 + 1 + TIME(9,0,0)))>0, "O", "X") -> O | G80: =IF(COUNTIFS('설문지 응답 시트1'!$C:$C, $C80, '설문지 응답 시트1'!$A:$A, ">="&(G$6 + TIME(17,0,0)), '설문지 응답 시트1'!$A:$A, "<"&(G$6 + 1 + TIME(9,0,0)))>0, "O", "X") -> X | H80: =IF(COUNTIFS('설문지 응답 시트1'!$C:$C, $C80, '설문지 응답 시트1'!$A:$A, ">="&(H$6 + TIME(17,0,0)), '설문지 응답 시트1'!$A:$A, "<"&(H$6 + 1 + TIME(9,0,0)))>0, "O", "X") -> O | I80: =IF(COUNTIFS('설문지 응답 시트1'!$C:$C, $C80, '설문지 응답 시트1'!$A:$A, ">="&(I$6 + TIME(17,0,0)), '설문지 응답 시트1'!$A:$A, "<"&(I$6 + 1 + TIME(9,0,0)))>0, "O", "X") -> O
B81: 개인 | C81: 김지훈 | D81: =COUNTIFS(F81:I81, "X", F$6:I$6, "<"&TODAY()) -> 3 | E81: =COUNTIFS(F81:I81, "O", F$6:I$6, "<"&TODAY())/COUNTIF(F$6:I$6,"<"&TODAY()) -> 0.25 | F81: =IF(COUNTIFS('설문지 응답 시트1'!$C:$C, $C81, '설문지 응답 시트1'!$A:$A, ">="&(F$6 + TIME(17,0,0)), '설문지 응답 시트1'!$A:$A, "<"&(F$6 + 1 + TIME(9,0,0)))>0, "O", "X") -> O | G81: =IF(COUNTIFS('설문지 응답 시트1'!$C:$C, $C81, '설문지 응답 시트1'!$A:$A, ">="&(G$6 + TIME(17,0,0)), '설문지 응답 시트1'!$A:$A, "<"&(G$6 + 1 + TIME(9,0,0)))>0, "O", "X") -> X | H81: =IF(COUNTIFS('설문지 응답 시트1'!$C:$C, $C81, '설문지 응답 시트1'!$A:$A, ">="&(H$6 + TIME(17,0,0)), '설문지 응답 시트1'!$A:$A, "<"&(H$6 + 1 + TIME(9,0,0)))>0, "O", "X") -> X | I81: =IF(COUNTIFS('설문지 응답 시트1'!$C:$C, $C81, '설문지 응답 시트1'!$A:$A, ">="&(I$6 + TIME(17,0,0)), '설문지 응답 시트1'!$A:$A, "<"&(I$6 + 1 + TIME(9,0,0)))>0, "O", "X") -> X
B82: 개인 | C82: 이석훈 | D82: =COUNTIFS(F82:I82, "X", F$6:I$6, "<"&TODAY()) -> 4 | E82: =COUNTIFS(F82:I82, "O", F$6:I$6, "<"&TODAY())/COUNTIF(F$6:I$6,"<"&TODAY()) -> 0 | F82: =IF(COUNTIFS('설문지 응답 시트1'!$C:$C, $C82, '설문지 응답 시트1'!$A:$A, ">="&(F$6 + TIME(17,0,0)), '설문지 응답 시트1'!$A:$A, "<"&(F$6 + 1 + TIME(9,0,0)))>0, "O", "X") -> X | G82: =IF(COUNTIFS('설문지 응답 시트1'!$C:$C, $C82, '설문지 응답 시트1'!$A:$A, ">="&(G$6 + TIME(17,0,0)), '설문지 응답 시트1'!$A:$A, "<"&(G$6 + 1 + TIME(9,0,0)))>0, "O", "X") -> X | H82: =IF(COUNTIFS('설문지 응답 시트1'!$C:$C, $C82, '설문지 응답 시트1'!$A:$A, ">="&(H$6 + TIME(17,0,0)), '설문지 응답 시트1'!$A:$A, "<"&(H$6 + 1 + TIME(9,0,0)))>0, "O", "X") -> X | I82: =IF(COUNTIFS('설문지 응답 시트1'!$C:$C, $C82, '설문지 응답 시트1'!$A:$A, ">="&(I$6 + TIME(17,0,0)), '설문지 응답 시트1'!$A:$A, "<"&(I$6 + 1 + TIME(9,0,0)))>0, "O", "X") -> X
B83: 개인 | C83: 조현일 | D83: =COUNTIFS(F83:I83, "X", F$6:I$6, "<"&TODAY()) -> 0 | E83: =COUNTIFS(F83:I83, "O", F$6:I$6, "<"&TODAY())/COUNTIF(F$6:I$6,"<"&TODAY()) -> 1 | F83: =IF(COUNTIFS('설문지 응답 시트1'!$C:$C, $C83, '설문지 응답 시트1'!$A:$A, ">="&(F$6 + TIME(17,0,0)), '설문지 응답 시트1'!$A:$A, "<"&(F$6 + 1 + TIME(9,0,0)))>0, "O", "X") -> O | G83: =IF(COUNTIFS('설문지 응답 시트1'!$C:$C, $C83, '설문지 응답 시트1'!$A:$A, ">="&(G$6 + TIME(17,0,0)), '설문지 응답 시트1'!$A:$A, "<"&(G$6 + 1 + TIME(9,0,0)))>0, "O", "X") -> O | H83: =IF(COUNTIFS('설문지 응답 시트1'!$C:$C, $C83, '설문지 응답 시트1'!$A:$A, ">="&(H$6 + TIME(17,0,0)), '설문지 응답 시트1'!$A:$A, "<"&(H$6 + 1 + TIME(9,0,0)))>0, "O", "X") -> O | I83: =IF(COUNTIFS('설문지 응답 시트1'!$C:$C, $C83, '설문지 응답 시트1'!$A:$A, ">="&(I$6 + TIME(17,0,0)), '설문지 응답 시트1'!$A:$A, "<"&(I$6 + 1 + TIME(9,0,0)))>0, "O", "X") -> O

Sheet 0120
B2: 날짜 | C2: 46042
B4: 팀 | C4: 이름 | D4: 작업량 | E4: 한마디 | F4: 비고 | G4: 상태
B5: 1 | C5: 승정하 | D5: 1 | E5: 팀원분들이 항상 생산적인 방향을 중심으로 소통하시는 것 같아서 원할하게 첫날이 진행된 것 같습니다. 1조 팀원분들 칭찬드립니다! | G5: 양호
B6: 1 | C6: 정석현 | D6: 0.25 | E6: 메이플월드에 적용이 가능한 사운드 포맷, 스토리에 맞는 사운드 레퍼런스 방향성 잡기를 완료하였다. 지금은 AMB와 SFX를 분리시키는 코딩 작업을 시도중인데 쉽지 않다... 첫날이라 다들 방향성이 모호하고 처음 해보는 작업들도 있다보니 우왕좌왕 했던것 같지만 차차 방향성이 잡혀가고 있다는 느낌이 들어서 뿌듯함도 느껴졌다. | G6: 대기
B7: 1 | C7: 곽용준 | D7: 0.5 | E7: 서로 피드백을 자유롭게 해주고 내가 잘못한 점에 대해 완곡하면서도 핵심적인 부분을 충고해주어서 좋았다 앞으로 더 좋은 방향으로 발전할 수 있을 것 같다는 느낌을 강하게 받았다 | G7: 대기
B8: 1 | C8: 정수진 | D8: 0.25 | E8: 처음쓰는 엔진인 만큼 스크립트에 대해 공부를 했습니다! | G8: 대기
B9: 1 | C9: 한의호 | D9: 0.8 | E9: 팀원 분들이랑 작업 방식이나 기준을 하나 하나 맞춰 가면서 갈피가 잡히기 시작하니 어제보다도 진행 속도는 빠르게 흘러가는 것 같습니다. 오늘 목표치를 달성 하고 추가 작업을 할 수도 있겠다는 생각에 조금 안심이 되는 느낌이었습니다. 다만 한 가지 아쉬운 점이 있다면 시나리오의 표현 수위 조절을 위해 몰입감을 조금 포기해야 하는 부분이 아쉬웠습니다. | G9: 대기
B10: 1 | C10: 이도건 | D10: 0.5 | E10: 시나리오 기획을 지망하고 어제 밤을 새서 시나리오를 썼지만 아쉽게도 다른 팀원분의 시나리오가 채택되어 약간은 아쉬웠습니다. 그래도 팀을 위한 좋은 방향이라 생각하면서 열심히 참여하려고 하고 있습니다. UI 및 연출 담당을 새로 맡게 되었는데 처음 접하는 부분이어서 솔직히 좀 막막했습니다. 하지만 팀원분들이 서로 잘 소통해주고 도와주셔서 방향을 알게 되었습니다. 역시 생각만 하는 것과 실제로 만드는 것은 천차만별인 것 같습니다. 남은 시간도 화이팅 해보겠습니다. | G10: 대기
B11: 2 | C11: 조준현 | D11: 0.25 | E11: 팀장이지만 짬통이된듯한 이 상황...사실 팀장인지도 모르겠는 이 상황..ㅠ | F11: [김상준] 먼저 DM으로 소통해보겠습니다. | G11: 주의
B12: 2 | C12: 장호윤 | D12: 0.25 | E12: 15세 이용가정도면 될줄 알았는데 13세이용가라서 핸들을 살짝 틀어야 했었습니다... | G12: 대기
B13: 2 | C13: 권수빈 | D13: 0.25 | E13: 팀 내적이나 외적으로 심의를 다루는 게 가장 어렵습니다 | G13: 대기
B14: 2 | C14: 예인해 | D14: 0.1 | E14: 검열이 너무 싫습니다... | F14: [양윤석] 이걸 어케 처리해야할지 고민이 됩니다 | G14: 대기
B15: 2 | C15: 우현승 | D15: 0.25 | E15: 팀원 1명과 캐릭터 설정과 일러스트 등의 콘셉, 아트를 담당했다. 저는 로컬 SD, 팀원은 NovelAI를 활용해서 이미지를 생성했는데, 그림체가 달라서 통일시키고 그 이미지를 일관성 있게 변형하려고 하는과정이 개인적으로 굉장히 어렵고 답답했다. | G15: 대기
B16: 2 | C16: 김경민 | D16: 0.1 | E16: 팀원들과 방식을 맞춰가며 작업을 하는게 힘들었습니다. | G16: 비상
B17: 3 | C17: 박영성 | D17: 0.25 | E17: 생각 이상으로 소통의 빈도와 구체적아어야 하는 수준이 높아서 실습을 통해 경험을 얻을 수 있는 점이 좋았습니다. 또 PD로서 어떤 점을 염두에 둬야하고 어디까지 방향성을 공유해야 하는지에 대한 경험이 특히 유익한 것 같고, 이전 조에서 얻은 경험들 덕에 스스로 발전한거 같아서 즐겁습니다. 다만 AI가 생각보다도 리소스 생성에 시간이 많이 드는 점도 알수 있었어서, 일정 관리에 대해선 더 감을 잡아가야 할 것 같습니다. 팀원분들이 각기 장점이 명확하고 의욕적이면서 소통도 적극적으로 해주셔서 첫 PD로서 너무 감사한 조인거 같습니다. | G17: 대기
B18: 3 | C18: 맹지훈 | D18: 0.25 | E18: 이미지를 기대 이상으로 생성하고 준비해주셔서 놀랐습니다. | G18: 대기
B19: 3 | C19: 손호진 | D19: 0.25 | E19: 업무 분담과 서로 소통을 하는 데에도 하루를 쓴 것에 대해 시간이 너무 빠름을 느꼈습니다. 더 속도를 가해서 해야겠습니다 | G19: 대기
B20: 3 | C20: 김흥규 | D20: 0.25 | E20: 코드를 오랜만에 만지니까 새로운 거 하나 추가하는 것도 어려웠다. 시나리오랑 아트는 진도를 쫙쫙 나가는데 엔진 담당인 나만 진도가 잘 안 나가는 거 같아서 걱정이 되지만 오늘은 밤에도 시간 투자를 한다면 괜찮지 않을까 생각을 해본다. 팀원들은 각자의 자리에서 너무 잘해줘서 정말 정말 감사하다. | G20: 대기
B21: 3 | C21: 김현우A | G21: 대기
B22: 3 | C22: 정재용 | D22: 0.25 | E22: 다들 잘 진행해주시고 팀장님의 리더쉽이 최고였습니다! | G22: 대기
B23: 4 | C23: 이석훈 | G23: 대기
B24: 4 | C24: 이승구 | D24: 0.75 | E24: 개인적 이슈 : 기본 태도가 불량한 팀원이 있습니다. 팀 내 이슈 : 볼륨을 어떻게 붙일 것 인가에 대한 이슈 근황 토크 : 살려주세요!! 궁금점 : 사운드 관련 기획은 처음인데 참고할 만한 자료나 영상이 있을까요? | F24: [김상준] 이석훈 이슈, 사운드 기획, 서진호 학생의 엔진 파트 이슈에 대해 20분정도 이야기 나누었습니다. 프로젝트 기간이 짧은 만큼 본격적인 기획 문서를 작성 후 이를 바탕으로 작업하는 프로세스가 쉽지 않은 것이 당연하고, 결과물 vs 학습 중 어느 쪽을 택할 지를 고민해보면 좋을 것 같다고 이야기했습니다. | G24: 비상
B25: 4 | C25: 장근혁 | D25: 0.5 | E25: 팀원분들이 수정사항도 너무 잘 수긍해주시고 분위기가 너무 좋았다 | G25: 대기
B26: 4 | C26: 박민규 | D26: 0.5 | E26: 중간 팀내에서 건설적인 토론 과정이 있었습니다 | G26: 대기
B27: 4 | C27: 서진호 | D27: 0.75 | E27: 조금 과열되서 파충류가 되는 상황이 좀 있었는데 강사님들과 매니저님의 도움으로 잘 해결됐습니다. 내일부터는 PD님께서 이틀간 안계시는데 잘 만들어보도록 하겠습니다. 현재까지는 재밌게 즐기고 있습니다 감사합니다! | G27: 대기
B28: 5 | C28: 이정헌 | D28: 0.75 | E28: 생각보다 시간분배가 어려운 것 같습니다... 팀 인원간 역량체크를 포함해서 중간중간 분량이 과도하지 않게 개입해서 조절은 하고있으나 쉽지 않은것 같습니다 | G28: 대기
B29: 5 | C29: 홍태광 | D29: 0.75 | E29: 이야기의 토대를 짜는 것이 많이 어려웠습니다. 4일이라는 짧은 기간이다보니 생각했던 이야기 볼륨에서 많이 축소를 해야 했던 것 같습니다. | G29: 대기
B30: 5 | C30: 박원우 | D30: 0.5 | E30: 시간이..부족해오... | G30: 대기
B31: 5 | C31: 김민수 | D31: 혹시 퍼센트의 의미를 알 수 있을까요? 오늘 원하는 작업은 전부하긴했습니다 | E31: 부족한 기능을 추가하는 점이 어려웠습니다. 팀원들과 소통을 통해 작업을 하는 점이 저희 팀의 장점이라고 생각하고 정헌님의 팀을 이끄는 리더십이 배울 점이라고 생각합니다 | G31: 대기
B32: 5 | C32: 김태환 | D32: 0.25 | E32: 진행이 순서대로 이루어져야 하기 때문에 분업이 어려웠음. 카테고리별로 업무를 나누면 대기를 해야하는 상황 발생. 서로 시간에 쫓기는 작업이 어려웠음. | G32: 주의
B33: 6 | C33: 오동건 | D33: 25 > 검열로 0 | E33: 리더는 어렵다. 명확한 지시를 내리지 않으면 내맘대로 안굴러간다. 역할 분담은 확실하게 해야 한다. 그리고 서로의 영역을 존중해야 한다. 결정을 내리는 위치 - 책임이 무겁다. | G33: 대기
B34: 6 | C34: 한재환 | D34: 12세이기 때문에 스토리에 난항을 겪고 다시 처음 기획부터 시작합니다. | E34: 소심한 성격을 고쳐야 합니다. | G34: 대기
B35: 6 | C35: 이형진 | D35: 50% 이상이었다가, 검열 이후 자신있는 서브컬처 종목으로 변경하였습니다. 대부분의 시간을 엔진 기능 구현에 사용하였기에, 기존에 만들어진 부분을 잘 활용한 후 시나리오와 리소스만 변경한다면 어려울 것 없을 것 같습니다. | E35: 어제 조금 어려운 방향으로 가고 있었는데 원만한 합의와 진행이 된 것 같습니다. 아쉽게 게임을 엎었지만, 오히려 모두가 잘 아는 서브컬쳐 게임으로 진행하는 오히려 좋은 상황이 된 것 같습니다. | G35: 대기
B36: 6 | C36: 조현일 | D36: 0.25 | E36: 시나리오 작업을 열중해서 했으나....0부터 다시 시작이네요. 그래도 금일 조원분들에게 엑셀이나 DB에 대해 배운것들이 있어 유익한 시간이 되었던거 같습니다. 감사합니다. | G36: 대기
B37: 6 | C37: 이균호 | D37: 0%. 수업 종료 직전에 내용이 엎어짐. 아주 기초적인 부분을 의논중임 | E37: 각자 역할에 맞춰 열심히 해줘서 일이 어느정도 진행되는 것을 보니 기분이 묘하다. 하지만 결과적으로 검열 때문에 게임 스토리와 스타일을 처음부터 갈아엎는 걸로 진행하게 되었다. 오늘 열심히 작업한 것이 아쉽지만 내일 더욱 노력해서 시간 내로 게임을 완성할 수 있도록 해야겠다. | G37: 대기
B38: 7 | C38: 김민제 | D38: 0.5 | E38: 포지셔닝 배분이 제일 어려웠다. 2명이서 스토리 짜는게 생각보다 힘들다... 머릿속의 정리가 잘 되면 좋겠는데.. 역량 부족인 것 같다 ㅠㅠ | G38: 대기
B39: 7 | C39: 강유민 | D39: 0.25 | E39: 팀 내 제작 방향 및 업무 분담을 진행했습니다. | G39: 대기
B40: 7 | C40: 강태성 | D40: 0.25 | E40: 팀원들의 의지가 시험받고 있습니다... 게임을 대부분 처음 만들다보니 컨셉 잡는데 시간을 많이 쓰고 있어요. 개인적인 소감으론, 제미나이가 생각보다 Lua 문법을 잘다루는군요 아주 좋습니다. | G40: 대기
B41: 7 | C41: 김지훈 | D41: 0.1 | E41: 높은 목표대비 진전이 안나갑니다 | G41: 대기
B42: 7 | C42: 고승주 | D42: 0.25 | E42: 역할을 나누는 것이 어려웠습니다. 진행하며 유동적으로 조율해야 할 것 같습니다. | G42: 대기
...

Sheet 0121
B2: 날짜 | C2: 46043
B4: 팀 | C4: 이름 | D4: 작업량 | E4: 한마디 | F4: 비고 | G4: 상태
B5: 1 | C5: 승정하 | D5: 1 | E5: 여러 파트 분들이 작업에 집중하시다 보니 소통이 2번 3번 해야 하는 상황 조금 생겼던 것 같습니다. 그래도 모든 분들이 감정적이지 않게 서로를 존중하는 모습으로 소통해주셔서 제가 조금 더 원할하게 소통할 수 있도록 조율하는게 그렇게 어렵지 않았던 것 같아서 팀원분들을 칭찬합니다. | G5: 대기
B6: 1 | C6: 정석현 | D6: 0.5 | E6: 소통 방식 정립, 리소스 취합 등 어느정도 프로젝트가 진행되고 있다는 느낌이 들었던 하루였다. 어제 구현했던 코드도 정상적으로 그룹 프로젝트에 적용했고 사운드 레퍼런스를 구체적으로 잡고 확장자 변경 프로그램을 확보하는 등 성과를 거두었다. 50%로 표기하긴 했지만 아직 할 일이 산더미같이 많다. 처음 해보는 작업 방식이기도 하고, 모르는 영역을 배워야 하기도 하다 보니 내가 맡은 바를 다 하기도 힘든 것 같다. 나 뿐만 아닌 우리 조, 다른 조의 모든 분들이 같은 마음으로 작업에 임하고 있을 것 같다. 그저 힘내자는 말 밖에 못 해주겠다... | G6: 대기
B7: 1 | C7: 곽용준 | D7: 0.5 | E7: 피드백을 적극적으로 받으려고 하고 있습니다 어제 했던 일들을 바탕으로 평가를 받는 시간을 가지고 개인적으로 했던 밤샘 작업들로 앞으로의 방향성도 잡았습니다 | G7: 대기
B8: 1 | C8: 정수진 | D8: 0.5 | E8: 엔진 코딩 구현하기 어렵습니다... | G8: 대기
B9: 1 | C9: 한의호 | G9: 대기
B10: 1 | C10: 이도건 | D10: 0.5 | E10: 처음에는 너무 복잡한 코드들, UI 작업들 이라는 생각이 들어 걱정이 많이 되었지만 계속 궁금한것을 팀원들과 나누고 서로 피드백하고 수정하며 점점 무엇인가 만들어지고 있다는 생각이 들었습니다. 앞으로도 열심히 해보겠습니다. | G10: 대기
B11: 2 | C11: 조준현 | D11: 0.15 | E11: 오늘은 선택지 선택에 따른 호감도 상승 감소를 체크하는 시스템과 초상화가 최대 3개까지 화면에 나오는 시스템을 구현했다. 이제 엔딩을 위해 호감도를 확인하고 엔딩의 id로 보내는 시스템을 만들면 된다. 초상화가 움직이거나 fade 관련의 연출을 해달라고 하는데 또 코드를 짜라고 할거 같다. | F11: [김상준] 어제 면담 진행한 인원입니다. 이번 프로젝트에서 개선하기는 힘들겠지만, 배워갈 점과 다음 프로젝트에 적용할 점에 대해 좀더 고민하겠다고 합니다. | G11: 주의
B12: 2 | C12: 장호윤 | D12: 30?퍼 35퍼? 정도 진행된 것 같습니다 | E12: 오늘도 검열을 피하지 못했습니다... 건전함을 향해서 열심히 전진해보도록 하겠습니다! | G12: 대기
B13: 2 | C13: 권수빈 | D13: 0.25 | E13: 시간 안에 끝낼 수 있을까요.... | G13: 대기
B14: 2 | C14: 예인해 | D14: 0.25 | E14: 검 열 싫 어 요 | G14: 주의
B15: 2 | C15: 우현승 | D15: 0.5 | E15: 다른 조 팀원을 통해서 로컬 i2i 활용 방법을 배우게 되었더니, 드디어 일러스트 개인 작업 진도가 나가기 시작했다. | G15: 대기
B16: 2 | C16: 김경민 | G16: 대기
B17: 3 | C17: 박영성 | D17: 1 | E17: 어제 자에 다들 AI한테 줄 레퍼런스가 덜 확보 된 상태에선 AI를 활용했을때 예상보다 시간을 몇배로 잡아먹었는데, 팀원분들이랑 제가 AI에 좀 익숙해지고 레퍼런스가 확보되니까 급속도로 속도가 붙은 것 같습니다. + 왜 실무에서 PD를 따로 빼는 직군으로 형성하는지 알겠습니다... 아트 디렉터 + PD + UI 작업 중인데 생각보다 살펴봐야하는 분야와 모멘텀이 잦아서 정신없이 움직이게 되는 것 같습니다 | G17: 대기
B18: 3 | C18: 맹지훈 | D18: 1 | E18: 안되면 그냥 빼자고 말하려던 연출과 시스템 고민없이 빼자고 말하려고, 관련 유형정리하고 대체안 생각해뒀는 데, 여기저기서 실현하는 거 보고 오늘 실수로 전체 채팅에 '오 주여'를 외쳤습니다. [분기 시스템, 캐릭터 표정 묘사] | G18: 대기
B19: 3 | C19: 손호진 | G19: 대기
B20: 3 | C20: 김흥규 | D20: 0.5 | E20: 사운드를 개별적으로 볼륨 조절하고 싶었는데 내 실력은 구현해내기 터무니 없는 실력이었다. 이제 개별 프로젝트에서 고친 내용을 그룹 프로젝트로 옮겨봐야 하는데 혹시나 잘 안 될까봐 걱정이다. 팀원들이 다들 각자의 자리에서 너무 잘하고 계셔서 더 걱정이다ㅜㅜ 화이팅! | G20: 대기
B21: 3 | C21: 김현우A | G21: 대기
B22: 3 | C22: 정재용 | G22: 대기
B23: 4 | C23: 이석훈 | G23: 대기
B24: 4 | C24: 이승구 | D24: 0.75 | E24: 프로토타입을 만든건 좋은 선택이었던 것 같습니다. 팀 내 이슈는 크게 없었고 개인적으로 어려웠던 점은 생성형 AI가 원하는 사이즈의 이미지를 지원하지 않아서 포토샵이 필요하게 되었습니다. | G24: 대기
B25: 4 | C25: 장근혁 | D25: 0.5 | E25: 알파테스트를 진행했는데 수정사항이 너무 많이 나왔다. | G25: 대기
B26: 4 | C26: 박민규 | D26: 0.75 | E26: 프로토타입 개발이 완료 되었으며 수정부분과 추가할 부분이 생겨 그것을 작업해야합니다 | G26: 대기
B27: 4 | C27: 서진호 | D27: 1 | E27: 팀 내 이슈 - 하나도 없었음 어려웠던 점 - 알파 버전을 만들기 위해서 리소스를 급하게 완성했고, 스토리의 부족함을 체감함 배운 점 - 일단 알파 버전(거의 프로토 타입)을 완성하고 서로 의견을 나누는 시간에서 배운 게 많았습니다. 스토리 적으로 어떤 부분이 부족했는지, 리소스적으로 어떤 부분이 부족했는지, 어떤 부분에서 버그가 발생헀는지에 대한 이야기를 할 수 있어서 좋았습니다 또한 아트팀이나 프로그래밍팀의 고충도 알 수 있었습니다 칭찬 - 다들 열심히 하시고 의견도 잘 주고받고 파충류가 되지 않으시고 정말 좋습니다 그리고 부족한 저를 많이 도와주셔서 정말 감사합니다 건의 - 없습니다 근황 토크 - 2조의 인해님과 현승님과 같이 AI와 관련해 의견을 주고받고 했었는데 배워가는 것도 많았고 제가 알려드린 눈차쿠도 잘 적용해서 이용 하신다고 하니 뿌듯했습니다 저희는 로컬 이미지를 거의 생성 안했지만.... 아무튼 좋았쓰 오늘 하루도 수고 많으셨습니다 | G27: 대기
B28: 5 | C28: 이정헌 | D28: 0.75 | E28: 전일보다 수월하게 진행되었던 것 같습니다. 계획을 조금 타이트하게 잡았음에도 계획의 대부분이 진행됐다고 생각합니다. 팀원간에도 의견조율간에 마찰이 없었고, 무난하게 잘 진행되었다고 생각합니다. 작업간에도 특정역할에 고정되지 않고 유기적으로 진행 되었던 점도 긍정적으로 판단합니다. 그럼에도 작업량에 100%를 하지 않은것은, 현재상태로는 출시할 수 없기에 프로토타입이더라도 출시할 수 있을 정도가 된 이후 부터 계획달성도에 따라 100%가 될 수도 있을 것 같습니다. | G28: 대기
B29: 5 | C29: 홍태광 | D29: 1 | E29: 서로가 같은 목표를 정했다 보니 생각보다 빠르게 나아갈 수 있는 것 같습니다. | G29: 대기
B30: 5 | C30: 박원우 | D30: 0.75 | E30: 매우 순항중입니다 | G30: 대기
B31: 5 | C31: 김민수 | D31: 0.75 | E31: 동시작업이 어려워서 구현간 언어가 겹치지 않을 수 있어 어려웠다. 태환님의 사운드 기술력이 엄청나셨습니다 | G31: 대기
B32: 5 | C32: 김태환 | D32: 1 | E32: 작업 안정화 첫날에 서두른 덕에 마감일보다 조금 더 빨리 완성할 수 있을 것 같음 | G32: 대기
B33: 6 | C33: 오동건 | D33: 0.5 | E33: 팀장인데 하는게 없는 것 같다。첫날에는 결정하고、 시키고 했지만 내 결정이 맞을까에 대해 계속 생각하니 자꾸 소극적이게 된다。차라리 팀원이면 시킨거 한거 하면 되는데。。。。 | F33: [양윤석] 자신감 심어주는 면담 필요해보입니다. -해결 완- | G33: 주의
B34: 6 | C34: 한재환 | D34: 연출 기획 담당인데, 붕 뜬 느낌이라, 0%인 것 같습니다. | E34: 다들 잘하고 제가 소심해서... 조에서 제가 너무 하는 것 없고 버스를 타는 것 같습니다. 그래서 내일부터 적극적으로 사운드 쪽을 어필해야 겠습니다. | G34: 주의
B35: 6 | C35: 이형진 | D35: 0.5 | E35: 내일 손만 쉬지 않는다면 무난히 완성할 수 있을 것 같습니다. AI의 발전이 정말 좋으면서도 제가 AI에게 설명을 잘 못하고, 학습된 데이터에 제가 원하는 장면이 없어 인체가 엉키거나, 일본의 배경으로 넘어가는 등 답답한 부분이 많았습니다. 그래도 간접적으로 게임 제작을 하는데 어떤 부분이 고려되어야 하고, DB의 실질적 활용을 해보니 시스템 기획이 얼마나 중요한지 다시 한 번 알게된 것 같습니다.. | G35: 대기
B36: 6 | C36: 조현일 | D36: 0.5 | E36: 연령 제한 이슈로 방향을 급선회 했지만 조원 분들이 모두 빠르게 적응하셔서 각자의 작업을 원활히 해주신 게 매우 인상적이었습니다. 금일 제가 한 시나리오 검수와 보완 작업이 다른 조원 분들이 하신 것보다 적어 보여 더욱 분발해야겠다는 생각이 듭니다. 감사합니다. | G36: 대기
B37: 6 | C37: 이균호 | D37: 0.5 | E37: 오늘은 어제 작업했던 부분을 다 버리고 새 게임을 만들기 시작했다. 미연시를 만드려고 하는데 각자 아이디어를 작성해서 가져와가지고 괜찮은 거를 뽑기로 했는데 내가 작성한 설정과 스토리 골조가 뽑혔다. 그래서 어제까지는 리소스 제작을 맡았지만 오늘은 내가 작성한 것이기 때문에 내가 시나리오를 맡으라고 PD님이 조율해주셨다. 생각 못해본 부분이었는데 조율해주신 덕분에 더 좋은 결과가 나올 수 있었다고 생각한다. | G37: 대기
B38: 7 | C38: 김민제 | D38: 0.25 | E38: 소통문제로 인해 아침에 좀 트러블이 있었다. | G38: 대기
B39: 7 | C39: 강유민 | D39: 0.5 | E39: 팀 내 이슈: 조장님과 일부 팀원 간의 마찰이 발생했습니다. 서로 소통에 있어서 불만을 제기했고 그걸 조율하기 위해 얘기를 서로 나누다가 저를 통해 중재하는 것으로 마무리가 되었습니다. 일단 표면적으로는 해결을 한 상황이나, 내적으로는 맡은 업무와 상대에 대한 아쉬움이 해소되지 않아서 프로젝트 기간 동안 지켜보며 잘 조율해보려고 합니다. 더 큰 문제로 이어지게 된다면 매니저님이나 강사님들께 도움을 요청 드리겠습니다. 관계가 나아질 수 있을거라 생각하며, 이번 프로젝트 열심히 해보겠습니다. | F39: [양윤석] 내일 면담 진행하고자 합니다 김지훈과 있었던 트러블입니다. 양쪽 의견을 들어봐야 정확한 진단을 할거같습니다 | G39: 주의
B40: 7 | C40: 강태성 | D40: 0.5 | E40: 초반에 다들 많이 혼란스러웠던 모양인지, 분위기가 심상치 않긴 했습니다. 솔직히 그럴만해요. 컨셉 기획도 제대로 잡히지 않은데다 시스템 기획은 아무도 손대고 있지 않았거든요. 연출적인 부분을 개발할 수 있도록 디렉션이 있었음 좋겠지만, 어쩌겠습니까. 그게 삶인거죠. 일단은 이 툴을 그럴듯하게 다듬는데 집중해야겠어요. 타이핑 효과랑 세이브 슬롯 구현한 것으로 만족합니다. - DateTime에 지역 시간 변환도 없는 언어로 프로그래밍을 하고 있는 건에 대하여 | G40: 대기
B41: 7 | C41: 김지훈 | G41: 대기
B42: 7 | C42: 고승주 | D42: 0.5 | E42: 역할 분담이 역시 어려운 것 같습니다. | G42: 대기
...

Sheet 0122
B2: 날짜 | C2: 46044
B4: 팀 | C4: 이름 | D4: 작업량 | E4: 한마디 | F4: 비고 | G4: 상태
B5: 1 | C5: 승정하 | D5: 1 | E5: 특정 파트가 진행도가 조금 더뎌지는 부분이 생겼습니다. 이 부분에 대해서 팀적으로 공유가 되었지만 그 시점이 기존 목표치 달성이 가능하게 도움을 주기에는 늦어버렸습니다. 진행이 빠른 타 파트 담당자들이 서포팅을 해주셔서 기존 목표치를 어느정도는 채울 수 있게 되었지만 PD이자 PM으로서 정기적으로 진행도를 확인하는 정도 vs 자율적인 작업 속도나 작업량에 대한 신뢰간의 균형을 잡기가 생각보다 어렵다는 생각이 들었습니다. 팀적인 소통이 아직 서툰 팀원분들을 위해 조금 더 적극적이고 섬세하게 작업 속도와 현황에 대한 소통 환경을 조성해야겠다는 생각이 들었습니다. | G5: 대기
B6: 1 | C6: 정석현 | D6: 담당 외 업무 진행, 작업 방식 변경 | E6: 오늘은 사운드 리소스를 잠시 내려놓고 기획서 검토 및 수정사항 기록에 역할을 할당했다. 3일이라는 시간이 정말 쏜살같이 지나가버렸다. 내일 게임을 구동하며 QA를 진행하기 전에 추가해야할 리소스도 남아있고, 아마 QA가 진행되면 또 해야할 일이 쌓일 것 같다. 다행히 주말에 스케줄이 없다! 화이팅! | G6: 대기
B7: 1 | C7: 곽용준 | D7: 0.75 | E7: 리소스 생성 작업량이 캐릭터 12개, 배경 5개가 남았다 밤샘 작업을 하여야 할 것 같다 | G7: 대기
B8: 1 | C8: 정수진 | G8: 대기
B9: 1 | C9: 한의호 | D9: 0.5 | E9: 생각보다 작업 진행 속도가 더뎌져서 조금 서둘러야 할 것 같습니다. | G9: 대기
B10: 1 | C10: 이도건 | D10: 0.75 | E10: 팀원 모두 짧은 시간이지만 6시 이후 늦게 까지 본인 할당량을 맡아주고 팀원의 작업이 좀 어려워보인다고 느낀다면 모두 솔선수범해서 도와주려고 해서 감사했습니다. 앞으로 또 같이 열심히 마무리하겠습니다. | G10: 대기
B11: 2 | C11: 조준현 | D11: 0.25 | E11: 아직도 데이터 테이블이 대사도 완료되지 않았다...언제 넣고 파일명 알려줘서 이미지를 채우고 코드상에 분기점 별로 점수 부여하는 아이디를 써넣을까...첫날부터 강조한 목요일 오전까지는 무조건 데이터 테이블이 완성되야 한다는 말을 분명 팀 문서 1페이지 첫줄에 써두고 강조까지 했는데... 눈앞이 캄캄해졋다.. | G11: 대기
B12: 2 | C12: 장호윤 | D12: 0.75 | E12: 코인이 모자랍니다... 더 많은 그림... 더 많은 그림을 뽑아야해요... | G12: 대기
B13: 2 | C13: 권수빈 | D13: 0.75 | E13: 새벽 4시까지 작업했습니다. 살려주세요. | G13: 대기
B14: 2 | C14: 예인해 | D14: 1 | E14: 욕심과 현실의 줄타기가 어려운거 같습니다. 목표 분량과 실제 수행 가능 분량이 분리되어 있다보니... | G14: 대기
B15: 2 | C15: 우현승 | D15: 0.75 | E15: 기본 스탠딩 일러스트를 어느정도 마무리 했다. 처음 진행은 대사 스크립트에 필요한 표정과 자세를 확인 후 생성하는 방식이었는데, 생각보다 결과물이 만족스럽지 않아서 마지막에 다양한 표정을 미리 만들어놓고 선택하는 방식으로 변경이 되었다. | G15: 대기
B16: 2 | C16: 김경민 | G16: 대기
B17: 3 | C17: 박영성 | D17: 0.75 | E17: 부서 간의 업무 속도 차이가 나고, 어딘가는 일이 과중 되는데 어딘가는 필수적인 일이 마무리 되어가는 상황에서 혼선을 크게 겪게 되는 것 같습니다. 이럴수록 소통도 점점 빈약해지고 요청사항이 오갈때 오류가 나타나고 있는데 PD로서 이 문제는 고민 해 봐야 할 것 같습니다. | G17: 대기
B18: 3 | C18: 맹지훈 | D18: 1 | E18: 프로토타입을 보는 데 스크립트 구분을 너무 세세하게 했나 걱정입니다. 팀원분들한테 스토리 수정할 부분 있으면 말씀해달라 했습니다. | G18: 대기
B19: 3 | C19: 손호진 | D19: 0.5 | E19: 이제 게임에서 사용할 기능들은 전부 다 검사까지 끝내서 사용할 수 있게 했기 때문에, 가장 중요한 스토리 테이블에 스토리를 넣는 일만 남았습니다. 일정 내로 맞춰서 완성 또한 중요하기 때문에 남은 마지막 날까지 열심히 해보겠습니다. | G19: 대기
B20: 3 | C20: 김흥규 | D20: 0.5 | E20: 이미지의 해상도 깨짐이나 여러 가지 문제 등으로 리소스를 넣어 완성하기 전까지는 걱정이 많이 됐는데 막상 1챕터를 만들고 나보니 생각보다 괜찮아서 조금 안도감이 들었다. 이제 화면 특수효과 같은 거나 게임 종료 시 자연스럽게 만들어가게 해놓으면 잘 끝낼 수 있을 거 같다. | G20: 대기
B21: 3 | C21: 김현우A | G21: 대기
B22: 3 | C22: 정재용 | D22: 0.75 | E22: 오늘 제작한 게임 첫 파트 플레이를 해봤는데 재밌어요 | G22: 대기
B23: 4 | C23: 이석훈 | G23: 대기
B24: 4 | C24: 이승구 | D24: 0.75 | E24: 창작의 고통-! | G24: 대기
B25: 4 | C25: 장근혁 | D25: 0.75 | E25: 모든것이 수월하다 | G25: 대기
B26: 4 | C26: 박민규 | D26: 베타버전 출시후 마지막 공정들어갑니다! | E26: 팀 활동이 너무 즐겁습니다! | G26: 대기
B27: 4 | C27: 서진호 | D27: 1 | E27: 오늘도 구현 요청을 하신 것은 다 했습니다 게임 내용 1~3일차도 거의 90%정도는 구현했고 중간중간 오류를 잡으면 되고 내일까진 어찌저찌 QA까지 해서 준비가 될 것 같은데 발표 준비까지 진행이 가능할진 모르겠지만 힘내보겠습니다 오늘 하루도 고생 하셨어요 (특히 검열이슈...ㅋㅋㅋㅋㅋ) | G27: 대기
B28: 5 | C28: 이정헌 | D28: 0.5 | E28: 예상했던 계획만큼은 진행하지 못했던 것 같습니다. 비주얼노벨장르 특성상, 시나리오의 비중이 크고 작업이 선행되어야 이후 작업이 원활해지는 듯 했는데, 시나리오 작업간에 진척이 빠르게 진행되지는 않았던 점과, 작업자의 작업 완성도에 대한 욕심이 전체 지연으로 이어지는 부분에 대해서 원활한 설득을 진행하는 것이 어려웠던 것 같습니다. 감정을 상하지 않게 말하는 것과 '반드시' 설득해야 하는 상황에서 어떻게 잘 해야 하느냐가 정말 어려웠던 것 같습니다. 작업계획에 대해서도 일정을 일부러 타이트하게 잡긴했지만, 생각보다 계획대로 진행되기가 힘들었던 것 같습니다. | G28: 대기
B29: 5 | C29: 홍태광 | D29: 0.75 | E29: 스토리 설정을 명확하게 정해놓지 않고 시작하다보니 이와 관련한 의견충돌이 있었습니다. | F29: [김상준] 엔딩 시나리오에 대한 방향성 차이가 있었는데, 이정헌이 잘 중재했다고 합니다. | G29: 주의
B30: 5 | C30: 박원우 | D30: 1 | E30: 구현하고자 하는건 전부구현하였고 내일 디테일작업만 들어가면 좋은데 요즘 초등학생컷이 높아서 죽을것 같습니다. 오류 수정 어떻게하는지.. | G30: 대기
B31: 5 | C31: 김민수 | G31: 대기
B32: 5 | C32: 김태환 | D32: 1 | E32: 주말까지 프로젝트가 넘어가지는 않을 것 같아 다행입니다. | G32: 대기
B33: 6 | C33: 오동건 | D33: 0.75 | E33: 오늘은 순조로웠다. 내 할일 제대로 한 느낌. | G33: 대기
B34: 6 | C34: 한재환 | D34: 0.5 | E34: 많이 부족함을 느끼는 중입니다. 특히 의사소통 부분에서 미숙한 부분이 많다고 느끼는 중입니다. | G34: 대기
B35: 6 | C35: 이형진 | D35: 0.75 | E35: 이제 알맞은 RUID만 집어넣고, QA하면 마무리 됩니다! 야근을 더 하고 싶은데, 규칙이 야근 금지라 더 손보지 못하는게 아쉽네요.. | G35: 대기
B36: 6 | C36: 조현일 | D36: 0.75 | E36: 금일은 시나리오 담당에서 시나리오 검수와 캐릭터 리소스 제작을 담당하니 시간이 배로 순삭 되는 거 같습니다. 동시에 하나씩 배워가는 점이 있어 유익하다고 생각합니다. 감사합니다. | G36: 대기
B37: 6 | C37: 이균호 | D37: 0.75 | E37: 게임 하나 만드는데 어떤 작업이 필요할지 정확히 모르고 하면서 파악해나가다 보니까 작업의 틀이 안 갖춰져있는게 얼마나 비효율적인 건지 알게되었습니다. 작업의 틀, 데이터입력 규칙 등등 하나하나 모두가 다 동일하게 약속한 게 없다보니 소통하는데 오류가 많이 생기고 또 그 오류를 고치는데 시간이 많이 허비되었습니다. 이번에야 짧은 프로젝트니 그렇다치더라도 다음에 장기 프로젝트를 한다면 이런 공통된 약속을 꼭 만들고 시작해야겠다고 생각했습니다. | G37: 대기
B38: 7 | C38: 김민제 | D38: 0.5 | E38: 가뜩이나 5명으로 시잗했는데 이제 거의 4명이 되어 상당히 버겁습니다... 타협의 때가 온 것 같습니다 | G38: 주의
B39: 7 | C39: 강유민 | D39: 0.75 | E39: 팀 내 이슈: 무사고 1일차 유지가 꽤 어렵네요. | G39: 대기
B40: 7 | C40: 강태성 | D40: 0.6 | E40: 늦었다아아앗 | G40: 대기
B41: 7 | C41: 김지훈 | G41: 대기
B42: 7 | C42: 고승주 | D42: 0.75 | E42: 각자 맡은 일을 성실하게 해내서 좋았습니다. | G42: 대기
...

Sheet 0123
B2: 날짜 | C2: 46045
B4: 팀 | C4: 이름 | D4: 작업량 | E4: 한마디 | F4: 비고 | G4: 상태
B5: 1 | C5: 승정하 | D5: 0.75 | E5: 시나리오 분량이 생각보다 많아져서 전체적인 완성도는 높아졋지만 개발 진행도가 조금 늦춰졌습니다. 그래도 마지막 날인만큼 이전 작업일들보다 협업이나 작업 속도등이 많이 좋아져서 정규 작업 기간에 초기 프로토 타입 구동까지 완료했습니다. 대부분의 기능이 잘 작동해서 약간의 디버깅과 세부 리소스 조정만 남겨놓고 있습니다. 아직 정식 출시 전이지만 팀원 모두 결과물을 보면서 보람과 설렘을 느꼈던 오늘 하루 마무리 였습니다. 발표와 개발 마무리까지 화이팅! | G5: 대기
B6: 1 | C6: 정석현 | D6: 0.75 | E6: 역시 주말 작업은 피할 수 없었다. 그래도 테스트 해보는 것 까진 성공했다. 나온 화면 토대로 추가 사운드 리소스를 추가하기만 하면 될 것 같다. 진짜 싸움은 지금부터 시작이다. 조원분들 모두 능력있고 활발한 소통이 가능했어서 작업 진행에 문제가 있진 않았지만, 리소스 양이 방대해져서 작업량이 많아진 것이 문제였던 것 같다. 프로젝트 관리 면에서도 많은 부분을 배웠다. 조금만 더 하면 끝나니 조금만 더 힘내자... | G6: 대기
B7: 1 | C7: 곽용준 | D7: 1 | E7: 새벽 7시까지 진행하여서 2시간 수면 후 일어났습니다 놀랍게도 감자가 되지 않았습니다 새벽동안 열심히 해서 그런지 꽤 시간이 남았기에 기획서를 쓸 시간이 생겼습니다 여러므로 좋은 경험이었지만 아무래도 쿨타임이라는게 존재해야 할 것 같기에... 밤샘 작업을 자주 하지는 않아도 가끔? 하는 건 괜찮은 것 같습니다 | G7: 대기
B8: 1 | C8: 정수진 | D8: 0.75 | E8: 시간이 촉박해서 주말까지 활용해야할거같습니다.. | G8: 대기
B9: 1 | C9: 한의호 | D9: 0.75 | E9: 시나리오 연출 작성을 빨리 했어야 하는데 늦어진 것 같아서 팀원 분들께 송구스럽기 그지 없었습니다;; | G9: 대기
B10: 1 | C10: 이도건 | D10: 0.9 | E10: 마지막 날이어서 약간 촉박한 감이 없지 않아 있었지만 다들 열심히 작업해주어 현재는 첫 구동을 하고 있습니다. 마치 같이 만든 영화를 보는 느낌이 있기도 하고 내가 만든 UI가 반영되어 있는 걸 보니 신기하기도 하고 걱정도 되고 그럽니다. 다음주 발표때까지 또 마무리 작업하고 완성하겠습니다. | G10: 대기
B11: 2 | C11: 조준현 | D11: 1 | E11: 코드 구현 다했더니 ppt를 해야한다 주말에 할게 너무 많다.... | G11: 대기
B12: 2 | C12: 장호윤 | D12: 100%를 향해서... | E12: 끝나기 전까지 끝난게 아닙니다 진짜 안끝났다는게 너무 슬퍼요 | G12: 대기
B13: 2 | C13: 권수빈 | D13: 0.5 | E13: 주말 비상입니다. | G13: 대기
B14: 2 | C14: 예인해 | D14: 1 | E14: 처음 목표는 무조건 소박하게 잡아야 한다는 것을 뼈져리게 느끼고 있습니다... | G14: 대기
B15: 2 | C15: 우현승 | D15: 0.75 | E15: 스탠딩 일러스트들 마무리하고, bgm을 선정하기 시작했다. 게임 플레이타임이 짧아서 전개가 빠른 편이라 어떻게 적절하게 배치해야하는지 고민을 했던것같다. | G15: 대기
B16: 2 | C16: 김경민 | G16: 대기
B17: 3 | C17: 박영성 | D17: 0.5 | E17: 프로그래밍이란게 이해도가 없는 PD(저 자신입니다...) 측에서 일정 관리를 하니까 변수가 터지는 것에 대해서 일정 계산이 취약한 감이 큰것 같습니다. 그만큼 코딩 팀이랑 면밀하게 소통이 되어야 했었는데, 그러지 못해서 제한 시간 내 프로젝트가 마무리 되지 않고 추가 작업 시간을 할애애야 하는 상황을 만든게 죄송스러웠습니다. 제가 잘 모르는 분야일수록 더 면밀하게 소통할 필요가 있다는 것을 느낄 수 있었습니다. 또 특장점 하나 없는 PD를 존중해주고 적극적으로 임해주신 3조 여러분 모두에게 너무 감사합니다.... | G17: 대기
B18: 3 | C18: 맹지훈 | D18: 0.75 | E18: 음향 리소스를 코드로 입력해야한다는 것을 간과하고 시나리오 및 BGM연출을 작성한 것에 대해 엔진분께 죄송한 날이었습니다. 마케팅 과정 - 팀원이 제약사항만 반복적으로 얘기하는 경우 (진행의 도돌이 표 발생) 어떤 흐름으로 대화해야할지를 좀 더 고민해봐야 겠습니다. | G18: 대기
B19: 3 | C19: 손호진 | D19: 0.75 | E19: 조금 더 잘했으면 시간 내에 잘 마무리 될 수 있을 것 같은데, 약간 진도가 나가지 않아 예정보다 더 오래 하게 되었습니다. 이번 일을 잘 생각하면서 다음에는 어떻게 조율을 해나가야 할지에 대한 고민을 해봐야겠습니다. | G19: 대기
B20: 3 | C20: 김흥규 | D20: 0.75 | E20: 어... 팀원분들 죄송합니다. 코드가 꼬여서 세이브를 제대로 구현하지 못했네요. 사과드리긴 했지만 제 자신에게 너무 실망했습니다. 흐윽흐윽ㅜㅜ 3조 팀원분들 진짜 너무 좋았습니다 | G20: 대기
B21: 3 | C21: 김현우A | G21: 대기
B22: 3 | C22: 정재용 | D22: 0.75 | E22: 다들 지금까지 한 사람도 빠짐 없이 의견을 내주셨고, 그 의견도 수용하며 프로젝트를 진행했습니다. 물론 프로젝트 기한에 맞추진 못했고 오늘도 늦게 까지 남아있어야 하고 내일도 아마 이어서 진행해야 할 것 같지만 그래도 제가 기획에 참여하고 만든 게임이 작동되는 것을 보면 무언가 뿌듯함이 남아 있습니다. | G22: 대기
B23: 4 | C23: 이석훈 | G23: 대기
B24: 4 | C24: 이승구 | D24: 1 | E24: 1. 팀 내 이슈 작업물 관리가 제대로 되지 않아 누락되거나 파일 이름이 다른 등 프로그래밍 담당자가 작업하기 매우 힘든 형태로 관리 됨 2. 칭찬 : 진호님 커피 사주기 3. 건의 휴가 일정이 잡힌 인원 때문에 4인이 작업해야 하는 어려움이 있었습니다 오늘 발생한 팀 내 이슈 또한 전체를 보고 관리하는 역할 때문에 생긴 일이라고 생각이드네요! 앞으로의 프로젝트에서 휴가가 잡힌 팀원이 있고 ,이에 대해 운영진 측과 공유가 되었다면 저희조는5인 다른조는 6인인 곳이 있다고 들었는데 휴가 인원 포함 조는 6인으로 배정되길 건의드립니다. 4. 개인적 이슈 다음에는 석훈님과 같은 조가 되고 싶지 않습니다. 오히려 휴가 다녀오셔서 다행이라고 생각합니다. 사유1. 잘 모르는데 뭐든지 아는 것 처럼 이야기 함, 사실 아무것도 모름... 일을 안 해본 티가 많이 남 적극적인게 아니라 자기가 주인공이 되는 것을 즐기는 것 같아 보임 사유2. 작업을 하기를 꺼려하고 상황만 통제하길 원함, 작업물을 맡기면 책임감 있게 작업하는 것이 아닌 미루거나 어떻게 해야 할지 모르겠다 이렇게 할 필요가 없다는 등 핑계를 대고 일을 맡기고 시간이 지난 뒤 작업물에 대해 물어보면 어떻게 하는지 몰라서 안하고 있었다, 아까 이야기했는데 못 들었냐 등의 핑계를 댐, 정상적인 사람이라면 이야기 했을 때 이야기를 잘 들었는지 확인하는데 항상 혼잣말로 중얼거리시고 이야기 했다고 착각하심. 사유3. 팀원에 대한 배려 없이 필터링을 거치지 않거나 생각을 정리해서 말하는 것이 아닌 떠오르는대로만 이야기 해서 듣는 입장에서 무슨 말을 하는 건지 도통 알아먹을수가 없음. 본인만 그렇게 느끼는 걸 수는 있으니 다른 팀원들의 의견도 궁금함, 굳이 이런 내용을 공유하면서 정치질 하고 싶지는 않아요 사유4. 역량에 비해 자존심이 지나치게 강함, 누군가 반대 의견을 내거나 자신과 다른 의견을 대면 개인적으로 생각했을 때 말도 안되는 사유를 들며 반대하거나 정상적인 사람이라면 이해가 되게끔 설명했음에도 뜻을 굽히지 않음, 결말이 "나는 이해가 안되지만 여러분들이 그렇게 생각하면 그렇게 해라" 식 사유5. 운영진이 보고 있을 때 상황을 주도하는 것처럼 보이고 싶어함, 기획서가 필요하다고 초반에 이야기 했음에도 이번 과제는 기획하는게 아니라 경험하는게 목표라서 필요 없다고 해놓고 끝날 때 와서 필요하다고 강사님께서 짚어주셨을 때, 여기에 대해 제가 이야기를 꺼냄 > 운영매니저님이 계실 때 이야기를 했더니 기획서 없는걸 운영 매니저님 앞에서 말하면 안된다는 식으로 메시지를 함, 무슨 심리인지 궁금함; 꿀밤 마려웠습니다. :) 사유6. 기본적인 참여 태도가 불량함, 캠, 마이크 정해진 시간에 안 키는 경우가 많으며 캠 킬 때는 다른 것에 몰두하고 있는지 팀원 모두 이야기 한 내용에 대해서 혼자만 모르고 있는 경우가 있음, 사람마다 과제에 중요도를 판단하는 정도는 다르기 때문에 적극적 참여는 어려울 수 있으나 기본적인 해야 할 작업의무조차 지키지 않고 분위기를 흐림 징징거려서 죄송하다고 생각하지만 만약 석훈님이 조금 소극적인 팀원이나 아직 사회생활을 하지 못한 분들과 팀원이 된다면 어떤 일이 발생할지 가늠이 안가고, 그 분들이 가스라이팅 당하거나 자신있게 말하는 모습에 맞다고 생각하면서 받을 피해가 더욱 안타까움, 그렇다고 본인이 석훈님과 같은 조가 되고싶은 생각도 없기에 말씀드립니다. 긴 글 읽어주셔서 감사합니다. 행복한 주말 보내세요 ~_~ | G24: 비상
B25: 4 | C25: 장근혁 | D25: 1 | E25: 모오든게 순조롭게 진행이 되었다 99.99999완성 | G25: 대기
B26: 4 | C26: 박민규 | D26: 다 완성되었지만 프로그램 부분을 담당 하신 분이 추가 하고 싶은 것이 있다고 하여 추가 작업이 있을 예정입니다. | E26: 오늘 중간 회의가 있었을 때 특정 인원이 다른 조원의 도움요청을 그저 모른다고 답하며 거부하였고 자기 의견만 피력해서 분위기가 가열된적이 있었습니다. | G26: 주의
B27: 4 | C27: 서진호 | D27: 1 | E27: 팀 내 이슈는 생략하도록 하겠습니다 1. 플레이가 가능한 정도로 99.99% 완성했습니다 2. 나머지 디테일한 부분은 주말에 채우고, 월요일에 릴리즈 할 수 있도록 준비 하겠습니다 3. 팀원 여러분 정말 수고 많으셨습니다! | G27: 대기
B28: 5 | C28: 이정헌 | D28: 1 | E28: 막연하게 이렇게 하면 되겠지 생각했는데, 인원관리나 일정관리, 진행등에 대해서 쉽게만 진행되진 않았던 것 같습니다. 작업자들의 열의는 좋지만 기간내 완성을 고려하여서, 잘 설득하여 반려하는 것에 대해 상처주지 않고 설득하는 좋은 방법이 있을까에 대해 고민이 있었습니다. 그래도 이번 한 과정을 통해서 다음번에는 어떻게 해야 더 잘 할 수 있을지 좋은 경험이었던 것 같습니다. | G28: 대기
B29: 5 | C29: 홍태광 | D29: 1 | E29: 스토리 부분 신입을 뽑지 않는 이유를 이번에 배우게 되었습니다... | G29: 대기
B30: 5 | C30: 박원우 | D30: 1 | E30: 5팀 다들 고생많으셨습니다!! | G30: 대기
B31: 5 | C31: 김민수 | D31: 1 | E31: 팀활동 경험이 많지만 제대로 하나를 완성해본 경험은 적어서 너무 좋은 경험이라고 생각했습니다 다만 모든 갈등을 4일 만에 겪은 기분입니다 좋은 수업 감사합니다 | F31: [김상준] 그냥 팀 작업간에 일반적으로 생기는 갈등정도였으며, 분위기 좋다고 합니다. | G31: 주의
B32: 5 | C32: 김태환 | D32: 1 | E32: 시간내에 완성해서 좋아요~ | G32: 대기
B33: 6 | C33: 오동건 | G33: 대기
B34: 6 | C34: 한재환 | D34: 1 | E34: 이 프로젝트를 통해, 제가 뭐가 부족한지, 무엇이 문제인지 알 수 있어 확실히 좋았습니다. 이후에는 이 단점을 해결해보도록 하겠습니다. | G34: 대기
B35: 6 | C35: 이형진 | G35: 대기
B36: 6 | C36: 조현일 | D36: 1 | E36: 이번에 팀 프로젝트를 하며 조원분들에게서 배우는 점들이 여럿 있었다고 생각합니다. 더욱 유기적인 기획자가 되도록 노력하겠습니다. 감사합니다 | G36: 대기
B37: 6 | C37: 이균호 | D37: 1 | E37: 예상치 못한 일이 많이 생겨서 뭔가 더 추가적인 일은 못했지만 그래도 우당탕탕하며 어떻게든 목표했던 부분을 작업 완료했다. 정말 계획대로 된 게 하나도 없었고 작업 파이프라인을 확실하게 잡아놓는 것이 중요하다는 것을 배울 수 있었다. 다음 프로젝트에서는 성장하여 좀 덜 우당탕탕하면서 만들 수 있기를 희망한다. | G37: 대기
B38: 7 | C38: 김민제 | D38: 0.75 | E38: 4명 정예가 되었지만 끝이 보입니다. pd로서 부족한 점이 많지만 너무 잘 이해해주시고 따라와주셔서 감사하고 있습니다. | G38: 대기
B39: 7 | C39: 강유민 | D39: 90%! | E39: 프로젝트 마지막 날인데 진행하는 동안 부끄러운 모습들을 많이 보인 것 같아 죄송합니다. 첫 단추를 어떻게 꿰었어야 했던 것일까 생각해보게 되는데... 참 쉽지 않네요. 잘 해쳐나가겠습니다. | G39: 대기
B40: 7 | C40: 강태성 | D40: 0.9 | E40: 살려주세요데이터테이블에사람있어요아니왜UID같은걸집어넣어가지고보기도불편한데ㅔㅔㅔㅔ데이터시트구분하기도너무귀차ㅏㅏㅏㅏㅏㅏㅏㅏㅏ809b46f0d4f343a699e6113d32cbe59666d2ba4157274ceb9622826837e2c08dc5c7134b3655486ca028deeed0b28d23c48ef7fe9e0940e99349512858d146ded4843763d1b54da69857d199ea43ae385d04b0de4eaf4af3849b24fb7482f36fce2558a346c74cada1b65e68175d1863 | F40: [김상준] ? | G40: 양호
B41: 7 | C41: 김지훈 | G41: 대기
B42: 7 | C42: 고승주 | G42: 대기
...
