Workbook

Sheet 설문지 응답 시트1
A1: 타임스탬프 | B1: 이메일 주소 | C1: 이름 | D1: 소속 팀 | E1: 작성 날짜 | F1: 오늘의 작업 이력 | G1: 자유로운 한마디
A3: 46066.747 | B3: dt8922dt8922@gmail.com | C3: 오동건 | D3: 9팀 | E3: 46066 | F3: # 2/13 1. 목표 1. 두개의 미니게임 기획서 작성하기 2. 결과 1. 두개의 미니게임 기획서 작성 완료, HTML로 30% 구현 | G3: 3. 다음 시간 1. 구현 가능한지 확인 후 수정 필요. MSW로 구현 불가능할 수 있음 2. 애매하면 그날 엎고 다시 만들기 미니게임을 구상하는데, 볼륨이 좀 크고, 너무 내 의도가 많이 들어간 것 같다. 그냥 엄청 간단한, 미니게임 다운 미니게임으로 다시 바꿀까 싶기도 하다. 근데 그러면 그냥 흔한 어디에나 있는 게임과 똑같아 질 것 같아서 볼륨이 커졌는데, 간단하지만 획기적인 시스템을 구상해 봐야 할 것 같다. 사실 원래 하고 싶었던거는 대작을 만들고 싶어서 그런거 같은데 자아를 좀 죽여야겠다.
A4: 46066.747 | B4: cjsdudgus1@gmail.com | C4: 천영현 | D4: 11팀 | E4: 46066 | F4: 게임 선정, 역할 배분, 캐릭터 설정 | G4: 너무 잘 맞아요~
A5: 46066.747 | B5: spiderjocker@gmail.com | C5: 박민규 | D5: 9팀 | E5: 46066 | F5: 메이플 월드로 만들 게임의 전체적인 기획서와 개인이 만들어야할 미니게임 2가지 기획서와 게임을 만들었습니다, | G5: 저희 절대로 부정출발 아닙니다!!
A6: 46066.747 | B6: gimyungyu9@gmail.com | C6: 김윤규 | D6: 6팀 | E6: 46066 | F6: 챕터 1 시나리오 완성, 시나리오 계획서 작성 | G6: 팀원들이 너무 좋아요...각자 할 일도 너무 잘하시고 책임감도 있으셔서 작업이 너무 수월합니다. 팀장님 뿐 아니라 조원들의 단합력도 너무 좋아서 작업이 재밌습니다...ㅎㅎ
A7: 46066.747 | B7: jechy0514@gmail.com | C7: 장호윤 | D7: 8팀 | E7: 46066 | F7: 컨셉 회의, 각자 일 지정, 시나리오 작업, UI 디자인 기획, 레퍼런스 이미지 작업 | G7: 연휴에도 작업 렛츠고~
A8: 46066.747 | B8: baoo88000@gmail.com | C8: 김태훈 | D8: 6팀 | E8: 46066 | F8: 엔진에서의 기능 구현 : 캐릭터의 움직임 애니메이션, 마우스 커서에 따른 방향 변화, 마우스 커서에 따른 무기의 각도 변화, 마우스 커서 이미지 교체, 총알 발사 | G8: mlua프로그래밍 하는 거보다 엔진내부기능 쓰는게 더 어려운 것 같습니다...
A9: 46066.747 | B9: reals2006n@gmail.com | C9: 오종호 | D9: 4팀 | E9: 46066 | F9: 메인캐릭터 스프라이트 제작, 상점 캐릭터 제작, 캐릭터 컨셉 제작 | G9: 리소스 만들기 힘듭니다.
A10: 46066.747 | B10: gustlrdn3@gmail.com | C10: 김현우B | D10: 13팀 | E10: 46066 | F10: 다같이 게임의 핵심과 방향 및 기획서 초안 작성 | G10: 게임의 대한 재미를 정하는게 힘들었지만 다들 적극적인 의견으로 다양하게 들었습니다.
A11: 46066.747 | B11: dlehalssla@gmail.com | C11: 이도민 | D11: 9팀 | E11: 46066 | F11: 미니 게임 : 오래 살아남기 기획서 & Html 게임 제작 완료 | G11: 난이도 조절 실패 / 새롭게 추가한 아이템 요소 관련 버그 / 추가 예상치 못한 버그
A12: 46066.747 | B12: zeno9758@gmail.com | C12: 신석균 | D12: 13팀 | E12: 46066 | F12: 초안 기획서를 제작하였다. | G12: 전체적인 방향성을 잡는데 생각보다 오랜 시간이 걸렸으며 많은 방황을 하였다. 팀의 방향을 잡는 게 전혀 쉽지 않다는 것을 다시 한 번 느꼈다.
A13: 46066.747 | B13: cowlgud9888@gmail.com | C13: 채지형 | D13: 7팀 | E13: 46066 | F13: 캐릭터, 스테이지, 적관련 레벨, 벨런스 데이터 테이블 작성? mlua 만져보기(오류만뜨고 연동안됨) | G13: 너무 어렵습니다.
A14: 46066.747 | B14: tarrot00@gmail.com | C14: 김수환 | D14: 1팀 | E14: 46066 | F14: 아이템 드랍 시스템 기획서를 제작 및 장비, 타일 드랍과 관련한 의견을 공유하였습니다. | G14: 이제 프로젝트가 시작되어 앞으로 열심히 프로젝트를 진행해보겠습니다.
... A481: 46080.785 | B481: eogks3681@gmail.com | C481: 김재환 | D481: 8팀 | E481: 46080 | F481: 열심히 발표를 듣기만 했습니다 (왜 메모를 하지 않은 거야 바보야 상태입니다) | G481: 무사히 프로젝트가 끝나서 다행입니다 수고하셨습니다

Sheet Base
B2: 날짜 | C2: 46042
B4: 팀 | C4: 이름 | D4: 작업량 | E4: 한마디 | F4: 비고 | G4: 상태
B5: 1 | C5: 이승구 | G5: 대기
B6: 1 | C6: 김경민 | G6: 대기
B7: 1 | C7: 김수환 | G7: 대기
B8: 1 | C8: 박영성 | G8: 대기
B9: 1 | C9: 유해찬 | G9: 대기
B10: 1 | C10: 한의호 | G10: 대기
B11: 2 | C11: 김범진 | G11: 대기
B12: 2 | C12: 박현수 | G12: 대기
B13: 2 | C13: 이균호 | G13: 대기
B14: 2 | C14: 이석훈 | G14: 대기
B15: 2 | C15: 손호진 | G15: 대기
B16: 2 | C16: 정재용 | G16: 대기
... B82: 14 | C82: 홍태광 | G82: 대기

Sheet 종합
B2: 데일리 체크인 종합 시트
B4: - 데일리 체크인 작성이 결국 개인 성실성과 과정 신뢰도, 과정 운영의 지시를 따르는 지표가 될 것으로 보입니다. - 작성의 판단 기준은 당일 오후 5:00 ~ 다음날 오전 9:00 까지 작성된 데이터를 기준으로 판단합니다.
B6: 팀 | C6: 이름 | D6: 미작성 횟수 | E6: 응답 비율 | F6: 46066 | G6: 46072 | H6: 46073 | I6: 46076 | J6: 46077 | K6: 46078 | L6: 46079
B7: 1 | C7: 강유민 | D7: =COUNTIFS(F7:L7, "X", F$6:L$6, "<"&TODAY()) -> 0 | E7: =COUNTIFS(F7:L7, "O", F$6:L$6, "<"&TODAY())/COUNTIF(F$6:L$6,"<"&TODAY()) -> 1 | F7: =IF(COUNTIFS('설문지 응답 시트1'!$C:$C, $C7, '설문지 응답 시트1'!$A:$A, ">="&(F$6 + TIME(17,0,0)), '설문지 응답 시트1'!$A:$A, "<"&(F$6 + 1 + TIME(9,0,0)))>0, "O", "X") -> O | G7: =IF(COUNTIFS('설문지 응답 시트1'!$C:$C, $C7, '설문지 응답 시트1'!$A:$A, ">="&(G$6 + TIME(17,0,0)), '설문지 응답 시트1'!$A:$A, "<"&(G$6 + 1 + TIME(9,0,0)))>0, "O", "X") -> O | H7: =IF(COUNTIFS('설문지 응답 시트1'!$C:$C, $C7, '설문지 응답 시트1'!$A:$A, ">="&(H$6 + TIME(17,0,0)), '설문지 응답 시트1'!$A:$A, "<"&(H$6 + 1 + TIME(9,0,0)))>0, "O", "X") -> O | I7: =IF(COUNTIFS('설문지 응답 시트1'!$C:$C, $C7, '설문지 응답 시트1'!$A:$A, ">="&(I$6 + TIME(17,0,0)), '설문지 응답 시트1'!$A:$A, "<"&(I$6 + 1 + TIME(9,0,0)))>0, "O", "X") -> O | J7: =IF(COUNTIFS('설문지 응답 시트1'!$C:$C, $C7, '설문지 응답 시트1'!$A:$A, ">="&(J$6 + TIME(17,0,0)), '설문지 응답 시트1'!$A:$A, "<"&(J$6 + 1 + TIME(9,0,0)))>0, "O", "X") -> O | K7: =IF(COUNTIFS('설문지 응답 시트1'!$C:$C, $C7, '설문지 응답 시트1'!$A:$A, ">="&(K$6 + TIME(17,0,0)), '설문지 응답 시트1'!$A:$A, "<"&(K$6 + 1 + TIME(9,0,0)))>0, "O", "X") -> O | L7: =IF(COUNTIFS('설문지 응답 시트1'!$C:$C, $C7, '설문지 응답 시트1'!$A:$A, ">="&(L$6 + TIME(17,0,0)), '설문지 응답 시트1'!$A:$A, "<"&(L$6 + 1 + TIME(9,0,0)))>0, "O", "X") -> O
B8: 1 | C8: 이유송 | D8: =COUNTIFS(F8:L8, "X", F$6:L$6, "<"&TODAY()) -> 1 | E8: =COUNTIFS(F8:L8, "O", F$6:L$6, "<"&TODAY())/COUNTIF(F$6:L$6,"<"&TODAY()) -> 0.85714286 | F8: =IF(COUNTIFS('설문지 응답 시트1'!$C:$C, $C8, '설문지 응답 시트1'!$A:$A, ">="&(F$6 + TIME(17,0,0)), '설문지 응답 시트1'!$A:$A, "<"&(F$6 + 1 + TIME(9,0,0)))>0, "O", "X") -> O | G8: =IF(COUNTIFS('설문지 응답 시트1'!$C:$C, $C8, '설문지 응답 시트1'!$A:$A, ">="&(G$6 + TIME(17,0,0)), '설문지 응답 시트1'!$A:$A, "<"&(G$6 + 1 + TIME(9,0,0)))>0, "O", "X") -> O | H8: =IF(COUNTIFS('설문지 응답 시트1'!$C:$C, $C8, '설문지 응답 시트1'!$A:$A, ">="&(H$6 + TIME(17,0,0)), '설문지 응답 시트1'!$A:$A, "<"&(H$6 + 1 + TIME(9,0,0)))>0, "O", "X") -> O | I8: =IF(COUNTIFS('설문지 응답 시트1'!$C:$C, $C8, '설문지 응답 시트1'!$A:$A, ">="&(I$6 + TIME(17,0,0)), '설문지 응답 시트1'!$A:$A, "<"&(I$6 + 1 + TIME(9,0,0)))>0, "O", "X") -> O | J8: =IF(COUNTIFS('설문지 응답 시트1'!$C:$C, $C8, '설문지 응답 시트1'!$A:$A, ">="&(J$6 + TIME(17,0,0)), '설문지 응답 시트1'!$A:$A, "<"&(J$6 + 1 + TIME(9,0,0)))>0, "O", "X") -> X | K8: =IF(COUNTIFS('설문지 응답 시트1'!$C:$C, $C8, '설문지 응답 시트1'!$A:$A, ">="&(K$6 + TIME(17,0,0)), '설문지 응답 시트1'!$A:$A, "<"&(K$6 + 1 + TIME(9,0,0)))>0, "O", "X") -> O | L8: =IF(COUNTIFS('설문지 응답 시트1'!$C:$C, $C8, '설문지 응답 시트1'!$A:$A, ">="&(L$6 + TIME(17,0,0)), '설문지 응답 시트1'!$A:$A, "<"&(L$6 + 1 + TIME(9,0,0)))>0, "O", "X") -> O
B9: 1 | C9: 이동현 | D9: =COUNTIFS(F9:L9, "X", F$6:L$6, "<"&TODAY()) -> 1 | E9: =COUNTIFS(F9:L9, "O", F$6:L$6, "<"&TODAY())/COUNTIF(F$6:L$6,"<"&TODAY()) -> 0.85714286 | F9: =IF(COUNTIFS('설문지 응답 시트1'!$C:$C, $C9, '설문지 응답 시트1'!$A:$A, ">="&(F$6 + TIME(17,0,0)), '설문지 응답 시트1'!$A:$A, "<"&(F$6 + 1 + TIME(9,0,0)))>0, "O", "X") -> O | G9: =IF(COUNTIFS('설문지 응답 시트1'!$C:$C, $C9, '설문지 응답 시트1'!$A:$A, ">="&(G$6 + TIME(17,0,0)), '설문지 응답 시트1'!$A:$A, "<"&(G$6 + 1 + TIME(9,0,0)))>0, "O", "X") -> X | H9: =IF(COUNTIFS('설문지 응답 시트1'!$C:$C, $C9, '설문지 응답 시트1'!$A:$A, ">="&(H$6 + TIME(17,0,0)), '설문지 응답 시트1'!$A:$A, "<"&(H$6 + 1 + TIME(9,0,0)))>0, "O", "X") -> O | I9: =IF(COUNTIFS('설문지 응답 시트1'!$C:$C, $C9, '설문지 응답 시트1'!$A:$A, ">="&(I$6 + TIME(17,0,0)), '설문지 응답 시트1'!$A:$A, "<"&(I$6 + 1 + TIME(9,0,0)))>0, "O", "X") -> O | J9: =IF(COUNTIFS('설문지 응답 시트1'!$C:$C, $C9, '설문지 응답 시트1'!$A:$A, ">="&(J$6 + TIME(17,0,0)), '설문지 응답 시트1'!$A:$A, "<"&(J$6 + 1 + TIME(9,0,0)))>0, "O", "X") -> O | K9: =IF(COUNTIFS('설문지 응답 시트1'!$C:$C, $C9, '설문지 응답 시트1'!$A:$A, ">="&(K$6 + TIME(17,0,0)), '설문지 응답 시트1'!$A:$A, "<"&(K$6 + 1 + TIME(9,0,0)))>0, "O", "X") -> O | L9: =IF(COUNTIFS('설문지 응답 시트1'!$C:$C, $C9, '설문지 응답 시트1'!$A:$A, ">="&(L$6 + TIME(17,0,0)), '설문지 응답 시트1'!$A:$A, "<"&(L$6 + 1 + TIME(9,0,0)))>0, "O", "X") -> O
B10: 1 | C10: 정우경 | D10: =COUNTIFS(F10:L10, "X", F$6:L$6, "<"&TODAY()) -> 2 | E10: =COUNTIFS(F10:L10, "O", F$6:L$6, "<"&TODAY())/COUNTIF(F$6:L$6,"<"&TODAY()) -> 0.71428571 | F10: =IF(COUNTIFS('설문지 응답 시트1'!$C:$C, $C10, '설문지 응답 시트1'!$A:$A, ">="&(F$6 + TIME(17,0,0)), '설문지 응답 시트1'!$A:$A, "<"&(F$6 + 1 + TIME(9,0,0)))>0, "O", "X") -> O | G10: =IF(COUNTIFS('설문지 응답 시트1'!$C:$C, $C10, '설문지 응답 시트1'!$A:$A, ">="&(G$6 + TIME(17,0,0)), '설문지 응답 시트1'!$A:$A, "<"&(G$6 + 1 + TIME(9,0,0)))>0, "O", "X") -> O | H10: =IF(COUNTIFS('설문지 응답 시트1'!$C:$C, $C10, '설문지 응답 시트1'!$A:$A, ">="&(H$6 + TIME(17,0,0)), '설문지 응답 시트1'!$A:$A, "<"&(H$6 + 1 + TIME(9,0,0)))>0, "O", "X") -> O | I10: =IF(COUNTIFS('설문지 응답 시트1'!$C:$C, $C10, '설문지 응답 시트1'!$A:$A, ">="&(I$6 + TIME(17,0,0)), '설문지 응답 시트1'!$A:$A, "<"&(I$6 + 1 + TIME(9,0,0)))>0, "O", "X") -> X | J10: =IF(COUNTIFS('설문지 응답 시트1'!$C:$C, $C10, '설문지 응답 시트1'!$A:$A, ">="&(J$6 + TIME(17,0,0)), '설문지 응답 시트1'!$A:$A, "<"&(J$6 + 1 + TIME(9,0,0)))>0, "O", "X") -> O | K10: =IF(COUNTIFS('설문지 응답 시트1'!$C:$C, $C10, '설문지 응답 시트1'!$A:$A, ">="&(K$6 + TIME(17,0,0)), '설문지 응답 시트1'!$A:$A, "<"&(K$6 + 1 + TIME(9,0,0)))>0, "O", "X") -> O | L10: =IF(COUNTIFS('설문지 응답 시트1'!$C:$C, $C10, '설문지 응답 시트1'!$A:$A, ">="&(L$6 + TIME(17,0,0)), '설문지 응답 시트1'!$A:$A, "<"&(L$6 + 1 + TIME(9,0,0)))>0, "O", "X") -> X
B11: 1 | C11: 김현우A | D11: =COUNTIFS(F11:L11, "X", F$6:L$6, "<"&TODAY()) -> 7 | E11: =COUNTIFS(F11:L11, "O", F$6:L$6, "<"&TODAY())/COUNTIF(F$6:L$6,"<"&TODAY()) -> 0 | F11: =IF(COUNTIFS('설문지 응답 시트1'!$C:$C, $C11, '설문지 응답 시트1'!$A:$A, ">="&(F$6 + TIME(17,0,0)), '설문지 응답 시트1'!$A:$A, "<"&(F$6 + 1 + TIME(9,0,0)))>0, "O", "X") -> X | G11: =IF(COUNTIFS('설문지 응답 시트1'!$C:$C, $C11, '설문지 응답 시트1'!$A:$A, ">="&(G$6 + TIME(17,0,0)), '설문지 응답 시트1'!$A:$A, "<"&(G$6 + 1 + TIME(9,0,0)))>0, "O", "X") -> X | H11: =IF(COUNTIFS('설문지 응답 시트1'!$C:$C, $C11, '설문지 응답 시트1'!$A:$A, ">="&(H$6 + TIME(17,0,0)), '설문지 응답 시트1'!$A:$A, "<"&(H$6 + 1 + TIME(9,0,0)))>0, "O", "X") -> X | I11: =IF(COUNTIFS('설문지 응답 시트1'!$C:$C, $C11, '설문지 응답 시트1'!$A:$A, ">="&(I$6 + TIME(17,0,0)), '설문지 응답 시트1'!$A:$A, "<"&(I$6 + 1 + TIME(9,0,0)))>0, "O", "X") -> X | J11: =IF(COUNTIFS('설문지 응답 시트1'!$C:$C, $C11, '설문지 응답 시트1'!$A:$A, ">="&(J$6 + TIME(17,0,0)), '설문지 응답 시트1'!$A:$A, "<"&(J$6 + 1 + TIME(9,0,0)))>0, "O", "X") -> X | K11: =IF(COUNTIFS('설문지 응답 시트1'!$C:$C, $C11, '설문지 응답 시트1'!$A:$A, ">="&(K$6 + TIME(17,0,0)), '설문지 응답 시트1'!$A:$A, "<"&(K$6 + 1 + TIME(9,0,0)))>0, "O", "X") -> X | L11: =IF(COUNTIFS('설문지 응답 시트1'!$C:$C, $C11, '설문지 응답 시트1'!$A:$A, ">="&(L$6 + TIME(17,0,0)), '설문지 응답 시트1'!$A:$A, "<"&(L$6 + 1 + TIME(9,0,0)))>0, "O", "X") -> X
B12: 1 | C12: 정석현 | D12: =COUNTIFS(F12:L12, "X", F$6:L$6, "<"&TODAY()) -> 1 | E12: =COUNTIFS(F12:L12, "O", F$6:L$6, "<"&TODAY())/COUNTIF(F$6:L$6,"<"&TODAY()) -> 0.85714286 | F12: =IF(COUNTIFS('설문지 응답 시트1'!$C:$C, $C12, '설문지 응답 시트1'!$A:$A, ">="&(F$6 + TIME(17,0,0)), '설문지 응답 시트1'!$A:$A, "<"&(F$6 + 1 + TIME(9,0,0)))>0, "O", "X") -> O | G12: =IF(COUNTIFS('설문지 응답 시트1'!$C:$C, $C12, '설문지 응답 시트1'!$A:$A, ">="&(G$6 + TIME(17,0,0)), '설문지 응답 시트1'!$A:$A, "<"&(G$6 + 1 + TIME(9,0,0)))>0, "O", "X") -> X | H12: =IF(COUNTIFS('설문지 응답 시트1'!$C:$C, $C12, '설문지 응답 시트1'!$A:$A, ">="&(H$6 + TIME(17,0,0)), '설문지 응답 시트1'!$A:$A, "<"&(H$6 + 1 + TIME(9,0,0)))>0, "O", "X") -> O | I12: =IF(COUNTIFS('설문지 응답 시트1'!$C:$C, $C12, '설문지 응답 시트1'!$A:$A, ">="&(I$6 + TIME(17,0,0)), '설문지 응답 시트1'!$A:$A, "<"&(I$6 + 1 + TIME(9,0,0)))>0, "O", "X") -> O | J12: =IF(COUNTIFS('설문지 응답 시트1'!$C:$C, $C12, '설문지 응답 시트1'!$A:$A, ">="&(J$6 + TIME(17,0,0)), '설문지 응답 시트1'!$A:$A, "<"&(J$6 + 1 + TIME(9,0,0)))>0, "O", "X") -> O | K12: =IF(COUNTIFS('설문지 응답 시트1'!$C:$C, $C12, '설문지 응답 시트1'!$A:$A, ">="&(K$6 + TIME(17,0,0)), '설문지 응답 시트1'!$A:$A, "<"&(K$6 + 1 + TIME(9,0,0)))>0, "O", "X") -> O | L12: =IF(COUNTIFS('설문지 응답 시트1'!$C:$C, $C12, '설문지 응답 시트1'!$A:$A, ">="&(L$6 + TIME(17,0,0)), '설문지 응답 시트1'!$A:$A, "<"&(L$6 + 1 + TIME(9,0,0)))>0, "O", "X") -> O
B13: 1 | C13: 임소영 | D13: =COUNTIFS(F13:L13, "X", F$6:L$6, "<"&TODAY()) -> 4 | E13: =COUNTIFS(F13:L13, "O", F$6:L$6, "<"&TODAY())/COUNTIF(F$6:L$6,"<"&TODAY()) -> 0.42857143 | F13: =IF(COUNTIFS('설문지 응답 시트1'!$C:$C, $C13, '설문지 응답 시트1'!$A:$A, ">="&(F$6 + TIME(17,0,0)), '설문지 응답 시트1'!$A:$A, "<"&(F$6 + 1 + TIME(9,0,0)))>0, "O", "X") -> X | G13: =IF(COUNTIFS('설문지 응답 시트1'!$C:$C, $C13, '설문지 응답 시트1'!$A:$A, ">="&(G$6 + TIME(17,0,0)), '설문지 응답 시트1'!$A:$A, "<"&(G$6 + 1 + TIME(9,0,0)))>0, "O", "X") -> X | H13: =IF(COUNTIFS('설문지 응답 시트1'!$C:$C, $C13, '설문지 응답 시트1'!$A:$A, ">="&(H$6 + TIME(17,0,0)), '설문지 응답 시트1'!$A:$A, "<"&(H$6 + 1 + TIME(9,0,0)))>0, "O", "X") -> X | I13: =IF(COUNTIFS('설문지 응답 시트1'!$C:$C, $C13, '설문지 응답 시트1'!$A:$A, ">="&(I$6 + TIME(17,0,0)), '설문지 응답 시트1'!$A:$A, "<"&(I$6 + 1 + TIME(9,0,0)))>0, "O", "X") -> O | J13: =IF(COUNTIFS('설문지 응답 시트1'!$C:$C, $C13, '설문지 응답 시트1'!$A:$A, ">="&(J$6 + TIME(17,0,0)), '설문지 응답 시트1'!$A:$A, "<"&(J$6 + 1 + TIME(9,0,0)))>0, "O", "X") -> X | K13: =IF(COUNTIFS('설문지 응답 시트1'!$C:$C, $C13, '설문지 응답 시트1'!$A:$A, ">="&(K$6 + TIME(17,0,0)), '설문지 응답 시트1'!$A:$A, "<"&(K$6 + 1 + TIME(9,0,0)))>0, "O", "X") -> O | L13: =IF(COUNTIFS('설문지 응답 시트1'!$C:$C, $C13, '설문지 응답 시트1'!$A:$A, ">="&(L$6 + TIME(17,0,0)), '설문지 응답 시트1'!$A:$A, "<"&(L$6 + 1 + TIME(9,0,0)))>0, "O", "X") -> O
B14: 1 | C14: 박현수 | D14: =COUNTIFS(F14:L14, "X", F$6:L$6, "<"&TODAY()) -> 2 | E14: =COUNTIFS(F14:L14, "O", F$6:L$6, "<"&TODAY())/COUNTIF(F$6:L$6,"<"&TODAY()) -> 0.71428571 | F14: =IF(COUNTIFS('설문지 응답 시트1'!$C:$C, $C14, '설문지 응답 시트1'!$A:$A, ">="&(F$6 + TIME(17,0,0)), '설문지 응답 시트1'!$A:$A, "<"&(F$6 + 1 + TIME(9,0,0)))>0, "O", "X") -> X | G14: =IF(COUNTIFS('설문지 응답 시트1'!$C:$C, $C14, '설문지 응답 시트1'!$A:$A, ">="&(G$6 + TIME(17,0,0)), '설문지 응답 시트1'!$A:$A, "<"&(G$6 + 1 + TIME(9,0,0)))>0, "O", "X") -> O | H14: =IF(COUNTIFS('설문지 응답 시트1'!$C:$C, $C14, '설문지 응답 시트1'!$A:$A, ">="&(H$6 + TIME(17,0,0)), '설문지 응답 시트1'!$A:$A, "<"&(H$6 + 1 + TIME(9,0,0)))>0, "O", "X") -> O | I14: =IF(COUNTIFS('설문지 응답 시트1'!$C:$C, $C14, '설문지 응답 시트1'!$A:$A, ">="&(I$6 + TIME(17,0,0)), '설문지 응답 시트1'!$A:$A, "<"&(I$6 + 1 + TIME(9,0,0)))>0, "O", "X") -> O | J14: =IF(COUNTIFS('설문지 응답 시트1'!$C:$C, $C14, '설문지 응답 시트1'!$A:$A, ">="&(J$6 + TIME(17,0,0)), '설문지 응답 시트1'!$A:$A, "<"&(J$6 + 1 + TIME(9,0,0)))>0, "O", "X") -> O | K14: =IF(COUNTIFS('설문지 응답 시트1'!$C:$C, $C14, '설문지 응답 시트1'!$A:$A, ">="&(K$6 + TIME(17,0,0)), '설문지 응답 시트1'!$A:$A, "<"&(K$6 + 1 + TIME(9,0,0)))>0, "O", "X") -> O | L14: =IF(COUNTIFS('설문지 응답 시트1'!$C:$C, $C14, '설문지 응답 시트1'!$A:$A, ">="&(L$6 + TIME(17,0,0)), '설문지 응답 시트1'!$A:$A, "<"&(L$6 + 1 + TIME(9,0,0)))>0, "O", "X") -> X
B15: 2 | C15: 김서현 | D15: =COUNTIFS(F15:L15, "X", F$6:L$6, "<"&TODAY()) -> 0 | E15: =COUNTIFS(F15:L15, "O", F$6:L$6, "<"&TODAY())/COUNTIF(F$6:L$6,"<"&TODAY()) -> 1 | F15: =IF(COUNTIFS('설문지 응답 시트1'!$C:$C, $C15, '설문지 응답 시트1'!$A:$A, ">="&(F$6 + TIME(17,0,0)), '설문지 응답 시트1'!$A:$A, "<"&(F$6 + 1 + TIME(9,0,0)))>0, "O", "X") -> O | G15: =IF(COUNTIFS('설문지 응답 시트1'!$C:$C, $C15, '설문지 응답 시트1'!$A:$A, ">="&(G$6 + TIME(17,0,0)), '설문지 응답 시트1'!$A:$A, "<"&(G$6 + 1 + TIME(9,0,0)))>0, "O", "X") -> O | H15: =IF(COUNTIFS('설문지 응답 시트1'!$C:$C, $C15, '설문지 응답 시트1'!$A:$A, ">="&(H$6 + TIME(17,0,0)), '설문지 응답 시트1'!$A:$A, "<"&(H$6 + 1 + TIME(9,0,0)))>0, "O", "X") -> O | I15: =IF(COUNTIFS('설문지 응답 시트1'!$C:$C, $C15, '설문지 응답 시트1'!$A:$A, ">="&(I$6 + TIME(17,0,0)), '설문지 응답 시트1'!$A:$A, "<"&(I$6 + 1 + TIME(9,0,0)))>0, "O", "X") -> O | J15: =IF(COUNTIFS('설문지 응답 시트1'!$C:$C, $C15, '설문지 응답 시트1'!$A:$A, ">="&(J$6 + TIME(17,0,0)), '설문지 응답 시트1'!$A:$A, "<"&(J$6 + 1 + TIME(9,0,0)))>0, "O", "X") -> O | K15: =IF(COUNTIFS('설문지 응답 시트1'!$C:$C, $C15, '설문지 응답 시트1'!$A:$A, ">="&(K$6 + TIME(17,0,0)), '설문지 응답 시트1'!$A:$A, "<"&(K$6 + 1 + TIME(9,0,0)))>0, "O", "X") -> O | L15: =IF(COUNTIFS('설문지 응답 시트1'!$C:$C, $C15, '설문지 응답 시트1'!$A:$A, ">="&(L$6 + TIME(17,0,0)), '설문지 응답 시트1'!$A:$A, "<"&(L$6 + 1 + TIME(9,0,0)))>0, "O", "X") -> O
B16: 2 | C16: 김태환 | D16: =COUNTIFS(F16:L16, "X", F$6:L$6, "<"&TODAY()) -> 1 | E16: =COUNTIFS(F16:L16, "O", F$6:L$6, "<"&TODAY())/COUNTIF(F$6:L$6,"<"&TODAY()) -> 0.85714286 | F16: =IF(COUNTIFS('설문지 응답 시트1'!$C:$C, $C16, '설문지 응답 시트1'!$A:$A, ">="&(F$6 + TIME(17,0,0)), '설문지 응답 시트1'!$A:$A, "<"&(F$6 + 1 + TIME(9,0,0)))>0, "O", "X") -> X | G16: =IF(COUNTIFS('설문지 응답 시트1'!$C:$C, $C16, '설문지 응답 시트1'!$A:$A, ">="&(G$6 + TIME(17,0,0)), '설문지 응답 시트1'!$A:$A, "<"&(G$6 + 1 + TIME(9,0,0)))>0, "O", "X") -> O | H16: =IF(COUNTIFS('설문지 응답 시트1'!$C:$C, $C16, '설문지 응답 시트1'!$A:$A, ">="&(H$6 + TIME(17,0,0)), '설문지 응답 시트1'!$A:$A, "<"&(H$6 + 1 + TIME(9,0,0)))>0, "O", "X") -> O | I16: =IF(COUNTIFS('설문지 응답 시트1'!$C:$C, $C16, '설문지 응답 시트1'!$A:$A, ">="&(I$6 + TIME(17,0,0)), '설문지 응답 시트1'!$A:$A, "<"&(I$6 + 1 + TIME(9,0,0)))>0, "O", "X") -> O | J16: =IF(COUNTIFS('설문지 응답 시트1'!$C:$C, $C16, '설문지 응답 시트1'!$A:$A, ">="&(J$6 + TIME(17,0,0)), '설문지 응답 시트1'!$A:$A, "<"&(J$6 + 1 + TIME(9,0,0)))>0, "O", "X") -> O | K16: =IF(COUNTIFS('설문지 응답 시트1'!$C:$C, $C16, '설문지 응답 시트1'!$A:$A, ">="&(K$6 + TIME(17,0,0)), '설문지 응답 시트1'!$A:$A, "<"&(K$6 + 1 + TIME(9,0,0)))>0, "O", "X") -> O | L16: =IF(COUNTIFS('설문지 응답 시트1'!$C:$C, $C16, '설문지 응답 시트1'!$A:$A, ">="&(L$6 + TIME(17,0,0)), '설문지 응답 시트1'!$A:$A, "<"&(L$6 + 1 + TIME(9,0,0)))>0, "O", "X") -> O
B17: 2 | C17: 장윤우 | D17: =COUNTIFS(F17:L17, "X", F$6:L$6, "<"&TODAY()) -> 0 | E17: =COUNTIFS(F17:L17, "O", F$6:L$6, "<"&TODAY())/COUNTIF(F$6:L$6,"<"&TODAY()) -> 1 | F17: =IF(COUNTIFS('설문지 응답 시트1'!$C:$C, $C17, '설문지 응답 시트1'!$A:$A, ">="&(F$6 + TIME(17,0,0)), '설문지 응답 시트1'!$A:$A, "<"&(F$6 + 1 + TIME(9,0,0)))>0, "O", "X") -> O | G17: =IF(COUNTIFS('설문지 응답 시트1'!$C:$C, $C17, '설문지 응답 시트1'!$A:$A, ">="&(G$6 + TIME(17,0,0)), '설문지 응답 시트1'!$A:$A, "<"&(G$6 + 1 + TIME(9,0,0)))>0, "O", "X") -> O | H17: =IF(COUNTIFS('설문지 응답 시트1'!$C:$C, $C17, '설문지 응답 시트1'!$A:$A, ">="&(H$6 + TIME(17,0,0)), '설문지 응답 시트1'!$A:$A, "<"&(H$6 + 1 + TIME(9,0,0)))>0, "O", "X") -> O | I17: =IF(COUNTIFS('설문지 응답 시트1'!$C:$C, $C17, '설문지 응답 시트1'!$A:$A, ">="&(I$6 + TIME(17,0,0)), '설문지 응답 시트1'!$A:$A, "<"&(I$6 + 1 + TIME(9,0,0)))>0, "O", "X") -> O | J17: =IF(COUNTIFS('설문지 응답 시트1'!$C:$C, $C17, '설문지 응답 시트1'!$A:$A, ">="&(J$6 + TIME(17,0,0)), '설문지 응답 시트1'!$A:$A, "<"&(J$6 + 1 + TIME(9,0,0)))>0, "O", "X") -> O | K17: =IF(COUNTIFS('설문지 응답 시트1'!$C:$C, $C17, '설문지 응답 시트1'!$A:$A, ">="&(K$6 + TIME(17,0,0)), '설문지 응답 시트1'!$A:$A, "<"&(K$6 + 1 + TIME(9,0,0)))>0, "O", "X") -> O | L17: =IF(COUNTIFS('설문지 응답 시트1'!$C:$C, $C17, '설문지 응답 시트1'!$A:$A, ">="&(L$6 + TIME(17,0,0)), '설문지 응답 시트1'!$A:$A, "<"&(L$6 + 1 + TIME(9,0,0)))>0, "O", "X") -> O
B18: 2 | C18: 유해찬 | D18: =COUNTIFS(F18:L18, "X", F$6:L$6, "<"&TODAY()) -> 1 | E18: =COUNTIFS(F18:L18, "O", F$6:L$6, "<"&TODAY())/COUNTIF(F$6:L$6,"<"&TODAY()) -> 0.85714286 | F18: =IF(COUNTIFS('설문지 응답 시트1'!$C:$C, $C18, '설문지 응답 시트1'!$A:$A, ">="&(F$6 + TIME(17,0,0)), '설문지 응답 시트1'!$A:$A, "<"&(F$6 + 1 + TIME(9,0,0)))>0, "O", "X") -> O | G18: =IF(COUNTIFS('설문지 응답 시트1'!$C:$C, $C18, '설문지 응답 시트1'!$A:$A, ">="&(G$6 + TIME(17,0,0)), '설문지 응답 시트1'!$A:$A, "<"&(G$6 + 1 + TIME(9,0,0)))>0, "O", "X") -> O | H18: =IF(COUNTIFS('설문지 응답 시트1'!$C:$C, $C18, '설문지 응답 시트1'!$A:$A, ">="&(H$6 + TIME(17,0,0)), '설문지 응답 시트1'!$A:$A, "<"&(H$6 + 1 + TIME(9,0,0)))>0, "O", "X") -> O | I18: =IF(COUNTIFS('설문지 응답 시트1'!$C:$C, $C18, '설문지 응답 시트1'!$A:$A, ">="&(I$6 + TIME(17,0,0)), '설문지 응답 시트1'!$A:$A, "<"&(I$6 + 1 + TIME(9,0,0)))>0, "O", "X") -> X | J18: =IF(COUNTIFS('설문지 응답 시트1'!$C:$C, $C18, '설문지 응답 시트1'!$A:$A, ">="&(J$6 + TIME(17,0,0)), '설문지 응답 시트1'!$A:$A, "<"&(J$6 + 1 + TIME(9,0,0)))>0, "O", "X") -> O | K18: =IF(COUNTIFS('설문지 응답 시트1'!$C:$C, $C18, '설문지 응답 시트1'!$A:$A, ">="&(K$6 + TIME(17,0,0)), '설문지 응답 시트1'!$A:$A, "<"&(K$6 + 1 + TIME(9,0,0)))>0, "O", "X") -> O | L18: =IF(COUNTIFS('설문지 응답 시트1'!$C:$C, $C18, '설문지 응답 시트1'!$A:$A, ">="&(L$6 + TIME(17,0,0)), '설문지 응답 시트1'!$A:$A, "<"&(L$6 + 1 + TIME(9,0,0)))>0, "O", "X") -> O
... B80: 10 | C80: 정재용 | D80: =COUNTIFS(F80:L80, "X", F$6:L$6, "<"&TODAY()) -> 0 | E80: =COUNTIFS(F80:L80, "O", F$6:L$6, "<"&TODAY())/COUNTIF(F$6:L$6,"<"&TODAY()) -> 1 | F80: =IF(COUNTIFS('설문지 응답 시트1'!$C:$C, $C80, '설문지 응답 시트1'!$A:$A, ">="&(F$6 + TIME(17,0,0)), '설문지 응답 시트1'!$A:$A, "<"&(F$6 + 1 + TIME(9,0,0)))>0, "O", "X") -> O | G80: =IF(COUNTIFS('설문지 응답 시트1'!$C:$C, $C80, '설문지 응답 시트1'!$A:$A, ">="&(G$6 + TIME(17,0,0)), '설문지 응답 시트1'!$A:$A, "<"&(G$6 + 1 + TIME(9,0,0)))>0, "O", "X") -> O | H80: =IF(COUNTIFS('설문지 응답 시트1'!$C:$C, $C80, '설문지 응답 시트1'!$A:$A, ">="&(H$6 + TIME(17,0,0)), '설문지 응답 시트1'!$A:$A, "<"&(H$6 + 1 + TIME(9,0,0)))>0, "O", "X") -> O | I80: =IF(COUNTIFS('설문지 응답 시트1'!$C:$C, $C80, '설문지 응답 시트1'!$A:$A, ">="&(I$6 + TIME(17,0,0)), '설문지 응답 시트1'!$A:$A, "<"&(I$6 + 1 + TIME(9,0,0)))>0, "O", "X") -> O | J80: =IF(COUNTIFS('설문지 응답 시트1'!$C:$C, $C80, '설문지 응답 시트1'!$A:$A, ">="&(J$6 + TIME(17,0,0)), '설문지 응답 시트1'!$A:$A, "<"&(J$6 + 1 + TIME(9,0,0)))>0, "O", "X") -> O | K80: =IF(COUNTIFS('설문지 응답 시트1'!$C:$C, $C80, '설문지 응답 시트1'!$A:$A, ">="&(K$6 + TIME(17,0,0)), '설문지 응답 시트1'!$A:$A, "<"&(K$6 + 1 + TIME(9,0,0)))>0, "O", "X") -> O | L80: =IF(COUNTIFS('설문지 응답 시트1'!$C:$C, $C80, '설문지 응답 시트1'!$A:$A, ">="&(L$6 + TIME(17,0,0)), '설문지 응답 시트1'!$A:$A, "<"&(L$6 + 1 + TIME(9,0,0)))>0, "O", "X") -> O
B81: 개인 | C81: 김지훈 | D81: =COUNTIFS(F81:L81, "X", F$6:L$6, "<"&TODAY()) -> 3 | E81: =COUNTIFS(F81:L81, "O", F$6:L$6, "<"&TODAY())/COUNTIF(F$6:L$6,"<"&TODAY()) -> 0.57142857 | F81: =IF(COUNTIFS('설문지 응답 시트1'!$C:$C, $C81, '설문지 응답 시트1'!$A:$A, ">="&(F$6 + TIME(17,0,0)), '설문지 응답 시트1'!$A:$A, "<"&(F$6 + 1 + TIME(9,0,0)))>0, "O", "X") -> O | G81: =IF(COUNTIFS('설문지 응답 시트1'!$C:$C, $C81, '설문지 응답 시트1'!$A:$A, ">="&(G$6 + TIME(17,0,0)), '설문지 응답 시트1'!$A:$A, "<"&(G$6 + 1 + TIME(9,0,0)))>0, "O", "X") -> X | H81: =IF(COUNTIFS('설문지 응답 시트1'!$C:$C, $C81, '설문지 응답 시트1'!$A:$A, ">="&(H$6 + TIME(17,0,0)), '설문지 응답 시트1'!$A:$A, "<"&(H$6 + 1 + TIME(9,0,0)))>0, "O", "X") -> O | I81: =IF(COUNTIFS('설문지 응답 시트1'!$C:$C, $C81, '설문지 응답 시트1'!$A:$A, ">="&(I$6 + TIME(17,0,0)), '설문지 응답 시트1'!$A:$A, "<"&(I$6 + 1 + TIME(9,0,0)))>0, "O", "X") -> O | J81: =IF(COUNTIFS('설문지 응답 시트1'!$C:$C, $C81, '설문지 응답 시트1'!$A:$A, ">="&(J$6 + TIME(17,0,0)), '설문지 응답 시트1'!$A:$A, "<"&(J$6 + 1 + TIME(9,0,0)))>0, "O", "X") -> O | K81: =IF(COUNTIFS('설문지 응답 시트1'!$C:$C, $C81, '설문지 응답 시트1'!$A:$A, ">="&(K$6 + TIME(17,0,0)), '설문지 응답 시트1'!$A:$A, "<"&(K$6 + 1 + TIME(9,0,0)))>0, "O", "X") -> X | L81: =IF(COUNTIFS('설문지 응답 시트1'!$C:$C, $C81, '설문지 응답 시트1'!$A:$A, ">="&(L$6 + TIME(17,0,0)), '설문지 응답 시트1'!$A:$A, "<"&(L$6 + 1 + TIME(9,0,0)))>0, "O", "X") -> X
B82: 개인 | C82: 이석훈 | D82: =COUNTIFS(F82:L82, "X", F$6:L$6, "<"&TODAY()) -> 6 | E82: =COUNTIFS(F82:L82, "O", F$6:L$6, "<"&TODAY())/COUNTIF(F$6:L$6,"<"&TODAY()) -> 0.14285714 | F82: =IF(COUNTIFS('설문지 응답 시트1'!$C:$C, $C82, '설문지 응답 시트1'!$A:$A, ">="&(F$6 + TIME(17,0,0)), '설문지 응답 시트1'!$A:$A, "<"&(F$6 + 1 + TIME(9,0,0)))>0, "O", "X") -> O | G82: =IF(COUNTIFS('설문지 응답 시트1'!$C:$C, $C82, '설문지 응답 시트1'!$A:$A, ">="&(G$6 + TIME(17,0,0)), '설문지 응답 시트1'!$A:$A, "<"&(G$6 + 1 + TIME(9,0,0)))>0, "O", "X") -> X | H82: =IF(COUNTIFS('설문지 응답 시트1'!$C:$C, $C82, '설문지 응답 시트1'!$A:$A, ">="&(H$6 + TIME(17,0,0)), '설문지 응답 시트1'!$A:$A, "<"&(H$6 + 1 + TIME(9,0,0)))>0, "O", "X") -> X | I82: =IF(COUNTIFS('설문지 응답 시트1'!$C:$C, $C82, '설문지 응답 시트1'!$A:$A, ">="&(I$6 + TIME(17,0,0)), '설문지 응답 시트1'!$A:$A, "<"&(I$6 + 1 + TIME(9,0,0)))>0, "O", "X") -> X | J82: =IF(COUNTIFS('설문지 응답 시트1'!$C:$C, $C82, '설문지 응답 시트1'!$A:$A, ">="&(J$6 + TIME(17,0,0)), '설문지 응답 시트1'!$A:$A, "<"&(J$6 + 1 + TIME(9,0,0)))>0, "O", "X") -> X | K82: =IF(COUNTIFS('설문지 응답 시트1'!$C:$C, $C82, '설문지 응답 시트1'!$A:$A, ">="&(K$6 + TIME(17,0,0)), '설문지 응답 시트1'!$A:$A, "<"&(K$6 + 1 + TIME(9,0,0)))>0, "O", "X") -> X | L82: =IF(COUNTIFS('설문지 응답 시트1'!$C:$C, $C82, '설문지 응답 시트1'!$A:$A, ">="&(L$6 + TIME(17,0,0)), '설문지 응답 시트1'!$A:$A, "<"&(L$6 + 1 + TIME(9,0,0)))>0, "O", "X") -> X
B83: 개인 | C83: 조현일 | D83: =COUNTIFS(F83:L83, "X", F$6:L$6, "<"&TODAY()) -> 4 | E83: =COUNTIFS(F83:L83, "O", F$6:L$6, "<"&TODAY())/COUNTIF(F$6:L$6,"<"&TODAY()) -> 0.42857143 | F83: =IF(COUNTIFS('설문지 응답 시트1'!$C:$C, $C83, '설문지 응답 시트1'!$A:$A, ">="&(F$6 + TIME(17,0,0)), '설문지 응답 시트1'!$A:$A, "<"&(F$6 + 1 + TIME(9,0,0)))>0, "O", "X") -> O | G83: =IF(COUNTIFS('설문지 응답 시트1'!$C:$C, $C83, '설문지 응답 시트1'!$A:$A, ">="&(G$6 + TIME(17,0,0)), '설문지 응답 시트1'!$A:$A, "<"&(G$6 + 1 + TIME(9,0,0)))>0, "O", "X") -> O | H83: =IF(COUNTIFS('설문지 응답 시트1'!$C:$C, $C83, '설문지 응답 시트1'!$A:$A, ">="&(H$6 + TIME(17,0,0)), '설문지 응답 시트1'!$A:$A, "<"&(H$6 + 1 + TIME(9,0,0)))>0, "O", "X") -> O | I83: =IF(COUNTIFS('설문지 응답 시트1'!$C:$C, $C83, '설문지 응답 시트1'!$A:$A, ">="&(I$6 + TIME(17,0,0)), '설문지 응답 시트1'!$A:$A, "<"&(I$6 + 1 + TIME(9,0,0)))>0, "O", "X") -> X | J83: =IF(COUNTIFS('설문지 응답 시트1'!$C:$C, $C83, '설문지 응답 시트1'!$A:$A, ">="&(J$6 + TIME(17,0,0)), '설문지 응답 시트1'!$A:$A, "<"&(J$6 + 1 + TIME(9,0,0)))>0, "O", "X") -> X | K83: =IF(COUNTIFS('설문지 응답 시트1'!$C:$C, $C83, '설문지 응답 시트1'!$A:$A, ">="&(K$6 + TIME(17,0,0)), '설문지 응답 시트1'!$A:$A, "<"&(K$6 + 1 + TIME(9,0,0)))>0, "O", "X") -> X | L83: =IF(COUNTIFS('설문지 응답 시트1'!$C:$C, $C83, '설문지 응답 시트1'!$A:$A, ">="&(L$6 + TIME(17,0,0)), '설문지 응답 시트1'!$A:$A, "<"&(L$6 + 1 + TIME(9,0,0)))>0, "O", "X") -> X

Sheet Date
A1: 46066
A2: 46072
A3: 46073
A4: 46076
A5: 46077
A6: 46078
A7: 46079
A8: 46080

Sheet 시트4

Sheet 213
B2: 날짜 | C2: 46066
B4: 팀 | C4: 이름 | D4: 작업량 | E4: 한마디 | F4: 비고 | G4: 상태
B5: 1 | C5: 이승구 | D5: WBS 업데이트 간트차트 업데이트 번다운 그래프 업데이트 기획서 역할 및 범위 논의 오전 작업 회의 진행(09:30 ~ 10:30) 구현 범위 공유 구현 범위 축소 및 확장 논의 R&R 진행 업무 프로세스 정하기 점심 산출물 개인 미팅 진행 산출물 확인 후 유관 기획 파트와 의견 조율 오후 프로젝트 진행 현황 공유 및 이슈 정리 *숙제 밸런스 관련 계획 세우기 개발 이슈 논의 ㄴ 타일이 합쳐지는 구현 불가능성 제시 ㄴ 대안으로 이미지는 변하지 않더라도 데이터로 효과는 구현 가능함 인지 | E5: 우리팀 짱! 개발자는 신이다. 어려웠던 점 기획 시 선행 기획되어야 하는 부분이 있어야 하는 이슈가 있었고, 해당 문제를 해결하기 위해서는 기획파트를 나누는 행위에서부터 고민되어야 함을 인지함, 현재 상황에서 되돌리기? 불가능, 진행 하되 기획자가 모래주머니를 찬 것 같음 | G5: 대기
B6: 1 | C6: 김경민 | D6: 맵, 타일 시스템 설계 초안 작성 | E6: 개발이 가능한 정도의 구체적인 시스템 기획이 낯설어 힘듦 | G6: 대기
B7: 1 | C7: 김수환 | D7: 아이템 드랍 시스템 기획서를 제작 및 장비, 타일 드랍과 관련한 의견을 공유하였습니다. | E7: 이제 프로젝트가 시작되어 앞으로 열심히 프로젝트를 진행해보겠습니다. | G7: 대기
B8: 1 | C8: 박영성 | D8: 전투 시스템의 기획 - 기획서 0.0.1. 컨펌 완료 - 컨펌 결과 : - 전투 시작 조건은 기획서 3안 우선 추진 - 단, 제약 상황에 타협 시 2안 추진 - 배치는 적의 배치 위치 3x3 칸 구성 - 배치 로직은 아이디어는 보존 하되 일단은 난수 배치 - 공격 우선 순위는 우선은 1 2 3열 순서, 각 열 내에선 상단 우선 - 공격 방식은 캐릭터 및 각 적에게 공격 요구 칸 수가 표시되고, 해당 칸이 다 차면 공격이 나가는 식 - 이때, 공격 받으면 공격 횟수만큼 칸이 하나 더 참 - 칸 하나가 차는데 걸리는 시간은 임시로 0.5초로 가정 | E8: 시나리오와 리소스에만 집중하던 지난 프로젝트와 다르게 다방면으로 유기적인 기획을 기획서를 쓰며 상호 소통하는 과정이 어려우면서도 중요한 것 같습니다. | G8: 대기
B9: 1 | C9: 유해찬 | D9: 타일맵, 타일배치, 캐릭터 루프(순환)이동, 전투 팝업 생성, 전투 캐릭터,몬스터 배치. | E9: 또..또또 개발해야한다니!! 이야아아아 파이팅. | 저희 팀이 잘 소통하고 회의가 잘되서 마음이 편합니다 | G9: 대기
B10: 1 | C10: 한의호 | D10: 장비 시스템 기획 및 테이블 임시 작성 | E10: 아직 기획 초기 단계라 서로 맡은 파트별로 기획을 한 뒤 조정을 하는 과정을 거치는 중입니다. 정확한 기준이 없어서 아직 무언가 생각 해 내기가 어려운 부분이 있습니다. | G10: 대기
B11: 2 | C11: 김범진 | D11: 시스템 통일, 컨셉 기획 진행, 역할 및 인원 배분 | E11: 팀 내 인원 한분과 의사소통으로 인해 프로젝트의 지연이 있었지만 최소 목표인 인원배분과 시스템 및 게임 컨셉 기획을 진행한 상태입니다. 인원끼리의 의사소통을 할 떄, 입장차이가 있기 때문에 그것을 조율하는 것이 생각보다 너무 어렵다는 것을 알았습니다. PM은 대단하다고 생각합니다. 내 적성이 아닌가 싶기도 하고 뭐 그렇습니다. ㅎㅎㅎ 남은 기간 프로젝트 화이팅하겠습니다. | G11: 주의
B12: 2 | C12: 박현수 | G12: 대기
B13: 2 | C13: 이균호 | D13: 오늘 역할 분배, 그리고 프로그래밍 작업 준비를 했음. 그리고 작업 진행 중 속도를 보고 추가적으로 시스템 기획 역할도 맡게 됨 | E13: 팀원 간 불만 사항이 조금 있어서 최대한 모나지 않게 서로 대화를 나누는 시간을 가졌다. 서로 감정 상하는 일 없도록 최대한 모나지 않게 조심조심 전달하는 데 굉장히 노력했고 다행히 화기애애한 분위기로 작업을 이어갈 수 있었다. 팀 프로젝트 첫날이라 무엇을 해야할지 정하고 그 안에서도 또 어떤 일을 해야할지 어떻게 해야할지 고민하는 시간을 많이 가졌다. 앞으로 남은 시간 동안 팀원들과 열심히 협력하여 재밌는 게임을 만들어야겠다. | G13: 대기
B14: 2 | C14: 이석훈 | D14: 팀 내 기획 요소 재점검및 논의 팀 내 역할분배 | E14: [팀 내의 갈등] "이석훈님은 자꾸 주제를 자기마음대로 바꾸는거같아요" [현재 팀의 상황/한 행동] 팀 구성원이 A컨텐츠를 ~~하게 넣겠다는 말은 했지만 정확히 A컨텐츠가 어떤식으로 작동하는지는 생각을 덜 해본경우 관련 질문으로 A컨텐츠가 게임에 적용되었을때, A* , A-,A",A' 같은 문제가 발생할 수 있고 그러면 해당 방법은 A-1, A-2,A-3으로도 해결하는데 각 방법은 그러면 어떻게 해결해야할까? 그 문제를 저 방식대로 해결하려고하면기존 기획의도랑 달라질거같은데, 그럼 그걸 살리면서 A-1, A-2, A-3은 어떻게 적용시킬까? 그렇다면 진짜 기획의도는 뭘까? 기획의도는 그래서 정말 기존의 A방식을 활용해서 플레이어에게 경험시켜야할까? 같은 기획의 깊은곳을 물어보는 꼬리질문 속에서 [A 제안 → A의 문제점 발견 → 해결책 모색 → 기획 의도와 충돌 → 근본적인 기획 의도 재점검] 이라고 생각했지만 해당 사실이 팀 구성원들에게는 잘 전달되지 않은 것으로 사료됨. 그 과정속에서 인지부조화를 겪은것이 아닐까 추정 [왜 이런 일이 발생했을까? 느낀 이유는 무엇일까?] 받은 피드백 "필요한 질문인건 알겠는데, 너무 어려워요." "생각해보지 않은 영역에 대해서 질문이 너무 많이 들어와요" "어차피 생각해나가다보면 하게 되는 고민을 일찍 하게 되는거같아요" 추정되는 문제점: 1. 선택지가 없는 서술형 질문을 준비되지 않은 상태에서 받았다 > 과하게 방어적인 대답이 유도되거나, 그렇게 느낌. 2. 질문의 난이도가 높았?다? >언제나 안 생각해본걸 질문을 받자마자 하는건 어렵고 힘들다. 충분한 시간이 필요했던 반면, 계속 마주보고있는 상황(디스코드 등에서) 에서 충분한 시간이 부여되지 못했고, 불합리한 상황이 길어져야만 했다. 3. "나는 부족한 사람인가?" 부정적인 생각의 전염 > 공개적인(조원 다같이 있는곳)장소에서 피드백 및 질의가 오가다보니 눈치보임, 즉시 답해야할거같은 부담이 증가 (어쨋건) 긍정피드백으로 다가오는것이 아니라 답하기 어려운데, 납득은되는, 나는 이런 답을 못하는 사람인가? 라는 생각이 팀 구성원에게 전파되는 위험 소지가 있음. 4. 팀장 부담급증 >팀장 초행인 범진님 기준으로 일정진행 압박 및 퀄리티를 두고 깊은 고민을 하고 있는데 타 구성원의 기획의도를 깊게 파고, 어떻게 적용시킬지 모두 고민하고 결정하는것은 실제로 쉽지 않은 영역이고 결국 부담이 급격히 상승하는 어려움이 발생함. + 실제로 지적되고있는 부분들의 상당수가 최종적으로 팀장이 결정해야하는 영역이고 팀장이 해 왔어야 하는 일인데 놓친 일이라는것을 스스로가 깨닫고 있는 상황이라 팀장의 권위가 위협받는 상황으로 보여질 수 있음 [어떤 개선점을 앞으로 가져야할까] 1. 논의 내용을 우선 듣고 정리 > 즉시 피드백을 가능한 많이 피할것. 팀 내부적으로도 '이런식의 브레이크 자체는 필요하다' 에 모두들 공감하고 있으니 무리해서 팀원들의 자존감을 떨어뜨릴필요 X 2. 정리한 내용을 바탕으로 팀장에게 따로 자리를 잡아 논의를 진행 공개적인 장소에서 이야기를 피함으로서 팀장의 눈치보기우려 없애고 부담감을 낮춘 상황에서 논의를 진행 2-1 그래서 논의 결과는 팀장이 발표하도록, 혹은 팀장이 각 개인에게 전달할 수 있도록 유도하여 팀장의 권위/체면이 손상되지 않도록 만들어 팀장 스스로가 효능감을 느끼고 서로의 의견이 적극적으로 수용되어 퀄리티향상에 도움줄수 있도록 2-3 단, 팀장이 내 의견의 대변인이 되도록 구워삶거나 해서는 안된다. 결정권이 팀장에 있음을 존중하고 준비해온 자료를 바탕으로 건설적인 논의를 할 수 있어야 한다 3. 질문에는 언제나 두가지 이상의 선택지를 제공해 답변하는 팀원으로 하여금 고민의 부담을 낮추고 팀원 개인의 부족함, 모르는 부분에 초점을 잡기보다 건설적인 방향으로의 논점을 잡을수 있도록 논의 진행. 3-1 선택지를 줄 때는 두 가지 모두 기획적으로 타당성이 있거나, 장단점이 뚜렷한 진짜 '고민해 볼 만한 옵션'을 던져주어야한다. 누가봐도 아닌것같은 오답과, 그럴듯한 선택지 두가지를 던져주고서 논의를 진행하면 답정너식의 논의밖에 되지 못한다. 그 점을 깊게 유의하고 제안자의 기획의도에 근접한 타당한 옵션을 제공하여 논의를 건설적으로 유도해야한다. | G14: 주의
B15: 2 | C15: 손호진 | D15: 시스템 기획을 보조하면서 시스템을 잡아가는 과정이 있었습니다. | E15: 시스템 안에서도 다양한 규칙을 정하는 데 많은 시간이 걸렸고, 각각의 장단점을 비교하면서 정해가는 과정이 힘들었지만, 의견 통합을 하고 있는 것 같아 좋았습니다. | G15: 대기
B16: 2 | C16: 정재용 | D16: 캐릭터 컨셉 기획서 작성, 각 캐릭터의 초안을 뽑아 공유 후 어떤 식의 캐릭터를 잡아야 될지 확인 후 확정 | E16: 저희 팀은 120Km로 달려가는 슈퍼카 입니다. 근데 바로 앞에서 좌회전을 해야 돼서 천천히 브레이크를 밟았는데 브레이크의 성능이 너무 좋아 급정거 하는 식으로 멈춰버렸습니다. 멈춘 것은 좋습니다. 그런데 멈추는 방식이 부담이 많이 된 엔진도 있었습니다. 오늘 많은 대화를 들었습니다. 저희 조가 어떻게 이 프로젝트를 완성하게 될지 잘 모르겠습니다. 그래도 저는 팀장 님을 믿고 팀원을 믿고 제 할 일을 묵묵히 해낼 수 밖에 없을 것 같습니다. 화이팅! | G16: 주의
B17: 3 | C17: 김시온 | G17: 대기
B18: 3 | C18: 윤동현 | D18: 오늘은 특전 시스템의 개요, 등장 규칙, 특전 UI등장 위치, 특전의 종류(스탯, 패시브, 스킬), 플레이어 공격 스타일 선택 등등을 작업했습니다. | E18: 특전같은 경우 전투와 관련된 요소가 많기 때문에 아직 스탯의 수치나, 전투 기획자가 바라는 각 공격 스타일에 따른 스킬 연출과 효과 및 모션 등등 같이 논의를 하고 진행해야하는 것이 많았기에 힘들었던 게 첫번째고, 두번째는 각 특전마다의 능력, 효과, 연출, 스킬 이름 등등 설정하는 부분에서 게임의 틀을 넘지 않고 리소스 또한 최대한 적게 하려는 방향으로 하다보니 머리를 좀 많이 쓰게된 것 같습니다. 다음 프로젝트 작업 때는 좀 더 미리미리 정보들을 파악하고 소통을 하여 진행을 해야할 것 같습니다. | G18: 대기
B19: 3 | C19: 장윤우 | D19: 시나리오 - 컨셉 문서 작성, 스프라이트 이미지 생성을 메인으로 진행했습니다. | E19: ai가 말을 안들어요... 이것 때문에 제미나이 프로도 샀는데... 왜 다리를 번갈아서 움직이는걸 못만드냐고!!!! 다리 바꿔달라고 했잖아!!!으아아가ㅏㅏㅏㅏㅏ... 시나리오만 쓰던 때가 그리워요... | G19: 대기
B20: 3 | C20: 정재훈 | D20: 전투 기획서 작성, 전투 기획, 플레이어 스탯, 플레이어 무기 2종, 스테이지 1 잡몹과 보스 기획 | E20: 모션 이미지를 구현하려다 보니 생각보다 이미지 출력에 어려움을 겪고 있는데, ai를 좀더 다루는 연습이 필요할것 같다 | G20: 대기
B21: 3 | C21: 정우경 | D21: 프로그램 시스템 담당, 데모 구현 | E21: 시스템은 어려운것이다. | G21: 대기
B22: 3 | C22: 한재환 | G22: 대기
B23: 4 | C23: 이형진 | D23: WBS된 시스템 기획 기능 명세 및 DB 목록화, DB 예상 컬럼 도출 테스트 및 연습으로 만들었던 테스트 월드를 팀 월드로 이사 및 최적화 팀원 분업 및 업무 지정, 매 쉬는 시간 종료 후 업무 보고/점심시간, 수업 종료 전 중간 보고 3가지 무기 투사체 구현 주말 작업을 대비한 팀원 업무 분업, 기존 사용중 노션 이사, 꾸준한 회의를 통한 방향성 점검 | E23: 저희 팀원분들 모두 훌륭하지만... 왜 컨텐츠 기획 5명 | 시스템 1명(개발)이고 그 한명이 팀장인 저일까요 ㅠㅠㅠㅠ 팀장은 최대한 업무를 덜 받으라고 하셨지만... 생각보다 잘 안되는 것 같습니다 제가 애초에 욕심이 많기도 하고... 그래도 저희 팀원분들 모두 의욕이 넘치시니, 맡은바 끝까지 책임을 다하겠습니다... | G23: 대기
B24: 4 | C24: 곽용준 | D24: 콘텐츠 기획서 작성(연휴동안 수정 요망) | E24: 처음부터 다른 게임을 구상하고 있어서 팀원들을 따라가지 못했다... | G24: 주의
B25: 4 | C25: 이가현 | D25: 메월드 엔진 내에서 코드 넣는 법 정리 팀원에게 게임 방향성 설명 및 규칙 정리 캐릭터 무기 및 공격 방법 구체화_ 컨텐츠정리 | E25: 제작하는 게임에 대해서 방향성이 다른 팀원을 케어했습니다. 레퍼런스 게임을 같이 플레이 하고, 해당 요소 중 저희가 활용하는 부분과 변형하는 부분 등을 설명하였습니다. 이후 해당 팀원과 캐릭터의 공격 방법 및 스타일을 체계화하며 세부 규칙을 설정하였습니다. 업무 종료 전 해당 건을 팀장님과 소통하며 진행방향을 논의하고 업무 분담을 새롭게 했습니다. 이후 회의록 정리 및 플레이어2의 기획을 진행하고자 합니다. | G25: 대기
B26: 4 | C26: 이승진 | D26: 그동안 미리(...) 작업한 기획서 초안을 바탕으로 변경된 점들과 추가된 세부사항을 포함해 세계관, 배경, 캐릭터 컨셉 기획서를 다시 작성했습니다. 야심차게 제목 예시도 몇개 짰는데 제목마저 A.I 돌린거 강사님께 딱 걸려서 제목도 아직 확정짓지 못했습니다. 컨셉 기획서조차 짜야할게 한참 남았기때문에 주말과 설 연휴를 최대한 활용할 생각입니다. 컨셉이 확정되면 리소스 제작으로 돌입할듯 합니다. | E26: 의견교환이 활발하긴 했으나 저를 비롯해서 이제는 다들 양보하는 분위기라 팀 내 이슈는 딱히 없었습니다. 다만 제 의견을 어디까지 개진해야할지 그 부분은 여전히 어렵습니다. 물론 아무 말도 안하는것보단 의견을 내는게 좋기는 하지만... 적정선을 찾긴 어려운거 같습니다. 그래도 책임감있게 이끌어주시는 팀장님과 다른 팀원분들 모두 제 역할에 충실하고 있어서 작업 자체는 순조롭습니다. 다만 마일스톤 내로 완성할수 있을지는 기획도 완성되지 않은 시점이라 아직은 보이지 않습니다. 세부 기획과 개발이 동시에 이뤄지는건 아마 현업에서도 흔하지 않을까 싶어 (그렇지않다면 기획자는 개발기간에 놀테니) 마냥 조급할 필요는 없다고 생각하지만 너무 여유롭게 생각해선 안되겠죠. 오늘 당번을 처음 해봤는데 당번이 생각보다 힘들었습니다. 쉬는 시간을 할애해서 음악을 트는게 전부였는데 그것조차 전 너무 피곤하더라고요. 쉬는시간에도 열심히 작업하는 분들 음악으로 피해나 주는게 아닌가 싶기도 하고... 여튼... 열심히 해봐야겠죠. 매일매일 고민해보고... 매일매일 실행해보고... | G26: 대기
B27: 4 | C27: 오종호 | D27: 메인캐릭터 스프라이트 제작, 상점 캐릭터 제작, 캐릭터 컨셉 제작 | E27: 리소스 만들기 힘듭니다. | G27: 대기
B28: 4 | C28: 임소영 | D28: 게임 전체UI 시스템 규칙 설계 | E28: 팀원분 중에 자신의 작업물에 대한 방향성을 잡기 어려워하시는 분이 계셔서 어떤 부분에서 막히시는지, 문제가 발생한 지점을 찾는 1:1 대화를 진행했습니다. 천천히 대화를 진행하다보니 문서를 작성하는 목적과 목표에 대한 부분이 정확하게 정의되지않아 문서 작업에 어려움을 겪고 있다고 체크되어 작업물에 대한 목적과 목표 설정, 작성 가이드 라인을 제시해드리니 작업에 속도가 붙게 되는걸 확인할 수 있었습니다. 앞으로 다른 팀원분들에게 분업을 나눠드리게 되면 문서를 작성하게 되는 목적, 목표, 의도 등 해당 부분을 가볍게 생각하지않고 명확히 작성해 전달해드리자고 생각하게되었습니다. | G28: 양호
B29: 5 | C29: 승정하 | D29: 일정 관리 양식 정리 프로젝트 컨셉 기획 + 방향성 논의 조율 선정된 원페이지 기획서의 시스템 및 콘텐츠 수정 논의 및 컨펌 2/13 (1일차) 작업 현황 기록 추후 계획 공유 | E29: 팀 역량 파악과 게임 볼륨 조절이 상당히 어렵다고 느꼈습니다... 주어진 자원과 시간을 어떤 범위까지 개발이 가능하다고 판단하는게 참 어렵고, 경험이 중요하다는 생각이 새삼 들었습니다. 그래도 오늘 팀원들이 많이 생산적인 이야기들을 해줘서 통일된 방향성이 생긴것 같아서 앞으로가 기대됩니다. | G29: 대기
B30: 5 | C30: 고승주 | D30: 제작 게임 확정, 세부 컨셉 확정, 파트 분배, WBS, 간트 차트 작성, | E30: 어렵지만 기대가 됩니다. | G30: 대기
B31: 5 | C31: 김민수 | D31: 원페이지 기획서를 발표를 진행하여 게임을 정했습니다 그리고 기획을 일부 세분화를 진행하고 wbs를 나눠 배분했습니다. 저는 바이브코딩을 안티그래비티와 코덱스를 연동하여 쓸 수 있는 환경을 구성했습니다. | E31: 좋습니다 기능이 많아서 걱정은 되는데 노력해봐야죠.. 조금 힘들 거 같긴합니다 | G31: 대기
B32: 5 | C32: 예인해 | D32: 팀 방향성 회의, 기본 이동 구현 | E32: 저희만 정상적으로 오늘부터 진행했는데 이거 맞나요...? | G32: 대기
B33: 5 | C33: 이원홍 | D33: 프로젝트 선정 및 마인드맵 작성 및 세부기획 목록 작성 | E33: 설날이 껴있다보니 일정이 빡셀것같아 두렵습니다. 수고하셨습니다. | G33: 대기
B34: 5 | C34: 한지우 | D34: 세부 일정 리스트 작성 우선순위 작성 컨셉 기획서 초안 작성 | E34: 컨셉을 창조하는면에서 많이 어려웠지만 팀원분들이 친절하게 인도해주시고 정리에 도움주셔서 나도 누군가에게 도움이 될수있는 기회가 온다면 도움이 될수있도록 하자 라는 생각이 드는 하루였습니다 | G34: 대기
... B37: 6 | C37: 김지훈 | D37: 몬스터 이미지 생성, 오픈소스/로컬 생성 모델 개발, 스프라이트 제작 서치 | E37: 늘 챌린지해서 어렵습니다. | G37: 대기
B38: 6 | C38: 김태환 | G38: 대기
B39: 6 | C39: 김태훈 | D39: 엔진에서의 기능 구현 : 캐릭터의 움직임 애니메이션, 마우스 커서에 따른 방향 변화, 마우스 커서에 따른 무기의 각도 변화, 마우스 커서 이미지 교체, 총알 발사 | E39: mlua프로그래밍 하는 거보다 엔진내부기능 쓰는게 더 어려운 것 같습니다... | G39: 대기
B40: 6 | C40: 맹지훈 | D40: 플레이어블 캐릭터 구도별 스프라이트 애니메이션 생성 및 수정 | E40: 저는 참 기분이 좋습니다. | G40: 대기
B41: 7 | C41: 김영도 | D41: 세계관 작성, 캐릭터 기획,팀원들 논의,시나리오 작성, 원페이지 기획 가볍게 작성 | E41: 프로그램 구현 이슈가 있었습니다. 좀 더 명확하게 의도 전달하는 것 방향성을 더 명확하게 전하기 | G41: 대기
B42: 7 | C42: 권수빈 | D42: 캐릭터 플로라, 트리키 기본 설정 (이름, 나이, 호칭, 말투, 외모, 성격(겉), 성격(속), 특징, 취미, 평판, 콤플렉스) | E42: 게임 장르 (포트리스)를 메월드에 구현하는 것에 있어 어려움을 느껴 탄막 슈팅게임으로 장르를 변경할까 팀내 고민도 있었지만, 한번 결정한 장르로 되는데 까지 최대한 해보자는 의견이 나와 최선을 다 해 시도해 보기로 했습니다. | G42: 대기
B43: 7 | C43: 김현우A | G43: 대기
B44: 7 | C44: 박원우 | G44: 대기
...

Sheet 219
B2: 날짜 | C2: 46072
B4: 팀 | C4: 이름 | D4: 작업량 | E4: 한마디 | F4: 비고 | G4: 상태
B5: 1 | C5: 이승구 | D5: 작업 속도에 따른 기획 파트 재분배 레벨 디자인 및 몬스터 기획 - 김수환. 김경민 와이어프레임 작업 - 박영성 장비 기획서 다듬기 - 한의호 카드 기획 - 박영성,한의호 장비 시스템 관련 개발 논의 논점1. 장비 시스템의 세트 옵션의 갯수가 랜덤하게 붙는게 구현이 가능하고 개발 공수가 현실적인가? > 가능 게임의 재미요소, 정체성, 개발 난이도 및 일정, 밸런스를 모두 고려하여 기존 기획을 유지 및 개발 하자는 결론 단, 기획서는 알아볼 수 있도록 재수정 필요함 업무 현황 공유, 기존 기획 및 개발 된 시스템 및 아이템 드롭 시스템 작동 원리 프레젠테이션 레벨 디자인 논의 (김경민,김수환)루프 수를 줄이고 루프를 위한 타일 수를 늘리는 방향은 어떤지? > 타일 수를 늘리게 되면 같은 레벨의 몬스터와 장비를 오랫동안 경험하여 유저 경험을 해치지는 않는가? > 장비 성능이 루프 수에 따라서 증가되는데 타 기획 부서와 논의가 필요함 - 위 내용을 포함하여 다른 방법을 찾아보거나 기각 기획서 확정 (김수환) - 마을 시스템 기획서 확정 > 별도로 수정 X 단, 구체적인 소모량과 제한성 그리고 레벨 제한 등은 이후 장비 기획 이후에 재논의 인벤토리 및 손패 칸 수 제한 - 고민중 메인 기획서 업데이트 | E5: 크게 어려운 점은 없었는데 시간상 안될 것 같은 것들이 개발자가 가능하다고 하는데 걱정이 됩니다. | G5: 대기
B6: 1 | C6: 김경민 | G6: 대기
B7: 1 | C7: 김수환 | D7: 성장 시스템 기획서 작성 / 레벨 디자인 기획서 작성 (진행중) | E7: 점점 프로젝트가 가시화 되어가고 있지만, 그만큼 타협해야 하는 부분도 많아져서 아쉽습니다. | G7: 대기
B8: 1 | C8: 박영성 | G8: 대기
B9: 1 | C9: 유해찬 | D9: 데이터테이블 연동해서 클라이언트에서 사용하기. 그에 따른 임시로 작업해둔 수치 수정. | E9: ; - ; 파...이팅... | G9: 대기
B10: 1 | C10: 한의호 | D10: 장비 데이터 테이블 형식 확립, 임시 데이터 값 입력 및 정리, 스킬 시스템 공동 기획. | E10: 생각보다 어려운 점은 없지만 작업 진행 상황이 살짝 늦는 것 같아 약간 불안한 느낌이 있습니다. | G10: 대기
B11: 2 | C11: 김범진 | D11: 1. 게임 시스템 방향성 설정. 2. 시스템 플로우 차트 출력 3. 이미지 컨셉 확정 SD: 카툰 스타일 | E11: 팀장이라는 자리가 너무 어렵다고 느꼈습니다. 사람이 가장 힘든 것 같습니다. 게임 디테일에 대한 방향을 오늘 오전에 설정해서 완성이 될지 불안한 마음이 있습니다. | F11: [안중재] - 내일 면담 예정 | G11: 주의
B12: 2 | C12: 박현수 | D12: 금일 - 게임의 핵심 싸이클 + 핵심재미 공유 - 전쟁시대 플레이 경험 공유 - 유저에게 압박감 전달 + 구현 방식 에 대한 논의를 아침에 진행하였고 저는 - 적 유닛 종류(어떤 적들이 나와야하는지) - 스킬 구성 - 데이터테이블 컬럼 리스트업 를 작업하는 중입니다(아직 안끝났어요 ㅠㅠ) | E12: 아침에 게임에 대한 핵심 재미 논의가 잘 이루어졌다는 생각이 들었고요 작업진행속도를 더 빨리 할 수있도록 증진해야겠다는 생각이 들었습니다 | G12: 대기
B13: 2 | C13: 이균호 | D13: 오전에 팀원들과 게임 방향성에 대해서 확실하게 다지는 회의를 하고 오후에는 MVP를 위한 플로우차트 작성을 했다. | E13: 조금 느리더라도 착실하게 한 걸음 한 걸음 나아가면서 프로젝트가 진행되고 있다. 예정대로 진행해서 일정 내로 꼭 완성해보고 싶다. | G13: 대기
B14: 2 | C14: 이석훈 | G14: 대기
B15: 2 | C15: 손호진 | D15: 컨텐츠 기획, 데이터 테이블 구성 등 기획 보조 역할을 담당했습니다. | E15: 내일부터 부득이하게 휴가를 쓰게 되어 비는 일정이 생겼습니다. 도움이 될 수 있다면 오늘은 최대한 많은 부분을 서포팅하고 가야 해서, 더 작업을 진행하려고 합니다. | G15: 대기
B16: 2 | C16: 정재용 | D16: 캐릭터 컨셉 이야기 및 아트 초안 공유 | E16: 힘내보겠습니다...! | G16: 대기
B17: 3 | C17: 김시온 | D17: 리소스 관리 규칙 문서 v0.1 작성, 회의록 작성, 특전 시스템 작성 | E17: 메이플스토리 월드는 스프라이트를 자동으로 쪼개주지도 않고, 폰트를 넣을 수도 없다는 충격적인 사실을 알게됐다... 핵심 시스템의 조작이 너무 이질적이고 불편하다는 문제가 생겨버려서 게임의 핵심재미라 정의했던 내용이 엎어질 위기가 생겼다. 뭔가 에블린 패러독스가 발생한것 같기도 하다. 내가 리더에 부담을 느끼는 이유도 결국 이런 상황이 오면 막지 못한 내 책임이라 좀 힘들어서기도 한데... 최대한 지금까지 진행된 상황과 구현하기 어려운 점의 절충안을 빨리 찾고 결정해야겠다. | G17: 대기
B18: 3 | C18: 윤동현 | G18: 대기
B19: 3 | C19: 장윤우 | D19: 카론 캐릭터 디자인, 카론 등장 배경 리소스 제작, bgm 리소스 제작 중, 보스 컨셉 기획 등 | E19: ai와의 치열한 전투였습니다. 후... 다들 열심히 해주는 것 같아서 좋습니다. | G19: 대기
B20: 3 | C20: 정재훈 | D20: 보스 전투 기획, 보스 아트 리소스 작업 | E20: 컨디션 조절을 잘 해야할것같다. 오늘은 연휴 끝나고 바로 시작이라 수면패턴 조절에 실패해서 너무 졸려서 작업시간이 좀 더뎠던 것같다. | G20: 대기
B21: 3 | C21: 정우경 | D21: 시스템 | E21: 시스템은 어렵다. 무한한 에러가 발생하고 있다. 하지만 반드시 해결하고 우리팀은 성공할 것이다. | G21: 대기
B22: 3 | C22: 한재환 | D22: 캐릭터 및 몬스터 관련 각종 데이터 테이블 작성함. | E22: 이전보다 자신있게 말하고 있지만 아직 많이 부족하고 말투 역시 어눌해서 참... 노력해야 겠네요. | G22: 양호
B23: 4 | C23: 이형진 | D23: 2일차(?)답게, 다 같이 모여 방향성을 재검토 1차 완성본 확립, 오늘할 일 오전/오후로 배분 이펙트 구현 오전에 마무리 및 상점 구현 R&D 용준님 피드백 하는 시간이 길어 제대로된 작업 진행 안됨 | E23: 오늘도 느낀점은 팀장은 개발을 맡으면 안되는 것 같습니다... 개발에 온전히 집중할 수 없으니 개발이 밀리고, 그렇다고 프로젝트에 신경을 안쓸 수 없으니 능률이 굉장히 떨어집니다. 또, DB 설계 과정에서 꽤 논리적이었다고 생각했으나, AI에 의해 작성되고, AI에 의해 검증받다 보니, 상당한 허점이 있었던 것을 뒤늦게 파악해버렸습니다. 구현 불가능한 것은 아니나, 비효율적인 부분이 많았습니다. 개발에 몰두하지 않았다면, 좀 더 신경써서 볼 수 있었던 부분이었는데 아쉬운 부분입니다... 또, 팀에서 혼자 작업이 불가능할 만큼 실력? 이해력? 이 부족한 분은 어떻게 끌고 가야하는지 고민입니다. 단순 레퍼런스 조사에도 애를 먹었고, 직접 둘이 같이 작업해서 완성했던 작업을 다시 맡겨드렸더니, 전혀 이해를 못하셔서, 그 인원을 케어하기 위한 인원이 빠져 오히러 -2인이 되는 상황이 발생하고 있습니다. 팀워크라는건 각자의 일에 최선을 다할 수 있는 환경을 만드는 일이라고 생각합니다. 하지만, 팀으로 배정받은 이상 두고갈 수도 없죠... 딜레마입니다... 2인이 달라붙어 0.3인분의 결과물이 나오고, 의욕도 저하됩니다... | G23: 대기
B24: 4 | C24: 곽용준 | D24: 아트 캐릭터 컨텐츠 정리 | E24: 배워야 할 점이 많습니다... 문서 작업 정리 기초 작업부터 배워야 할 것 같습니다 | F24: [김상준] 팀장과의 고민 상담 진행쪽으로 이야기하고, 팀장과도 해당 이슈에 대해 이야기했습니다. 상당히 결과물이 미진했다고 하여, 팀장인 이형진 학생에게 보다 단순한 작업 진행 or 매우 구체적인 작업 방식 안내쪽으로 진행하는 것을 권유했습니다. | G24: 주의
B25: 4 | C25: 이가현 | D25: 몬스터 디자인 : 컨셉, 이미지 리소스, 체력, 이동 속도, 데미지, 등장 비율 밸런싱 디자인 : 몬스터 체력을 기준으로 플레이 타임을 고려하여 캐릭터 공격 수치 조정 | E25: 체력의 한계라기 보다는 집중력의 한계가 있는 것 같습니다. 그리고 개발 담당의 부담을 줄이고자 개발된 기능의 활용을 중점으로 생각하면서 다양한 기믹이 나오게 하고 싶었습니다. 코딩 관련으로 좀 더 공부하고 짜여진 코드를 분석하면서 새로운 기능이나 부담이 가지 않는 방향으로 진행하고자 합니다;. | F25: [안중재] - 정신 관리 리마인드 | G25: 대기
B26: 4 | C26: 이승진 | D26: 1스테이지 몬스터, 보스 기획 1스테이지 몬스터, 보스 리소스 플레이어블 캐릭터(프로그래머, 기획자, 아트 디자이너) 5레벨 단어장 작업 아트 디자이너 1~5레벨 단어장 작업 하루만에 다 끝낸건 아니고 아직 한창 진행중입니다. | E26: 정리정돈 안된 상태에서 막 작업하다보니 공유해야할 내용도 빠졌고 중구난방이었습니다. 몬스터 기획 같은 부분은 한 팀원의 지각으로 급하게 담당하게 된 부분이라 더 그런 감이 있고요. 시스템과 UI을 맡았던 다른 한 팀원은 입원하게 되어서 이쪽도 어떻게 메워야할지 고민인데 일단 다른 팀원이 맡아주기로 했습니다. 기획이 제대로 잡히지 않은 상태에서 기획과 개발이 동시에 굴러가는 정신없는 구조다보니 정말 어지럽긴 하네요. 다만 게임의 많은 영역의 기획을 제가 담당하고 있는 점에서 기획자로서 정말 많이 배웁니다. 컨셉 기획이어도 시스템을 고려해야한다거나, 좀 더 구체화된 기획을 전달해야한다거나 하는 부분들 말이죠. 프로그래머는 오늘도 안된다고 말하는 상황을 직접 겪어보니 와닿는 부분도 많습니다. 오늘 하루도 고생하셨습니다. | G26: 대기
B27: 4 | C27: 오종호 | D27: 플레이어캐릭터 3종 스프라이트 (기본, 공격, 피격, 필살기) 완성. PC 3종 애니메이션화 완료. 캐릭터 3종 선택창용 일러스트 제작 완료. 상점캐릭터 일러스트 제작.기본 시나리오 텍스트 완필. 도입부1,2, 엔딩, 타이틀화면 CG 제작중. | E27: 시스템쪽을 하고 싶지만 그런 상황이 아닌거 같다. 각자 잘하는 쪽을 최대한 활용해서 차질없이 해야 겨우 게임이 완성될거 같은 느낌이다. | G27: 대기
B28: 4 | C28: 임소영 | G28: 대기
B29: 5 | C29: 승정하 | D29: 1. 협업 방식 논의 내용 정리 및 공지 2. 세부 기획서 검토 3. 개별 면담 4. 작업 현황 확인 (매우 간략하게 문서화) | E29: 역량을 파악하고, 공수를 계산하고, 나름대로 고민도 많이 했지만 업무를 어떻게 서로간에 조율할 건지, 또 문서를 어떻게 관리할건지에 대해서조차도 많이 부족함을 느끼고 있는것 같습니다. 팀원분들에게 확실한 업무 진행 과정을 보여주려고 플로우 차트를 만들었는데, 논의한 내용을 다 확실하게 담으려고 자세하게 만들다 보니 도식화의 의미가 퇴색이 되기도 했고, 간트 차트로 정해놓은 마일스톤이 현실적으로 어려운 일정이 되어버려 일정을 크게 손봐야하는 과정도 겪었습니다. 몸도 힘들고 생각할것도 많은 과정인데... 사실 즐겁다는 생각이 크게 듭니다. 일단 제 방식대로 프로젝트 매니징과 게임 개발의 팀장으로서 진행해보고, 팀원분들과 이에 대해서 개방적으로 대화도 나누고 피드백도 받으면서 어떤 점을 개선하면 좋을지 시행착오들을 겪어서, 프로젝트를 완성했을때의 퀄리티는 떨어질지 몰라도, 같이 많이 배울 수 있는 기회가 된 것 같아서 좋습니다. | G29: 대기
B30: 5 | C30: 고승주 | D30: 칸반 작성 - 금일 목표 작업량 설정 플레이어 성장 레벨 디자인 기획 및 데이터 테이블 작성 몬스터 레벨 디자인 기획 및 몬스터 데이터 테이블 작성 | E30: 일일 작업의 계획을 세우고 회고를 작성하는 것이 어려운 것 같습니다. 기획서를 미리 작성하며 기획을 하는 것도 어려운 일인 거 같습니다. | G30: 대기
B31: 5 | C31: 김민수 | G31: 대기
B32: 5 | C32: 예인해 | D32: 연휴 기간동안 작업한 작업물에 대한 피드백과 수정, 추가로 이후 시간에 진행할 작업의 방향 결정.(금일 수업 종료 후, 익일 수업 시작 전까지 전장의 안개 시스템, 무기 레벨업 시스템 기획 예정) | E32: 각 팀들이 작업물을 공유하며 서로가 발전하는 방향이 아닌 팀의 작업물을 숨기고 본인의 것을 하기에도 바빠 교류나 토의 같은 시간이 발생하지 않는거 같습니다. 추가로 ai에게 작업을 대신 시키고 그것으로 끝내는 분들도 있는거 같아서 그 부분이 아쉽다고 생각합니다. | G32: 대기
B33: 5 | C33: 이원홍 | D33: 기획서에서 부족한 부분 추가작성 | E33: 오늘도 그럭저럭 크런치한 하루였습니다. | G33: 대기
B34: 5 | C34: 한지우 | D34: 캐릭터 리소스 R&D 찾기 캐릭터 A의 인게임 캐릭터 리소스 찾기 캐릭터 B의 인게임 캐릭터 리소스 찾기 둘 다 메이플 도트 스타일의 SD 리소스 작업중에 벨루아 즐겨찾기 파츠 날아감….. 컨셉 이미지 첨부 이런 느낌으로 연구소를 표현하자라는 느낌으로 스테이지 AI 이미지 첨부 캐릭터 배경 세밀하게 보충 내용 캐릭터 배경이 게임내의 어떠한 요소에서 보여 지는가? 구체적으로 배경을 함축한 요약 기획의도 | E34: 작업속도가 느려서 고민이기도 하고 ..걱정이 됩니다 저 하나 때문에 팀원분들께서 피해를 보실까봐요 ㅠㅠ 팀원분들 다들 친절하십니다 종종 웃겨서 아이스브레이킹이 자동으로 되는것 같아요 :D | G34: 대기
B35: 6 | C35: 이정헌 | D35: 회의록 작성, 기획서 수정, 논의, 의견 조율, 작업물 검토, 작업 분배, 일정 관리 | E35: 조원 분들이 다 적극적으로 참여해 주셔서 특별한 고민은 없습니다! 다만 중간 중간 시간이 쪼금 씩 비는 부분이 발생하는 것 같은데, 정말 여유가 있어서 인지 아니면 제가 뭔가 놓치고 있어서 여유가 있다고 느끼는 것인지 잘 모르겠습니다. | G35: 대기
B36: 6 | C36: 김윤규 | D36: 챕터 2 시나리오 기획서 및 시나리오 작성, 챕터 2 배경 스토리보드 작성 | E36: 머리가 뜨거워요... 그치만 개인프로젝트가 아니라 '팀프로젝트'여서 이렇게까지 열심히 할 수 있게 되는 것 같습니다! | G36: 대기
B37: 6 | C37: 김지훈 | G37: 대기
B38: 6 | C38: 김태환 | D38: 스테이지 선택/진입 구현 | E38: 메이플 월드 넌 대체 뭐냐. 어째서 코드는 똑같이 복사했는데 새 월드를 만들면 정상작동 하는거냐.......................................................... | F38: [안중재] ㅋ | G38: 대기
B39: 6 | C39: 김태훈 | D39: 엔진 내에서의 기능 구현; 기능목록 : 플레이어의 무기 3종 구현, 적(플레이어 추적, 플레이어에게 데미지, 일정 범위에서 시간당 생성, 피격시 사망),플레이어(피격시 효과, 피격시 데미지, 스킬 2번) 구현 | E39: 엔진이 알면 알수록 어려워지는거 같습니다... 스크립트로 모든것을 제어할줄 안 제 오만을 반성합니다 | G39: 대기
B40: 6 | C40: 맹지훈 | D40: 월드맵 이미지 리소스 생성, 배경 아트 기획서 작성, 1스테이지 적 스프라이트 생성, 스테이지 선택용 UI 리소스 일부 생성. | E40: 팀장님은 제가 혼자 연휴에 작업을 너무 많이해서 당분간 쉬엄쉬엄 작업하라고 하고 싶어하셨지만, 우리는 혹시 모를 작업 지연을 우려하여 대비용 리소스를 뽑기로 했습니다. | G40: 대기
B41: 7 | C41: 김영도 | D41: 시나리오 데이터 테이블,스테이지 테이블 | E41: 그래도 현재는 잘 진행되고 있는 것 같고, 팀원 분들이 열심히 해주셔서 더 탄탄하게 진행방향성을 잡아주면서 간다면 충분히 완성 가능할 것 같다는 생각이 듭니다. | G41: 대기
B42: 7 | C42: 권수빈 | G42: 대기
...

Sheet 220
B2: 날짜 | C2: 46073
B4: 팀 | C4: 이름 | D4: 작업량 | E4: 한마디 | F4: 비고 | G4: 상태
B5: 1 | C5: 이승구 | G5: 대기
B6: 1 | C6: 김경민 | G6: 대기
B7: 1 | C7: 김수환 | D7: 레벨디자인 및 몬스터 디자인 완료 | E7: 게임 스테이지의 진행 방식에 대해 소통이 잘 이루어 지지 못해 다시 의견을 공유하는 시간을 가졌습니다. | G7: 대기
B8: 1 | C8: 박영성 | D8: 의호님과 공동으로 카드(스킬) 시스템 기획 / 초고 기획 문서화 - (3 일차) 2026. 02. 20. 팀 전체 진행 상황 - 밸런스 진입 - 레벨 디자인 / 장비 상호 규격 설정 / 수치 입력 진행 중 - 스테이지 3 우선순위 후순위화. 스테이지 2까지 구현 개인 진행 상황 - 스킬 카드 기획 의호님과 함께 진행 - 내용 구성물 미완 및 공수 양에 따라 시스템 간소화 필요할 가능성 존재 - 현 시점까지 논의된 바 기획 문서화 | E8: 구현하면 좋을 기획 의도는 무궁 무진한데 정말 이게 시간 / 공수와의 싸움인 것 같습니다. 더불어 프로그래머 해주고 계신 해찬님께 너무나 감사드립니다........ | G8: 대기
B9: 1 | C9: 유해찬 | D9: 맵 테이블 연동, 적 캐릭터 테이블 기반 배치 완료 / 배치된 데이터 접촉시 전투시에 사용하는 데이터에 연동하는 과정 진행중. | E9: ; ^ ; | F9: [양윤석] 개발만 하느라 힘들어 보입니다. [김상준] 관련하여 지난주 소통 진행했으며, 힘들긴 하지만 기획적으로도 성장하는 발판이 된다고 생각하고 있습니다. | G9: 대기
B10: 1 | C10: 한의호 | D10: 전투 구현 로직 설계, 데미지 계산 방식 설계 | E10: 게임의 코어 루프 부분에서 팀원 간의 이해 방식이 달라 조정해야 하는 이슈가 있었습니다. 장비 기획 파트인 만큼 레벨 디자인과 깊게 연관 되어있는 작업이다 보니 수치에 대한 조정을 해야 하는 부분에 있어서 난항을 겪었으나 팀원분들과 충분한 상의 끝에 밸런스의 기준을 세우고 작업을 이어나갈 수 있었습니다. | G10: 대기
B11: 2 | C11: 김범진 | G11: 대기
B12: 2 | C12: 박현수 | D12: 어제 아군 유닛과 적유닛에 대한 설계를 마치고 플로우차트를 만들었습니다 공격 로직에 대해서 만들었는데 굉장히 생각해야되는 부분들이 많아서 어려웠습니다 그러나 머리가 아픈만큼 저의 기획역량에 도움이 되는 시간이라 생각하기에 재밌었습니다! | E12: 프로그래밍에 대한 이해가 기획적 사고에 굉장히 많은 도움이 된다는 것을 깨달았습니다 | G12: 대기
B13: 2 | C13: 이균호 | D13: 어제 작성한 플로우차트를 바탕으로 메이플월드에서 MVP 구현 | E13: 범진님이 도와주시는데 코딩하고 있으니까 속이 울렁거립니다... 하하하 | G13: 대기
B14: 2 | C14: 이석훈 | G14: 대기
B15: 2 | C15: 손호진 | G15: 대기
B16: 2 | C16: 정재용 | D16: 생성 캐릭터의 부족한 점을 체크하여 움직임을 표현할 수 있는 것 2프레임 씩 만든 후 공유 | E16: 힘내보겠습니다..! | G16: 대기
B17: 3 | C17: 김시온 | G17: 대기
B18: 3 | C18: 윤동현 | D18: 오늘은 어제 작업하고 마무리하지 못한 특전 관련 UI 및 아이콘 등을 모두 제작 완료했습니다. 추가적으로 WBS를 확인해보니 거의 모든 UI 리소스가 제게 맡겨져서 UI관련 부분은 제가 해본 적이 많이 없던 터라 공부를 좀 해야할 거 같습니다. 특히 관련 이미지들을 손수 제작하려고 했으나 경험이 없던 탓에 시간이 너무 지체되는 것 같아 결국 제미나이 프로를 구매하고 진행하게 되었네요. 물론 프로를 이미 구매한 팀원들에게 도움을 구하거나 일을 맡기는 식의 진행도 가능하기야 하겠지만 해본 적 없던 것이니 이왕에 경험을 하여 나중에 있을 플밍반과의 합반 때를 위해 제가 진행하기로 마음 먹게된 것 같습니다. | E18: 아직까지는 큰 이슈는 없는 것 같습니다. 다만 프로젝트 진행 중에 게임의 장르가 바뀔 수도 있는 의견이 몇 번 나왔어서 작업에 집중이 조금 안된 경험이 있긴 한 것 같습니다. 결국 기존에 정했던 장르로 가게 되었지만, 뭔가 팀의 방향성이 한번 씩 흐트러지는 느낌이라 아쉽긴 한 것 같습니다 | G18: 대기
B19: 3 | C19: 장윤우 | D19: 시나리오 연출 시스템 기획서를 작성했습니다. 튜토리얼 이벤트, npc 등장 이벤트, 엔딩 이벤트, 인게임 텍스트 시스템 등등 | E19: 으윽 시간이 부족해요 시간이! 물리적인 시간이 부족합니다. 욕심은 한가득인데... 그래도 열심히 하겠습니다. 그것이 인간... | G19: 대기
B20: 3 | C20: 정재훈 | D20: 보스 스테이지 제작, 보스 아트 리소스 제작 | E20: 어제 저녁에 갑자기 프로젝트 게임 장르를 바꾸는게 어떠냐는 얘기가 나왔어서 어제 작업을 미처 못하고 오전 회의까지 하다보니 시간을 좀 많이 뺏긴것 같았다. | G20: 대기
B21: 3 | C21: 정우경 | D21: 데모버전 복구 | E21: 에러가 너무 많이 발생한다. 완성할 수 있을지 걱정이다. 하지만 꼭 완성하고 싶다. 내 자신을 너무 갈아넣고 싶지 않다. 하지만 꼭 성공하고 싶다. 팀원들이 많이 도와주는데 감사한 마음과 미안한 마음이 동시에 생긴다. | F21: [양윤석] 월요일날 면담 해보면 좋을거 같아요 [안중재] 정기면담도 진행 전이라 면담 진행하겠습니다 | G21: 대기
B22: 3 | C22: 한재환 | D22: 데이터 테이블 정규화 작업 | E22: 열심히 참여하긴 했지만, 다른 분에 비해 활약하는 건 없는 느낌이 듭니다. 뭐, 그래도 점점 나아질 것이라 생각이 듭니다. | G22: 대기
B23: 4 | C23: 이형진 | G23: 대기
B24: 4 | C24: 곽용준 | D24: 인게임 채팅 UI 작업 완료 | E24: 오늘 작업의 방향성이 어느 정도 잡힌 것 같습니다 | G24: 대기
B25: 4 | C25: 이가현 | D25: 밸런스 디자인 및 QA (무기 데미지, 무기 투사체 개수, 속성 데미지, 적 체력, 적 이동속도, 웨이브 당 등장하는 적 분량, 웨이브 당 등장하는 적 종류 및 비율, 적 처치 후 획득 골드) 엔진 코드 해석 적 모델 추가 (1~3스테이지 용 약한 모델) | E25: 밸런스 디자인에 너무 다양한 요소가 얽혀 있어 특정한 값을 지정하기가 어려웠습니다. 무기 1가지의 공격력을 강화하면 다른 무기와의 조합과 밸런스가 무너지고, 적을 약화하자니 이후 스테이지를 위해 적 모델 생성의 공수가 올라가는 등의 고민이 많았습니다. 특히 타자 게임으로 유저의 타자 속도에 따라 격차가 강하기 때문에 팀원들에게 잦은 QA를 요청하며 의견을 듣는 과정이 필수적이었습니다. | G25: 대기
B26: 4 | C26: 이승진 | D26: 배경 리소스 탐방 UI 디자인 기획 보조 | E26: UI 디자인 방향을 잡는게 처음이라 이게 좀 난항이었습니다. 사실 제 담당도 아니었는데 열심히 보조하다보니 제 할일에 집중하진 못했습니다. 하지만 UI 방향성을 잡으면서 UI 기획에 대해 많이 고민해보고 팀원들의 조언을 통해 많이 배울수 있었던 하루였기에 배울점은 많았다 싶어서 만족스럽습니다. 제 담당 자체가 우선순위가 높은 편은 아니기때문에 좀 더 시급한 UI쪽을 도와주는게 올바른 판단이지않았나 싶습니다. 야근... 을 통해 제 할일을 마저하는것도 좋지만 주말도 있고 오늘은 쉬자는 이야기들이 나왔으니 저도 오늘은 좀 쉴듯 합니다. 오늘 하루도 모두들 감사했습니다. | G26: 대기
B27: 4 | C27: 오종호 | D27: 캐릭터&타이틀 BGM, 게임 QA, 필살기 기획 | E27: 열심히 잘하고 있고 팀 분위기도 잘 살리고 있는거 같다 나 칭찬해 | G27: 대기
B28: 4 | C28: 임소영 | G28: 대기
B29: 5 | C29: 승정하 | G29: 대기
B30: 5 | C30: 고승주 | G30: 대기
B31: 5 | C31: 김민수 | D31: 팀원들 기획서 템플릿에 맞춰 수정, 지침서 작성, 몬스터 스폰 시스템 구성, 랭킹 시스템 재논의 무기발사시스템 재논의 | E31: 생각보다 구현위치에 오니 기획서에 들어가면 좋겠는 내용이 너무 많아서 많은걸 배우고 있습니다 | G31: 대기
B32: 5 | C32: 예인해 | D32: 무기 레벨업 기획, 아이템 드랍 루팅 기획, (타이머 시스템 리빌딩 진행중...), 무한모드, 패널티 시스템 초기안 작성 | E32: 뜌땨이땨땨 사람이 개처럼 일하는데 어필을 안하면 사람을 개로 본다를 알았읍니다. 응애... | G32: 주의
B33: 5 | C33: 이원홍 | D33: 수정사항 반영 및 맡은 기획서 컨펌 완료, 다른 업무 추가지원 | E33: 오늘도 고생하십니다 모두! | G33: 대기
B34: 5 | C34: 한지우 | D34: 오늘 하루는 컨셉으로 잡은 실험실 테마 리소스 찾아서 즐겨찾기 등록하고 문서에 옮겨놓는 작업을 했습니다 별로 없을줄 알았는데 찾아보니 꽤 많이 있었습니다 | E34: 눈이 바쁜 하루였구용 ㅠㅠ 컨디션도 잘 챙겨야 겠습니다! | G34: 대기
B35: 6 | C35: 이정헌 | D35: 기획서 정리, 작업 일정 추가 그리고 수정 및 재분배, ppt발표자료 초기준비, 회의록 작성, 데이터 테이블 초안작성, 아트 리소스 검수, 사운드 리소스 검수, 탄환 사출이미지 리소스 제작 | E35: 순항중인 것 같습니다. 월드를 따로 생성하여 기능구현 두분이서 따로 작업을 하고 있는데 합쳐서 충돌만 나지 않는다면 큰 문제가 없을것 같습니다. 오히려 너무 순항중인듯 하여 놓치고 있는게 있는가 걱정이 듭니다. | G35: 대기
B36: 6 | C36: 김윤규 | D36: 사운드 작업 및 게임 배경음악 작업 | E36: 사운드쪽은 처음 만져보는데 머리가 많이 뜨겁습니다... 효과음같은 게 많이 골때리네요... | G36: 대기
B37: 6 | C37: 김지훈 | D37: 보스/몬스터 다운샘플링, 스프라이트 생성 | E37: 디자인만 하다보니 재미가 없는 거 같습니다 | G37: 대기
B38: 6 | C38: 김태환 | D38: 스테이지 선택 / 대화창 프리셋 완성 | E38: 바이브 코딩은 꼭 하나하나 점검해나가면서 작성하자... 나중에 고치려고하면 코드내용을 확실하게 아는 것이 아니라 고치기 너무 힘들다.......... | G38: 대기
B39: 6 | C39: 김태훈 | D39: 플레이어 HPui 제작, 플레이어 레벨 및 경험치 로직 제작, 무기스킬 완성, 적 2종류 로직 완성 | E39: 개발하고 항상 메모를 해야 되는 버릇을 가져야 된다고 생각이 된 하루인것 같습니다. 어제한거를 오늘 까먹어요 ㅠㅠ | G39: 대기
B40: 6 | C40: 맹지훈 | D40: 대비용 캐릭터 스프라이트 작업, 로비 이동 타이틀 샷 작업, UI 아트 관련 기획서 1목차 작성(메인 스테이지) | E40: 저는 적 스프라이트가 완성이 안될까 우려가 심합니다. 점점 이미지 화질 높이는 방법이 구체화해가고 있습니다. | G40: 대기
B41: 7 | C41: 김영도 | D41: 통합 기획서 데이터 테이블 작성 | E41: 아직 메이플 월드 시스템 구축에 좀 힘든 점이 있는 것 같다는 생각이 듭니다. | G41: 대기
B42: 7 | C42: 권수빈 | D42: 사운드 기획서 작성, 배경 음악 1 생성, 효과음 생성 및 수집 | E42: 프로젝트는 잘 진행되고 있고, 어제는 개인사정으로 프로젝트에 참여하지 못했기에 남은 시간 더 열심히 해야겠습니다. | G42: 대기
...

Sheet 223
B2: 날짜 | C2: 46076
B4: 팀 | C4: 이름 | D4: 작업량 | E4: 한마디 | F4: 비고 | G4: 상태
B5: 1 | C5: 이승구 | D5: 리소스 수집 업무 지정 발표자료 작성 | E5: 살려주세요! | G5: 주의
B6: 1 | C6: 김경민 | G6: 대기
B7: 1 | C7: 김수환 | D7: 메인 타이틀 페이지 생성 | E7: 점차 게임이 만들어 지고 있어 가시화 되고 있는 것 같습니다. | G7: 대기
B8: 1 | C8: 박영성 | D8: - 타일 관련 리소스 산출 작업 - 필수 리소스들 1차 초안 산출 완료 (맵 / 구획별 길 타일 1개 혹은 후보군) - 데코레이션 타일 작업 게시 - 데코레이션 타일 1스테이지 분량 초안 산출 완료 | E8: 내일 대학교 휴학 문제로 불가피하게 하루를 비워야 하는데 한창 다들 일하고 있을때 죄송스러운 기분이 듭니다... 남은 시간은 더 열심히 해야겠습니다 | G8: 대기
B9: 1 | C9: 유해찬 | G9: 대기
B10: 1 | C10: 한의호 | D10: 배경 리소스 추출 및 보정 작업 | E10: 하루 종일 AI 써서 배경 리소스만 뽑으니 머리 쓸 일이 줄어서 편하긴 한데 imageFX가 이상하게 이미지 뽑으면 답답해서 소통이 안 되는 동료와 함께 일 하면 이런 기분이겠구나 싶다는 느낌이 들었습니다. | G10: 대기
B11: 2 | C11: 김범진 | D11: 게임 로직 진행, 팀원간의 작업 분배 시작했습니다. | E11: 오늘 작업이 많이 바빠서 회고를 짧게 올리겠습니다. 여유되면 제대로 작성하겠습니다. | G11: 대기
B12: 2 | C12: 박현수 | D12: - 중간 기획서 작성(1시간 내외로) - 정예몹 소환조건 설정 - 수치 데이터 - 넉백 + 피격제한(플로우차트 - 스킬 + 스테이지 설계 | E12: 프로젝트가 마무리되는 단계이고 꼭 출시할 수 있도록 마지막까지 열심히 할 생각입니다! | G12: 대기
B13: 2 | C13: 이균호 | D13: 타이틀 화면부터 엔딩화면까지 플로우차트 작성 그리고 필요한 UI 이미지 작업 | E13: 오늘은 코딩도 아니고 기획서 작성도 아니고 엔진을 많이 만지는 날이었다. 직접 만져보니 개발자가 게임을 만들기 쉽도록 도와주는 프로그램이란 말이 어떤 의미인지 느꼈다. | G13: 대기
B14: 2 | C14: 이석훈 | G14: 대기
B15: 2 | C15: 손호진 | G15: 대기
B16: 2 | C16: 정재용 | D16: 모든 이미지의 누끼를 따고 이미지 변화 및 배경화면 작업 | E16: 앞으로 일주일도 안남았네요.. 더욱더 힘내보겠습니다 | G16: 대기
B17: 3 | C17: 김시온 | D17: 튜토리얼 스테이지스프라이트 교체 및 배경, 배경음까지 배치 완료. 레벨디자인에서 건들 것은 없으며, 예상 튜토리얼 시간은 40초 정도. 중간 보고 제출. WBS 업데이트. map02 레벨디자인 중. 경험치 공식(예상 테이블)도 제공할 예정. 지수 함수에 보정을 섞을 수 있음. | E17: 슬슬 눈이 화끈화끈하고 몸이 이상신호를 보내긴 합니다 ㅋㅋㅋㅋ 그래도 점점 완성되고 있는 게 눈에 보여 기분이 좋습니다. | G17: 대기
B18: 3 | C18: 윤동현 | D18: 스킬 세부 기획서 v0.2 (타격 판정, 타입 / 타수 / 사거리 / 데미지 및 효과 등등) / 망치 클래스 스킬 스프라이트 제작 | E18: 콘텐츠 기획서 상에 특전 스킬에 대한 기획서가 작성되어있었지만, 너무 설명서? 같은 느낌이라 특전 스킬에 관해 세부적으로 정리한 기획서를 작성하였습니다. 그리고 스킬 이펙트 스프라이트 제작의 경우 제가 프롬프트를 잘 못 주는 건지 맘에 드는 스프라이트 시트가 나오질 않아서 시간을 많이 태워먹은 것 같습니다.. | G18: 대기
B19: 3 | C19: 장윤우 | D19: 검스킬 사운드 1234 추가, 일반 몬스터 c 생산, 엘리트 몬스터 1 idle, skill1, skill2 제작 시나리오 데이터 시트 제작( 추후 추가 수정) | E19: 구글 제미나이와 루도는 신이야!구글 제미나이와 루도는 신이야!구글 제미나이와 루도는 신이야!구글 제미나이와 루도는 신이야!구글 제미나이와 루도는 신이야!구글 제미나이와 루도는 신이야!구글 제미나이와 루도는 신이야!구글 제미나이와 루도는 신이야!구글 제미나이와 루도는 신이야! | G19: 대기
B20: 3 | C20: 정재훈 | D20: 보스 스테이지 제작 완료, 엔딩 시나리오 스테이지 80퍼센트 완성 | E20: 디벨로켓 아트반이 있었다면... 아트에 들이는 시간을 줄일 수 있지 않았을까? 하는 생각을 하곤 합니다 | G20: 대기
B21: 3 | C21: 정우경 | G21: 대기
B22: 3 | C22: 한재환 | D22: Ruid로 수정, 이미지와 연출 두 가지로 나눔. | E22: 흠... 잘하고 있는지는 모르겠네요. 다들 잘하시는 분들이라.. | G22: 대기
B23: 4 | C23: 이형진 | D23: 아침 회의 게임 방향성 결정 (완성형 게임) 레벨디자인 피드백 및 공동 작업 UI 피드백 및 팀원 상담, 공동 작업 데미지 출력 구현 갈아 엎은 DB 불러오기, 상점에 적용 기획서 피드백 칸반 작성 및 최신화 | E23: 팀장부터 의욕이 점점 빠지기 시작합니다... 체력 이슈인 것인지 월요병인 것인지 팀원들의 사기도 조금씩 꺾이고 있는 것이 보였습니다. 어떻게 해야 이 의욕이 조금씩 잔잔하게 타오를지 고민입니다... 근데 반대로 팀원들에게 "일 좀 주세요!" 하고 쪼아지는 느낌입니다... | F23: [김상준] 리소스 퀄리티 업 쪽에 대한 작업을 추가 지시했다고 합니다. | G23: 주의
B24: 4 | C24: 곽용준 | D24: 마켓 UI (배경, 스킬 아이콘 하나씩) 피스톨, 샷건, 스나이퍼, 관통, 연사, 출혈 1, 2, 3, 4, 5, 6 선술집 배경 같은 느낌 반영 완료 | E24: 팀장님과 앞으로의 방향성에 대한 이야기를 하여서 좋았습니다 앞으로 다른 학우분들과도 좋은 대화를 하며 배울 수 있었으면 좋겠습니다 | G24: 대기
B25: 4 | C25: 이가현 | D25: 경제 밸런싱 디자인 : 웨이브당 등장하는 적의 수, 적 처치 시 획득하는 보상, 강화에 필요한 재화, 유저의 예상 레벨 등을 고려하여 재화 가치를 조정했습니다. 최종 스테이지 직전에 전체 만렙이 아닌 6개의 항목 중 3개 이상 만렙이고 4개까지는 만렙이 되지 않도록 조정하는 것이 목표였습니다. 이를 위해서, 최대 획득 재화량과 각 스테이지별 분배, 몬스터 스폰 개수를 정리했습니다. | E25: 3일 동안 밸런스만 만지고 있어서 조금 답답하고 막막합니다. 정말 너무 많은 요소들이 연계되어 있어서 한 가지를 확정 지을 수 없는데, 기준점이 없다는 것이 진행을 더디게하니 진행이 안되고 있는 것 같습니다. 우선 오늘 강화 비용과 재화 기준을 확정하고 이후 공격력과 몬스터 체력을 조정하며 레벨 벨런스가 진행될 것이라 기대해봅니댜 | G25: 대기
B26: 4 | C26: 이승진 | D26: 단어장 난이도 수정 필살기 대사 3종 | E26: 팀에서 저에게 거는 기대가 별로 없는거 같아서 편한듯 하면서도 불편하네요. 의욕만 앞서고 능력은 별로 없는 팀원이었던거 같습니다. 저도 이것저것 분명히 많이 한거 같은데 팀원들의 신뢰를 얻을만큼 잘하진 못했던거 같아요. 슬프지만 이번에 느낀 제 한계점들 잘 파악해서 다음엔 더 잘해야겠죠. | F26: [김상준] DM으로 소통해보겠습니다. | G26: 주의
B27: 4 | C27: 오종호 | D27: 모든 캐릭터 필살기 연출 제작 | E27: 영혼을 갈아만든 내 딸들이 검열을 당할 위기에 쳐해있다. | G27: 대기
B28: 4 | C28: 임소영 | D28: 컨셉 기획서, QA | E28: 핵심 콘텐츠 어느정도 완성되서 1스테이지 레벨 디자인을 다같이 진행했습니다. | G28: 대기
B29: 5 | C29: 승정하 | G29: 대기
B30: 5 | C30: 고승주 | D30: 콘텐츠 기획서 개선 작업 1. 레퍼런스 추가, 보스 패턴 가독성 향상 차 표 작성 2. 상점 콘텐츠, 무한모드 콘텐츠, 랭킹 콘텐츠 기획서 개선 작업 | E30: 작업 속도가 안나오는 거 같아 팀원들에게 미안하군요 | G30: 대기
B31: 5 | C31: 김민수 | D31: 데이터 테이블 정규화, 캐릭터 컨셉 A,B 기획서 재작성, 2d 도트 아트 리소스 작업 | E31: 구현할 수 없는 기획서가 많아서 기획서를 재점검했습니다. 너무 힘듭니다. 모두를 믿고 가는게 맞다고 생각했는데 역량 차이에서 오는 인원들의 부담을 해소할 좋은 방법이 있을까요 | G31: 대기
B32: 5 | C32: 예인해 | D32: 타이머 시스템 리빌딩, 보스 시스템 기획, 무기 콘텐츠 기획서 수정 | E32: 살려주세ㅛ... | G32: 대기
B33: 5 | C33: 이원홍 | D33: 맵타일 만들기, 몬스터 아트 리소스정리, QA 참고용 성장디자인 곡선작성, 추가적인 아트 리소스 RUID 정리 | E33: 당번도 하면서 할일이 많았지만 저도 그렇고 다들 오늘도 고생 많으셨습니다. | G33: 대기
B34: 5 | C34: 한지우 | D34: 로그라이크 장르에 이해도를 높히기 위한 래퍼런스 게임을 플레이 해봤구요 QA리스트를 급하게 짜게 됬습니다 처음짜는거라 머리가 어지럽군요 | E34: QA리스트 작성은 게임을 쪼개는 작업 같습니다 복잡하네용 | G34: 대기
B35: 6 | C35: 이정헌 | D35: 기획서 수정 및 정리, 작업 진행내역 검토, 작업 재분배, 사운드 리소스 선별작업 '팀원 사기 북돋아주기' | E35: 정신없는 것에 익숙해져 있어서 그런지, 문제가 없는 부분이 제가 놓친게 있지 않나 하는 불안이 들면서도, 잘 협조해주시는 팀원들 분들에게 감사한 마음입니다. | G35: 대기
B36: 6 | C36: 김윤규 | D36: 어제꺼인데 몸이 안좋아 조퇴를 해서 작성을 못했습니다 ㅠ | E36: 프로젝트도 좋지만 역시 몸관리가 가장 중요한 것 같습니다! | G36: 대기
B37: 6 | C37: 김지훈 | D37: 몬스터 사망 동작/효과 구현, 기본 스프라이트 스플릿 및 완성, 기획서 완성 | E37: 슬슬 노트북이 한계가 와서 업그레이드를 하고 있다. | G37: 대기
B38: 6 | C38: 김태환 | D38: 작성한 코드 합치기 전체 사이클 구현하기 | E38: 작업이 진행될수록 시간의 압박을 느끼는중... 정리가 중요하다. 언제나 내가 지금 하고 있는 일, 해야하는 일을 시각화 할 수 있기를. 나중에 뭐랑 같이 해야지가 늘어나면 기간에 맞출 수 없다. | G38: 대기
B39: 6 | C39: 김태훈 | D39: 내외부 시스템 통합 작업, 타이머 구현, 시스템(플레이어, 전투)기획서 작성 중, 맵 이동 구현 | E39: 시스템 기획서를 쓰는데 뭔가 양이 적고 더 적을게 있어야 될거 같지만 더 적을게 생각나지 않는게 고통스러운 것 같습니다 ㅠㅠ | G39: 대기
B40: 6 | C40: 맹지훈 | D40: 메인화면 UI 및 스프라이트 이미지 작업 진행, 선택 카드 UI 디자인 작업 진행, UI 아트 관련 기획서 수정 및 추가 작성, 엔딩 이미지 컷신 작업 진행(3/5), 포트레잇용 콘셉트 아트 작업 계획. | E40: 서브 아트분이 프로젝트 마무리하기 3일전인데도 스프라이트 작업이 안끝납니다. 시나리오분이 제가 작업할 적 포트레잇 콘셉안잡아두기 + 기획서마다 명칭 통일화안되어 있어서 오늘 작업할 포트레잇 이미지 작업 중 절반이 다음날로 지연되었습니다. 어느정도 아트 작업 쌓인거 다 끝냈다 싶었더니 엔딩 크레딧 작업이 들어왔습니다. 서브 아트는 아직도 일분배가 안되는 상황입니다. 스프라이트가 완성이 안됐습니다 아직도. 화가났지만 일단 팀장님께 우선 보고 후 익일 논의에서 해결하는 것으로 결론이 났습니다. 내일 면담을 부탁드려야할지 깊은 고민을 하는 날이었습니다. | F40: [김상준] DM으로 소통 완료했습니다. 김지훈 학생의 작업 속도가 너무 느린 점에 대해 팀장인 이정헌 학생과 이미 소통을 계속 진행하고 있고, 작업 속도가 느린 원인은 항상 '토큰을 금방 다 소모해서' 였다고 합니다. | G40: 주의
B41: 7 | C41: 김영도 | D41: 시스템 타이틀 작업 스테이지 분류 진행 작업 통합기획서 작성 추가 콘텐츠 구상 | E41: 메이플 월드가 참 이상합니다. 차라리 유니티면 ai가 더 잘 설명해 줄텐데 이런 생각이 듭니다 | G41: 대기
B42: 7 | C42: 권수빈 | D42: 비는 bgm, sfx 생성, 게임에 삽입될 비주얼 노벨 bgm 항목 스크립트 작성 | E42: 열심히 하겠습니다. | G42: 대기
...

Sheet 224
B2: 날짜 | C2: 46077
B4: 팀 | C4: 이름 | D4: 작업량 | E4: 한마디 | F4: 비고 | G4: 상태
B5: 1 | C5: 이승구 | D5: 시스템 기획 시각화 아이템 드롭 ~ 획득 장비 장착~ 해제 인벤토리 발표자료 준비 업무분배 레벨 디자인 조형물 타일, 타일 배치 - 김경민 조형물 타일 제작 - 한의호 | E5: 해찬님 미안해요~! ㅠㅠ | G5: 대기
B6: 1 | C6: 김경민 | D6: 사운드 리소스 작업 마무리, QA 후 간략한 전투UI 구상도 완성, 스테이지1 맵 배경과 타일 배치및 구상 | E6: - | G6: 대기
B7: 1 | C7: 김수환 | G7: 대기
B8: 1 | C8: 박영성 | G8: 대기
B9: 1 | C9: 유해찬 | D9: 기획서에 따라 보상 아이템 생성 규칙에 따라 보상아이템 생성 및 테이블에서 가져오기위해 테이블 생성, 해당 내용 저장 및 보여주기 . | E9: 정보공유.. 작업 내용 공유.. 가 매우 중요하다는 것을 또 깨우쳐간다! | G9: 대기
B10: 1 | C10: 한의호 | D10: 인게임 데코레이션 타일 이미지 생성 및 수정 작업 | E10: 제미나이에게 철저히 능욕 당하면서 아직 인간이 업계에 발 디딜 공간이 남아있다는 부분에 대한 안도감을 대가로 스트레스로 수명을 15년 잃었습니다... | G10: 대기
B11: 2 | C11: 김범진 | D11: QA 진행하고 있고 에러 수정 중 입니다. | E11: 많은 점이 있지만, 특히나 프로젝트 막바지에 있어서 팀원들과의 대화가 많아져서 좋았습니다. | G11: 대기
B12: 2 | C12: 박현수 | D12: - 타이틀 표지 + 이미지 로고 - 카메라 줌인아웃 체크 - QA 시 발생 문제점들 정리 후 전달 | E12: QA를 하는데 1 이라는 문제가 발생을 해서 얘를 체크해보면 1-1, 1-2,, 이런식으로 계속 생기니까 너무 골때립니다 ㅋㅋㅋㅋㅋ 왜 버퍼를 넉넉히 둬야하는지 몸으로 깨우치고있어요 | G12: 대기
B13: 2 | C13: 이균호 | D13: 오늘은 어제에 이어 UI 리소스 작업 남은 것 마무리하고 이것저것 자잘한 기능 추가나 버그를 고쳤다. | E13: 어제 범진님이 정말 엄청나게 기능들을 추가하셨는데 그 때문인지 오늘은 콜라에 멘토스 넣은 것 마냥 버그가 불어났다. 오늘 하루는 이걸 고치느라 다 쓰셨다. 내일은 이 버그들을 어느 정도 잡아서 나머지 남은 부분을 구현하여 완성할 수 있으면 좋겠다. | G13: 대기
B14: 2 | C14: 이석훈 | F14: 휴가자 | G14: 대기
B15: 2 | C15: 손호진 | D15: 현재까지 만들어진 인게임 구현에 따라 QA를 진행하고, 의도되지 않은 기능과 버그를 발견하여 수정 방안을 제시하였습니다. | E15: 이미 만들어진 기능을 바꿔야했던 번거로움이 있을 것 같아, 작업을 이어서 하면서 기능이 잘 구현되는지 체크해보고 다른 방향성도 제시하는 등 도움을 주었습니다. | G15: 대기
B16: 2 | C16: 정재용 | D16: BGM, 게임 스테이지 배경 작업, 타워 작업 | E16: 다들 프로젝트의 끝이 가까워서 그런지 다들 조용히 집중만 하는 것 같습니다... 분위기가 살벌해요.. | G16: 대기
B17: 3 | C17: 김시온 | D17: 밸런싱 시트 만들기... 수식 만들고, 뜯고... 다시 만들고 뜯고... 이를 바탕으로 map별 몬스터 배치도 하는 중. | E17: 밸런싱 어떻게 하나요.. 너무 어려워요 흐어어어... 캐릭터 조작은 간단하고 당연한 부분이라 생각했는데, 조작에 관한 규칙을 정리한 문서도 분명 필요했겠다는 생각이 들고 있다. | G17: 대기
B18: 3 | C18: 윤동현 | D18: - 검/망치 스킬 스프라이트 완료 - 스킬 세부 기획서 v0.3 업데이트 (스킬 이펙트 및 사거리 규격 정의, 패시브 1종 데미지 수정 및 이펙트 효과,규격, 스프라이트 추가 완료) - UI 배치 작업 중 (체력, 경험치바 수정 해야함.(테두리 1, 게이지 2, 뒷배경 3 순으로 구분화)) | E18: 저는 일단 저희 팀을 칭찬하겠습니다. 서로 맡은 파트가 아니여도 시간이 된다면 다들 도와주거나 겸업하여 진행해주시는 팀원분들 너무 감사합니다. 그리고 특히 팀장인 시온님.. 여러 파트에서 필요한 부분들을 도와주시거나 업을 해주셔서 정말 도움이 많이 되고 있습니다... 음 그리고 오늘은 작업 중에 WBS 상에서 작업 현황이 적혀는 있지만 최신화가 제대로 이루어지는지 확인이 잘 안되어서 팀장님께도 물어보며 제가 할 일이나 팀원이 이미 해버린 일 등등 최신화 작업도 하였고, 아직 스킬들의 수치나 범위 등등에 대해서도 정해지지 않았기에 얼른 완성을 해보고 QA를 진행해야하는데 게임의 스케일이 커진 건지 저희가 느린 건지 .. 얼른 빠르게 작업하여 완성을 해야할 것 같습니다 .. | G18: 양호
B19: 3 | C19: 장윤우 | D19: 엘리트 보스 B 작업 완료 ( Idle, die, 그로기 전환, 그로기 상태, 그로기 복원, patten1, patten2, attack ) 로비 및 엔딩 노래 작업 중 | E19: 오늘 신을 만나는 토큰을 모두 사용해버렸습니다....크아아아악!!!! 신이시여 제발!!!! | G19: 대기
B20: 3 | C20: 정재훈 | D20: 엔딩 스테이지 마무리, 엘리트보스 스테이지 패턴 구현, 이미지 제작, 두번째 엘보 기획서 작성, 아트 리소스 제작 | E20: 개발자가 없어서 바이브코딩에 의존하다보니, 제미나이 한도에 막혔을때 너무 무력함이 느껴집니다 프로 업그레이드했는데 왜이렇게 빨리 막히는걸까 | G20: 대기
B21: 3 | C21: 정우경 | D21: 트리거 제공, 특전 정리, | E21: 무너진 폐허에서 건물을 다시 세우는 기분, 모든 걸 놓고 싶었지만 팀원들의 도움으로 극복하고 있다. 감사하고 끝까지 최선을 다하고 싶다. | G21: 대기
B22: 3 | C22: 한재환 | D22: 수정된 특전 데이터 테이블 재작성, 이미지와 모션이 추가된 부분을 데이터 테이블에 추가 완료 몬스터 데이터 테이블 수정 시작, 버그 리포트 체크리스트의 우선순위와 위험도를 추가해 작성 | E22: 화이팅! | G22: 대기
B23: 4 | C23: 이형진 | D23: 아침 회의 및 일감 배분 기획서 및 리소스 피드백 필살기 구현 및 HP바 구현 게임 난이도 피드백 | E23: 오늘 팀장 분들과 얘기를 나눴을 때도, 다른 기획 4기 분들과 얘기를 나눴을 때도, 강사님들과 얘기를 나눴을 때도, 항상 이석훈님에 대한 피해를 호소하셨습니다. 저도 팀원들과 디스코드에서 회의 중 난입하셔서 반말 섞인 말투 + 특유의 공격적 어투 + 친절하게 말해도 본인이 피해자라 생각하며 망상을 하십니다. 그래도 친절하게 얘기를 마무리 하고, "회의 마무리를 위해 자리를 비켜주셨으면 좋겠습니다" 라고 말씀드렸으나 "아 꺼지라고요? 예~ 꺼져드릴께요~" 라며 상당히 팀의 분위기를 해치셨습니다. 외에도, 얇은 개인적 경험을 지식이라 생각하며 남을 가르치려 들고, 어디서 주워들은 이상한 말로 꼬치꼬치 트집을 잡으십니다. 아마 피해 사례는 저 말고도 많은 분들이 호소하셨을 것이라 생각되는데요, 오늘 강사님과 면담을 하면서 직접적으로 말씀 드렸지만, 저는 이런 분과 프로젝트를 진행하며 피해를 보고 싶지 않습니다. 또, 할 마음도 없습니다. 운영진 분들도 충분히 고민하고 계신다고 생각하고, 국가지원사업인 만큼 어쩔 수 없다고는 생각하나, 저는 언젠가 도려내야할 부분이라고 생각합니다. 이런걸 직접적으로 잘 말씀드리지 않으나, 피해를 보신 분들이 많고, 지금이야 3일, 일주일 프로젝트라서 "놓아준다" 라는 느낌으로 포기하시는 분들도 많습니다. 하지만, 그 한 분 때문에 여러 명의 팀원이 한 달 이상의 프로젝트에서 손해를 보게 된다면, 저는 그것이 단순 개인의 책임만 있을 것 같지는 않습니다. 부디, 학원 측에서도 좋은 결정이 나와 더 이상 피해보는 인원이 없었으면 좋겠습니다. | G23: 주의
B24: 4 | C24: 곽용준 | D24: 상점 UI 제작 | E24: 해야할 일을 먼저 끝내고 다른 일을 배워보려고 하자 | G24: 대기
B25: 4 | C25: 이가현 | D25: 벨런싱 마무리 작업 완료, 팀원들과 QA 하며 웨이브별 세부 벨런스를 조정하고 있습니다. 벨런스를 조절하는 방법이 다양해서 여러 의견을 들으며 조정 할 수 있었습니다. 하지만 제한된 인원에서 반복된 QA로 난이도나 루즈해지는 주관적인 평가가 퇴색됨을 느끼고 있습니다. | E25: 오늘의 플래그 : 이거 금방 끝나서, 끝나면 도와드릴게요 QA 나 세부 사항 보완 작업이 끝날 듯 끝나지 않고 있습니다. 지루한 작업이기도 하고 노가다성 작업도 많은데 그렇다고 간단간단하게 하기에는 게임에 영향력이 작지 않은 부분이더군요. 늘 현실에 맞춰서 중요하고 필요한 부분을 포기해야하는데 그러한 가치판단 합의가 어려웠습니다. 될때까지 해보자는 분과 만들어진 걸 보완하자는 의견이 달라서 조금 방황하기도 했습니다. | G25: 대기
B26: 4 | C26: 이승진 | D26: 무기 이펙트 리소스 DB화 무기 이펙트 리소스 인게임 적용 | E26: 2캐릭터 무기 이펙트만 만졌음에도 하루가 금새 훅갔습니다. 캐릭터 하나 더 남았고 인게임 적용은 한참 더 해야합니다. 잡일에 가깝다고 생각했는데 생각보다 고된 작업이어서 게임 개발이 얼마나 힘든건지 느꼈네요. 그래도 크게 할일이 없던 어제보다는 (작업 난이도가 높진 않았어도) 좀 더 보람찬 하루였던거 같습니다. 워낙 퍼포먼스가 낮았던 팀원이라 자신감, 자존감, 의욕 전부 무너졌었는데 오늘 조금은 회복했습니다. | G26: 대기
... B42: 7 | C42: 권수빈 | D42: NPCTalk 사운드 기입, NPCTalk 포트레이트 기입, bgm 생성 | E42: 프로젝트 끝까지 화이팅 | G42: 대기
B43: 7 | C43: 김현우A | G43: 대기
B44: 7 | C44: 박원우 | D44: 전체 시스템 안정화/ 스테이지구분/vns디버그버튼 전투시스템 확립/ | E44: 점점 익숙해지는 저를 칭찬하고싶어요 | G44: 대기
B45: 7 | C45: 송아영 | D45: 이모티콘 작업,표정작업,이미지사이즈 정리했습니다!기획서에 마케팅 내용은 없으신거같아서 건의도 하고..뭐 그렇게..하루를 보냈습니다 @@) | E45: 너무 정시퇴근했나..야근이 눈앞에 아른거려요... | G45: 대기
B46: 7 | C46: 채지형 | D46: 캐릭터와 적대적 몹 스킬 확장 (보스 스킬, 강공격, 플레이어 스킬 등)시도 했지만 오류로 아직 미구현 | E46: ai를 사용해서 코딩을 했지만 항상 확장성을 염두해두고 해야 할 것 같습니다.. 전에는 괜찮았는데 추가하려니까 오류가 생기면서 하나둘씩 꼬이기 시작하네요 다행히 됐었던 전 버전은 깃헙에 올려놨었는데, 계속 오류가 나는게 어렵네요 | G46: 대기
B47: 8 | C47: 이영우 | D47: 엘리니아 보스 기획/구현, 헤네시스 보스 기획/구현 | E47: 제미나이가 신에서 인간 중에 좀 똑똑한 수준으로 내려온 것 같습니다. | G47: 대기
B48: 8 | C48: 강유민 | D48: 시나리오 컷신 및 기타 이미지 리소스 제작 / 영상 AI를 활용하여 PV제작 | E48: 제작 초반에 바빴던 상황과 달리 후반으로 갈 수록, 업무가 적어지는 경험을 하고 있습니다. 팀원 분들에게 말해서 조금씩 할 수 있는 부분을 받아서 진행하고 있는데, 어째... 코드 구현 개발에 있어서는 도움이 되지 못해 조금 미안한 마음입니다. | G48: 대기
B49: 8 | C49: 권현민 | D49: 바이브코딩으로 몬스터 두 종류를 만들었습니다. | E49: 완성이 되어가고 있는데 끝까지 해보고 볼 일인가 봅니다 | G49: 대기
B50: 8 | C50: 김재환 | D50: 오전 오후 오늘도 신나는? 엔진에서 구현 작업 어제는 진행도 안되던 것이 AI가 어떤 바람이 불었는지 잘 대답해주고 따라 하기만 해도 뭔가가 나오긴 했다(이게 맞나?) | E50: 바이브 코딩이 오래 걸리는 건지 내가 못하는 건지 잘 모르겠어요 | G50: 대기
B51: 8 | C51: 이준혁 | D51: 센터 맵 구현, 튜토리얼 구현, 튜토리얼에 필요한 리소스 제작, 각 맵 연결, 변경되는 설계에 따라 레벨디자인 변경, 스테이지 클리어조건 부여, 프로젝트 전체적인 방향성 조율 요청(컨텐츠요소 등) | E51: 인간이 밉다 | G51: 주의
B52: 8 | C52: 장호윤 | D52: 변신모드 슬롯 교체를 드디어 구현했습니다 아이고 경사났네 그외에 저를 고생시키던 기타 버그들도 하나 둘 잡아서 없애는 중입니다 | E52: 다들 열일하는데 저만 기능 구현에 막혀서 삽질중인 것 같아 살짝 불안했는데 딱 회의 1분전에 문법 오류 없이 딱 성공을 해부렀습니다 퇴근 전 회의에 할 말이 생겨서 참 다행이라고 느꼈습니다 넵 그러므로 오늘 야근은 기분이 매우 좋을 예정입니다... 마지막까지 화이팅! | G52: 대기
