Workbook

Sheet Base
B2: 날짜 | C2: 46099
B4: 팀 | C4: 이름 | D4: 작업량 | E4: 한마디 | F4: 비고 | G4: 상태
B5: 1 | C5: 강유민 | D5: {=IF($C5:$C999="","", IFERROR( VLOOKUP( $C5:$C999 & "│" & TEXT($C$2,"yyyy-mm-dd"), SORT({ '설문지 응답 시트1'!$B$2:$B999 & "│" & TEXT('설문지 응답 시트1'!$D$2:$D999,"yyyy-mm-dd"), '설문지 응답 시트1'!$E$2:$E999, '설문지 응답 시트1'!$A$2:$A999 }, 3, FALSE), 2, FALSE ), "" ) )} | E5: {=IF($C5:$C999="","", IFERROR( VLOOKUP( $C5:$C999 & "│" & TEXT($C$2,"yyyy-mm-dd"), SORT({ '설문지 응답 시트1'!$B$2:$B999 & "│" & TEXT('설문지 응답 시트1'!$D$2:$D999,"yyyy-mm-dd"), '설문지 응답 시트1'!$F$2:$F999, '설문지 응답 시트1'!$A$2:$A999 }, 3, FALSE), 2, FALSE ), "" ) )} | G5: 대기
B6: 1 | C6: 이유송 | G6: 대기
B7: 1 | C7: 이동현 | D7: 로그라이크 코어 루프 확립하도록 노력했습니다. 추가로 시스템 흐름도 가이드 조건대로 작성 중입니다. | E7: 팀원들이 저마다 생각하는 것이 다를 수 있기에, 프로젝트에는 서로 간의 생각 체크나 레퍼런스 체크 등이 확실히 이루어져야 한다고 생각했습니다. | G7: 대기
B8: 1 | C8: 정우경 | D8: 시스템 기획 캐릭터 전투 몬스터 등등 | E8: 컨셉 및 핵심 시스템 기획이 매우 힘들었다. | G8: 대기
B9: 1 | C9: 김현우A | D9: 전투시스템 기획이 완료 | E9: 대략적인 전투 회의를 마쳤다 12시 까지 회의를 한 강행군이었다. 중간에 게임 시스템이 갈아업어져서 팀원간 충돌이 있었고 분의기가 살벌해졌지만 그래도 강사님이 수습을 해주어서 어느정도 수습이 되었고긴 회의 끝내 전투시스템 기획이 완료되었다 | G9: 대기
B10: 1 | C10: 정석현 | D10: 컨셉 기획 토의 UI / 이미지 레퍼런스 수집 | E10: 역시 재미를 만드는 건 쉬운 일이 아닌 것 같다. 오늘도 야근이다. | G10: 대기
B11: 1 | C11: 임소영 | D11: 컨셉 기획 회의 | E11: 다같이 아이디어를 하나 놓고 대화하는 방식으로 진행하니 서로 해당 시스템에 대해 분석해볼 시간이 부족해서 분석적인 내용없이 대화가 오간게 아쉬웠다. | G11: 대기
B12: 1 | C12: 박현수 | D12: 컨셉회의 간단하게 마무리하고 WBS 업무분배 작업하다가 컨셉이 엎어져서 할게 사라졌습니다... 기존에 있던 게임을 그대로 옮기는거 뿐이라 콘텐츠 기획쪽에선 무엇을 해야할지 어렵네요 | E12: 화이팅! | G12: 대기
B13: 2 | C13: 김서현 | D13: 1. 원페이지 기획서 작성 후, 공유 2. 기획안 확정 및 게임 코어 정립 3. 기획서 피드백 진행 4. 발표 자료 기반 작성 (미완) | E13: PM님과의 소통 부재가 있다고 느낍니다. 분명 사전에 방향성을 정했는데, 추후 얘기 없이 다른 방향성으로 진행되는 것이 많이 혼란스러웠습니다. 오늘은 좀 더 대화를 나눠보고자 합니다. 팀장으로서 부족한 것은 아닐까 하는 걱정이 앞섭니다. 깐부를 믿기! PM을 믿기! 이겨내겠습니다. | G13: 대기
B14: 2 | C14: 김태환 | D14: 업무 분담, 기획서 초안 확인 | E14: 기획 방향을 크게 틀게 되었지만 그럼에도 불구하고 이제 가닥이 잡혀가는 것 같아서 다행입니다. 다만, 볼륨에 대해 얼마나 협의를 볼 수 있을지 걱정입니다. | G14: 대기
B15: 2 | C15: 장윤우 | D15: 팀 컨셉 확정, 컨셉 시나리오 기획서 작성, 리소스 정리를 진행했습니다. | E15: 팀원들을 믿고 열심히 진행하겠습니다. | G15: 대기
B16: 2 | C16: 유해찬 | D16: 인게임 uI 작성을 요청받아 작업함. | E16: 내가 잘하고있을까아... 모르겠다 | G16: 대기
B17: 2 | C17: 박기은 | D17: 다같이 컨셉기획 마무리, 아트로 배정 받음!! 아트 스타일, 주인공 이미지, 배경 분위기 등에 대해 팀원분들과 이야기하고 대충 그려보는 시간을 가졌습니다. | E17: 화이팅.... | G17: 대기
B18: 2 | C18: 이원홍 | D18: 팀적으로 전체적인 컨셉 기획 완료 / 스테이지1 프로토타입 구상/ 레벨디자인 통합 문서 작성 진행중 | E18: 프로젝트가 진행이 되어가는 느낌이라 매우 좋습니다! | G18: 대기
... B55: 7 | C55: 이균호 | D55: 테마, 컨셉, 기본적인 시스템과 컨텐츠를 정했다. 각 인원의 팀 내 역할을 확정했다. | E55: 그 동안 시스템 기획만 쭈욱 해왔는데 이번에 처음으로 시스템이 아닌 레벨/전투 디자인을 맡게 되었다. 익숙하지 않은 부분을 하게 되어서 조금 두렵기도 하지만 한 편으로는 해보고 싶었던 레벨 디자인을 하게 되어 기대된다. 내일도 화이팅이다! | G55: 대기
B56: 7 | C56: 최선동 | G56: 대기
B57: 8 | C57: 예인해 | D57: 팀원 작업 확인 및 팀원 상담. PM과 WBS 내용 상세화, html 목업 생산, 진행사항 보고 | E57: 저!는! 행!복!합!니!다! 강!사!님!들!과! 매!니!저!님!도!행!복!하!시!온! | G57: 대기
B58: 8 | C58: 이도민 | D58: 작업 리스트 및 우선 순위 정리 | E58: 없습니다 ! | G58: 대기
B59: 8 | C59: 김시온 | D59: MainSystem_FSM, Stage_FSM,DataTable 임시 구조 정리 | E59: 시간이 너무 빨리갑니다. | G59: 대기
B60: 8 | C60: 이준혁 | D60: 배정받은 파트 아이데이션 1차 완료, 블록매치 상호작용 기획서 작성, 보스 기획, 패턴 기획, 블록 효과설정, 기타 부가효과 설정, 스파이 활동 | E60: 세상이 아름답습니다. | G60: 대기
B61: 8 | C61: 이승진 | D61: 게임 컨셉 기획서 및 이벤트 스토리 보드에 대해 작업했습니다. 주로 세계관, 캐릭터, 스토리, 설정, 게임의 진행 흐름 위주로 작업했습니다. | E61: 크런치가 사실상 필수라서 좀 부담되긴 하지만 아직은 버틸만합니다. 훌륭한 팀원들, 좋아하는 팀원들 몰아서 배치받은듯해서 배려해주셔서 감사합니다. 이번엔 팀원분들과 부딪히지않고, 저 스스로에 대한 자괴감 느끼는 일 없이 잘 해내고 싶네요. | G61: 대기
B62: 8 | C62: 김윤규 | D62: 컨셉 기획, 스테이지 사이 이벤트 기획 | E62: 분업이 잘 되고 시작한 것 같아서 좋습니다 | G62: 대기
B63: 8 | C63: 김범진 | D63: 전투 시스템 플로우 차트 작성, 전투 밸런싱 보조 | E63: 팀원들이 제 역활에 맞게 잘해주고 있습니다. 너무 깔끔합니다. 특히 팀장이란 이런거구나 라는걸 배우는 중입니다. | G63: 대기
B64: 8 | C64: 배주빈 | D64: PPT 발표자료 작성 | E64: 오늘은 정말 힘들었었다 | G64: 대기
B65: 9 | C65: 서진호 | D65: 1. 어제 작업하던 컨셉기획을 마무리하고, 원페이지 기획서를 각자 작성하고 장단점과 구현이 얼마나 걸릴지에 대해서 정한 후 문서 하나로 통합하는 작업을 했습니다. 이후 프로토타이핑을 위해 개별 문서를 작성했고, 개인 시간을 조금 할애해서 내일 오전까지 플레이 가능한 프로토타입을 만들 예정입니다. 2. 내일 PM님이 안계시기 때문에 오후 일정을 어떻게 배분할지에 대해서 이야기를 했었고 전체적인 일정 조율을 조금 더 했습니다. 3. 프로토타입 제작에 에셋을 쓰는건 조금 별로일까? 싶긴했는데, 에디터만 나왔지만 조금 고되더라도 하길 잘했다는 생각이 듭니다. 4. 특이하게도 업무를 하면서 더더욱 아이스 브레이킹이 되어가고 있습니다. 고작 이틀차지만, 화기애애해서 좋고 다들 게임의 방향성도 잘 이해하고 순항 중인 것 같습니다. 특히 원우님께선 어제 예비군으로 못오셨었는데, 갈피를 바로 잡으시고 문서 작성도 정말 잘 해주셨습니다. 5. 방금도 말했듯이 고작 이틀차지만, 지금 기획 팀원 분들과는 작업을 하는데에 있어 크게 어려울 거 같단 생각이 들지않을 정도로 저는 만족합니다. 6. 아까 말씀 해주셨던 것 처럼 구현 난이도가 꽤 있는데, 타일 배치와 관련해서 설명을 조금 더 보강하자면, 온천예제로 들면 온천을 1타일씩 추가하는 것이 아니라 3x3이나 5x3처럼 정해진 프리셋이 있어서, 그걸 설치하는 방식이였습니다. 스타듀 밸리를 생각해주시면 될 것 같습니다. 물론 스타듀밸리도 구현하려면 굉장히 어렵기 때문에, 기술적 구현 등의 문제들을 어떻게 해야할지에 대해서도 조금씩이라도 고민을 좀 해봐야겠네요. 7. 프로그래밍 분들과 같이 작업하는 건 간만이라서 꽤 긴장되네요 제가 프로그래밍을 하던 시절이 약 19년 전 이야기라 우매함 봉우리 그 자체라서 소통하는 방법이 과거에 제가 배웠던 것들이 아직도 통할지도 모르겠어서 걱정스럽긴 합니다. 그래도 저희 팀원 분들을 전적으로 믿듯이 프로그래밍 팀 분들도 전적으로 믿고 작업을 하는게 최선의 선택이라 생각합니다. | E65: 오전에 원우님께서 개인 프로젝트 작업을 병행하고 계셨는데 사전에 이야기를 안해주셔서 조금 꼬일뻔 했으나 다행히 잘 해결이 됐습니다. 오늘 하루도 무사히 넘어갔네요 내일은 더욱 더 열심히 해보겠습니다 수고하셨습니다 | G65: 대기
B66: 9 | C66: 강태성 | D66: 1페이지 기획안 확정 및 프로토타입용 기획안 작성 도움, 내일 일정 배분, WBS 작성 준비 | E66: 여기 분위기 좋은데요. 어라, 그동안 제가 한 팀 프로젝트는 이런게 아니였는데 스타크씨... 기분이 이상해요 | G66: 대기
B67: 9 | C67: 박민규 | D67: 컨샙 기획과 프로토 타입 개발 기획을 마쳤습니다! | E67: 캐릭터를 많이 만들고싶습니다! | G67: 대기
B68: 9 | C68: 김경민 | D68: 원페이지, 기획서 작성, 타이쿤게임의 기본적인 UI/UX 와이어 프레임 피그마로 작성 | E68: 음.. 다른 부분은 모두 순조롭지만 초기 구상 분량이 많아 어느정도까지 구현이 될지 조금 걱정이 됩니다. | G68: 대기
... B75: 10 | C75: 홍태광 | D75: 1. 팀원분들과 함께 게임 컨셉을 구체화 후 확정. WBS를 작성하는 시간을 가졌습니다. 2. 전투화면 UI의 기본적인 레이아웃, 팝업 레이아웃을 구상하였습니다. | E75: 저희 조 주제가 다른 주제와 비교해 범위가 작은 덕분에 빠르게 컨셉을 확정할 수 있었던 것 같습니다. | G75: 대기
B76: 10 | C76: 정재훈 | G76: 대기
B77: 10 | C77: 한의호 | D77: 소통 원활화를 위한 게임 내 용어 정리, UI목업 회의, 개발 필요 요소 정리 | E77: 장르를 잘 뽑아서 진행이 비교적 빠른 것 같아 정말 다행인 것 같습니다. | G77: 대기
B78: 10 | C78: 정재용 | D78: 게임 컨샙 구체화 후 확정, WBS작성, 우선 순위 설정 | E78: 행복합니다 ^^; | G78: 대기
B79: 개인 | C79: 김지훈 | D79: 생성 ai 파이프라인 세팅 | E79: 환경 세팅에 많은 시간이 드는 거 같다 | G79: 대기
B80: 개인 | C80: 이석훈 | D80: 이름짓기 기능 개발 | E80: UI랑 엮는게 쉽지않네요 | G80: 대기
B81: 개인 | C81: 조현일 | D81: 컨셉 기획서의 토대를 다지는 작업을 했습니다. | E81: 차분하게 현재 할 수 있는것들을 쌓아나가는것이 관건이라 생각합니다. 전진하겠습니다. | G81: 대기

Sheet Date
A1: 46099
A2: 46100
A3: 46101
A4: 46104
A5: 46105
A6: 46106
A7: 46107
A8: 46108
A9: 46111
A10: 46112
A11: 46113
A12: 46114
... A16: 46120

Sheet 설문지 응답 시트1
A1: 타임스탬프 | B1: 이름 | C1: 소속팀 | D1: 작성 날짜 | E1: 오늘 작업한 내용 | F1: 자유로운 한마디
A2: 46099.732 | B2: 정석현 | C2: 1팀 | D2: 46099 | E2: 컨셉 기획 토의 UI / 이미지 레퍼런스 수집 | F2: 역시 재미를 만드는 건 쉬운 일이 아닌 것 같다. 오늘도 야근이다.
A3: 46099.732 | B3: 박원우 | C3: 9팀 | D3: 46099 | E3: 원페이지 기획 컨셉공유 역할배분 회의 | F3: 매우 좋은 진행인것같아서 안심됩니다
A4: 46099.732 | B4: 김영도 | C4: 3팀 | D4: 46099 | E4: 컨셉 기획 | F4: 컨셉 기획에서 제가 기존에 생각한 컨셉이 되어서 조금 기뻤습니다. 오늘 에셋을 찾아봤는데 기획과 정확하게 매치되는 것은 없었지만 그래도 나쁘지 않은 엣셋이 있어서 다행이라고 느끼기도 했습니다
A5: 46099.733 | B5: 권수빈 | C5: 3팀 | D5: 46099 | E5: 컨셉 기획 선정 | F5: 순조롭게 진행 중입니다. 열심히 하겠습니다.
A6: 46099.733 | B6: 박민규 | C6: 9팀 | D6: 46099 | E6: 컨샙 기획과 프로토 타입 개발 기획을 마쳤습니다! | F6: 캐릭터를 많이 만들고싶습니다!
A7: 46099.734 | B7: 장호윤 | C7: 10팀 | D7: 46099 | E7: 컨셉 회의 및 업무 분담, 원페이지 기획서 작업 | F7: 머리털 빠질 것 같습니다...
A8: 46099.735 | B8: 이석훈 | C8: 개인 프로젝트 | D8: 46099 | E8: 이름짓기 기능 개발 | F8: UI랑 엮는게 쉽지않네요
A9: 46099.736 | B9: 김서현 | C9: 2팀 | D9: 46099 | E9: 1. 원페이지 기획서 작성 후, 공유 2. 기획안 확정 및 게임 코어 정립 3. 기획서 피드백 진행 4. 발표 자료 기반 작성 (미완) | F9: PM님과의 소통 부재가 있다고 느낍니다. 분명 사전에 방향성을 정했는데, 추후 얘기 없이 다른 방향성으로 진행되는 것이 많이 혼란스러웠습니다. 오늘은 좀 더 대화를 나눠보고자 합니다. 팀장으로서 부족한 것은 아닐까 하는 걱정이 앞섭니다. 깐부를 믿기! PM을 믿기! 이겨내겠습니다.
A10: 46099.737 | B10: 김윤규 | C10: 8팀 | D10: 46099 | E10: 컨셉 기획, 스테이지 사이 이벤트 기획 | F10: 분업이 잘 되고 시작한 것 같아서 좋습니다
A11: 46099.737 | B11: 윤동현 | C11: 3팀 | D11: 46099 | E11: 오늘은 팀에서 컨셉을 정하기 위해 각자 원페이지 기획서를 작성하고 투표를 하는 식으로 컨셉을 정하게 되었습니다. 그래서 저희 팀은 좀비물로 가기로 정해졌습니다 이후에 추가적으로 토의를 진행 했었는데 저는 좀비물 게임 경험이 적어서 쉽게 의견을 말하진 못한 것 같습니다. 경험이 있었다면 더 많은 아이디어를 얘기하고 팀원들과 소통하여 정할 수 있었는데 살짝은 아쉬운 느낌이 듭니다. 그리고 아직 컨셉 기획단계이긴 하지만 각자 무슨 파트를 맡을 건지도 팀장님과 피디님이 얘기 후에 정해주셨습니다. 저는 밸런스를 맡게 되었습니다. 이전 메이플월드 프로젝트 때는 콘텐츠를 맡게 되었었는데, 이번에는 밸런스라서 기대되기도 하고 어느 힘듦이 존재하는지 경험을 쌓아볼 수 있을 것 같아서 긍정적이게 생각 중입니다. | F11: 음 컨셉이나 등등 아이디어에 대해 얘기를 하다보니 점점 스케일이 커지는 것만 같은 느낌이 들어서 가늠하기가 힘든 느낌이 있었던 것 같습니다. 말고는 제가 관련 분야에 대해 경험이 없어서 걱정이 조금 있는 것 같습니다 하하
A12: 46099.737 | B12: 신석균 | C12: 5팀 | D12: 46099 | E12: 컨셉기획을 완료하고 세계관 설정을 완료했다. | F12: 일정이 너무 빡빡하다
A13: 46099.737 | B13: 천영현 | C13: 10팀 | D13: 46099 | E13: PM 역할 1. 의견 조율 2. 회의록 작성 및 정리 3. 진행 유도 4. WBS 정리 5. WBS 우선순위 정리 | F13: 너무 작업이 잘돼서 무서워요~ 팀원 분들이 너무 좋습니다!!
... A261: 46104.747 | B261: 한의호 | C261: 10팀 | D261: 46104 | E261: 유닛 기획 시트 수정, 시너지 기획 시트 수정, 적 유닛 기획 시트 작성 | F261: 수정을 진행하며 게임 시스템에 대한 정리와 이해가 필요해서 팀원들과 논의 하는 데에 시간을 많이 쓴 것 같습니다.
A262: 46104.747 | C262: 개인 프로젝트 | D262: 46104 | E262: 우분투 백업 복구 및 구입 피씨 세팅 | F262: 16기가로 안돼, 결국 200이상 써서 컴퓨터를 구매해야했다/
A263: 46104.748 | B263: 김태훈 | C263: 6팀 | D263: 46104 | E263: UI 설명서 컨펌 확인/아이콘 AI 제작/개발자와의 소통 | F263: 행복합니다
A264: 46104.748 | B264: 이승구 | C264: 7팀 | D264: 46104 | E264: [1]시스템개요 ~ [2] 캐릭터 조작 및 액션 기획서 작성 V1 [1]~[2] 섹션 분할 및 PDF 변환 V2 기본적인 문서 전달 형태 [PDF] [섹션 분리] [1차 피드백 내용 반영] - 자료형 제거 - 스태틱, 다이나믹과 같은 합의되지 않응 용어 제외 - 시야각은 90도 고정으로 예외처리 파트 제거 - 섹션 하나씩 잘라서 PDF로 한 번에 업로드 [링크] [시스템 개요_V2](https://drive.google.com/file/d/1a9okQdDcxCDWsZUZSNAjprUUK_Vo2YH5/view?usp=drive_link) [캐릭터 조작 및 액션_V2](https://drive.google.com/file/d/1PazVjmyuwwOG_LhlKq4jweYNzmEVldn4/view?usp=drive_link) | F264: 테이블 확정을 어느 시점에서 해야할지 헷갈렸으나 해결되었습니다! 큰 이슈는 없이 마무리 되었던 것 같습니다. 자료형이나 데이터구조 등의 내용을 수업 때 배워서 기획 내용에 포함했는데 삭제 요청을 받아서 당황했으나 기획서 작성 전에 어떤 게임을 만들지를 개발자와 함깨 논의하고 기획서 작성 규칙이나 전체적인 디테일의 수준을 합의하는 과정을 거쳤다면 이러한 문제들은 어느정도는 해소가 되었을 것 같습니다! 갈색두건산적단 화이팅!
A265: 46104.748 | B265: 정재용 | C265: 10팀 | D265: 46104 | E265: 맵 밸런스 구상 및 초안 작성 | F265: 오늘 10팀 기획팀 집중력이 되게 높았는지 작업 속도가 빨랐다고 생각합니다. 10팀 화이팅!
A266: 46104.749 | B266: 채지형 | C266: 7팀 | D266: 46104 | E266: 데이터 테이블 정리, 플밍반분들한테 넘길 기획서 작성, 전달 | F266: 오늘 진행이 매끄럽게돼서 좋습니다
A267: 46104.749 | B267: 김윤규 | C267: 8팀 | D267: 46104 | E267: 이벤트 보상 스테이지 대사 작성, 이벤트 보상 구조 및 내용 설정 | F267: 머리에 쥐나요. 살려달라고 하면 안되겠죠?
A268: 46104.749 | B268: 최선동 | C268: 7팀 | D268: 46104 | E268: 플레이어 성장 시스템 피드백 및 수정 | F268: 내일은 기획리뷰 하는 날! 화이팅 하겠습니다
A269: 46104.75 | B269: 김민제 | C269: 3팀 | D269: 46104 | E269: 에셋이 완전 바뀌어서 거기에 맞춰 몬스터 기획서의 수정 및 수치 추가, 표로 정리. 무기 기획서의 수치 추가. | F269: 게임의 최종 제출이 4월 9일인데, 마치 이번 주까지가 최종인 마냥 너무나도 많은 시스템 및 콘텐츠를 자르고 있어서 불만이다. 플밍반이 괜찮다고 하면 어떤 시스템을 넣자고 모두 합의 했는데, 정작 플밍반이 완전 괜찮다, 힘든일 전혀 아니다라고 하자 말을 바꿔서 기획일이 늘어날 것 같다, 나중에 시간 남으면 추가하자라고 했다. 그것도 또 나중에 말을 바꿔서는 해당 시스템은 없애기로 했는데 왜 기획서에 적으셨나요? 이러는게 참.. 불만이다. 그래서 나는 나중에 시간 남으면 하기로 했었기 때문에 넣었고 비고에 해당 사항 적었다고 했다. 이럴거면 회의는 왜 하고 합의는 왜하는지 의문이다. 또한 플밍반과 아이스브레이킹 시간을 전혀 가지지 않고 회의도 거의 따로 하고 서로 이름도 아직 거의 못 외운채로 프로젝트를 하고 있다. 참.. pd와 pm이 여러모로 너무 너무 조급해하는 것 같다.
A270: 46104.752 | B270: 홍태광 | C270: 10팀 | D270: 46104 | E270: UI 에셋 테스트 | F270: UI의 픽셀을 어떻게 맞춰야 할지 감도 안잡히는 것 같네요...ㅎㅎ
A271: 46104.753 | B271: 이찬규 | C271: 6팀 | D271: 46104 | E271: 사운드 에셋 정리, 사운드 에셋(BGM) 생성, 데이터테이블 최신화 및 수정 | F271: .
A272: 46104.753 | B272: 배주빈 | C272: 8팀 | D272: 46104 | E272: 03/23 오늘 해야할 일 1. 플로우 차트 2. 튜토리얼 기능 안내별 연출 예외처리 3. 윤규님의 튜토리얼 적&보상 기다렸다가 갱신하기 오전 작업 착수 순서 1. 플로우 차트 2. 플로우 차트 컨펌받기전 UI로 관해 인해님과 승진님의 의논하는 동안 예외처리 수정하며 대기중 3. 플로우 차트 완료 후 json과 png 파일 다운로드 및 드라이브&슬라이드 업로드 4. 튜토리얼 연출 문서 수정 후 컨펌 요청 4-1. 튜토리얼 연출 문서 수정사항 a. 조건 정리 b. 예외처리 정리 c. 연출 UI 일부 수정 5. 컨펌 대기하는 동안 튜토리얼 보상 에셋 이미지 선정해서 보상 컨셉까지 다듬고 컨셉팀에 확인받기. 5-1. 전날, 윤규님께서 보내주신 에셋 링크에서 찾기. 점심 회의 튜토리얼 끝나면 테이블짜기로 넘어갈 예정 오후 작업 착수 1. 튜토리얼 연출 컨펌 후 작업 진행 1-1. 1,2번 슬라이드 설명 문구 수정&추가 1-2. 3번 슬라이드 표에서 문장으로 변환 후 문장 수정 1-3. 4번 슬라이드 수정&추가 2. 튜토리얼 보상 에셋 리서치 1-1. 눈물 모양 보석의 색깔별 스프라이트 리서치 1-2. 파일경로 1-3. 눈물 모양 보석의 색깔별 스프라이트의 각 파일명 1-4. 눈물 모양 보석의 색깔별 스프라이트의 각 PNG 캡쳐 3. 튜토리얼 연출 컨펌 후 작업 2차 진행 3-1. 4번 슬라이드 예외처리 정리 a. '이전, 스킵'의 두가지 기능에 대한 명시 b. 문장 수정 4. 튜토리얼 연출 컨펌 후 작업 3차 진행 4-1. 4번 슬라이드 예외처리 정리 a. 문장 정리 b. 문장 배열 통일화 | F272: 크아아악!!! 컨펌 지옥....
A273: 46104.753 | B273: 안성진 | C273: 3팀 | D273: 46104 | E273: 오늘 시스템 완 | F273: 없습니다
A274: 46104.754 | B274: 권수빈 | C274: 3팀 | D274: 46104 | E274: 맵 별 몬스터 비율 지정, 맵 에셋 지정 | F274: 열심히 하겠습니다.
... A933: 46115.743 | B933: 조현일 | C933: 개인 프로젝트 | D933: 46115 | E933: 테이블 작업 및 연출 작업을 하며 진행 불가의 버그에 빠졌으나 차분히 해결하며 진행하였습니다. | F933: 정진하겠습니다.
A934: 46115.743 | B934: 한재환 | C934: 4팀 | D934: 4/3/0026 | E934: 데이터 테이블 완성. | F934: 화이팅!
A935: 46115.743 | B935: 조준현 | C935: 4팀 | D935: 46115 | E935: 썸네일과 게임 프로필 아이콘 | F935: 나는 아무것도 몰라용
A936: 46115.744 | B936: 송아영 | C936: 6팀 | D936: 46115 | E936: 빌드가 나와서 플레이해보는 중입니다 즐 겁 다 ! | F936: 저희 itchio 너무 귀엽게 잘나왔습니다 6팀 최고~~~
A937: 46115.746 | B937: 서진호 | C937: 9팀 | D937: 46115 | E937: 오늘은 효과음 정리와 BGM 제작을 했습니다. 테스트 케이스도 만들긴 했는데 AI 도움을 받아서 제가 했단 생각은 안들긴 합니다... 그리고 itch.io의 권한을 받아 작성 및 편집하기 시작했습니다. | F937: 오늘 드디어 프로그래밍 팀장님과 업무적인 대화가 시작 됐습니다. 아마 스레드를 보시면 여태까지 했던 것 보다 많은 대화가 이루어 졌던 것을 확인하실 수 있으실 거예요 남은 기간도 오늘만큼 더 소통했으면 좋겠네요 이번 한 주도 수고 많으셨습니다.
A938: 46115.747 | B938: 이형진 | C938: 5팀 | D938: 46115 | E938: 이치아이오 출시 작업 및 개발 현황 체크 및 여러 회의 | F938: 출시를 미루게 됐는데 저는 오히려 좋다고 생각합니당
A939: 46115.747 | B939: 채지형 | C939: 7팀 | D939: 46115 | E939: QA테스트 했습니다! | F939: 없습니다!
A940: 46115.747 | B940: 정재용 | C940: 10팀 | D940: 46115 | E940: 사운드 에셋 정리, QA및 밸런스 조절 | F940: 벌써 출시 및 발표까지 일주일정도 밖에 안남았네요.. 파이팅 하겠습니다..!
A941: 46115.749 | B941: 한의호 | C941: 10팀 | D941: 46115 | E941: 마케팅 이미지 제작 | F941: QA 기간을 길게 주셔서 감사합니다...
A942: 46115.749 | B942: 임동균 | C942: 9팀 | D942: 46115 | E942: 테스트케이스 작성, QA간단하게 진행(기록만함), 기획서 일부 수정. | F942: UI쪽은 다른 사람이 담당했었는데, 예외처리가 거의 안되어있는 느낌이었다.. 그래서 해당 부분을 엄청 많이 고쳐야할 것 같다.. UI가 어떻게보면 실제로 상호작용하는 영역이다보니 잘못 작동할 때 짜증나는게 더 커서 집중적으로 이 부분을 관리해야할 것 같다.
A943: 46115.749 | B943: 이영우 | C943: 10팀 | D943: 46115 | E943: 게임하고 놀았습니다. | F943: 버그를 고치면 버그가 생기고 그걸 예측해서 버그를 테스트하면 예측 밖에 버그가 생기고 또 그걸 고치면...
A944: 46115.749 | B944: 이석훈 | C944: 개인 프로젝트 | D944: 46115 | E944: 코딩 | F944: 로시 40챠 신난다 이쁘다 + 전무 1돌 40챠컷 ㄴㅇㅅ
A945: 46115.75 | B945: 천영현 | C945: 10팀 | D945: 46115 | E945: 밸런스패치 QA | F945: 화이팅 플밍팀!!
...

Sheet 종합
B2: 데일리 체크인 종합 시트
B4: - 데일리 체크인 작성이 결국 개인 성실성과 과정 신뢰도, 과정 운영의 지시를 따르는 지표가 될 것으로 보입니다. - 작성의 판단 기준은 당일 오후 5:00 ~ 다음날 오전 9:00 까지 작성된 데이터를 기준으로 판단합니다.
B6: 팀 | C6: 이름 | D6: 미작성 횟수 | E6: 응답 비율 | F6: 46099 | G6: 46100 | H6: 46101 | I6: 46104 | J6: 46105 | K6: 46106 | L6: 46107 | M6: 46108 | N6: 46111 | O6: 46112 | P6: 46113 | Q6: 46114 | R6: 46115 | S6: 46118 | T6: 46119 | U6: 46120
B7: 1 | C7: 강유민 | D7: =COUNTIFS(F7:U7, "X", F$6:U$6, "<"&TODAY()) -> 5 | E7: =COUNTIFS(F7:U7, "O", F$6:U$6, "<"&TODAY())/Countif(F$6:U$6,"<"&Today()) -> 0.6875 | F7: =IF(COUNTIFS('설문지 응답 시트1'!$B:$B, $C7, '설문지 응답 시트1'!$A:$A, ">="&(F$6 + TIME(17,0,0)), '설문지 응답 시트1'!$A:$A, "<"&(F$6 + 1 + TIME(9,0,0)))>0, "O", "X") -> X | G7: =IF(COUNTIFS('설문지 응답 시트1'!$B:$B, $C7, '설문지 응답 시트1'!$A:$A, ">="&(G$6 + TIME(17,0,0)), '설문지 응답 시트1'!$A:$A, "<"&(G$6 + 1 + TIME(9,0,0)))>0, "O", "X") -> O | H7: =IF(COUNTIFS('설문지 응답 시트1'!$B:$B, $C7, '설문지 응답 시트1'!$A:$A, ">="&(H$6 + TIME(17,0,0)), '설문지 응답 시트1'!$A:$A, "<"&(H$6 + 1 + TIME(9,0,0)))>0, "O", "X") -> X | I7: =IF(COUNTIFS('설문지 응답 시트1'!$B:$B, $C7, '설문지 응답 시트1'!$A:$A, ">="&(I$6 + TIME(17,0,0)), '설문지 응답 시트1'!$A:$A, "<"&(I$6 + 1 + TIME(9,0,0)))>0, "O", "X") -> O | J7: =IF(COUNTIFS('설문지 응답 시트1'!$B:$B, $C7, '설문지 응답 시트1'!$A:$A, ">="&(J$6 + TIME(17,0,0)), '설문지 응답 시트1'!$A:$A, "<"&(J$6 + 1 + TIME(9,0,0)))>0, "O", "X") -> O | K7: =IF(COUNTIFS('설문지 응답 시트1'!$B:$B, $C7, '설문지 응답 시트1'!$A:$A, ">="&(K$6 + TIME(17,0,0)), '설문지 응답 시트1'!$A:$A, "<"&(K$6 + 1 + TIME(9,0,0)))>0, "O", "X") -> X | L7: =IF(COUNTIFS('설문지 응답 시트1'!$B:$B, $C7, '설문지 응답 시트1'!$A:$A, ">="&(L$6 + TIME(17,0,0)), '설문지 응답 시트1'!$A:$A, "<"&(L$6 + 1 + TIME(9,0,0)))>0, "O", "X") -> O | M7: =IF(COUNTIFS('설문지 응답 시트1'!$B:$B, $C7, '설문지 응답 시트1'!$A:$A, ">="&(M$6 + TIME(17,0,0)), '설문지 응답 시트1'!$A:$A, "<"&(M$6 + 1 + TIME(9,0,0)))>0, "O", "X") -> O | ... U7: =IF(COUNTIFS('설문지 응답 시트1'!$B:$B, $C7, '설문지 응답 시트1'!$A:$A, ">="&(U$6 + TIME(17,0,0)), '설문지 응답 시트1'!$A:$A, "<"&(U$6 + 1 + TIME(9,0,0)))>0, "O", "X") -> O
B8: 1 | C8: 이유송 | D8: =COUNTIFS(F8:U8, "X", F$6:U$6, "<"&TODAY()) -> 3 | E8: =COUNTIFS(F8:U8, "O", F$6:U$6, "<"&TODAY())/Countif(F$6:U$6,"<"&Today()) -> 0.8125 | F8: =IF(COUNTIFS('설문지 응답 시트1'!$B:$B, $C8, '설문지 응답 시트1'!$A:$A, ">="&(F$6 + TIME(17,0,0)), '설문지 응답 시트1'!$A:$A, "<"&(F$6 + 1 + TIME(9,0,0)))>0, "O", "X") -> X | G8: =IF(COUNTIFS('설문지 응답 시트1'!$B:$B, $C8, '설문지 응답 시트1'!$A:$A, ">="&(G$6 + TIME(17,0,0)), '설문지 응답 시트1'!$A:$A, "<"&(G$6 + 1 + TIME(9,0,0)))>0, "O", "X") -> O | H8: =IF(COUNTIFS('설문지 응답 시트1'!$B:$B, $C8, '설문지 응답 시트1'!$A:$A, ">="&(H$6 + TIME(17,0,0)), '설문지 응답 시트1'!$A:$A, "<"&(H$6 + 1 + TIME(9,0,0)))>0, "O", "X") -> X | I8: =IF(COUNTIFS('설문지 응답 시트1'!$B:$B, $C8, '설문지 응답 시트1'!$A:$A, ">="&(I$6 + TIME(17,0,0)), '설문지 응답 시트1'!$A:$A, "<"&(I$6 + 1 + TIME(9,0,0)))>0, "O", "X") -> O | J8: =IF(COUNTIFS('설문지 응답 시트1'!$B:$B, $C8, '설문지 응답 시트1'!$A:$A, ">="&(J$6 + TIME(17,0,0)), '설문지 응답 시트1'!$A:$A, "<"&(J$6 + 1 + TIME(9,0,0)))>0, "O", "X") -> O | K8: =IF(COUNTIFS('설문지 응답 시트1'!$B:$B, $C8, '설문지 응답 시트1'!$A:$A, ">="&(K$6 + TIME(17,0,0)), '설문지 응답 시트1'!$A:$A, "<"&(K$6 + 1 + TIME(9,0,0)))>0, "O", "X") -> O | L8: =IF(COUNTIFS('설문지 응답 시트1'!$B:$B, $C8, '설문지 응답 시트1'!$A:$A, ">="&(L$6 + TIME(17,0,0)), '설문지 응답 시트1'!$A:$A, "<"&(L$6 + 1 + TIME(9,0,0)))>0, "O", "X") -> O | M8: =IF(COUNTIFS('설문지 응답 시트1'!$B:$B, $C8, '설문지 응답 시트1'!$A:$A, ">="&(M$6 + TIME(17,0,0)), '설문지 응답 시트1'!$A:$A, "<"&(M$6 + 1 + TIME(9,0,0)))>0, "O", "X") -> X | ... U8: =IF(COUNTIFS('설문지 응답 시트1'!$B:$B, $C8, '설문지 응답 시트1'!$A:$A, ">="&(U$6 + TIME(17,0,0)), '설문지 응답 시트1'!$A:$A, "<"&(U$6 + 1 + TIME(9,0,0)))>0, "O", "X") -> O
B9: 1 | C9: 이동현 | D9: =COUNTIFS(F9:U9, "X", F$6:U$6, "<"&TODAY()) -> 0 | E9: =COUNTIFS(F9:U9, "O", F$6:U$6, "<"&TODAY())/Countif(F$6:U$6,"<"&Today()) -> 1 | F9: =IF(COUNTIFS('설문지 응답 시트1'!$B:$B, $C9, '설문지 응답 시트1'!$A:$A, ">="&(F$6 + TIME(17,0,0)), '설문지 응답 시트1'!$A:$A, "<"&(F$6 + 1 + TIME(9,0,0)))>0, "O", "X") -> O | G9: =IF(COUNTIFS('설문지 응답 시트1'!$B:$B, $C9, '설문지 응답 시트1'!$A:$A, ">="&(G$6 + TIME(17,0,0)), '설문지 응답 시트1'!$A:$A, "<"&(G$6 + 1 + TIME(9,0,0)))>0, "O", "X") -> O | H9: =IF(COUNTIFS('설문지 응답 시트1'!$B:$B, $C9, '설문지 응답 시트1'!$A:$A, ">="&(H$6 + TIME(17,0,0)), '설문지 응답 시트1'!$A:$A, "<"&(H$6 + 1 + TIME(9,0,0)))>0, "O", "X") -> O | I9: =IF(COUNTIFS('설문지 응답 시트1'!$B:$B, $C9, '설문지 응답 시트1'!$A:$A, ">="&(I$6 + TIME(17,0,0)), '설문지 응답 시트1'!$A:$A, "<"&(I$6 + 1 + TIME(9,0,0)))>0, "O", "X") -> O | J9: =IF(COUNTIFS('설문지 응답 시트1'!$B:$B, $C9, '설문지 응답 시트1'!$A:$A, ">="&(J$6 + TIME(17,0,0)), '설문지 응답 시트1'!$A:$A, "<"&(J$6 + 1 + TIME(9,0,0)))>0, "O", "X") -> O | K9: =IF(COUNTIFS('설문지 응답 시트1'!$B:$B, $C9, '설문지 응답 시트1'!$A:$A, ">="&(K$6 + TIME(17,0,0)), '설문지 응답 시트1'!$A:$A, "<"&(K$6 + 1 + TIME(9,0,0)))>0, "O", "X") -> O | L9: =IF(COUNTIFS('설문지 응답 시트1'!$B:$B, $C9, '설문지 응답 시트1'!$A:$A, ">="&(L$6 + TIME(17,0,0)), '설문지 응답 시트1'!$A:$A, "<"&(L$6 + 1 + TIME(9,0,0)))>0, "O", "X") -> O | M9: =IF(COUNTIFS('설문지 응답 시트1'!$B:$B, $C9, '설문지 응답 시트1'!$A:$A, ">="&(M$6 + TIME(17,0,0)), '설문지 응답 시트1'!$A:$A, "<"&(M$6 + 1 + TIME(9,0,0)))>0, "O", "X") -> O | ... U9: =IF(COUNTIFS('설문지 응답 시트1'!$B:$B, $C9, '설문지 응답 시트1'!$A:$A, ">="&(U$6 + TIME(17,0,0)), '설문지 응답 시트1'!$A:$A, "<"&(U$6 + 1 + TIME(9,0,0)))>0, "O", "X") -> O
B10: 1 | C10: 정우경 | D10: =COUNTIFS(F10:U10, "X", F$6:U$6, "<"&TODAY()) -> 0 | E10: =COUNTIFS(F10:U10, "O", F$6:U$6, "<"&TODAY())/Countif(F$6:U$6,"<"&Today()) -> 1 | F10: =IF(COUNTIFS('설문지 응답 시트1'!$B:$B, $C10, '설문지 응답 시트1'!$A:$A, ">="&(F$6 + TIME(17,0,0)), '설문지 응답 시트1'!$A:$A, "<"&(F$6 + 1 + TIME(9,0,0)))>0, "O", "X") -> O | G10: =IF(COUNTIFS('설문지 응답 시트1'!$B:$B, $C10, '설문지 응답 시트1'!$A:$A, ">="&(G$6 + TIME(17,0,0)), '설문지 응답 시트1'!$A:$A, "<"&(G$6 + 1 + TIME(9,0,0)))>0, "O", "X") -> O | H10: =IF(COUNTIFS('설문지 응답 시트1'!$B:$B, $C10, '설문지 응답 시트1'!$A:$A, ">="&(H$6 + TIME(17,0,0)), '설문지 응답 시트1'!$A:$A, "<"&(H$6 + 1 + TIME(9,0,0)))>0, "O", "X") -> O | I10: =IF(COUNTIFS('설문지 응답 시트1'!$B:$B, $C10, '설문지 응답 시트1'!$A:$A, ">="&(I$6 + TIME(17,0,0)), '설문지 응답 시트1'!$A:$A, "<"&(I$6 + 1 + TIME(9,0,0)))>0, "O", "X") -> O | J10: =IF(COUNTIFS('설문지 응답 시트1'!$B:$B, $C10, '설문지 응답 시트1'!$A:$A, ">="&(J$6 + TIME(17,0,0)), '설문지 응답 시트1'!$A:$A, "<"&(J$6 + 1 + TIME(9,0,0)))>0, "O", "X") -> O | K10: =IF(COUNTIFS('설문지 응답 시트1'!$B:$B, $C10, '설문지 응답 시트1'!$A:$A, ">="&(K$6 + TIME(17,0,0)), '설문지 응답 시트1'!$A:$A, "<"&(K$6 + 1 + TIME(9,0,0)))>0, "O", "X") -> O | L10: =IF(COUNTIFS('설문지 응답 시트1'!$B:$B, $C10, '설문지 응답 시트1'!$A:$A, ">="&(L$6 + TIME(17,0,0)), '설문지 응답 시트1'!$A:$A, "<"&(L$6 + 1 + TIME(9,0,0)))>0, "O", "X") -> O | M10: =IF(COUNTIFS('설문지 응답 시트1'!$B:$B, $C10, '설문지 응답 시트1'!$A:$A, ">="&(M$6 + TIME(17,0,0)), '설문지 응답 시트1'!$A:$A, "<"&(M$6 + 1 + TIME(9,0,0)))>0, "O", "X") -> O | ... U10: =IF(COUNTIFS('설문지 응답 시트1'!$B:$B, $C10, '설문지 응답 시트1'!$A:$A, ">="&(U$6 + TIME(17,0,0)), '설문지 응답 시트1'!$A:$A, "<"&(U$6 + 1 + TIME(9,0,0)))>0, "O", "X") -> O
B11: 1 | C11: 김현우A | D11: =COUNTIFS(F11:U11, "X", F$6:U$6, "<"&TODAY()) -> 11 | E11: =COUNTIFS(F11:U11, "O", F$6:U$6, "<"&TODAY())/Countif(F$6:U$6,"<"&Today()) -> 0.3125 | F11: =IF(COUNTIFS('설문지 응답 시트1'!$B:$B, $C11, '설문지 응답 시트1'!$A:$A, ">="&(F$6 + TIME(17,0,0)), '설문지 응답 시트1'!$A:$A, "<"&(F$6 + 1 + TIME(9,0,0)))>0, "O", "X") -> X | G11: =IF(COUNTIFS('설문지 응답 시트1'!$B:$B, $C11, '설문지 응답 시트1'!$A:$A, ">="&(G$6 + TIME(17,0,0)), '설문지 응답 시트1'!$A:$A, "<"&(G$6 + 1 + TIME(9,0,0)))>0, "O", "X") -> X | H11: =IF(COUNTIFS('설문지 응답 시트1'!$B:$B, $C11, '설문지 응답 시트1'!$A:$A, ">="&(H$6 + TIME(17,0,0)), '설문지 응답 시트1'!$A:$A, "<"&(H$6 + 1 + TIME(9,0,0)))>0, "O", "X") -> X | I11: =IF(COUNTIFS('설문지 응답 시트1'!$B:$B, $C11, '설문지 응답 시트1'!$A:$A, ">="&(I$6 + TIME(17,0,0)), '설문지 응답 시트1'!$A:$A, "<"&(I$6 + 1 + TIME(9,0,0)))>0, "O", "X") -> X | J11: =IF(COUNTIFS('설문지 응답 시트1'!$B:$B, $C11, '설문지 응답 시트1'!$A:$A, ">="&(J$6 + TIME(17,0,0)), '설문지 응답 시트1'!$A:$A, "<"&(J$6 + 1 + TIME(9,0,0)))>0, "O", "X") -> X | K11: =IF(COUNTIFS('설문지 응답 시트1'!$B:$B, $C11, '설문지 응답 시트1'!$A:$A, ">="&(K$6 + TIME(17,0,0)), '설문지 응답 시트1'!$A:$A, "<"&(K$6 + 1 + TIME(9,0,0)))>0, "O", "X") -> O | L11: =IF(COUNTIFS('설문지 응답 시트1'!$B:$B, $C11, '설문지 응답 시트1'!$A:$A, ">="&(L$6 + TIME(17,0,0)), '설문지 응답 시트1'!$A:$A, "<"&(L$6 + 1 + TIME(9,0,0)))>0, "O", "X") -> O | M11: =IF(COUNTIFS('설문지 응답 시트1'!$B:$B, $C11, '설문지 응답 시트1'!$A:$A, ">="&(M$6 + TIME(17,0,0)), '설문지 응답 시트1'!$A:$A, "<"&(M$6 + 1 + TIME(9,0,0)))>0, "O", "X") -> X | ... U11: =IF(COUNTIFS('설문지 응답 시트1'!$B:$B, $C11, '설문지 응답 시트1'!$A:$A, ">="&(U$6 + TIME(17,0,0)), '설문지 응답 시트1'!$A:$A, "<"&(U$6 + 1 + TIME(9,0,0)))>0, "O", "X") -> X
B12: 1 | C12: 정석현 | D12: =COUNTIFS(F12:U12, "X", F$6:U$6, "<"&TODAY()) -> 0 | E12: =COUNTIFS(F12:U12, "O", F$6:U$6, "<"&TODAY())/Countif(F$6:U$6,"<"&Today()) -> 1 | F12: =IF(COUNTIFS('설문지 응답 시트1'!$B:$B, $C12, '설문지 응답 시트1'!$A:$A, ">="&(F$6 + TIME(17,0,0)), '설문지 응답 시트1'!$A:$A, "<"&(F$6 + 1 + TIME(9,0,0)))>0, "O", "X") -> O | G12: =IF(COUNTIFS('설문지 응답 시트1'!$B:$B, $C12, '설문지 응답 시트1'!$A:$A, ">="&(G$6 + TIME(17,0,0)), '설문지 응답 시트1'!$A:$A, "<"&(G$6 + 1 + TIME(9,0,0)))>0, "O", "X") -> O | H12: =IF(COUNTIFS('설문지 응답 시트1'!$B:$B, $C12, '설문지 응답 시트1'!$A:$A, ">="&(H$6 + TIME(17,0,0)), '설문지 응답 시트1'!$A:$A, "<"&(H$6 + 1 + TIME(9,0,0)))>0, "O", "X") -> O | I12: =IF(COUNTIFS('설문지 응답 시트1'!$B:$B, $C12, '설문지 응답 시트1'!$A:$A, ">="&(I$6 + TIME(17,0,0)), '설문지 응답 시트1'!$A:$A, "<"&(I$6 + 1 + TIME(9,0,0)))>0, "O", "X") -> O | J12: =IF(COUNTIFS('설문지 응답 시트1'!$B:$B, $C12, '설문지 응답 시트1'!$A:$A, ">="&(J$6 + TIME(17,0,0)), '설문지 응답 시트1'!$A:$A, "<"&(J$6 + 1 + TIME(9,0,0)))>0, "O", "X") -> O | K12: =IF(COUNTIFS('설문지 응답 시트1'!$B:$B, $C12, '설문지 응답 시트1'!$A:$A, ">="&(K$6 + TIME(17,0,0)), '설문지 응답 시트1'!$A:$A, "<"&(K$6 + 1 + TIME(9,0,0)))>0, "O", "X") -> O | L12: =IF(COUNTIFS('설문지 응답 시트1'!$B:$B, $C12, '설문지 응답 시트1'!$A:$A, ">="&(L$6 + TIME(17,0,0)), '설문지 응답 시트1'!$A:$A, "<"&(L$6 + 1 + TIME(9,0,0)))>0, "O", "X") -> O | M12: =IF(COUNTIFS('설문지 응답 시트1'!$B:$B, $C12, '설문지 응답 시트1'!$A:$A, ">="&(M$6 + TIME(17,0,0)), '설문지 응답 시트1'!$A:$A, "<"&(M$6 + 1 + TIME(9,0,0)))>0, "O", "X") -> O | ... U12: =IF(COUNTIFS('설문지 응답 시트1'!$B:$B, $C12, '설문지 응답 시트1'!$A:$A, ">="&(U$6 + TIME(17,0,0)), '설문지 응답 시트1'!$A:$A, "<"&(U$6 + 1 + TIME(9,0,0)))>0, "O", "X") -> O
B13: 1 | C13: 임소영 | D13: =COUNTIFS(F13:U13, "X", F$6:U$6, "<"&TODAY()) -> 10 | E13: =COUNTIFS(F13:U13, "O", F$6:U$6, "<"&TODAY())/Countif(F$6:U$6,"<"&Today()) -> 0.375 | F13: =IF(COUNTIFS('설문지 응답 시트1'!$B:$B, $C13, '설문지 응답 시트1'!$A:$A, ">="&(F$6 + TIME(17,0,0)), '설문지 응답 시트1'!$A:$A, "<"&(F$6 + 1 + TIME(9,0,0)))>0, "O", "X") -> X | G13: =IF(COUNTIFS('설문지 응답 시트1'!$B:$B, $C13, '설문지 응답 시트1'!$A:$A, ">="&(G$6 + TIME(17,0,0)), '설문지 응답 시트1'!$A:$A, "<"&(G$6 + 1 + TIME(9,0,0)))>0, "O", "X") -> X | H13: =IF(COUNTIFS('설문지 응답 시트1'!$B:$B, $C13, '설문지 응답 시트1'!$A:$A, ">="&(H$6 + TIME(17,0,0)), '설문지 응답 시트1'!$A:$A, "<"&(H$6 + 1 + TIME(9,0,0)))>0, "O", "X") -> X | I13: =IF(COUNTIFS('설문지 응답 시트1'!$B:$B, $C13, '설문지 응답 시트1'!$A:$A, ">="&(I$6 + TIME(17,0,0)), '설문지 응답 시트1'!$A:$A, "<"&(I$6 + 1 + TIME(9,0,0)))>0, "O", "X") -> O | J13: =IF(COUNTIFS('설문지 응답 시트1'!$B:$B, $C13, '설문지 응답 시트1'!$A:$A, ">="&(J$6 + TIME(17,0,0)), '설문지 응답 시트1'!$A:$A, "<"&(J$6 + 1 + TIME(9,0,0)))>0, "O", "X") -> O | K13: =IF(COUNTIFS('설문지 응답 시트1'!$B:$B, $C13, '설문지 응답 시트1'!$A:$A, ">="&(K$6 + TIME(17,0,0)), '설문지 응답 시트1'!$A:$A, "<"&(K$6 + 1 + TIME(9,0,0)))>0, "O", "X") -> X | L13: =IF(COUNTIFS('설문지 응답 시트1'!$B:$B, $C13, '설문지 응답 시트1'!$A:$A, ">="&(L$6 + TIME(17,0,0)), '설문지 응답 시트1'!$A:$A, "<"&(L$6 + 1 + TIME(9,0,0)))>0, "O", "X") -> X | M13: =IF(COUNTIFS('설문지 응답 시트1'!$B:$B, $C13, '설문지 응답 시트1'!$A:$A, ">="&(M$6 + TIME(17,0,0)), '설문지 응답 시트1'!$A:$A, "<"&(M$6 + 1 + TIME(9,0,0)))>0, "O", "X") -> X | ... U13: =IF(COUNTIFS('설문지 응답 시트1'!$B:$B, $C13, '설문지 응답 시트1'!$A:$A, ">="&(U$6 + TIME(17,0,0)), '설문지 응답 시트1'!$A:$A, "<"&(U$6 + 1 + TIME(9,0,0)))>0, "O", "X") -> X
B14: 1 | C14: 박현수 | D14: =COUNTIFS(F14:U14, "X", F$6:U$6, "<"&TODAY()) -> 2 | E14: =COUNTIFS(F14:U14, "O", F$6:U$6, "<"&TODAY())/Countif(F$6:U$6,"<"&Today()) -> 0.875 | F14: =IF(COUNTIFS('설문지 응답 시트1'!$B:$B, $C14, '설문지 응답 시트1'!$A:$A, ">="&(F$6 + TIME(17,0,0)), '설문지 응답 시트1'!$A:$A, "<"&(F$6 + 1 + TIME(9,0,0)))>0, "O", "X") -> O | G14: =IF(COUNTIFS('설문지 응답 시트1'!$B:$B, $C14, '설문지 응답 시트1'!$A:$A, ">="&(G$6 + TIME(17,0,0)), '설문지 응답 시트1'!$A:$A, "<"&(G$6 + 1 + TIME(9,0,0)))>0, "O", "X") -> O | H14: =IF(COUNTIFS('설문지 응답 시트1'!$B:$B, $C14, '설문지 응답 시트1'!$A:$A, ">="&(H$6 + TIME(17,0,0)), '설문지 응답 시트1'!$A:$A, "<"&(H$6 + 1 + TIME(9,0,0)))>0, "O", "X") -> O | I14: =IF(COUNTIFS('설문지 응답 시트1'!$B:$B, $C14, '설문지 응답 시트1'!$A:$A, ">="&(I$6 + TIME(17,0,0)), '설문지 응답 시트1'!$A:$A, "<"&(I$6 + 1 + TIME(9,0,0)))>0, "O", "X") -> O | J14: =IF(COUNTIFS('설문지 응답 시트1'!$B:$B, $C14, '설문지 응답 시트1'!$A:$A, ">="&(J$6 + TIME(17,0,0)), '설문지 응답 시트1'!$A:$A, "<"&(J$6 + 1 + TIME(9,0,0)))>0, "O", "X") -> O | K14: =IF(COUNTIFS('설문지 응답 시트1'!$B:$B, $C14, '설문지 응답 시트1'!$A:$A, ">="&(K$6 + TIME(17,0,0)), '설문지 응답 시트1'!$A:$A, "<"&(K$6 + 1 + TIME(9,0,0)))>0, "O", "X") -> O | L14: =IF(COUNTIFS('설문지 응답 시트1'!$B:$B, $C14, '설문지 응답 시트1'!$A:$A, ">="&(L$6 + TIME(17,0,0)), '설문지 응답 시트1'!$A:$A, "<"&(L$6 + 1 + TIME(9,0,0)))>0, "O", "X") -> X | M14: =IF(COUNTIFS('설문지 응답 시트1'!$B:$B, $C14, '설문지 응답 시트1'!$A:$A, ">="&(M$6 + TIME(17,0,0)), '설문지 응답 시트1'!$A:$A, "<"&(M$6 + 1 + TIME(9,0,0)))>0, "O", "X") -> O | ... U14: =IF(COUNTIFS('설문지 응답 시트1'!$B:$B, $C14, '설문지 응답 시트1'!$A:$A, ">="&(U$6 + TIME(17,0,0)), '설문지 응답 시트1'!$A:$A, "<"&(U$6 + 1 + TIME(9,0,0)))>0, "O", "X") -> O
B15: 2 | C15: 김서현 | D15: =COUNTIFS(F15:U15, "X", F$6:U$6, "<"&TODAY()) -> 6 | E15: =COUNTIFS(F15:U15, "O", F$6:U$6, "<"&TODAY())/Countif(F$6:U$6,"<"&Today()) -> 0.625 | F15: =IF(COUNTIFS('설문지 응답 시트1'!$B:$B, $C15, '설문지 응답 시트1'!$A:$A, ">="&(F$6 + TIME(17,0,0)), '설문지 응답 시트1'!$A:$A, "<"&(F$6 + 1 + TIME(9,0,0)))>0, "O", "X") -> O | G15: =IF(COUNTIFS('설문지 응답 시트1'!$B:$B, $C15, '설문지 응답 시트1'!$A:$A, ">="&(G$6 + TIME(17,0,0)), '설문지 응답 시트1'!$A:$A, "<"&(G$6 + 1 + TIME(9,0,0)))>0, "O", "X") -> O | H15: =IF(COUNTIFS('설문지 응답 시트1'!$B:$B, $C15, '설문지 응답 시트1'!$A:$A, ">="&(H$6 + TIME(17,0,0)), '설문지 응답 시트1'!$A:$A, "<"&(H$6 + 1 + TIME(9,0,0)))>0, "O", "X") -> O | I15: =IF(COUNTIFS('설문지 응답 시트1'!$B:$B, $C15, '설문지 응답 시트1'!$A:$A, ">="&(I$6 + TIME(17,0,0)), '설문지 응답 시트1'!$A:$A, "<"&(I$6 + 1 + TIME(9,0,0)))>0, "O", "X") -> O | J15: =IF(COUNTIFS('설문지 응답 시트1'!$B:$B, $C15, '설문지 응답 시트1'!$A:$A, ">="&(J$6 + TIME(17,0,0)), '설문지 응답 시트1'!$A:$A, "<"&(J$6 + 1 + TIME(9,0,0)))>0, "O", "X") -> O | K15: =IF(COUNTIFS('설문지 응답 시트1'!$B:$B, $C15, '설문지 응답 시트1'!$A:$A, ">="&(K$6 + TIME(17,0,0)), '설문지 응답 시트1'!$A:$A, "<"&(K$6 + 1 + TIME(9,0,0)))>0, "O", "X") -> X | L15: =IF(COUNTIFS('설문지 응답 시트1'!$B:$B, $C15, '설문지 응답 시트1'!$A:$A, ">="&(L$6 + TIME(17,0,0)), '설문지 응답 시트1'!$A:$A, "<"&(L$6 + 1 + TIME(9,0,0)))>0, "O", "X") -> X | M15: =IF(COUNTIFS('설문지 응답 시트1'!$B:$B, $C15, '설문지 응답 시트1'!$A:$A, ">="&(M$6 + TIME(17,0,0)), '설문지 응답 시트1'!$A:$A, "<"&(M$6 + 1 + TIME(9,0,0)))>0, "O", "X") -> O | ... U15: =IF(COUNTIFS('설문지 응답 시트1'!$B:$B, $C15, '설문지 응답 시트1'!$A:$A, ">="&(U$6 + TIME(17,0,0)), '설문지 응답 시트1'!$A:$A, "<"&(U$6 + 1 + TIME(9,0,0)))>0, "O", "X") -> O
B16: 2 | C16: 김태환 | D16: =COUNTIFS(F16:U16, "X", F$6:U$6, "<"&TODAY()) -> 12 | E16: =COUNTIFS(F16:U16, "O", F$6:U$6, "<"&TODAY())/Countif(F$6:U$6,"<"&Today()) -> 0.25 | F16: =IF(COUNTIFS('설문지 응답 시트1'!$B:$B, $C16, '설문지 응답 시트1'!$A:$A, ">="&(F$6 + TIME(17,0,0)), '설문지 응답 시트1'!$A:$A, "<"&(F$6 + 1 + TIME(9,0,0)))>0, "O", "X") -> O | G16: =IF(COUNTIFS('설문지 응답 시트1'!$B:$B, $C16, '설문지 응답 시트1'!$A:$A, ">="&(G$6 + TIME(17,0,0)), '설문지 응답 시트1'!$A:$A, "<"&(G$6 + 1 + TIME(9,0,0)))>0, "O", "X") -> X | H16: =IF(COUNTIFS('설문지 응답 시트1'!$B:$B, $C16, '설문지 응답 시트1'!$A:$A, ">="&(H$6 + TIME(17,0,0)), '설문지 응답 시트1'!$A:$A, "<"&(H$6 + 1 + TIME(9,0,0)))>0, "O", "X") -> X | I16: =IF(COUNTIFS('설문지 응답 시트1'!$B:$B, $C16, '설문지 응답 시트1'!$A:$A, ">="&(I$6 + TIME(17,0,0)), '설문지 응답 시트1'!$A:$A, "<"&(I$6 + 1 + TIME(9,0,0)))>0, "O", "X") -> O | J16: =IF(COUNTIFS('설문지 응답 시트1'!$B:$B, $C16, '설문지 응답 시트1'!$A:$A, ">="&(J$6 + TIME(17,0,0)), '설문지 응답 시트1'!$A:$A, "<"&(J$6 + 1 + TIME(9,0,0)))>0, "O", "X") -> O | K16: =IF(COUNTIFS('설문지 응답 시트1'!$B:$B, $C16, '설문지 응답 시트1'!$A:$A, ">="&(K$6 + TIME(17,0,0)), '설문지 응답 시트1'!$A:$A, "<"&(K$6 + 1 + TIME(9,0,0)))>0, "O", "X") -> O | L16: =IF(COUNTIFS('설문지 응답 시트1'!$B:$B, $C16, '설문지 응답 시트1'!$A:$A, ">="&(L$6 + TIME(17,0,0)), '설문지 응답 시트1'!$A:$A, "<"&(L$6 + 1 + TIME(9,0,0)))>0, "O", "X") -> X | M16: =IF(COUNTIFS('설문지 응답 시트1'!$B:$B, $C16, '설문지 응답 시트1'!$A:$A, ">="&(M$6 + TIME(17,0,0)), '설문지 응답 시트1'!$A:$A, "<"&(M$6 + 1 + TIME(9,0,0)))>0, "O", "X") -> X | ... U16: =IF(COUNTIFS('설문지 응답 시트1'!$B:$B, $C16, '설문지 응답 시트1'!$A:$A, ">="&(U$6 + TIME(17,0,0)), '설문지 응답 시트1'!$A:$A, "<"&(U$6 + 1 + TIME(9,0,0)))>0, "O", "X") -> X
B17: 2 | C17: 장윤우 | D17: =COUNTIFS(F17:U17, "X", F$6:U$6, "<"&TODAY()) -> 0 | E17: =COUNTIFS(F17:U17, "O", F$6:U$6, "<"&TODAY())/Countif(F$6:U$6,"<"&Today()) -> 1 | F17: =IF(COUNTIFS('설문지 응답 시트1'!$B:$B, $C17, '설문지 응답 시트1'!$A:$A, ">="&(F$6 + TIME(17,0,0)), '설문지 응답 시트1'!$A:$A, "<"&(F$6 + 1 + TIME(9,0,0)))>0, "O", "X") -> O | G17: =IF(COUNTIFS('설문지 응답 시트1'!$B:$B, $C17, '설문지 응답 시트1'!$A:$A, ">="&(G$6 + TIME(17,0,0)), '설문지 응답 시트1'!$A:$A, "<"&(G$6 + 1 + TIME(9,0,0)))>0, "O", "X") -> O | H17: =IF(COUNTIFS('설문지 응답 시트1'!$B:$B, $C17, '설문지 응답 시트1'!$A:$A, ">="&(H$6 + TIME(17,0,0)), '설문지 응답 시트1'!$A:$A, "<"&(H$6 + 1 + TIME(9,0,0)))>0, "O", "X") -> O | I17: =IF(COUNTIFS('설문지 응답 시트1'!$B:$B, $C17, '설문지 응답 시트1'!$A:$A, ">="&(I$6 + TIME(17,0,0)), '설문지 응답 시트1'!$A:$A, "<"&(I$6 + 1 + TIME(9,0,0)))>0, "O", "X") -> O | J17: =IF(COUNTIFS('설문지 응답 시트1'!$B:$B, $C17, '설문지 응답 시트1'!$A:$A, ">="&(J$6 + TIME(17,0,0)), '설문지 응답 시트1'!$A:$A, "<"&(J$6 + 1 + TIME(9,0,0)))>0, "O", "X") -> O | K17: =IF(COUNTIFS('설문지 응답 시트1'!$B:$B, $C17, '설문지 응답 시트1'!$A:$A, ">="&(K$6 + TIME(17,0,0)), '설문지 응답 시트1'!$A:$A, "<"&(K$6 + 1 + TIME(9,0,0)))>0, "O", "X") -> O | L17: =IF(COUNTIFS('설문지 응답 시트1'!$B:$B, $C17, '설문지 응답 시트1'!$A:$A, ">="&(L$6 + TIME(17,0,0)), '설문지 응답 시트1'!$A:$A, "<"&(L$6 + 1 + TIME(9,0,0)))>0, "O", "X") -> O | M17: =IF(COUNTIFS('설문지 응답 시트1'!$B:$B, $C17, '설문지 응답 시트1'!$A:$A, ">="&(M$6 + TIME(17,0,0)), '설문지 응답 시트1'!$A:$A, "<"&(M$6 + 1 + TIME(9,0,0)))>0, "O", "X") -> O | ... U17: =IF(COUNTIFS('설문지 응답 시트1'!$B:$B, $C17, '설문지 응답 시트1'!$A:$A, ">="&(U$6 + TIME(17,0,0)), '설문지 응답 시트1'!$A:$A, "<"&(U$6 + 1 + TIME(9,0,0)))>0, "O", "X") -> O
B18: 2 | C18: 유해찬 | D18: =COUNTIFS(F18:U18, "X", F$6:U$6, "<"&TODAY()) -> 2 | E18: =COUNTIFS(F18:U18, "O", F$6:U$6, "<"&TODAY())/Countif(F$6:U$6,"<"&Today()) -> 0.875 | F18: =IF(COUNTIFS('설문지 응답 시트1'!$B:$B, $C18, '설문지 응답 시트1'!$A:$A, ">="&(F$6 + TIME(17,0,0)), '설문지 응답 시트1'!$A:$A, "<"&(F$6 + 1 + TIME(9,0,0)))>0, "O", "X") -> O | G18: =IF(COUNTIFS('설문지 응답 시트1'!$B:$B, $C18, '설문지 응답 시트1'!$A:$A, ">="&(G$6 + TIME(17,0,0)), '설문지 응답 시트1'!$A:$A, "<"&(G$6 + 1 + TIME(9,0,0)))>0, "O", "X") -> O | H18: =IF(COUNTIFS('설문지 응답 시트1'!$B:$B, $C18, '설문지 응답 시트1'!$A:$A, ">="&(H$6 + TIME(17,0,0)), '설문지 응답 시트1'!$A:$A, "<"&(H$6 + 1 + TIME(9,0,0)))>0, "O", "X") -> O | I18: =IF(COUNTIFS('설문지 응답 시트1'!$B:$B, $C18, '설문지 응답 시트1'!$A:$A, ">="&(I$6 + TIME(17,0,0)), '설문지 응답 시트1'!$A:$A, "<"&(I$6 + 1 + TIME(9,0,0)))>0, "O", "X") -> O | J18: =IF(COUNTIFS('설문지 응답 시트1'!$B:$B, $C18, '설문지 응답 시트1'!$A:$A, ">="&(J$6 + TIME(17,0,0)), '설문지 응답 시트1'!$A:$A, "<"&(J$6 + 1 + TIME(9,0,0)))>0, "O", "X") -> O | K18: =IF(COUNTIFS('설문지 응답 시트1'!$B:$B, $C18, '설문지 응답 시트1'!$A:$A, ">="&(K$6 + TIME(17,0,0)), '설문지 응답 시트1'!$A:$A, "<"&(K$6 + 1 + TIME(9,0,0)))>0, "O", "X") -> O | L18: =IF(COUNTIFS('설문지 응답 시트1'!$B:$B, $C18, '설문지 응답 시트1'!$A:$A, ">="&(L$6 + TIME(17,0,0)), '설문지 응답 시트1'!$A:$A, "<"&(L$6 + 1 + TIME(9,0,0)))>0, "O", "X") -> X | M18: =IF(COUNTIFS('설문지 응답 시트1'!$B:$B, $C18, '설문지 응답 시트1'!$A:$A, ">="&(M$6 + TIME(17,0,0)), '설문지 응답 시트1'!$A:$A, "<"&(M$6 + 1 + TIME(9,0,0)))>0, "O", "X") -> O | ... U18: =IF(COUNTIFS('설문지 응답 시트1'!$B:$B, $C18, '설문지 응답 시트1'!$A:$A, ">="&(U$6 + TIME(17,0,0)), '설문지 응답 시트1'!$A:$A, "<"&(U$6 + 1 + TIME(9,0,0)))>0, "O", "X") -> O
... B80: 10 | C80: 정재용 | D80: =COUNTIFS(F80:U80, "X", F$6:U$6, "<"&TODAY()) -> 0 | E80: =COUNTIFS(F80:U80, "O", F$6:U$6, "<"&TODAY())/Countif(F$6:U$6,"<"&Today()) -> 1 | F80: =IF(COUNTIFS('설문지 응답 시트1'!$B:$B, $C80, '설문지 응답 시트1'!$A:$A, ">="&(F$6 + TIME(17,0,0)), '설문지 응답 시트1'!$A:$A, "<"&(F$6 + 1 + TIME(9,0,0)))>0, "O", "X") -> O | G80: =IF(COUNTIFS('설문지 응답 시트1'!$B:$B, $C80, '설문지 응답 시트1'!$A:$A, ">="&(G$6 + TIME(17,0,0)), '설문지 응답 시트1'!$A:$A, "<"&(G$6 + 1 + TIME(9,0,0)))>0, "O", "X") -> O | H80: =IF(COUNTIFS('설문지 응답 시트1'!$B:$B, $C80, '설문지 응답 시트1'!$A:$A, ">="&(H$6 + TIME(17,0,0)), '설문지 응답 시트1'!$A:$A, "<"&(H$6 + 1 + TIME(9,0,0)))>0, "O", "X") -> O | I80: =IF(COUNTIFS('설문지 응답 시트1'!$B:$B, $C80, '설문지 응답 시트1'!$A:$A, ">="&(I$6 + TIME(17,0,0)), '설문지 응답 시트1'!$A:$A, "<"&(I$6 + 1 + TIME(9,0,0)))>0, "O", "X") -> O | J80: =IF(COUNTIFS('설문지 응답 시트1'!$B:$B, $C80, '설문지 응답 시트1'!$A:$A, ">="&(J$6 + TIME(17,0,0)), '설문지 응답 시트1'!$A:$A, "<"&(J$6 + 1 + TIME(9,0,0)))>0, "O", "X") -> O | K80: =IF(COUNTIFS('설문지 응답 시트1'!$B:$B, $C80, '설문지 응답 시트1'!$A:$A, ">="&(K$6 + TIME(17,0,0)), '설문지 응답 시트1'!$A:$A, "<"&(K$6 + 1 + TIME(9,0,0)))>0, "O", "X") -> O | L80: =IF(COUNTIFS('설문지 응답 시트1'!$B:$B, $C80, '설문지 응답 시트1'!$A:$A, ">="&(L$6 + TIME(17,0,0)), '설문지 응답 시트1'!$A:$A, "<"&(L$6 + 1 + TIME(9,0,0)))>0, "O", "X") -> O | M80: =IF(COUNTIFS('설문지 응답 시트1'!$B:$B, $C80, '설문지 응답 시트1'!$A:$A, ">="&(M$6 + TIME(17,0,0)), '설문지 응답 시트1'!$A:$A, "<"&(M$6 + 1 + TIME(9,0,0)))>0, "O", "X") -> O | ... U80: =IF(COUNTIFS('설문지 응답 시트1'!$B:$B, $C80, '설문지 응답 시트1'!$A:$A, ">="&(U$6 + TIME(17,0,0)), '설문지 응답 시트1'!$A:$A, "<"&(U$6 + 1 + TIME(9,0,0)))>0, "O", "X") -> O
B81: 개인 | C81: 김지훈 | D81: =COUNTIFS(F81:U81, "X", F$6:U$6, "<"&TODAY()) -> 13 | E81: =COUNTIFS(F81:U81, "O", F$6:U$6, "<"&TODAY())/Countif(F$6:U$6,"<"&Today()) -> 0.1875 | F81: =IF(COUNTIFS('설문지 응답 시트1'!$B:$B, $C81, '설문지 응답 시트1'!$A:$A, ">="&(F$6 + TIME(17,0,0)), '설문지 응답 시트1'!$A:$A, "<"&(F$6 + 1 + TIME(9,0,0)))>0, "O", "X") -> O | G81: =IF(COUNTIFS('설문지 응답 시트1'!$B:$B, $C81, '설문지 응답 시트1'!$A:$A, ">="&(G$6 + TIME(17,0,0)), '설문지 응답 시트1'!$A:$A, "<"&(G$6 + 1 + TIME(9,0,0)))>0, "O", "X") -> O | H81: =IF(COUNTIFS('설문지 응답 시트1'!$B:$B, $C81, '설문지 응답 시트1'!$A:$A, ">="&(H$6 + TIME(17,0,0)), '설문지 응답 시트1'!$A:$A, "<"&(H$6 + 1 + TIME(9,0,0)))>0, "O", "X") -> X | I81: =IF(COUNTIFS('설문지 응답 시트1'!$B:$B, $C81, '설문지 응답 시트1'!$A:$A, ">="&(I$6 + TIME(17,0,0)), '설문지 응답 시트1'!$A:$A, "<"&(I$6 + 1 + TIME(9,0,0)))>0, "O", "X") -> X | J81: =IF(COUNTIFS('설문지 응답 시트1'!$B:$B, $C81, '설문지 응답 시트1'!$A:$A, ">="&(J$6 + TIME(17,0,0)), '설문지 응답 시트1'!$A:$A, "<"&(J$6 + 1 + TIME(9,0,0)))>0, "O", "X") -> X | K81: =IF(COUNTIFS('설문지 응답 시트1'!$B:$B, $C81, '설문지 응답 시트1'!$A:$A, ">="&(K$6 + TIME(17,0,0)), '설문지 응답 시트1'!$A:$A, "<"&(K$6 + 1 + TIME(9,0,0)))>0, "O", "X") -> X | L81: =IF(COUNTIFS('설문지 응답 시트1'!$B:$B, $C81, '설문지 응답 시트1'!$A:$A, ">="&(L$6 + TIME(17,0,0)), '설문지 응답 시트1'!$A:$A, "<"&(L$6 + 1 + TIME(9,0,0)))>0, "O", "X") -> O | M81: =IF(COUNTIFS('설문지 응답 시트1'!$B:$B, $C81, '설문지 응답 시트1'!$A:$A, ">="&(M$6 + TIME(17,0,0)), '설문지 응답 시트1'!$A:$A, "<"&(M$6 + 1 + TIME(9,0,0)))>0, "O", "X") -> X | ... U81: =IF(COUNTIFS('설문지 응답 시트1'!$B:$B, $C81, '설문지 응답 시트1'!$A:$A, ">="&(U$6 + TIME(17,0,0)), '설문지 응답 시트1'!$A:$A, "<"&(U$6 + 1 + TIME(9,0,0)))>0, "O", "X") -> X
B82: 개인 | C82: 이석훈 | D82: =COUNTIFS(F82:U82, "X", F$6:U$6, "<"&TODAY()) -> 3 | E82: =COUNTIFS(F82:U82, "O", F$6:U$6, "<"&TODAY())/Countif(F$6:U$6,"<"&Today()) -> 0.8125 | F82: =IF(COUNTIFS('설문지 응답 시트1'!$B:$B, $C82, '설문지 응답 시트1'!$A:$A, ">="&(F$6 + TIME(17,0,0)), '설문지 응답 시트1'!$A:$A, "<"&(F$6 + 1 + TIME(9,0,0)))>0, "O", "X") -> O | G82: =IF(COUNTIFS('설문지 응답 시트1'!$B:$B, $C82, '설문지 응답 시트1'!$A:$A, ">="&(G$6 + TIME(17,0,0)), '설문지 응답 시트1'!$A:$A, "<"&(G$6 + 1 + TIME(9,0,0)))>0, "O", "X") -> O | H82: =IF(COUNTIFS('설문지 응답 시트1'!$B:$B, $C82, '설문지 응답 시트1'!$A:$A, ">="&(H$6 + TIME(17,0,0)), '설문지 응답 시트1'!$A:$A, "<"&(H$6 + 1 + TIME(9,0,0)))>0, "O", "X") -> O | I82: =IF(COUNTIFS('설문지 응답 시트1'!$B:$B, $C82, '설문지 응답 시트1'!$A:$A, ">="&(I$6 + TIME(17,0,0)), '설문지 응답 시트1'!$A:$A, "<"&(I$6 + 1 + TIME(9,0,0)))>0, "O", "X") -> O | J82: =IF(COUNTIFS('설문지 응답 시트1'!$B:$B, $C82, '설문지 응답 시트1'!$A:$A, ">="&(J$6 + TIME(17,0,0)), '설문지 응답 시트1'!$A:$A, "<"&(J$6 + 1 + TIME(9,0,0)))>0, "O", "X") -> X | K82: =IF(COUNTIFS('설문지 응답 시트1'!$B:$B, $C82, '설문지 응답 시트1'!$A:$A, ">="&(K$6 + TIME(17,0,0)), '설문지 응답 시트1'!$A:$A, "<"&(K$6 + 1 + TIME(9,0,0)))>0, "O", "X") -> O | L82: =IF(COUNTIFS('설문지 응답 시트1'!$B:$B, $C82, '설문지 응답 시트1'!$A:$A, ">="&(L$6 + TIME(17,0,0)), '설문지 응답 시트1'!$A:$A, "<"&(L$6 + 1 + TIME(9,0,0)))>0, "O", "X") -> X | M82: =IF(COUNTIFS('설문지 응답 시트1'!$B:$B, $C82, '설문지 응답 시트1'!$A:$A, ">="&(M$6 + TIME(17,0,0)), '설문지 응답 시트1'!$A:$A, "<"&(M$6 + 1 + TIME(9,0,0)))>0, "O", "X") -> O | ... U82: =IF(COUNTIFS('설문지 응답 시트1'!$B:$B, $C82, '설문지 응답 시트1'!$A:$A, ">="&(U$6 + TIME(17,0,0)), '설문지 응답 시트1'!$A:$A, "<"&(U$6 + 1 + TIME(9,0,0)))>0, "O", "X") -> O
B83: 개인 | C83: 조현일 | D83: =COUNTIFS(F83:U83, "X", F$6:U$6, "<"&TODAY()) -> 1 | E83: =COUNTIFS(F83:U83, "O", F$6:U$6, "<"&TODAY())/Countif(F$6:U$6,"<"&Today()) -> 0.9375 | F83: =IF(COUNTIFS('설문지 응답 시트1'!$B:$B, $C83, '설문지 응답 시트1'!$A:$A, ">="&(F$6 + TIME(17,0,0)), '설문지 응답 시트1'!$A:$A, "<"&(F$6 + 1 + TIME(9,0,0)))>0, "O", "X") -> O | G83: =IF(COUNTIFS('설문지 응답 시트1'!$B:$B, $C83, '설문지 응답 시트1'!$A:$A, ">="&(G$6 + TIME(17,0,0)), '설문지 응답 시트1'!$A:$A, "<"&(G$6 + 1 + TIME(9,0,0)))>0, "O", "X") -> O | H83: =IF(COUNTIFS('설문지 응답 시트1'!$B:$B, $C83, '설문지 응답 시트1'!$A:$A, ">="&(H$6 + TIME(17,0,0)), '설문지 응답 시트1'!$A:$A, "<"&(H$6 + 1 + TIME(9,0,0)))>0, "O", "X") -> O | I83: =IF(COUNTIFS('설문지 응답 시트1'!$B:$B, $C83, '설문지 응답 시트1'!$A:$A, ">="&(I$6 + TIME(17,0,0)), '설문지 응답 시트1'!$A:$A, "<"&(I$6 + 1 + TIME(9,0,0)))>0, "O", "X") -> O | J83: =IF(COUNTIFS('설문지 응답 시트1'!$B:$B, $C83, '설문지 응답 시트1'!$A:$A, ">="&(J$6 + TIME(17,0,0)), '설문지 응답 시트1'!$A:$A, "<"&(J$6 + 1 + TIME(9,0,0)))>0, "O", "X") -> O | K83: =IF(COUNTIFS('설문지 응답 시트1'!$B:$B, $C83, '설문지 응답 시트1'!$A:$A, ">="&(K$6 + TIME(17,0,0)), '설문지 응답 시트1'!$A:$A, "<"&(K$6 + 1 + TIME(9,0,0)))>0, "O", "X") -> O | L83: =IF(COUNTIFS('설문지 응답 시트1'!$B:$B, $C83, '설문지 응답 시트1'!$A:$A, ">="&(L$6 + TIME(17,0,0)), '설문지 응답 시트1'!$A:$A, "<"&(L$6 + 1 + TIME(9,0,0)))>0, "O", "X") -> O | M83: =IF(COUNTIFS('설문지 응답 시트1'!$B:$B, $C83, '설문지 응답 시트1'!$A:$A, ">="&(M$6 + TIME(17,0,0)), '설문지 응답 시트1'!$A:$A, "<"&(M$6 + 1 + TIME(9,0,0)))>0, "O", "X") -> X | ... U83: =IF(COUNTIFS('설문지 응답 시트1'!$B:$B, $C83, '설문지 응답 시트1'!$A:$A, ">="&(U$6 + TIME(17,0,0)), '설문지 응답 시트1'!$A:$A, "<"&(U$6 + 1 + TIME(9,0,0)))>0, "O", "X") -> O

Sheet 양식
B2: 이름
B4: 날짜 | C4: 작업량 | D4: 한마디
B5: 46099 | C5: {=IF($B5:$B938="","", IFERROR( VLOOKUP( $B5:$B938 & "│" & TEXT($B$2,"yyyy-mm-dd"), SORT({ '설문지 응답 시트1'!$B$2:$B938 & "│" & TEXT('설문지 응답 시트1'!$D$2:$D938,"yyyy-mm-dd"), '설문지 응답 시트1'!$E$2:$E938, '설문지 응답 시트1'!$A$2:$A938 }, 3, FALSE), 2, FALSE ), "" ) )} | D5: {=IF($B5:$B938="","", IFERROR( VLOOKUP( $B5:$B938 & "│" & TEXT($B$2,"yyyy-mm-dd"), SORT({ '설문지 응답 시트1'!$B$2:$B938 & "│" & TEXT('설문지 응답 시트1'!$D$2:$D938,"yyyy-mm-dd"), '설문지 응답 시트1'!$F$2:$F938, '설문지 응답 시트1'!$A$2:$A938 }, 3, FALSE), 2, FALSE ), "" ) )}
B6: 46100
B7: 46101
B8: 46104
B9: 46105
B10: 46106
B11: 46107
B12: 46108
B13: 46111
B14: 46112
B15: 46113
B16: 46114
B17: 46115
... B20: 46120

Sheet 0318
B2: 날짜 | C2: 46099
B4: 팀 | C4: 이름 | D4: 작업량 | E4: 한마디 | F4: 비고 | G4: 상태
B5: 1 | C5: 강유민 | D5: {=IF($C5:$C999="","", IFERROR( VLOOKUP( $C5:$C999 & "│" & TEXT($C$2,"yyyy-mm-dd"), SORT({ '설문지 응답 시트1'!$B$2:$B999 & "│" & TEXT('설문지 응답 시트1'!$D$2:$D999,"yyyy-mm-dd"), '설문지 응답 시트1'!$E$2:$E999, '설문지 응답 시트1'!$A$2:$A999 }, 3, FALSE), 2, FALSE ), "" ) )} | E5: {=IF($C5:$C999="","", IFERROR( VLOOKUP( $C5:$C999 & "│" & TEXT($C$2,"yyyy-mm-dd"), SORT({ '설문지 응답 시트1'!$B$2:$B999 & "│" & TEXT('설문지 응답 시트1'!$D$2:$D999,"yyyy-mm-dd"), '설문지 응답 시트1'!$F$2:$F999, '설문지 응답 시트1'!$A$2:$A999 }, 3, FALSE), 2, FALSE ), "" ) )} | G5: 대기
B6: 1 | C6: 이유송 | G6: 대기
B7: 1 | C7: 이동현 | D7: 로그라이크 코어 루프 확립하도록 노력했습니다. 추가로 시스템 흐름도 가이드 조건대로 작성 중입니다. | E7: 팀원들이 저마다 생각하는 것이 다를 수 있기에, 프로젝트에는 서로 간의 생각 체크나 레퍼런스 체크 등이 확실히 이루어져야 한다고 생각했습니다. | G7: 대기
B8: 1 | C8: 정우경 | D8: 시스템 기획 캐릭터 전투 몬스터 등등 | E8: 컨셉 및 핵심 시스템 기획이 매우 힘들었다. | G8: 주의
B9: 1 | C9: 김현우A | D9: 전투시스템 기획이 완료 | E9: 대략적인 전투 회의를 마쳤다 12시 까지 회의를 한 강행군이었다. 중간에 게임 시스템이 갈아업어져서 팀원간 충돌이 있었고 분의기가 살벌해졌지만 그래도 강사님이 수습을 해주어서 어느정도 수습이 되었고긴 회의 끝내 전투시스템 기획이 완료되었다 | G9: 대기
B10: 1 | C10: 정석현 | D10: 컨셉 기획 토의 UI / 이미지 레퍼런스 수집 | E10: 역시 재미를 만드는 건 쉬운 일이 아닌 것 같다. 오늘도 야근이다. | G10: 대기
B11: 1 | C11: 임소영 | D11: 컨셉 기획 회의 | E11: 다같이 아이디어를 하나 놓고 대화하는 방식으로 진행하니 서로 해당 시스템에 대해 분석해볼 시간이 부족해서 분석적인 내용없이 대화가 오간게 아쉬웠다. | G11: 주의
B12: 1 | C12: 박현수 | D12: 컨셉회의 간단하게 마무리하고 WBS 업무분배 작업하다가 컨셉이 엎어져서 할게 사라졌습니다... 기존에 있던 게임을 그대로 옮기는거 뿐이라 콘텐츠 기획쪽에선 무엇을 해야할지 어렵네요 | E12: 화이팅! | G12: 대기
B13: 2 | C13: 김서현 | D13: 1. 원페이지 기획서 작성 후, 공유 2. 기획안 확정 및 게임 코어 정립 3. 기획서 피드백 진행 4. 발표 자료 기반 작성 (미완) | E13: PM님과의 소통 부재가 있다고 느낍니다. 분명 사전에 방향성을 정했는데, 추후 얘기 없이 다른 방향성으로 진행되는 것이 많이 혼란스러웠습니다. 오늘은 좀 더 대화를 나눠보고자 합니다. 팀장으로서 부족한 것은 아닐까 하는 걱정이 앞섭니다. 깐부를 믿기! PM을 믿기! 이겨내겠습니다. | G13: 주의
B14: 2 | C14: 김태환 | D14: 업무 분담, 기획서 초안 확인 | E14: 기획 방향을 크게 틀게 되었지만 그럼에도 불구하고 이제 가닥이 잡혀가는 것 같아서 다행입니다. 다만, 볼륨에 대해 얼마나 협의를 볼 수 있을지 걱정입니다. | G14: 대기
B15: 2 | C15: 장윤우 | D15: 팀 컨셉 확정, 컨셉 시나리오 기획서 작성, 리소스 정리를 진행했습니다. | E15: 팀원들을 믿고 열심히 진행하겠습니다. | G15: 대기
B16: 2 | C16: 유해찬 | D16: 인게임 uI 작성을 요청받아 작업함. | E16: 내가 잘하고있을까아... 모르겠다 | G16: 대기
B17: 2 | C17: 박기은 | D17: 다같이 컨셉기획 마무리, 아트로 배정 받음!! 아트 스타일, 주인공 이미지, 배경 분위기 등에 대해 팀원분들과 이야기하고 대충 그려보는 시간을 가졌습니다. | E17: 화이팅.... | G17: 대기
B18: 2 | C18: 이원홍 | D18: 팀적으로 전체적인 컨셉 기획 완료 / 스테이지1 프로토타입 구상/ 레벨디자인 통합 문서 작성 진행중 | E18: 프로젝트가 진행이 되어가는 느낌이라 매우 좋습니다! | G18: 대기
... B55: 7 | C55: 이균호 | D55: 테마, 컨셉, 기본적인 시스템과 컨텐츠를 정했다. 각 인원의 팀 내 역할을 확정했다. | E55: 그 동안 시스템 기획만 쭈욱 해왔는데 이번에 처음으로 시스템이 아닌 레벨/전투 디자인을 맡게 되었다. 익숙하지 않은 부분을 하게 되어서 조금 두렵기도 하지만 한 편으로는 해보고 싶었던 레벨 디자인을 하게 되어 기대된다. 내일도 화이팅이다! | G55: 대기
B56: 7 | C56: 최선동 | G56: 대기
B57: 8 | C57: 예인해 | D57: 팀원 작업 확인 및 팀원 상담. PM과 WBS 내용 상세화, html 목업 생산, 진행사항 보고 | E57: 저!는! 행!복!합!니!다! 강!사!님!들!과! 매!니!저!님!도!행!복!하!시!온! | G57: 대기
B58: 8 | C58: 이도민 | D58: 작업 리스트 및 우선 순위 정리 | E58: 없습니다 ! | G58: 대기
B59: 8 | C59: 김시온 | D59: MainSystem_FSM, Stage_FSM,DataTable 임시 구조 정리 | E59: 시간이 너무 빨리갑니다. | G59: 대기
B60: 8 | C60: 이준혁 | D60: 배정받은 파트 아이데이션 1차 완료, 블록매치 상호작용 기획서 작성, 보스 기획, 패턴 기획, 블록 효과설정, 기타 부가효과 설정, 스파이 활동 | E60: 세상이 아름답습니다. | G60: 대기
B61: 8 | C61: 이승진 | D61: 게임 컨셉 기획서 및 이벤트 스토리 보드에 대해 작업했습니다. 주로 세계관, 캐릭터, 스토리, 설정, 게임의 진행 흐름 위주로 작업했습니다. | E61: 크런치가 사실상 필수라서 좀 부담되긴 하지만 아직은 버틸만합니다. 훌륭한 팀원들, 좋아하는 팀원들 몰아서 배치받은듯해서 배려해주셔서 감사합니다. 이번엔 팀원분들과 부딪히지않고, 저 스스로에 대한 자괴감 느끼는 일 없이 잘 해내고 싶네요. | G61: 대기
B62: 8 | C62: 김윤규 | D62: 컨셉 기획, 스테이지 사이 이벤트 기획 | E62: 분업이 잘 되고 시작한 것 같아서 좋습니다 | G62: 대기
B63: 8 | C63: 김범진 | D63: 전투 시스템 플로우 차트 작성, 전투 밸런싱 보조 | E63: 팀원들이 제 역활에 맞게 잘해주고 있습니다. 너무 깔끔합니다. 특히 팀장이란 이런거구나 라는걸 배우는 중입니다. | G63: 양호
B64: 8 | C64: 배주빈 | D64: PPT 발표자료 작성 | E64: 오늘은 정말 힘들었었다 | G64: 대기
B65: 9 | C65: 서진호 | D65: 1. 어제 작업하던 컨셉기획을 마무리하고, 원페이지 기획서를 각자 작성하고 장단점과 구현이 얼마나 걸릴지에 대해서 정한 후 문서 하나로 통합하는 작업을 했습니다. 이후 프로토타이핑을 위해 개별 문서를 작성했고, 개인 시간을 조금 할애해서 내일 오전까지 플레이 가능한 프로토타입을 만들 예정입니다. 2. 내일 PM님이 안계시기 때문에 오후 일정을 어떻게 배분할지에 대해서 이야기를 했었고 전체적인 일정 조율을 조금 더 했습니다. 3. 프로토타입 제작에 에셋을 쓰는건 조금 별로일까? 싶긴했는데, 에디터만 나왔지만 조금 고되더라도 하길 잘했다는 생각이 듭니다. 4. 특이하게도 업무를 하면서 더더욱 아이스 브레이킹이 되어가고 있습니다. 고작 이틀차지만, 화기애애해서 좋고 다들 게임의 방향성도 잘 이해하고 순항 중인 것 같습니다. 특히 원우님께선 어제 예비군으로 못오셨었는데, 갈피를 바로 잡으시고 문서 작성도 정말 잘 해주셨습니다. 5. 방금도 말했듯이 고작 이틀차지만, 지금 기획 팀원 분들과는 작업을 하는데에 있어 크게 어려울 거 같단 생각이 들지않을 정도로 저는 만족합니다. 6. 아까 말씀 해주셨던 것 처럼 구현 난이도가 꽤 있는데, 타일 배치와 관련해서 설명을 조금 더 보강하자면, 온천예제로 들면 온천을 1타일씩 추가하는 것이 아니라 3x3이나 5x3처럼 정해진 프리셋이 있어서, 그걸 설치하는 방식이였습니다. 스타듀 밸리를 생각해주시면 될 것 같습니다. 물론 스타듀밸리도 구현하려면 굉장히 어렵기 때문에, 기술적 구현 등의 문제들을 어떻게 해야할지에 대해서도 조금씩이라도 고민을 좀 해봐야겠네요. 7. 프로그래밍 분들과 같이 작업하는 건 간만이라서 꽤 긴장되네요 제가 프로그래밍을 하던 시절이 약 19년 전 이야기라 우매함 봉우리 그 자체라서 소통하는 방법이 과거에 제가 배웠던 것들이 아직도 통할지도 모르겠어서 걱정스럽긴 합니다. 그래도 저희 팀원 분들을 전적으로 믿듯이 프로그래밍 팀 분들도 전적으로 믿고 작업을 하는게 최선의 선택이라 생각합니다. | E65: 오전에 원우님께서 개인 프로젝트 작업을 병행하고 계셨는데 사전에 이야기를 안해주셔서 조금 꼬일뻔 했으나 다행히 잘 해결이 됐습니다. 오늘 하루도 무사히 넘어갔네요 내일은 더욱 더 열심히 해보겠습니다 수고하셨습니다 | G65: 주의
B66: 9 | C66: 강태성 | D66: 1페이지 기획안 확정 및 프로토타입용 기획안 작성 도움, 내일 일정 배분, WBS 작성 준비 | E66: 여기 분위기 좋은데요. 어라, 그동안 제가 한 팀 프로젝트는 이런게 아니였는데 스타크씨... 기분이 이상해요 | G66: 양호
B67: 9 | C67: 박민규 | D67: 컨샙 기획과 프로토 타입 개발 기획을 마쳤습니다! | E67: 캐릭터를 많이 만들고싶습니다! | G67: 대기
B68: 9 | C68: 김경민 | D68: 원페이지, 기획서 작성, 타이쿤게임의 기본적인 UI/UX 와이어 프레임 피그마로 작성 | E68: 음.. 다른 부분은 모두 순조롭지만 초기 구상 분량이 많아 어느정도까지 구현이 될지 조금 걱정이 됩니다. | G68: 대기
... B75: 10 | C75: 홍태광 | D75: 1. 팀원분들과 함께 게임 컨셉을 구체화 후 확정. WBS를 작성하는 시간을 가졌습니다. 2. 전투화면 UI의 기본적인 레이아웃, 팝업 레이아웃을 구상하였습니다. | E75: 저희 조 주제가 다른 주제와 비교해 범위가 작은 덕분에 빠르게 컨셉을 확정할 수 있었던 것 같습니다. | G75: 대기
B76: 10 | C76: 정재훈 | G76: 대기
B77: 10 | C77: 한의호 | D77: 소통 원활화를 위한 게임 내 용어 정리, UI목업 회의, 개발 필요 요소 정리 | E77: 장르를 잘 뽑아서 진행이 비교적 빠른 것 같아 정말 다행인 것 같습니다. | G77: 대기
B78: 10 | C78: 정재용 | D78: 게임 컨샙 구체화 후 확정, WBS작성, 우선 순위 설정 | E78: 행복합니다 ^^; | G78: 대기
B79: 개인 | C79: 김지훈 | D79: 생성 ai 파이프라인 세팅 | E79: 환경 세팅에 많은 시간이 드는 거 같다 | G79: 대기
B80: 개인 | C80: 이석훈 | D80: 이름짓기 기능 개발 | E80: UI랑 엮는게 쉽지않네요 | G80: 대기
B81: 개인 | C81: 조현일 | D81: 컨셉 기획서의 토대를 다지는 작업을 했습니다. | E81: 차분하게 현재 할 수 있는것들을 쌓아나가는것이 관건이라 생각합니다. 전진하겠습니다. | G81: 대기

Sheet 0319
B2: 날짜 | C2: 46100
B4: 팀 | C4: 이름 | D4: 작업량 | E4: 한마디 | F4: 비고 | G4: 상태
B5: 1 | C5: 강유민 | D5: {=IF($C5:$C999="","", IFERROR( VLOOKUP( $C5:$C999 & "│" & TEXT($C$2,"yyyy-mm-dd"), SORT({ '설문지 응답 시트1'!$B$2:$B999 & "│" & TEXT('설문지 응답 시트1'!$D$2:$D999,"yyyy-mm-dd"), '설문지 응답 시트1'!$E$2:$E999, '설문지 응답 시트1'!$A$2:$A999 }, 3, FALSE), 2, FALSE ), "" ) )} -> 팀 제작 컨셉 완료 후, 발표를 위한 컨셉 기획서 작성. 1페이지 기획서 및 기타 요소 | E5: {=IF($C5:$C999="","", IFERROR( VLOOKUP( $C5:$C999 & "│" & TEXT($C$2,"yyyy-mm-dd"), SORT({ '설문지 응답 시트1'!$B$2:$B999 & "│" & TEXT('설문지 응답 시트1'!$D$2:$D999,"yyyy-mm-dd"), '설문지 응답 시트1'!$F$2:$F999, '설문지 응답 시트1'!$A$2:$A999 }, 3, FALSE), 2, FALSE ), "" ) )} -> 팀 내 이슈가 너무 많았습니다. 이건 제 역량이 부족한 것으로 보여요. 과정에서 조금 지치는 느낌이 있는데, 해소해보도록 하겠습니다. 그래도 오늘은 분위기를 만들 수 있었습니다. 무사히 완주하도록 부단히 노력하겠습니다. | G5: 주의
B6: 1 | C6: 이유송 | D6: (오전) 컨셉기획 회의 진행 (오후) 팀원 개별 면담, PM 업무 파악(마일스톤,WBS작성해야함) | E6: 1. 팀 내 이슈 : 없음. 2. 어려웠던 점 : PM의 역할을 내가 잘 하고 있나라는 것에 대한 고민. 내가 다 잘할 수 없다는 거 인정하고, 그렇다면 지금 내가 놓치는게 뭔지, 또는 내가 무조건 챙겨야하는게 뭔지 빠르게 파악한 다음에 내일부터 제대로 해봐야지. 잠깐 헤맸지만 그래도 pm모임시간 때 다른 팀들이 어떻게 진행하고 있는지 보면서 많이 배웠다. 3. 오늘 나의 상태 : 뭐가 어떻게 돌아가는지는 알겠는데, 뭘 해야하는지도 알겠는데, 어떻게 해야하는지 모르겠다?? 4. 현재 나의 상태 : 내가 이 일을 처음 경험하기 때문에 몰라서 못할 수 있다는 거 인정하고, 나 혼자 다 해결하려고 하지말고, 팀장, 팀원, 타팀 pm, 강사님들께 적극적으로 조언을 구해야겠다. 어떻게든 이 팀을 제대로 굴려보고 싶다. 화이팅! | G6: 주의
B7: 1 | C7: 이동현 | D7: 컨셉 기획서 확실하게 방향 확정, 코어 루프, 핵심 시스템 다이어그램으로 표현 및 간략한 문서화, 개발 및 시스템 관련 조언, 소통 관련 노력 | E7: 행복합니다~행복합니다~행복합니다~ | G7: 대기
B8: 1 | C8: 정우경 | D8: 시스템 기획, 코어 루프 작성 | E8: 팀원간의 의사소통이 많이 좋아졌다. 좋은 결과가 있을 것으로 기대된다. | G8: 대기
B9: 1 | C9: 김현우A | D9: 스킬 플레이어 캐릭터에게 기본으로 제공하게 될 스킬을 우선적으로 작업해주세요! 1플레이어 캐릭터가 사용할 수 있는 스킬 별 컨셉 기획 2공격 방식 3공격 범위, 공격 사거리 4재사용 대기시간 5주사위 1~6에 따라 변화 작업 -> 해당 스킬을 얻을 수 있는 스테이지 제한 요소가 필요하다면 해당 요소도 획득 조건으로 포함할 것 (ex. n스테이지 이상에서만 해당 장비가 드랍된다는 조건, 상점에서 구매를 통해서만 획득할 수 있다, 히든 요소를 추가하고싶다면 해당 부분에 대해서도 작성 필요) | E9: 철야 다운 철야를 오늘 했다고 생각합니다 | G9: 대기
B10: 1 | C10: 정석현 | D10: 컨셉 기획 마무리 장비 아이템 컨셉 기획 | E10: 해서 안되는건 없다!!!!!! 화이팅!!!!!!!!!!!!!! | G10: 대기
B11: 1 | C11: 임소영 | D11: 콘텐츠 파트 분배, 게임 콘텐츠 아이디어 제안 및 콘텐츠 원페이지 기획서 제작 | E11: 게임 내에 들어갈 콘텐츠 아이디어를 팀원분들에게 제안 이후 팀원분들이 이해할 수 있도록 원페이지로 작성해 이해를 돕고, 추후 세부 기획서 작성 및 추가되는 시스템이 있을 경우 오류나 컨셉에서 벗어나지 않는지에 대한 확인 작업이 이뤄질 수 있도록 돕는 컨셉 기획서 작성 작업을 진행했습니다. | G11: 대기
B12: 1 | C12: 박현수 | D12: 컨셉회의 마무리 + 콘텐츠 기획 초입부 플레이어&몬스터에 대해서 작성하였습니다 | E12: 큰 파도를 하나 넘긴거같아 다행임니다... | G12: 대기
B13: 2 | C13: 김서현 | D13: 발표 PPT자료 작성 했습니다. 레벨 디자인, UI 기획, 시스템 기획서 간략한 방향성 피드백 드렸습니다. 레벨 디자인 기획서 초안 작성 및 가이드라인 드렸습니다. | E13: 행복합니다!!!행복합니다!!! 제가 상황에 대해 상황 설명을 하고 팀장으로서 결정을 드렸음에도 계속 말이 반복되어서 너무 힘들었습니다.. 그 외에는 .. 작업을 안 하시고 계셔서 당황스러웠습니다. 작업물이 없다고 ... 말씀하셨.. 습니다...ㅠㅠ 힘내보겠습니다.. | G13: 대기
B14: 2 | C14: 김태환 | G14: 대기
B15: 2 | C15: 장윤우 | D15: 소개문, 튜토리얼 스테이지 시나리오, 1스테이지 시나리오, 2스테이지 시나리오 작성 | E15: 창작의 고통을 겪고 있습니다 으아아아아아아악 | G15: 대기
B16: 2 | C16: 유해찬 | D16: UI 기획 상세 설명 추가, UI 대화 내용 추가 | E16: ㅇ0ㅇ 일이 적당해서 부담이 없어서 좋습니다 :> | G16: 대기
B17: 2 | C17: 박기은 | D17: 오늘 맵과 캐릭터를 ai로 만들어보는 시간을 가졌습니다! | E17: 맵크기에 따라 배경아트가 변동될 사항이 많아서 고민이 많았네요ㅎㅎ.. 잘 완성되면 좋겠습니다..~ | G17: 대기
B18: 2 | C18: 이원홍 | D18: 플레이타임, 전체적인 스테이지 배치, 튜토리얼 등 회의를 통한 변경점 반영 | E18: 오늘도 고생하셨습니다. | G18: 대기
B19: 2 | C19: 오동건 | D19: 회의 시스템 기획서 작성한 내용에 회의록 반영 | E19: 뭔가 만들어지고 있다! | G19: 대기
B20: 3 | C20: 정수진 | D20: 각 파트별 세부 작업 진행, 시스템_플레이어, 전투 기획서 컨펌, 무기 콘텐츠 컨펌을 진행하였습니다. 컨셉 기획서 정리와 발표 준비도 함께 진행하였습니다 | E20: 각 파트별로 독립적으로 진행하였으면 했는데, 연계되는 내용에 있어서 동시작업되는 만큼 팀원들끼리 소통이 있었습니다. 그 과정에서 또 다른 논의 과정이 나오고 이야기가 길어지면서 기획서 작업의 진행속도가 느려진 상황이 생겨서 이를 정확히 잡고 가야할거같습니다. | G20: 대기
B21: 3 | C21: 우현승 | D21: WBS 작업리스트 세부 분류 및 우선순위 선정 개발기간 고려해서 1,2차 기획 목표 지정 | E21: 게임 제작 시 직관적인 시스템, 콘텐츠에 비해서 일이 상대적으로 후반부에 배치된 레벨, 밸런스 담당 인원에 대한 일정 배분에 고민이 많았다. 물론 아직 해결법을 알아내진 못하고 임의로 배정해준 느낌이 강하긴 해서 조금 걱정이 되긴 한다. 자주 작업 진도를 확인해야 할것 같다. | G21: 대기
B22: 3 | C22: 안성진 | D22: 플레이어 시스템 완료. 전투 시스템 진행중 | E22: 없습니다 | G22: 대기
B23: 3 | C23: 김민제 | D23: 원거리 무기 기획서 (각 총기의 기획의도, 공격력 순위, 경직 순위, 전투컨셉, 재장전 시간, 장탄수, 모델, 탄환, 궤도 FX) 일반 좀비 기획서 (밤에 시작) | E23: 본인한테 공유가 되지 않은 점이 있어서 기획하는 데 있어 오해 및 의견 차이가 생겼었고 꽤 토론을 오래 했고 모두가 납득하는 방향으로 해결됐다. | G23: 대기
B24: 3 | C24: 김영도 | D24: 무기 기획서 작성, 콘텐츠 컨셉 시스템 관련 회의 진행 | E24: 여러 기획서가 나오다보니 여러가지 회의를 하게 되었던 것 같습니다. | G24: 대기
B25: 3 | C25: 윤동현 | D25: 오늘은 컨셉에 관해 얘기한 후, 남은 시간동안 제가 맡은 밸런스 기획서 작성을 진행하였습니다. 하지만 작성 중에 시스템, 콘텐츠 담당자분들과 얘기가 오가야해서 제대로 작성을 하지 못한 부분이 많았습니다. 시간을 날린 셈이 되었긴 하지만... 소통의 아쉬움이라고 배우고 계속 진행하면 될 것 같습니다. 그리고 현재 근, 원거리 무기에 대해 넉백을 주니, 사거리는 어쩌니 등등 얘기가 오가길래 그냥 무기 데이터 테이블 시트를 작성할 때 넉백, 사거리 등에 대해 Bool로 선택을 주고 그 뒤에 수치를 입력하는 Float를 두어 해결하면 되지 않을까 라는 생각으로 팀원분들에게 얘기하기도 했습니다. 작동이 될 지 안될 진 잘 모르겠습니다 .. | E25: 생각보다도 더 시간이 매우 짧은 거 같아서 조바심이 듭니다. ... 플밍반분들 제발 잘 부탁드립니다 ㅠㅠㅠ | G25: 대기
B26: 3 | C26: 권수빈 | D26: 맵 시점 설정, 스테이지 구조 설계 | E26: 스테이지 구조에 대한 고민이 많은데 팀원들과 소통해서 열심히 하겠습니다 | G26: 대기
... B62: 8 | C62: 김윤규 | D62: 유물 보상 이벤트 설정, 스토리보드 작성, 엔딩 크레딧 작성 | E62: 재밌습니다이 | G62: 대기
B63: 8 | C63: 김범진 | G63: 대기
B64: 8 | C64: 배주빈 | D64: 튜토리얼 설계(구글 슬라이드) 1. 튜토리얼 설계 개요 2. 기능안내 UI 와이어 프레임 3. UI 아트리소스 구상안 | E64: 아직 파트배정을 받지 못한 부분이 아쉬웟지만 재미있었다(?) | G64: 대기
B65: 9 | C65: 서진호 | D65: 오늘은 프로토타입의 완성과 발표 문서를 작성하고, 팀원 분들의 세부적인 업무 분담을 진행했습니다. 오후에는 업무분담을 마친 후 어느정도는 서로 상의해가며 문서 작성을 시작하셨습니다. 개인적인 업무로는 PM님께서 예비군으로 인해 부재를 하셔서, 의견을 나눠야하는 내용을 정리하고 전달드렸습니다. | E65: 솔직히 말씀 드리자면 이번 PPT 제작 간에 레이아웃 디자인이 너무 힘들고 오래걸릴 것 같아서 목업과 텍스트만 좀 채우고 AI로 디자인을 해달라고 했는데, 바뀐 텍스트들이 좀 많아서 문제가 있었습니다 검수 작업 을 하다가 중간에 좀 이런저런 다른 작업이 있어서 제대로 못하고, 저녁 8시에 PM님과 대화를 하는데 AI가 주석을 달아놓았던 부분을 늦게 파악해 죄송스러웠습니다. 프로토타입 제작을 제가 맡고 세부 기획서를 작성하실 수 있도록 배려하고자 했던 부분에서 스스로의 일정 관리의 세부 버퍼를 고려하지 않아 발생한 문제같습니다. 일단 금일은 피곤하여 일찍 자고, 내일 새벽에 일찍 일어나 문서 검수 및 수정을 거치고 발표 연습을 해보려고 합니다. | G65: 대기
B66: 9 | C66: 강태성 | G66: 대기
B67: 9 | C67: 박민규 | D67: 오늘은 사용할 에셋 분류와 캐릭터 기획을 들어갔습니다. | E67: 내일은 드디어 플밍분들이 오는날 기대가 됩니다! | G67: 대기
B68: 9 | C68: 김경민 | D68: 초기UI플로우차트 | E68: - | G68: 대기
B69: 9 | C69: 박원우 | D69: 인원분배, 개인면담, 일정회의, 프로토타입 피드백, 역할관리 배치, 기타등 | E69: 이대로만 갑시다! | G69: 대기
B70: 9 | C70: 고승주 | D70: 역할 분담, 면담, 시스템 기획 일정 문서 작성 | E70: 플머분들이 왔을 때 드릴 일거리가 있어야 한다는 생각에 초조하군요 | G70: 대기
B71: 9 | C71: 임동균 | D71: 재화 시스템 전반적으로 설계하고, 이와 연관된 의뢰, 평판, 손님 기획을 메인으로 담당하기로 했다. 재화 시스템을 손보다보니 기본 재화인 골드와 특수 재화 크게 두가지로 나누다보니 초반/후반 재화 흐름도 고려하다보니 최종 목표에 대해서도 또 생각하고 설계해야 했다. | E71: 정말 배울게 많은 팀원들과 함께하고, 좋은 팀원과 하니까 더 자극되어서 열심히 하게 되는 것 같습니다. 공대에서 계산만 했지, 글을 작성을 거의 안해서 글 쓰는 재주가 너무 부족합니다. AI를 통해서 글을 다듬고 정리를 많이하는데 기획서 말고도 그냥 평소 아이디어나 생각 등을 툭툭 던져서 쓰고, AI가 정리한걸 보고 정제된 언어로 쓰는 방법을 연습해야겠습니다. AI 활용 말고도 글쓰기 관련 서적 등으로 공부를 해야겠다는 생각이 들었습니다. 이 내용도 쓴 뒤에 다듬었는데, 정말.. A해서 B했는데 C해서 D했고 E했는데..이렇게 쭉 이어지는게 보이네요. 대학원에서 논문 볼 때, 이런식으로 써진 글 보고 정말 싫어했는데 왜 그렇게 써져있었는지 알 것 같기도 하네요......... | G71: 대기
B72: 10 | C72: 장호윤 | D72: 발표 자료 준비, PPT 제작, HTML 프로토타입 준비, 팀원 기획서 피드백 및 회의 | E72: 내일 발표 첫빠따 너무 기대됩니다 저는 행복해요 | G72: 대기
B73: 10 | C73: 천영현 | D73: 1. 남은 와이어 프레임 작성 2. 밸런스 기획 초안 완성 3. 시스템 플로우 4. 시너지 구현 방식 구현 5. 세계관, 컨셉 설정 | E73: 팀원 분들 다들 뽜이팅 넘치고 좋습니다! | G73: 대기
B74: 10 | C74: 이영우 | G74: 대기
B75: 10 | C75: 홍태광 | D75: 전투화면 UI, 환경설정 UI 와이어프레임 구성 | E75: 오늘 우리 팀이 진도가 빠르다는 소식을 듣고 꽤나 놀랐습니다. | G75: 대기
B76: 10 | C76: 정재훈 | D76: 합성과 시너지에 대한 시스템 기획서 작성 | E76: 팀원들이 자기가 맡은 일을 너무 잘 해줘서 좋았습니다 | G76: 대기
B77: 10 | C77: 한의호 | D77: 시너지 컨셉, 시나리오 컨셉, 유닛 컨셉 기획 | E77: 아이디어는 좋은 게 나왔지만 구현에 얼마나 걸릴까 생각하니 망설여지는 부분이 있었습니다. 하지만 기간 내에 프로젝트 완성이 불가능한 수준이 아니라면 플밍 팀 입장에서도 난이도가 높은 시스템 구현을 해내는 것이 경험적인 측면에서 더 도움이 되지 않을까 싶어 일단 기획은 해 보아야겠다고 생각했습니다. | G77: 대기
...

Sheet 0320
B2: 날짜 | C2: 46101
B4: 팀 | C4: 이름 | D4: 작업량 | E4: 한마디 | F4: 비고 | G4: 상태
B5: 1 | C5: 강유민 | D5: {=IF($C5:$C999="","", IFERROR( VLOOKUP( $C5:$C999 & "│" & TEXT($C$2,"yyyy-mm-dd"), SORT({ '설문지 응답 시트1'!$B$2:$B999 & "│" & TEXT('설문지 응답 시트1'!$D$2:$D999,"yyyy-mm-dd"), '설문지 응답 시트1'!$E$2:$E999, '설문지 응답 시트1'!$A$2:$A999 }, 3, FALSE), 2, FALSE ), "" ) )} | E5: {=IF($C5:$C999="","", IFERROR( VLOOKUP( $C5:$C999 & "│" & TEXT($C$2,"yyyy-mm-dd"), SORT({ '설문지 응답 시트1'!$B$2:$B999 & "│" & TEXT('설문지 응답 시트1'!$D$2:$D999,"yyyy-mm-dd"), '설문지 응답 시트1'!$F$2:$F999, '설문지 응답 시트1'!$A$2:$A999 }, 3, FALSE), 2, FALSE ), "" ) )} | F5: 미작성 | G5: 대기
B6: 1 | C6: 이유송 | F6: 미작성 | G6: 대기
B7: 1 | C7: 이동현 | D7: 미니맵 ui 와이어프레임 피그마 프로토타입으로 작성, 세부 시스템 기획서 조금이나마 작성, 팀장님 미소녀 만들기 대성공 | E7: 시간이 두배로 늘어나면 좋겠습니다. | G7: 대기
B8: 1 | C8: 정우경 | D8: 개발팀과 미팅 | E8: 모든 일이 잘될것이다. 혹시 모를 문제가 발생할 수 있다. 다 극복하겠다. | G8: 대기
B9: 1 | C9: 김현우A | D9: 스킬 기획문서 작성 | E9: 내가 재대로 기획문서를 작성한것이 만든지 모르겠다 | G9: 대기
B10: 1 | C10: 정석현 | D10: 자기소개 및 아이스 브레이킹 컨셉, 시스템 등 게임 설명 팀명, 게임 제목 선정 | E10: 처음 하는 합반 협업이라 설렘 반 떨림 반으로 진행되고 있는 것 같은데, 플밍반 분들께서 우리 조 게임 컨셉과 시스템을 긍정적으로 봐주시고 계신 것 같아서 다행인 것 같다... | G10: 대기
B11: 1 | C11: 임소영 | D11: 콘텐츠 확정, 콘텐츠 파트 분할 배분, WBS 내용 정리 및 전체 흐름 체크 | E11: 팀원분들마다 파트 분할, 주말 자율 작업 요청, 팀원분들 전체 현재 작업 이해도 체크 | G11: 대기
B12: 1 | C12: 박현수 | D12: 플밍반 분들과 가벼운 자기소개 후 컨셉 리뷰를 진행하였고 대략적으로 잡은 작업파트에 대해서 구현 가능성과 난이도에 대한 논의를 진행하였습니다 | E12: 플밍반분들과 첫 협업이라 걱정이 되지만 열심히 하려합니다! | G12: 대기
B13: 2 | C13: 김서현 | D13: 아이스브레이킹 (각자 소개, 작업 공유) / 진행은 태환님께서 진행해주셔서 크게 제가 진행한 것은 없었습니다. UI/UX 피드백 및 방향성 제시 및 레벨 디자인 기획서 컨펌, 조작키 방향성 회의, 반전 및 줌아웃 시스템 관련 논의. | E13: 큰 문제는 없었습니다. 기획 팀 내 논의가 길어질 때, 가장 타당한 의견으로 결론을 지으면서 이유를 설명 드렸습니다! 좀 더 마무리 짓는 사람이 필요한 것 같다는 생각이 들어서 그 부분에 대해 좀 더 노력해 보려고 합니다! 프로그래밍반 분들과 나름대로 잘 대화하며 진행해보겠습니다! 화이팅! | G13: 대기
B14: 2 | C14: 김태환 | D14: 킥오프전 기획서 내용 취합. 현재 작업 달성도 확인 | E14: 일부 인원의 담당 업무 변경을 고려하고 있습니다......... | G14: 주의
B15: 2 | C15: 장윤우 | D15: 프로그래밍 분들과의 협업 관련 정리, 시스템 논의, 스테이지 3 진행 | E15: 플밍 분들이 너무 마음에 듭니다. 좋은 느낌이 들어요 최고입니다! | G15: 대기
B16: 2 | C16: 유해찬 | D16: UI 환경설정 , UI 대화창 업데이트 | E16: 기획서 피드백 받으면서 성장해 가는중입니다. | G16: 대기
B17: 2 | C17: 박기은 | D17: 오늘은 작업이 많지는 않았고 플밍반 분들과 아이스브레이킹 하고 함께 기획리뷰하는 시간을 가졌습니다. 또한 서현님과 게임 배경에 맞는 이미지 규격에 대해 얘기하고 확정 지었습니다. | E17: 드디어 플밍반 분들과 작업하게 되어서 기쁩니다~! 화이팅~ | G17: 대기
B18: 2 | C18: 이원홍 | D18: 플밍반과 사전합반을 통한 회의 정리 | E18: 고생합니다. 고생하고있습니다. 고생하셨습니다. | G18: 주의
... B49: 7 | C49: 김민수 | D49: 컨셉 발표, 프로그래머와의 아이스브레이킹, 대화의 간극 좁히기, 업무 프로세스 정리 | E49: 한 번에 여러 정보를 병렬적으로 처리하기가 너무 어렵습니다 ㅠㅠ 좋은 방법이 있을까요?ㅋㅋ ㅠㅠ | G49: 대기
B50: 7 | C50: 이정헌 | G50: 대기
B51: 7 | C51: 이승구 | D51: 아이스브레이킹! | E51: 잘 부탁드립니다 플밍 동기분들! | G51: 대기
B52: 7 | C52: 채지형 | D52: 플밍반과 기획반 같이 아이스브레이킹 | E52: 없습니다! | G52: 대기
B53: 7 | C53: 곽용준 | D53: 에셋 관련 피드백 받기 | E53: 주말동안 무엇을 해야할지 고민입니다 | G53: 대기
B54: 7 | C54: 이도건 | D54: 오늘 처음 프로그래밍 인원분들과 만나서 간단한 소개를 진행했습니다. 그리고 이전까지 진행한 틀에 대해서 프로그래밍 반 인원들과 공유를 하며 설명을 진행했는데 기획서가 다듬어지지 않은 상태였고, 프로그래밍 반 인원들도 이런 체계의 기획을 처음 접하다 보니, 정보를 받아들이고 정리하는 과정에서 간극이 있는 것 같습니다. 이 부분이 완전히 마무리 되지 않은 상태이기에 23일 다시 만나서 서로의 분야에 대한 이해에 관한 소통이 계속적으로 필요할 것 같습니다. | E54: 위에도 적었듯이 서로의 역량과 이후 진행할 작업에 관한 이해가 처음 접했다보니 간극이 매우 큰 것 같습니다. 이에 대해서 소통하는 과정이 중요할 것 같습니다. | G54: 대기
B55: 7 | C55: 이균호 | D55: - 프로그래밍 반 분들과 교류 - 아이스브레이킹(자기소개, 이상형 월드컵, 갈틱폰) | E55: 오늘 드디어 프로그래밍 분들과 이야기를 나누게 되었다. 낯설어하시는 분들도 계셨지만 역시나 공통 관심사인 게임 앞에서 마음의 장벽은 무의미했다. 게임 이상형 월드컵을 하면서 많은 분들이 마이크를 켜고 참여해주셔서 서로 잘 알아가는 시간이었다고 생각한다. 막상 프로그래머 분들과의 협업이 코 앞에 닥치니 어려움이 눈에 확 들어오기는 하지만 그럼에도 불구하고 깨지고 부딪히며 성장하여 협업 능력을 더욱 기른 기획자가 되겠다고 다짐하는 하루였다. | G55: 대기
B56: 7 | C56: 최선동 | D56: 아이스 브레이킹 / 게임 전체 볼륨 체크 / 플밍반 + 기획반 의견 나누기 / 일정 체크 | E56: 개발자와 시작하니 더욱 떨리는 프로젝트 같습니다. 화이팅! | G56: 대기
B57: 8 | C57: 예인해 | D57: 컨셉 발표, 플머팀과 단체 미팅, 기능 설명회, 팀명, 게임명 결정, 세부사항 조정. | E57: 발표한다고 너무 긴장해서 텐션이 안나온게 너무 아쉽습니다... | G57: 대기
B58: 8 | C58: 이도민 | D58: 기획 & 플밍 소개 및 작업 관련 논의 | E58: 없습니다 ! | G58: 대기
B59: 8 | C59: 김시온 | D59: 플밍분들과 자기소개, 시스템 기획서 컨펌 및 필요 사항논의, 팀명 정하기 | E59: 아직은 조금 어색해서 더 얘기를 많이 해야할 것같습니다 ㅎㅎ | G59: 대기
B60: 8 | C60: 이준혁 | D60: 너무 어색해하고 불편해하고 어려워하고 미워하길래 광대 역할을 했습니다. 작성한 기획서에 대한 설명을 했으며, 프로그래머에 대한 존중과 배려를 학습했음을 어필하며 서로 좋은 결과물을 내기 위해 최대한의 배려를 할 준비가 되어있다고 전달했습니다. | E60: 전반적으로 만족스럽습니다만, 컨디션에 따라 에티튜드가 나락으로 가는 팀원이 있습니다. 잘 케어해보겠습니다. | G60: 주의
B61: 8 | C61: 이승진 | D61: 오늘은 회의 위주라 한게 별로 없습니다. 기획서 약간 다듬고 WBS에 작업한거 정리한게 전부네요. | E61: QA 단계에서 깃허브 이슈를 쓰고싶단 플밍팀과 디스코드로 빠르게 소통하고싶단 기획팀의 의견이 갈린 일이 기억에 남습니다. 결론은 QA단계까지 일단은 보류하는걸로 결론이 났습니다. 추후 어떻게 될진 모르겠네요. 현업에서도 깃허브 이슈를 활용한다고하니 개인적으로 한번 써보고싶긴 하지만 기회가 이번에만 있는건 아닐테니까요. 오늘은 정말 뭐 한게 별로 없었던거 같아서 야근을 하든, 주말을 반납하든 뭐라도 좀 더 해야할거 같습니다. 짧은 기간 내 해야할 일은 정말 많으니까요. | G61: 주의
B62: 8 | C62: 김윤규 | D62: 플밍팀과 협업 툴 공유, 기획서 발표 및 의견 조율, 서로 이해한 부분 체크하기 | E62: 처음으로 플밍팀과 함께 협업하니깐 좀 기대가 되면서도 걱정되네유 아자아자! | G62: 대기
... B67: 9 | C67: 박민규 | D67: 플밍분들과 만나서 아이스 브레이킹 작업을 했습니다 | E67: 기대가 됩니다 | G67: 대기
B68: 9 | C68: 김경민 | F68: 미작성 (결석) | G68: 대기
B69: 9 | C69: 박원우 | F69: 미작성 (조퇴) | G69: 대기
B70: 9 | C70: 고승주 | D70: 팀내 규칙 설정, wbs 작업 우선순위 설정 | E70: 플머분들이 하실만한 작업을 빨리 해야합니다 | G70: 대기
B71: 9 | C71: 임동균 | D71: 새로 만나게된 프로그래밍 반 팀원들과 만났다. 어느정도 구체적인 작업방식, 어떻게 진행할지, 계획, 그라운드 룰 등을 논의했다. | E71: 기획서를 일단 내용을 많이 담으려고 했는데, 잊고 있던 사실이 프로그래머가 보고 만드는 자료라는 사실이었다. 프로그래머가 보기 편하고 빠르게 정보를 습득할 수 있는 방식을 더 고민해보고 적용해봐야겠다. | G71: 대기
B72: 10 | C72: 장호윤 | D72: 즐거운 얼음부수기 갈틱폰, 첫 전체 팀 회의, WBS 논의 | E72: 플밍팀에 한분이 참석하지 않아서 따로 얼음부수기를 한번 더 해야할 것 같아 너무 즐겁습니다 갈틱폰 한판에 모두가 웃음폭탄! | G72: 대기
B73: 10 | C73: 천영현 | D73: 갈틱폰으로 플밍분들과 친해지기! 성공이였습니다 ㅎㅎ 남은 2시간을 활용해서 기획내용 설명드리고 개발 기간 산정에 어떤식으로 하실지 이야기를 나눈 뒤 추후 일정을 잡기로 헀습니다! | E73: 아무래도 개발 분들이 이번에 처음 오셔서 개발자 분들과 어떤 부분부터 상의를 해야할지 가늠을 못잡아서 어려웠습니다.. | G73: 대기
B74: 10 | C74: 이영우 | D74: 갈틱폰 했습니다. | E74: 팀내에 타워 디펜스를 만드신분이 계셔서 쉽게 진행될 것 같습니다 | G74: 대기
B75: 10 | C75: 홍태광 | D75: 아이스브레이킹, 게임기획 및 UI 공유 | E75: 갑작스런 한의호님의 결혼선언...(진짜로 결혼하는 것이 아닙니다.) | G75: 대기
B76: 10 | C76: 정재훈 | D76: 플밍분들과 아이스 브레이킹시간을 주로 가졌습니다. | E76: 아이스브레이킹을 주로 시간을 가져서 플밍분들이 실제 작업에 들어갔을때 어떤걸 어려워하고 힘들어 할지가 궁금해집니다. 프로젝트가 잘 진행됐으면 좋겠고, 기대됩니다. | G76: 대기
...

Sheet 0323
B2: 날짜 | C2: 46104
B4: 팀 | C4: 이름 | D4: 작업량 | E4: 한마디 | F4: 비고 | G4: 상태
B5: 1 | C5: 강유민 | D5: {=IF($C5:$C999="","", IFERROR( VLOOKUP( $C5:$C999 & "│" & TEXT($C$2,"yyyy-mm-dd"), SORT({ '설문지 응답 시트1'!$B$2:$B999 & "│" & TEXT('설문지 응답 시트1'!$D$2:$D999,"yyyy-mm-dd"), '설문지 응답 시트1'!$E$2:$E999, '설문지 응답 시트1'!$A$2:$A999 }, 3, FALSE), 2, FALSE ), "" ) )} -> 내러티브 기획 및 팀 전체 기획 문서 검토 수정. | E5: {=IF($C5:$C999="","", IFERROR( VLOOKUP( $C5:$C999 & "│" & TEXT($C$2,"yyyy-mm-dd"), SORT({ '설문지 응답 시트1'!$B$2:$B999 & "│" & TEXT('설문지 응답 시트1'!$D$2:$D999,"yyyy-mm-dd"), '설문지 응답 시트1'!$F$2:$F999, '설문지 응답 시트1'!$A$2:$A999 }, 3, FALSE), 2, FALSE ), "" ) )} -> 시간이 사라졌습니다... 오늘 정말 정신없이 지나갔네요 | G5: 대기
B6: 1 | C6: 이유송 | D6: 팀원 업무 진행 상황 파악, 개발팀 기획 서류 전달, 회의 진행(오전 전원 데일리 스크럼, 퇴근 전 팀장 회의) | E6: 걱정 많으신거 압니다. 저도 제가 걱정되긴 하거든요ㅋㅋ 근데 이제 조금씩 어떤 건지 알거 같습니다. 느리지만 조금씩 배우고 있습니다. 일단 어떻게든 해볼게요. 만약 제 머릿속이 궁금하시다면 1조 노션에서 제 회고 참고 부탁드립니다. https://www.notion.so/_-_-3261c30b8ab380eda325d3ebba7e8e80 | G6: 대기
