Workbook

Sheet 설문지 응답 시트1
A1: wnwo | B1: 이메일 주소 | C1: 1. 이름 | D1: 2. 성별 | E1: 3. 나이 | F1: 4. 최종학력 체크 | G1: 5. 본 과정과 연관하였을 때 여러분은 전공자인가요 ? | H1: 6. 학교와 전공 | I1: 7. 1분 자기소개를 작성해주세요. | J1: 8. 본 과정에 참여를 신청한 이유는 무엇인가요? | K1: 9. 지금까지 게임과 관련된 학습 및 업무 경험이 있습니까? | L1: 10. 과정과 관련된 취업 분야를 알고 있는만큼 적어주세요. | M1: 11. 수료 후 자신의 목표를 작성해주세요. | N1: 12. 화상 수업을 위한 캠 + 마이크 보유사항을 체크해주세요 | O1: 13. 본인이 앓고 있는 지병 혹은 질환이 있나요? | P1: (13번 질문에 예를 선택하신 경우)지병 혹은 질환이 있다면 어떤 상황인지, 복용하고 있는 약이 있다면 간략히 작성해주세요. 장기 훈련 과정을 진행하기에 앞서 도움을 드리기 위해 파악됩니다. | Q1: 14. 타인과의 갈등 속에서 당신은 어떻게 대처하나요? | R1: 15. 여러분은 자신의 실수나 실패에 대체로 어떻게 대응하시나요? | S1: 16. 타인의 부족한 부분을 보았을 때 어떻게 대처하시나요? | T1: 17. 본 과정은 장기 훈련과정입니다. 참여에 영향을 줄 경제적인 어려움이 있나요? (추가적인 정부 지원 안내를 위해 활용됩니다.) | U1: (17번 질문에 예를 선택하신 경우)어려움이 있다면 어떤 상황인지 간략히 작성해주세요. | V1: 18. 지인 중에 게임 업계 관련 종사자가 있습니까? | W1: 19. 추천을 받았다면 누구에게 받았습니까 ? | X1: 20. 궁금한 부분이 있거나 과정 참여 시 걱정되는 부분이 있다면 자유롭게 작성해주세요. | Y1: 이름 | Z1: 작성일자 | AA1: 개인정보 수집 및 이용에 동의하십니까? | AB1: 이름 2 | AC1: 작성일자 2 | AD1: 개인정보 처리방침에 동의하십니까?
A2: 45945.264 | B2: kny6900@gmail.com | C2: 강나영 | D2: 여 | E2: 26살(00년생) | F2: 대학교 졸업 유예 (수료완료) | G2: 비전공자 | H2: 한양대학교 경영학과 | I2: 안녕하세요, 게임기획을 처음 배우기 위해 신청하게 된 강나영입니다. 아직 기획에 대해서는 아는 것이 많지 않지만 제가 좋아하는 게임을 단순히 즐기는 것에 그치지 않고, 직접 만들어보고 제작 과정에 참여해 보고 싶다는 생각이 들어 이 과정을 신청하게 되었습니다. 처음이라 부족한 점이 많겠지만, 하나씩 배워가며 기본부터 확실히 익히고 배우고 싶습니다. 이 과정을 통해 제 아이디어를 구체화하고 실행할 수 있는 능력을 기르고, 꾸준히 성장하는 기획자가 되고 싶습니다. 감사합니다. | J2: 처음에는 단순히 게임을 즐기는 취미활동에만 관심을 가지다가 이러한 게임들이 어떻게 만들어지고, 다양한 아이디어가 구체화되는 과정에 궁금증을 가지게 되었습니다. 아직 게임 제작 과정이 정확히 어떻게 이루어지는지 잘 모르지만, 이번 과정을 통해 기획의 기본부터 천천히 배워가고 싶습니다. 특히 아이디어를 실제 기획 문서로 구체화하는 과정과, 팀원들과의 협업을 통해 결과물을 완성하는 경험을 해보고 싶어서 신청하게 되었습니다. 처음 배우는 만큼 막히는 부분도 많겠지만 배우고, 노력하면서 성장해 나가겠습니다. 이 과정을 통해 게임 제작 과정에 대해 배우고, 의미 있는 경험을 줄 수 있는 기획자로 성장하고 싶습니다. | K2: 직접적으로 관련된 경헙은 없습니다. | L2: 기획 분야에는 레벨 디자인, 밸러스 기획, BM 기획, 콘텐츠 기획, 시스템 기획, 시나리오 기획 등이 있는 것으로 알고 있습니다. | M2: 수료 후 배운 내용을 바탕으로 게임회사에 입사해 기획팀의 일원으로 일하고 싶습니다. 아직 정확히 어떤 분야에 일하고 싶은지는 정하지 못했지만, 팀과 함께 완성도 높은 게임을 만드는 기획자로 일하고 싶습니다. | N2: 보유 | O2: 아니오 | Q2: 대화와 타협을 통한 해결 | R2: 배움과 성장으로 받아들임 | S2: 문제 해결에 필요한 실질적 도움 제공 | T2: 아니요 | V2: 아니요 | W2: 없음 | X2: 과정에 참여하기 전에 미리 준비 또는 학습하면 좋은 것이 무엇이 있을까요? | Y2: 강나영 | Z2: 45945 | AA2: 동의함 | AB2: 강나영 | AC2: 45945 | AD2: 동의함
A3: 45958.631 | B3: yumin.k1023@gmail.com | C3: 강유민 | D3: 남 | E3: 32살(93년생) | F3: 대학교 졸업 | G3: 비전공자 | H3: 청주대학교 만화애니메이션 학과 / 한국영화아카데미 애니메이션 전공 | I3: 내러티브 콘텐츠 기획, 강유민입니다. 한국영화아카데미에서 애니메이션 시나리오 작성부터 장면 설계, 연출을 훈련했습니다. 이후 상업과 독립 현장의 IP를 기획, 개발하며 세계관과 캐릭터, 시나리오, 스토리보드, 연출, 피치덱 등 제작 총괄을 진행하여 실무 역량을 쌓았습니다. Netflix, Warner Bros, Disney, Bilibili 등 글로벌 시리즈와 메이플스토리, 마비노기 등 게임 PV에 프리프로덕션부터 메인제작까지 참여하며, 다 문화권 제작 환경의 협업을 통해 제작 프로세스와 프로젝트 관리, 커뮤니케이션 역량을 쌓았습니다. 또한, 독립 애니메이션 [창가로 나온 사람들], [푸름보다 흐린]을 연출했으며, 두 작품 모두 감독으로서 기획부터 후반작업까지 제작 전 과정을 총괄했습니다. 특히 [창가로 나온 사람들]은 오스카 스튜던트 애니메이션 세미파이널리스트, DYTIATKO 국제 미디어 페스티벌 파이널리스트, 상상마당 단편영화제, 부천국제애니메이션페스티벌 등 국내외 영화제에서 작품성을 인정받았으며, 현재 [푸름보다 흐린] 또한 국내외 영화제의 심사를 받고 있습니다. 저는 단순히 글을 쓰는 것이 아니라, 서사와 시각적 연출이 융합된 관객과 유저의 체험이 될 수 있는 인터렉티브한 내러티브 콘텐츠를 만드는 것을 지향하고 있으며, 제 경험과 역량을 통해 글로벌 시장에서 통할 수 있는 IP 기획에 도전해 보고자 합니다. | J3: 저는 영화와 애니메이션을 제작하면서 관객들이 결과물을 수동적으로 받아들이는 한계를 느끼곤 했습니다. 창작자가 아무리 의도와 의미를 담아도 그것이 온전히 전달되지 않는 경우가 있습니다. 게임도 어떤 면에선 동일한 한계가 있을 수 있으나, 유저가 캐릭터를 움직이고 선택하고 성취하는 과정에서 스스로 이야기를 써내려가는 경험을 하게 됩니다. 제작자가 만든 세계에서 유저가 직접 주체가 될 수 있는 이런 구조는 창작자와 유저의 거리를 좁히고 훨씬 몰입할 수 있게 합니다. 저는 단순히 글을 쓰는 것을 넘어서 서사와 시각적 연출이 결합된 내러티브 콘텐츠를 만드는 것을 지향하고 있습니다. 그렇기에 유저가 서사를 체험할 수 있는 게임의 특수성은 매력적으로 다가왔습니다. 어떻게 하면 매력적인 이야기의 콘텐츠를 만들 수 있을까 알아보던 중 온라인 게임 기획자 부트캠프를 알게 되어 신청하게 되었습니다. | K3: 게임의 PV애니메이션을 제작한 경험과 고등학생 시절 게임기획 공모를 했던 경험은 있으나 그외 게임과 직접적인 연관이 되는 학습 및 업무경험은 거의 무방합니다. | L3: 전투기획, 레벨디자인, 시나리오, 퀘스트기획, 콘텐츠기획, | M3: 오랫동안 관객이 세계관의 주인공이 되어 특별한 페이소스를 느낄 수 있는 내러티브 콘텐츠를 만드는 것에 노력했습니다. 수료 후 저는 유저가 체험할 수 있는 형태의 내러티브 콘텐츠를 만드는 것을 목표로 하여, 가지고 있는 IP로 직접 게임을 만들어보고 싶습니다. | N3: 미보유 | O3: 아니오 | Q3: 대화와 타협을 통한 해결 | R3: 배움과 성장으로 받아들임 | S3: 문제 해결에 필요한 실질적 도움 제공 | T3: 아니요 | V3: 예 | W3: 면접 봤던 회사의 면접관님 | X3: 게임업계로 취업을 목표로 하나, 게임을 제작해본 경험이 전무하여 아주 기초적인 부분부터 쌓아야 합니다. 해당 교육은 게임과 관련된 작업을 해본 경험이 있으신 분들이 대부분이라고 생각되어, 교육 이해도나 학업 성취면에서 차이가 발생할 것으로 생각합니다. 이 부분이 걱정되지만 교육을 잘 이수하여 취업해보겠습니다. | Y3: 강유민 | Z3: 45958 | AA3: 동의함 | AB3: 강유민 | AC3: 45958 | AD3: 동의함
A4: 45967.772 | B4: jaeseunggang283@gmail.com | C4: 강재승 | D4: 남 | E4: 26살(00년생) | F4: 고등학교 졸업 | G4: 비전공자 | H4: 인문계 > 위탁 제과제빵과 | I4: 안녕하세요 저는 게임을 좋아하고 여러 게임을 즐기다 나도 다수의 사람들이 재밌게 즐길 수 있는 게임을 만들고 싶다는 생각해 온라인 게임 기획자 부트캠프에 지원한 강재승입니다. | J4: 저는 비전공자 이지만 제가 생각하기에 개발에 대한 지식이 있다면 게임 기획 쪽 에서 큰 메리트가 될 수 있다고 생각합니다 예를 들면 기획 과정 중 비용 또는 개발 기술을 고려한 현실적인 기획이 가능하다고 생각합니다 또한 개발자와의 소통이나 문제가 생겼을 경우 원인 파악과 해결에도 메리트가 있다고 생각합니다 그렇기에 이곳 부트캠프 프로그램에서 개발도 배울 수 있다고 생각해 지원했습니다. | K4: 지금까지는 없습니다 | L4: 시스템 기획, 컨텐츠 기획, 경제 기획, 레벨 디자이너, 라이브 기획이 있다고 알고 있습니다 | M4: 희망사항은 RPG 장르를 주로 다루는 회사에서 시스템 기획자가 되고 싶습니다 | N4: 보유 | O4: 아니오 | Q4: 분노나 감정을 억누르고 침착함을 유지 | R4: 자신을 비난하고 자책하는 경향 | S4: 타인에게 엄격한 편이지만 굳이 얘기하지 않음 | T4: 아니요 | V4: 아니요 | W4: 없음 | X4: 최선을 다해서 노력하겠습니다 | Y4: 강재승 | Z4: 36874 | AA4: 동의함 | AB4: 강재승 | AC4: 36874 | AD4: 동의함
A5: 45932.696 | B5: soldnover@gmail.com | C5: 강준호 | D5: 남 | E5: 25살 (01년생) | F5: 고등학교 졸업 | G5: 비전공자 | H5: 숭실대학교 심리학과 | I5: 개인적으로 게임 개발하고 싶은 아이디어와 버킷리스트가 있었는데 그걸 이룰 기회가 와서 이루어 볼려고 합니다 | J5: 결벽증을 심하게 앓고 있어서 외출이 너무나도 힘들고 괴로워서 현재 휴학을 하게 됬습니다. 헌데 휴학 기간이 길어지니 나이먹는게 무서워지고 아직 이룬것이나 준비된것이 하나 없는데 나이먹는게 너무 무섭게 다가와서 뭐라도 해보자 하는 심정으로 신청하게 됬습니다. 노트북 지원에 월마다 일정금액 지원, 온라인 수업을하고 강의 영상이 제공된다는 점이 저에겐 참으로 고맙게 다가왔습니다. 그래서 이 기회를 놓치면 안돼겠다 싶어서 신청했습니다. | K5: 아뇨 전혀 없습니다.1부터 시작해야해요 | L5: 알고 있는게 전혀 없습니다. | M5: 내가 만들고자 한 게임을 만들고 그걸 기업에 팔아서 나오는 수익의 일정 %를 받고 유유자적하게 사는것 | N5: 미보유 | O5: 예 | P5: 결벽증입니다. | Q5: 대화와 타협을 통한 해결 | R5: 배움과 성장으로 받아들임 | S5: 상황에 대한 이해와 위로 | T5: 예 | U5: 기초생활수급자 입니다. | V5: 아니요 | W5: 없음 | X5: 아침에 일어나는 것이 힘든데 그게 가능할지 걱정됩니다 | Y5: 강준호 | Z5: 45932 | AA5: 동의함 | AB5: 강준호 | AC5: 45932 | AD5: 동의함
A6: 45940.619 | B6: soldnover@gmail.com | C6: 강준호 | D6: 남 | E6: 24살(01년생) | F6: 고등학교 졸업 | G6: 비전공자 | H6: 숭실대학교 심리학과 | I6: 안녕하세요. 저는 강준호라 합니다. 인스타를 보던중에 광고로 경일it 캠프에 대해 알게되었습니다. Pc에 대한 사양이 낮아서 바꿔야하는데 노트북 4050 지급과 더불어 ai를 통한 교육이라 제게는 비전공이라 얘기만 들어본 c언어나 언리얼 엔진을 접할 기회가 되면서 pc 사양까지 높일수있는 더할 나위 없는 계기가 되었습니다. 또한 게임을 좋아해서 이런 게임있었으면 좋겠다. 생각한게 있는데 비슷한것 조차 아직 시중에 나온건 없더라구요. 그걸 내손으로 만들어볼수있다는게 놓치면 안될것 같아서 지원했습니다. | J6: 게임한번 만들어보는게 버킷리스트로 있었는데 전공도 비전공이고 관련 지식도 전혀없고 유니티나 언리얼 엔진은 한번 해볼까? 하는 마음으로 결제하기엔 너무 터무니 없는 금액이고 pc사양도 안돼서 여러모로 포기하고 있었는데 본과정이 ai를 이용하고 노트북도 지급해서 할수있지 않을까? 하는 마음으로 신청했습니다. | K6: 없어요. | L6: 게임기획자, 개발자, qa | M6: 내가 만든 게임을 기업에 팔아서 나오는 수익의 일정퍼센테이지 만큼 받는것 | N6: 보유 | O6: 예 | P6: 결벽증(강박증) | Q6: 대화와 타협을 통한 해결 | R6: 배움과 성장으로 받아들임 | S6: 문제 해결에 필요한 실질적 도움 제공 | T6: 예 | U6: 기초생활수급자고 알바도 한적이 없기에 돈이 없읍니다. | V6: 아니요 | W6: 없음 | X6: 만약에 강의를 듣고 취업하지 못하면 다시는 못듣는건가요? | Y6: 강준호 | Z6: 45940 | AA6: 동의함 | AB6: 강준호 | AC6: 45940 | AD6: 동의함
A7: 45973.773 | B7: xotjd209@gmail.com | C7: 강태성 | D7: 남 | E7: 27살(99년생) | F7: 대학교 졸업 | G7: 전공자 | H7: 장안대학교 게임컨텐츠과 | I7: 비록 전공자이긴 하나 부족한 부분이 많습니다 그렇기 때문에 많이 배우고 갈고닦겠습니다 감사합니다. | J7: 순전히 우연이었습니다. 인터넷에 뜬 광고를 보아 신청을 하긴 했는데 직원분과 통화하며, 또 직접 알아보며 이번 과정에 대해 살펴보니 생각보다 좋은 기회라 여겨 참여를 희망하게 된것 같습니다. | K7: 장안대 게임컨텐츠과 졸업했습니다. 분과는 기획으로 나왔고 유니티와 프로그래밍의 기초적인 부분은 얼추 알고 있다 생각합니다. 학과 내 게임잼을 통해 사람들과 게임을 제작해본적도 있습니다. | L7: 밸런스 기획자, ui/ux 기획자, 시스템 기획자, 퀘스트 기획자 | M7: 솔직히 목표라는걸 잘 안세워두는 편이라 뭐라 적어야 할지 잘 모르겠는데요. 적당히 취직이나 해서 부모님한테 잔소리는 덜 듣고 싶네요. | N7: 미보유 | O7: 아니오 | Q7: 논리적인 논쟁으로 해결 | R7: 배움과 성장으로 받아들임 | S7: 문제 해결에 필요한 실질적 도움 제공 | T7: 아니요 | V7: 예 | W7: 없음 | X7: 열심히 하겠습니다 | Y7: 강태성 | Z7: 45973 | AA7: 동의함 | AB7: 강태성 | AC7: 45973 | AD7: 동의함
A8: 45943.665 | B8: seungjoo9611@gmail.com | C8: 고승주 | D8: 남 | E8: 30살(96년생) | F8: 대학교 졸업 | G8: 비전공자 | H8: 서울시립대학교(국어국문학, 도시문화컨텐츠학) | I8: 안녕하십니까 온라인 게임 기획자 부트캠프 4기 지원자 고승주입니다. 대학시절에는 국문학과 도시문화 컨텐츠학을 복수전공하며 컨텐츠 제작의 꿈을 키웠습니다. 대학시절 게임 동아리를 창설해 현재까지 PC 및 다양한 콘솔 기반의 게임 문화에 대한 관심을 꾸준히 이어온 바 한가지 장르에 국한되지 않는 다양한 게임에 대한 시야를 길러왔다고 자부합니다. 대학 졸업 이후 들어간 “해태제과”에서 영업사원으로 2년 반 동안 근무하며 B2B 영업에 관한 경험을 쌓았으며, 이를 통해 시장 분석, 행사 기획 등에 대한 경험을 쌓았습니다. 이번 부트캠프를 통해 게임 기획자로의 성공적인 커리어 전환을 이루고 장차 사용자들의 기억에 남는 게임 기획으로 게임 문화와 산업 발전에 이바지하고 싶습니다. | J8: 평소 즐겨보던 유튜브"G식백과"를 통해 본 프로그램에 대한 인지는 전부터 있었습니다. 게임과는 상관없는 업계에서 커리어를 시작하여 일을 배울수록 해당 업계 및 적성에 대한 회의가 생겼고, 그 결과 게임업계에 대한 커리어 전환을 목표로 하게 되었습니다. 비전공자인 동시에 관련 경험도 부족하였기에 신뢰있는 기관의 교육과정을 통해 관련 경험 및 전문성을 확보하고자 하였습니다. 본 과정의 취업률 및 커리큘럼 소개 등을 통해 신뢰감을 가질수 있었기에 신청을 결정하게 되었습니다. | K8: 대학시절 평생교육원을 통해 개설된 '리그 오브 레전드' 실력 향상과 관련된 강의를 수강한 적은 있으나 게임과 관련된 업무 및 개발과 관련된 학습 경험은 없습니다. | L8: 세계관 및 설정 기획, 컨텐츠 기획, 시스템 기획, QA | M8: 이번 부트캠프 수료를 통해 게임 기획자로의 커리어 전환을 이루고, 장차 국내외의 유명 게임사에서 근무할 수 있는 기반을 쌓고 싶습니다. 나아가 게임 제작 전반에 대한 이해를 키워나가며 주도적으로 개발한 게임을 출시하는 것이 목표입니다. | N8: 보유 | O8: 아니오 | Q8: 대화와 타협을 통한 해결 | R8: 배움과 성장으로 받아들임 | S8: 타인에게 엄격한 편이지만 굳이 얘기하지 않음 | T8: 아니요 | V8: 예 | W8: 없음 | X8: 성공적인 커리어 전환과 훌륭한 게임을 만들고 싶은 개인적인 꿈을 위해 이번 커리큘럼에 꼭 참여하고 싶습니다. 잘 부탁드립니다. | Y8: 고승주 | Z8: 45943 | AA8: 동의함 | AB8: 고승주 | AC8: 45943 | AD8: 동의함
A9: 45959.725 | B9: wyvern741@gmail.com | C9: 곽용준 | D9: 남 | E9: 23살(03년생) | F9: 대학교 휴학 | G9: 비전공자 | H9: 울산대학교, 생명과학부 | I9: 울산대학교에 휴학을 한 23살 3학년 곽용준입니다 군대는 어릴 적 수술로 인해 5급인 상태입니다 프로그래밍 언어는 고2 시절 C언어만 배운 상황입니다 물론 지금은 거의 다 까먹었지만 기획 단계에서도 C언어가 필요하다면 그 부분까지 다시 열심히 배울 자신이 있습니다 어린 시절의 불우한 삶을 게임에 녹여서 인생의 역경을 극복하는 주인공의 멋진 서사로 만들고 싶었습니다 비록 세계관이 어둡고 암울하더라도 빛나는 주인공의 모습을 보고 나도 저런 게임, 저렇게 주변인들한테 귀감이 되고 싶다는 생각을 했었고 그에 따른 게임의 스토리를 만들고 싶어서 지원을 했습니다 | J9: 어릴 때 겪은 불우한 삶을 시와 글로 써서 책을 만들다가 문득 애니메이션, PC 게임, 서브컬쳐 모바일 게임이라는 것을 접하게 되었고 그 중에서 서브컬쳐 모바일 게임의 스토리를 보면서 불우한 삶, 역경을 멋지게 극복한 사례가 있구나 나도 저런 멋있는 스토리를 만들어보고 싶다는 목표와 나도 저렇게 멋있게 역경을 극복해보고 주인공같은 삶을 살아보고 싶다는 생각이 들었고 힘들수록 나중에 더 많은 것을 얻게 될 수 있다는 경험으로 생각해서 게임 기획에 제 인생이 녹아들 수 있도록 열심히 임할 자신이 있습니다 단순한 관심에서 취미, 취미에서 인생이 녹아들만한 게임을 기획해보고 싶다는 꿈을 이뤄보고 싶습니다 | K9: 이번이 처음입니다... | L9: 게임기획자 | M9: 기승전결 구조가 완벽한 게임 개발 스토리 작성 인물들간의 서사 구조가 완벽하며 각 인물들의 감정선이 명확한 스토리 작성 게임 기획에 있어서 어떻게하면 몰입감 있게 컨텐츠를 제작할 수 있을지 기획안을 설정해보고 회사 입사 및 추후에 있을 1인 개발 도전 | N9: 보유 | O9: 예 | P9: 뇌출혈 경험(09년 당시) | Q9: 대화와 타협을 통한 해결 | R9: 배움과 성장으로 받아들임 | S9: 문제 해결에 필요한 실질적 도움 제공 | T9: 아니요 | V9: 아니요 | W9: 네이버 카페 멤버 | X9: 역경을 극복하여 모두의 귀감이 된 게임 속 주인공처럼 저도 역경을 극복하여 이 과정을 게임에 녹아들게 한 다음 모두한테 귀감이 될 수 있는 멋진 스토리를 작성하고 다양한 컨텐츠를 제작하여 지속적으로 플레이어 분들이 관심을 가지도록 할 수 있는게 목표입니다 | Y9: 곽용준 | Z9: 45959 | AA9: 동의함 | AB9: 곽용준 | AC9: 45959 | AD9: 동의함
A10: 45959.543 | B10: qqweeqqw@gmail.com | C10: 구준모 | D10: 남 | E10: 28살(98년생) | F10: 대학교 졸업 | G10: 비전공자 | H10: 신안산대학교 사무비서행정과 | I10: 대학 졸업과 동시에 로드매니저 반년, 프로야구 마스코트 1년 후 복싱코치로 2년간 일을 하다가 체육관 사정때문에 2025년 1월 권고사직을 당한 뒤 현재까지 취준생활을 이어가고 있습니다. 여러 직군과 회사에 지원을 해보았으나 어려움을 겪었고 국비지원이라는 좋은 제도를 이용하여 취업을 하고자 지원하였습니다 | J10: 주변에 게임 회사를 다니는 지인이 게임 업계에 대해 알려주었고 게임 회사에 최근 관심이 생겨 지원하게 되었습니다. 전문대 졸 그리고 취업과는 관련 없던 일자리로 스펙과 학력이 부족했던 저에게 마지막 취업의 문과도같아 지원하게 되었습니다 | K10: 없습니다 | L10: 게임기획자, 마케팅, 영업까지 전부 궁금합니다 | M10: 목표는 작은 회사에 취업하게 되면 역량을 키워 큰회사로 처음부터 중견이상에 가게 되면 정년퇴직까지 오래오래.. | N10: 보유 | O10: 아니오 | Q10: 대화와 타협을 통한 해결 | R10: 자신을 비난하고 자책하는 경향 | S10: 상황에 대한 이해와 위로 | T10: 예 | U10: 복싱코치 권고사직 후에 퇴직금을 주식에 넣었으나 청산을 다하고 배달을 하며 보험료,통신비,월세,관리비, 카드 할부,생활비(식비)를 벌어 겨우 생계 유지중.. | V10: 예 | W10: 지인 | X10: 사실 최대한 빠르게 취업하여 돈을 벌고 싶습니다 | Y10: 구준모 | Z10: 45959 | AA10: 동의함 | AB10: 구준모 | AC10: 45959 | AD10: 동의함
A11: 45981.704 | B11: koohyunmo352@gmail.com | C11: 구현모 | D11: 남 | E11: 22살(03년생) | F11: 대학교 졸업 | G11: 전공자 | H11: 경남대학교입니다 전공은 컴퓨터공학부 입니다 | I11: 안녕하세요 게임직종을 희망하는 구현모 학생입니다 제가 예전부터 게임직종을 희망하는 하고 있었습니다 처음에 게임잡이나 마산에 있는 취업정보센터에서 찾아봤습니다 | J11: 제가 예전부터 게임직종을 관련된 직종을 희망하고 있어요 사람인 홈페이지에서 많이 찾았습니다 처음에 초등학생때 부터 게임이라는 것에 취미를 붙였습니다. 유명한 게임회사의 정보과 절차 등 홈페이지에서 직접 찾으면서 이 직종에 관심이 많아서 많이 지원을 했습니다. | K11: IT쪽입니다 | L11: 게임밸런스는 캐릭터들의 생김새,npc 등 게임에 나타나는 과정이기도 합니다 | M11: 저는 나중에 외국에서 게임관련 직종과 기타직종을 희망하고 있습니다. | N11: 미보유 | O11: 아니오 | Q11: 대화와 타협을 통한 해결 | R11: 배움과 성장으로 받아들임 | S11: 문제 해결에 필요한 실질적 도움 제공 | T11: 아니요 | V11: 예 | W11: 대학교수님 | X11: 없습니다 | Y11: 구현모 | Z11: 45981 | AA11: 동의함 | AB11: 구현모 | AC11: 45981 | AD11: 동의함
A12: 45949.69 | B12: viliv8177@gmail.com | C12: 권수빈 | D12: 남 | E12: 29살(97년생) | F12: 대학교 졸업 | G12: 비전공자 | H12: 한국해양대 영어영문학과 | I12: 이번 부트 캠프에 합류하여 게임 기획자에 대해 제대로 배워 보고 싶습니다. 그리고 저 또한 게임을 사랑하는 한 명의 유저 로서, 유저의 시선에서 재미와 몰입을 설계하는 기획자가 되고 싶습니다. | J12: 지금까지 다양한 게임을 플레이하며 자연스레 게임 기획자에 대한 관심이 깊어졌습니다. 하지만 독학으로는 한계를 느껴, 기초부터 실무까지 체계적으로 배우고 싶고, 다양한 협업 과정을 경험해 보고 싶어 이 과정에 참여하게 되었습니다. | K12: 없습니다. | L12: 시나리오 기획자, 컨텐츠 기획자, 벨런스 기획자, 전투 기획자 | M12: 유저의 시선으로 바라보며, 재미와 몰입을 선사하는 기획자가 되고 싶습니다. | N12: 미보유 | O12: 아니오 | Q12: 분노나 감정을 억누르고 침착함을 유지 | R12: 다른 이유나 환경을 도출하려는 경향 | S12: 상황에 대한 이해와 위로 | T12: 아니요 | V12: 예 | W12: 없음 | X12: 제게 기회가 주어진다면 열심히 배우겠습니다. | Y12: 권수빈 | Z12: 45949 | AA12: 동의함 | AB12: 권수빈 | AC12: 45949 | AD12: 동의함
A13: 46010.76 | B13: cocohyeonmin@gmail.com | C13: 권현민 | D13: 여 | E13: 27(99년생) | F13: 대학교 졸업 | G13: 비전공자 | H13: 국민대학교 영상디자인학과 | I13: 게임이 좋아서 예체능을 전공했습니다. 게임 기획을 제대로 배워서 원하는 직무로 일하고 싶습니다 | J13: 게임 시나리오 라이터 또는 퀘스트 디자이너를 준비해왔으며, 기존 포트폴리오에서 게임 기획의 실무 경험이 부족하다고 생각했고, 기획 실무를 배우고 보강해서 취업에 성공하고 싶어 신청했습니다 | K13: 학교 내에서 개설된 언리얼 과목을 수강했습니다. 공부학원이나 부트캠프를 참여한 적은 없습니다. | L13: 퀘스트 디자이너, 레벨 디자이너, 전투 시스템 디자이너, 시나리오 라이터, 밸런스 기획자 | M13: 문서만 존재했던 포트폴리오에 실제 프로젝트를 첨부해서 취업 성공하고 싶습니다 | N13: 보유 | O13: 아니오 | Q13: 대화와 타협을 통한 해결 | R13: 배움과 성장으로 받아들임 | S13: 문제 해결에 필요한 실질적 도움 제공 | T13: 아니요 | V13: 아니요 | W13: 없음 | X13: 지난 취업 준비 기간동안 준비가 미흡했던 것을 깨닫고, 마지막 기회라고 생각하고 교육에 임하겠습니다. | Y13: 권현민 | Z13: 46010 | AA13: 동의함 | AB13: 권현민 | AC13: 46010 | AD13: 동의함
A14: 45998.841 | B14: khal0429@gmail.com | C14: 김경민 | D14: 남 | E14: 33살(92년생) | F14: 대학교 졸업 | G14: 비전공자 | H14: 강릉원주대 법학과 | I14: 안녕하세요. 게임 기획자 부트캠프 4기 교육과정에 지원하게된 김경민이라고 합니다. 잘 부탁드립니다. | J14: 게임개발과정을 구체적으로 배우고 이해하기 위해 지원 했습니다. 어렸을 때 부터 게임에 관심이 많았지만 게임의 구성에 대한 지식은 단편적이고 개발과정에 대해서도 파편적으로 밖에 알지 못 합니다. 이 교육과정을 통해 게임 개발과정에 대해 보다 세세히 배우고 싶습니다. | K14: 없음 | L14: 게임 기획자 | M14: 이 교육과정을 통해 게임 기획관련 직종에 종사해보고 싶습니다. | N14: 보유 | O14: 예 | P14: 약 15년전 허리디스크 적출 수술을 함. 현재 진행중인 치료는 없음. | Q14: 논리적인 논쟁으로 해결 | R14: 배움과 성장으로 받아들임 | S14: 문제 해결에 필요한 실질적 도움 제공 | T14: 아니요 | V14: 아니요 | W14: 없음 | X14: 혹시 오프라인 일정이 있다면 어디서 진행되는지 알고 싶습니다. | Y14: 김경민 | Z14: 45998 | AA14: 동의함 | AB14: 김경민 | AC14: 45998 | AD14: 동의함
A15: 45974.471 | B15: bangtore77@gmail.com | C15: 김도윤 | D15: 남 | E15: 32(94년생) | F15: 대학교 졸업 | G15: 비전공자 | H15: 인하대학교 고분자 공학과 | I15: [기획 분야 지원 이유] 저는 다양한 분야의 일을 경험하며 살아왔습니다. 공부, 식품 관련 업무, 물류 운반, 보드게임 카페 등 여러 서비스직 업무를 맡으며 노력했지만, 시간이 흐를수록 `내가 진정 하고 싶은 일은 무엇일까’라는 질문이 가슴에 남아있었습니다. 잦은 직종 변경을 해왔던 이유도 아마 이 이유가 원인이 된 것 같습니다. 그러던 중 나의 일을 찾고 싶다는 생각을 하였고, 열정을 갖고 해왔던 게임에 대해 본격적으로 공부를 하기 시작했습니다. 게임을 하면서 관심있게 봤던 부분은 게임을 즐겁게 하는 요소들에 대한 것이었습니다. 특히 전투 방법, 전투 밸런스, 캐릭터의 역할과 보상 구조에 관심을 가졌고, 게임 기획 분야에 관심을 갖는 계기가 되었습니다. [목표] 처음엔 작은 업무에서부터 시작하여 팀원들이 신뢰하는 동료가 되는 것이 목표입니다. 큰 프로젝트에 앞서 전체 구조와 업무의 흐름을 이해하는 것이 우선이라고 생각하기 때문입니다. 사용자 피드백 정리, 간단한 단발성 이벤트 기획 등 작은 업무를 맡아 책임감 있게 성실히 수행하려고 합니다. 이런 일들을 반복하여 수행하다 보면 자연스럽게 신뢰를 쌓을 수 있다고 생각합니다. 이 과정에서 유저가 만족할 만한 게임을 만드는 방법을 배우고 싶습니다. 단순한 성과를 확인하는 것이 아닌, 유저의 반응을 세밀하게 관찰하여 어떤 부분이 재미있는 요소였는지, 어떤 부분이 불만족스러웠는지를 파악하고자 합니다. 또한 협업 과정에서 다른 부서와의 커뮤니케이션 능력을 키우고 일을 알아가며 단순히 게임을 기획하는 기획자가 아닌 프로젝트 전체를 연결하는 기획자가 되고 싶습니다. 작은 일들을 반복하다 보면 자연스럽게 이루어질 것이라고 생각합니다. 장기 목표로는 한국의 문화를 알릴 수 있는 대형 게임 제작에도 도전해보고 싶습니다. 한옥이 주는 매력이나, 무속 신앙, 화랑과 같은 특징적인 요소를 지닌 문화를 현대적으로 해석해 게임에 담아 새로운 매력으로 전 세계 유저들에게 한국의 이야기를 전달하고 싶습니다. | J15: 게임 기획이라는 업무가 독학으로 준비하기에 어떤 준비를 해야하는지 감이 오지 않았습니다. 하지만 경일 아카데미의 커리큘럼을 보고 보다 체계적으로 기획 업무를 배울수 있고, 요즘 취업에 필요하다고 생각했던 ai를 활용할 수 있는 곳이라는 생각에 지원하였습니다. | K15: 설명회 느낌으로 한두번 다닌적 있습니다. | L15: 밸런스 기획, 전투 기획, 레벨 디자인, 시스템 기획, 몬스터 기획, 개발 pm, 사업 pm, 시나리오 라이터 | M15: 최종 목표는 평생 일할 수 있는 직장을 찾는 것입니다. 작게는 포트폴리오, 게임 개발 경험을 얻고 싶습니다. | N15: 미보유 | O15: 아니오 | Q15: 대화와 타협을 통한 해결 | R15: 배움과 성장으로 받아들임 | S15: 문제 해결에 필요한 실질적 도움 제공 | T15: 아니요 | V15: 아니요 | W15: 없음 | X15: 나이와 취업기간이 어느정도 되는지. 경력이 없어도 되는지. 게임 개발 경험을 쌓을수 있는지 궁금합니다. | Y15: 김도윤 | Z15: 45974 | AA15: 동의함 | AB15: 김도윤 | AC15: 45974 | AD15: 동의함
A16: 45953.025 | B16: zpswls2005@gmail.com | C16: 김도형 | D16: 남 | E16: 35 | F16: 고등학교 졸업 | G16: 비전공자 | H16: 디자인 | I16: 안녕하십니까. 게임 기획의 꿈을 가지고 이 자리에 서게 된 김도형 입니다. 저는 정규 대학 과정 대신 실무 역량으로 목표를 이뤄낸 경험이 있습니다. 과거 디자인 취업 학원에서 누구보다 성실하게 임했고, 그 결과 우수한 포트폴리오를 만들어 디자인 회사에 취업에 성공했습니다. 이후 디자인 경력을 쌓는 동안, 저는 사용자의 니즈를 분석하고, 아이디어를 시각화하며, 실제로 구현될 수 있도록 구체화하는 능력을 키웠습니다. 이 모든 과정이 결국 게임의 '재미'를 설계하는 기획의 기본기와 맞닿아 있다는 확신을 갖게 되었습니다. 새로운 도전을 위해 디자인 경력을 내려놓고, 이제 게임 기획이라는 목표에 집중하려 합니다. 저는 이론적인 배경보다는, 직접 부딪혀 성과를 만들어내는 실행력을 강점으로 가지고 있습니다. 이 아카데미에서 저의 창의적인 에너지와 실무 경험을 융합하여, 사용자에게 깊은 몰입감을 선사하는 기획자로 거듭나겠습니다. 감사합니다. | J16: 저는 어릴 때부터 게임을 매우 좋아해왔고, 지금도 직장 생활을 하면서 틈틈이 비디오게임을 즐기고 있습니다. 주변 친구들이 사회생활로 인해 게임을 멀리하게 되었지만, 저는 여전히 새로운 게임 소식을 놓치지 않으려 노력하며 높은 이해력과 넓은 시야로 게임을 분석하고 즐깁니다. 이러한 경험 덕분에 사람들의 반응을 빠르게 파악하고 분위기를 주도하는 능력을 길렀습니다. 저는 사람들에게 즐거움과 재미를 전달하는 일에 큰 보람을 느끼며, 이를 게임이라는 매개체를 통해 실현하고자 본 과정에 지원하게 되었습니다. | K16: 무 | L16: 게임기획자_시나리오, 세계관, 밸런스, 던전, 보스, 퀘스트, 기획서 작성 | M16: 취업을 하여 최대한 많은 경험을 쌓을 계획입니다 그리고 기회가 된다면 개인으로 아니면 작은 팀으로 인디게임도 제작해 보고 대회도 나가볼 계획입니다. | N16: 미보유 | O16: 아니오 | Q16: 대화와 타협을 통한 해결 | R16: 배움과 성장으로 받아들임 | S16: 상황에 대한 이해와 위로 | T16: 예 | U16: 큰 어려움은 아니지만 부유하지 않아서 지원을 받을 수 있다면 최대한 받고 싶습니다. | V16: 아니요 | W16: 없음 | X16: 궁금한건 전화 상담 때 친절하게 알려주셔서 없습니다. | Y16: 김도형 | Z16: 45953 | AA16: 동의함 | AB16: 김도형 | AC16: 45953 | AD16: 동의함
A17: 45940.571 | B17: girin0179@gmail.com | C17: 김도훈 | D17: 남 | E17: 26살(00년생) | F17: 대학교 졸업 | G17: 전공자 | H17: 국립부경대학교 컴퓨터·인공지능공학부 컴퓨터공학전공 | I17: 안녕하세요, 경일게임아카데미 온라인 게임 기획자 부트캠프 4기에 지원한 김도훈입니다. 타 학원에서 기초 과정을 이수했으며, 좀 더 실무에 가까운 기획을 공부해보고자 지원하게 되었습니다. 기존 학원에서 공부할 당시에 깊이에 대한 고민을 많이 했습니다. 어느 정도의 깊이로 파고들어야 설득력이 생길지, 혹은 너무 깊은 정보를 담아 오히려 이해에 혼란을 주진 않을까 등 적당한 깊이를 찾고자 노력하고 있습니다. 또한, 스스로 터득하고자 하는 자기주도적인 학습을 지향하여 기존 학원에서 배우지 않았던 여러 가지 시도를 혼자 해보곤 했습니다. 위의 태도는 경일게임아카데미의 부트캠프 과정 중에서도 큰 도움이 될 거라고 생각합니다. | J17: 기존 학원에서는 원론적인 부분, 이론에만 매진해서 불만을 느꼈고, 실제로 실무에 지원함에 있어 부족한 점이 많다고 느꼈습니다. 또한, 과제의 양의 부족, 포트폴리오 제작 주제의 제한, 명료하게 알려주는 부분이 적어 강의력 자체에도 아쉬움을 많이 느꼈습니다. 부트캠프를 통해 취업 준비의 과정, 포트폴리오 제작에 많은 시간을 쏟고 싶습니다. | K17: SBS게임아카데미 게임기획 과정 8개월 {2025.01.~2025.11 (2개월 휴학)} | L17: 게임 기획자에는 시나리오, 시스템, 콘텐츠, 레벨, 전투, 밸런스, BM, 경제 등 다양한 기획자가 있습니다. 저는 특히 시스템 기획과 전투, 밸런스 기획에 관심이 있습니다. | M17: 부트캠프 활동 중에 우수한 성적을 띄고, 가능하다면 수료 이전에 대기업 취업을 목표로 하고 있습니다. 수료 후에도 부트캠프 당시의 배움과 기억을 살려 빠른 시일 내에 취업하고 싶습니다. | N17: 보유 | O17: 아니오 | Q17: 대화와 타협을 통한 해결 | R17: 자신을 비난하고 자책하는 경향 | S17: 상황에 대한 이해와 위로 | T17: 아니요 | V17: 아니요 | W17: 없음 | X17: 초심을 잃지않고 수료까지 열심히 나아가겠습니다. 감사합니다. | Y17: 김도훈 | Z17: 45940 | AA17: 동의함 | AB17: 김도훈 | AC17: 45940 | AD17: 동의함
A18: 45961.933 | B18: ehdghrn154@gmail.com | C18: 김동호 | D18: 남 | E18: 32살(94년생) | F18: 전문학사졸 | G18: 비전공자 | H18: 정석항공과학고 / 항공정비 | I18: 비전공이기에 오히려 처음부터 기술을 쌓아갈 수 있는부분이 장점이라 생각합니다. 비전공자도 전공자보다 더 잘 할 수 있다는 것을 보여드리겠습니다. | J18: 전공을 살려서 취업하려 했지만 상황이 여의치 않았기에 먼저 뭘 잘하고 뭘 좋아하는지부터 생각해 봤습니다. 현재 32년이라는 삶을 살면서 좋아하는 일만을 할 수는 없다는 생각이었어서 게임회사는 아주 먼 꿈이라고만 생각했었습니다. 하지만 지금나이에서도 충분히 교육을 받고 내가 흥미를 잃지만 않는다면 꿈꿨던 게임회사에 취직할 수 있다는 생각이 너무나 들었습니다. 그렇기에 이런 좋은 기회를 놓치고 싶지 않아 신청하게 되었습니다. | K18: 게임 기획 및 개발과는 거리가 멀지만 TDCX KOREA란 회사에서 게임관련 CS업무를 한 경험이 있습니다. | L18: 게임 개발자, 게임 기획자, 게임 UI/UX 디자이너, 캐릭터 디자이너, 게임 관리자 | M18: 대기업에 취직하면 좋겠지만 저를 필요로 하는 게임회사가 있다면 언제든지 최선을 다하겠습니다. | N18: 보유 | O18: 아니오 | Q18: 분노나 감정을 억누르고 침착함을 유지 | R18: 배움과 성장으로 받아들임 | S18: 문제 해결에 필요한 실질적 도움 제공 | T18: 예 | U18: 대출 빚 | V18: 아니요 | W18: 없음 | X18: 항상 열심히 수업에 임하고 최종적으로 게임회사 입사까지 모든 노력을 동원해 앞으로의 미래를 위해서 최선을 다하겠습니다. | Y18: 김동호 | Z18: 45961 | AA18: 동의함 | AB18: 김동호 | AC18: 45961 | AD18: 동의함
A19: 45992.617 | B19: ahtmxmtpwndksl@gmail.com | C19: 김민서 | D19: 남 | E19: 24살(02년생) | F19: 대학교 졸업 | G19: 전공자 | H19: 없음 | I19: 안녕하십니까 트렌드에 대한 감각과 창의적인 기획력을 바탕으로 성실하게 결과를 만들어가는 게임 기획자 김민서입니다. 저는 어릴 때부터 게임을 좋아해 직접 카드나 규칙을 만들어 친구들과 놀며 게임의 구조나 재미에 대해 자연스럽게 관심을 가지게 되었습니다 대학교 시절에는 스터디와 학우회 여러 활동을 통해 여러 사람들과 협력하는 경험을 쌓았고 그 과정에서 의견을 조율하고 분위기를 만드는 주도적인 역할을 맡았습니다. 게임 기획에 대해 공부를 시작한 뒤에는 여러 문서를 작성하고 팀프로젝트를 진행하면서 게임을 단순히 즐기는 것을 넘어서 “왜 이런 경험이 만들어지는가”를 고민하는 습관이 생겼습니다 또한 꾸준히 기록하고 분석하는 루틴을 통해 하루하루 성장하는 기획자가 되기 위해 노력하고 있습니다. 저는 앞으로도 게임의 재미를 중심에 두고 책임감 있게 결과물을 만들어 팀에 신뢰를 주는 기획자로 성장하고 싶습니다. 면접 잘 부탁드리겠습니다. | J19: 제 목표인 라이브 서비스 게임은 지속적인 서비스와 지표 관리가 필수적이라고 생각합니다. 이번 과정에서 학습하는 ai와 같은 툴을 활용하여 데이터를 분석하고 시스템의 개선 방향을 도출하는 데이터 기반 기획 능력을 배우고 싶습니다. 또한 시스템 구조를 명확한 데이터 테이블과 로직으로 시각화 하는 실무역량을 키우고 개발팀과의 원활한 커뮤니케이션을 통해 제 실력을 한층 키우고 성장하고 싶어 지원하였습니다. | K19: 학원 | L19: 모바일 sng ux-ui 레벨기획 컨셉 게임기획 시나리오 퀘스트 성장밸런스 경제밸런스 시스템 컨텐츠 전투 bm 경제 사업pm 전투기획 이벤트기획 캐릭터전투 캐릭터컨셉 | M19: 수료 후 저의 목표는 회사에 취업하여 성장을 멈추지않는 기획자로서 회사에 실질적인 성과를 가져오는것입니다. 포트폴리오에 제시된 비전을 단기/중기/장기 로드맵으로 통합하여 말씀드리겠습니다. 입사 초기에는 조직에 빠르게 적응하여 신뢰를 쌓는것에 집중하겠습니다. 맡은 업무를 기간 내 완벽히 수행하여 믿고 일을 맡길 수 있는 신뢰도 높은 팀원이 되고싶습니다. 또한 팀에 사소한 아이디어라도 논리적인 근거를 갖춰 제안하여 팀에 도움이 되도록 노력하겠습니다. 중기적으로는 프로젝트에 깊이 기여하는 기획자가 되고싶습니다. 하나의 기획을 책임지고 설계하여 성공적으로 런칭시키는 경험을 쌓고싶습니다. 지표를 직접 분석하고 유저의 패턴을 읽어내어 시스템에 개선 방향을 도출하겠습니다. 궁극적으로는 팀을 이끌고 새로운 재미를 선사하는 리드 기획자가 되는 것입니다. 신규 프로젝트를 성공적으로 런칭하는 리드 기획자가 되고싶습니다. 유저에 대한 깊은 이해도를 바탕으로 프로젝트의 비전을 제시하며 저의 경험과 지식을 공유하여 뛰어난 후배 기획자들을 양성하고 시너지를 창출하는 팀을 만들어 회사에 기여하고싶습니다. 저는 성장을 멈추지않는 기획자로서 이 로드맵을 반드시 달성하여 핵심 인재가 되고싶습니다. | N19: 보유 | O19: 아니오 | Q19: 대화와 타협을 통한 해결 | R19: 배움과 성장으로 받아들임 | S19: 문제 해결에 필요한 실질적 도움 제공 | T19: 아니요 | V19: 아니요 | W19: 없음 | X19: 공책에 게임을 만들던 아이는 ‘재미’의 본질을 찾는 게임 기획자를 꿈꾸게 되었습니다. 하지만 길을 걷다 보니 게임과 관련된 길과 멀어지게 되었고 “이 진로가 맞을까 나는 게임개발을 꿈꿔왔는데?” 같은 고민에 빠지게 되었습니다. 꿈과 현실 사이 고민하던 저에게 많은 위로와 힘이 되어주었던 게임은 저에게 앞으로 나갈 힘을 주었습니다. 제가 게임을 통해 받았던 ‘원동력‘을 통해 목표가 분명해졌고 제가 느낀 원동력을 더 많은 유저들도 경험했으면 좋겠다는 목표가 생겼습니다. 그 꿈을 위해 저는 가만히 머무르지 않고 시스템을 분석하고 구조화 하는 훈련을 했습니다. ‘왜’ 라는 질문에 답하기 위해서 계속해서 고민하고 생각했습니다. 앞으로도 끊임없이 배우고 증명하는 자세로 냉철한 분석과 명확한 근거를 바탕으로 재미를 설계하는 기획자로 성장하고 싶습니다. | Y19: 김민서 | Z19: 45992 | AA19: 동의함 | AB19: 김민서 | AC19: 45992 | AD19: 동의함
A20: 45948.348 | B20: wlgns30617@gmail.com | C20: 김민수 | D20: 남 | E20: 00년생 | F20: 대학교 졸업 | G20: 전공자 | H20: 동서울대학교 게임콘텐츠학과 | I20: 안녕하십니까, 맡은 일 책임감 있게 하는 김민수입니다. 저는 동아리, 팀프로젝트를 항상 팀장을 맡아 진행하며 책임감있게 완수한 경험이 있으며, 아르바이트를 할 때도 단순한 돈벌이가 아닌 책임감 있게 일하며 자아실현을 목표로하며 리뷰 확인, 피드백, 자기개발을 멈추지 않았습니다. 만약 프로그램에 참여한다면 언제나 책임감 있게 멈추지 않고 자기개발하는 학생이 되어 성실히 프로그랳을 이수하겠습니다. | J20: 운좋게 취업에 성공하며 자만하며 시간을 지내왔는데, 배움이 부족하다고 생각이 되어 지원하게 되었습니다. 부트캠프의 커리큘럼이 제가 부족하다고 느낀 가려운 부분을 긁어줄 수 있다고 생각하게 되어 신청하게 되었습니다. | K20: SBS게임아카데미 , 펄어비스 | L20: 밸런스 기획자, 콘텐츠 기획자, 라이브 기획자 | M20: 프로그램 수료에 안주하지 않고 프로그램을 통해 배운 것을 이용하여 공부하여 인재로 거듭나는 것이 목표입니다. | N20: 보유 | O20: 예 | P20: 허리디스크가 있지만 심하지 않아 지속적으로 케어하고 있어서 과정에 문제 없습니다. | Q20: 대화와 타협을 통한 해결 | R20: 배움과 성장으로 받아들임 | S20: 문제 해결에 필요한 실질적 도움 제공 | T20: 아니요 | V20: 예 | W20: 없음 | X20: 실력은 몰라도 노력은 1등하겠습니다 | Y20: 김민수 | Z20: 45948 | AA20: 동의함 | AB20: 김민수 | AC20: 45948 | AD20: 동의함
A21: 45989.645 | B21: kmjzzang0808@gmail.com | C21: 김민제 | D21: 남 | E21: 만 28살(97년생) | F21: 대학교 졸업 | G21: 비전공자 | H21: 한국외국어대학교 일본어전공 (방송 영상 뉴미디어 이중전공) | I21: 일본어와 방송 영상을 전공하여 항상 스토리 컨텐츠를 만들고 싶었습니다. 영화, 드라마도 있지만 게임은 더욱 다양한 요소가 합쳐진 멀티미디어 컨텐츠라고 생각합니다. 재미와 감동을 주는 게임을 만들고싶습니다. 젤다의 전설, 소울류, 문명, 바이오쇼크, 용과 같이, 파이널판타지, 클레어 옵스퀴르 33 등등 다양한 장르의 싱글 플레이어 게임을 좋아합니다. | J21: 저는 항상 이야기를 만들고 싶었던 것 같습니다. 그래서 전공도 일본어, 방송 영상을 선택을 하였고 몇번 영상도 찍고 대본도 만들고 기획도 하였습니다만, 돌이켜보니 저는 국내 영상 매체에 그다지 흥미를 못느꼈었고, 정말 훌륭한 게임들을 하면서 게임이야말로 복합적 문화 예술 컨텐츠라고 생각하게 되었습니다. 그러다보니, 한번 저런 것들을 만들어보고 싶다라는 욕구가 생기게 되었습니다. AI와 그래픽 기술등의 발달들로 점차 기획의 한계는 사라지고 있기에 이미 나올것은 다 나왔다는 의견과는 반대로 앞으로도 무궁무진하게 게임 산업은 발달할 것이라고 생각합니다. 이에, 솔직히 말씀드리자면, 경일 아카데미에 대해서 모르고 있었던 때, 우선 MBC 컴퓨터 아카데미에서 4일정도 수강을 했습니다. 수업은 따라가겠으나, 자택이 왕복으로 4시간이 걸리는 용인시였기에, 후에 포트폴리오 작업을 하는데 지장이 클 것이라고 판단, 고민하던 중에 귀사의 온라인 게임 기획자 부트캠프에 대해 알게되었습니다. 훌륭한 교수진과 좋은 후기들, 그리고 온라인으로 행해진다는 것은 너무나 매력적이였습니다. 따라서, 단호히 MBC 아카데미를 자퇴, 귀사의 본 과정에 지원하게 되었습니다. 감사합니다. | K21: MBC 컴퓨터 아카데미에서 4일, 스파르타 코딩 클럽에서 무료 강의 2회, 3D 프린팅 자격증 취득 (3D 모델링 경험 유) | L21: 시스템 기획자, 시나리오 기획자, 콘텐츠 기획자, 밸런스 기획자, 레벨 디자이너, 클라이언트 개발자, 게임 엔진 개발자, 서버 개발자, 게임 원화가 | M21: 수업은 물론이고, 포트폴리오를 충실히 쌓아 국내 대기업 및 중견기업에 입사, 최종적으로는 일본 게임회사로 가고 싶습니다. 포트폴리오 관련해서는 수업을 들으면서 방향성을 찾아갈 수 있다고 생각합니다. 최종적으로는 만들고 싶은 게임을 만드는 게임 디렉터가 되고 싶습니다. | N21: 보유 | O21: 아니오 | Q21: 대화와 타협을 통한 해결 | R21: 배움과 성장으로 받아들임 | S21: 문제 해결에 필요한 실질적 도움 제공 | T21: 아니요 | V21: 아니요 | W21: 없음 | X21: 존경하는 미야자키 히데타카 감독께서도 30살이 되어서야 게임 업계에 들어가셨습니다. 저도 조금 늦은 감이 없지 않지만, 용기를 내어 열심히 배우고 익히고 만들고자 합니다. 감사합니다. | Y21: 김민제 | Z21: 45989 | AA21: 동의함 | AB21: 김민제 | AC21: 45989 | AD21: 동의함
A22: 46003.822 | B22: overman623@naver.com | C22: 김범진 | D22: 남 | E22: 37살(89년생) | F22: 대학교 졸업 | G22: 비전공자 | H22: 가천대학교 컴퓨터공학과 | I22: 안녕하세요! 저는 항상 새로운 것을 배우고 성장하려 노력하는 사람입니다. 긍정적인 태도로 다양한 경험을 즐기며 꾸준한 자기 계발을 통해 더 나은 모습을 만들어가고자 합니다. 이번 교육과정을 통해 평소에 관심이 있었던 게임 자체를 배우게 되는 기회로 삼고 있습니다. | J22: 게임을 스스로 만들어보기 위해 여러 방면으로 시도를 한 적이 있고, 간단한 미니 게임 정도는 만들 수 있을 것 같았지만, 만들고 난 결과물 확인해보니, 게임에 대한 이해 자체가 부족하다고 생각되었습니다. 결국 게임을 만드는건 하나의 세계를 만드는 것과 같은데 개발만으로는 이해할 수 없는 영역이 있기 때문에 게임 기획 수업을 찾고 있었습니다. | K22: 인터넷 강의로 유니티 엔진을 독학한 적이 있습니다. | L22: 클라이언트 개발자, 서버 개발자, 밸런스 기획자, 컨텐츠 기획자, 퀘스트 기획자, 시스템 기획자, 아트 | M22: 게임 자체에 대한 이해도를 높여 게임과 관련된 일을 하는 사람들과 새로운 관계를 맺고 싶습니다. | N22: 보유 | O22: 아니오 | Q22: 대화와 타협을 통한 해결 | R22: 배움과 성장으로 받아들임 | S22: 문제 해결에 필요한 실질적 도움 제공 | T22: 아니요 | V22: 아니요 | W22: 유튜브 | X22: 해당하는 교육 과정을 수강하여 게임을 이해하는데 도움이 되도록 하겠습니다. | Y22: 김범진 | Z22: 46003 | AA22: 동의함 | AB22: 김범진 | AC22: 46003 | AD22: 동의함
A23: 45993.698 | B23: papalagioj@gmail.com | C23: 김서현 | D23: 여 | E23: 27(99년생) | F23: 대학교 졸업 | G23: 전공자 | H23: 동서울대학교, 게임콘텐츠과 | I23: 안녕하십니까. 시스템의 의도를 파악하고 데이터를 구조화하여 재미를 설계하는 기획자 지망생, 김서현입니다. 저는 동서울대학교의 게임콘텐츠 전공 과정을 통해 기획을 비롯한 게임 개발의 전반적인 기초를 다졌으며, 게임의 본질은 유저에게 납득 가능한 도전을 제시하는 의도된 균형에 있다고 믿습니다. 경일게임IT아카데미에서 저의 열정과 지식을 증명하고 싶습니다. 저의 가장 큰 강점은 데이터 기반의 구조화 능력입니다. 전공 지식 외에도, 저는 7년간 파이널판타지14 레이드에서 공대장을 맡아 로그를 분석하여 직업별 밸런스와 시너지의 성공률을 정량화하고 조율하는 실습을 지속해왔습니다. 특히 스프레드시트 함수를 활용해 복잡한 실무 데이터를 90% 이상 효율화한 경험은, 복잡한 게임 시스템의 밸런스 테이블을 자동화하고 검증하는 능력으로 직결된다고 믿습니다. 저는 단순한 플레이를 넘어 시스템 설계의 의도를 분석하고 재구성하는 균형의 설계자가 되고 싶습니다. 니어 오토마타의 경주 퀘스트처럼, 유저가 시스템의 틀을 스스로 해석하고 새로운 규칙을 따르도록 선택의 여지를 설계하는 서브 시스템에 대한 깊은 애정이 있습니다. 또한, 공대장 경험을 통해 유저의 동기와 숙련도를 고려한 협력형 퀘스트 서사를 만드는 중요성을 체득했습니다. 부트캠프를 통해 이 분석적 사고와 실행력을 심화하고, 최종적으로 유저의 행동과 동기를 예측하며 의도와 균형이 명확한 시스템을 설계하는 기획자로 거듭나겠습니다. 감사합니다. | J23: 저는 20년도에 대학을 졸업하고, 졸업시기에 맞춰 코로나19의 발생으로 취업의 문이 좁아졌습니다. 가정형편상 오랜기간 구직활동을 할 수 없었기에 게임 기획자의 꿈을 잠시 내려놓고, 사회의 경험을 쌓게 되었습니다. 그럼에도 저는 꿈을 포기하지 않고, 꾸준히 다양한 게임을 즐기며 기획서를 작성하거나 분석을 해왔습니다. 하지만 긴 공백기 탓에 다시 전공을 살려 구직활동을 해왔지만 혼자서 취업의 트렌드를 파악하기 어려웠고, 오랜기간 사용하지 않은 용어들을 잘 기억하지 못하는 등의 문제가 있었습니다. 이에 대한 도움을 받고자, 경일IT아카데미의 부트캠프를 신청하게 되었습니다. | K23: 2년제 전문대학에서 게임을 전공했으며, 게임 기획서와 졸업 프로젝트를 만들며 졸업했습니다. | L23: 시스템 기획자, 콘텐츠 기획자, 레벨 디자이너, UI/UX 기획자, 시나리오 라이터, 설정 기획자, 전투 기획자, 몬스터 기획자 ... | M23: 이번 부트캠프를 통해, 기초의 기반을 더 탄탄하게 쌓고, 더 견고하고 완성도 높은 포트폴리오 기획서를 작성하여 게임 회사에 기획자로 취업하고자 합니다. 데이터 분석 기반의 시스템 설계 능력을 심화하고, 균형과 의도가 명확한 포트폴리오 기획서를 완성하여 현업 시스템 기획자로 취업하는 것이 목표입니다. | N23: 보유 | O23: 아니오 | Q23: 대화와 타협을 통한 해결 | R23: 배움과 성장으로 받아들임 | S23: 문제 해결에 필요한 실질적 도움 제공 | T23: 아니요 | V23: 예 | W23: 없음 | X23: 부트캠프를 통해 저의 분석적 사고와 실행력을 심화하고, 최종적으로 유저의 행동과 동기를 예측하며 의도와 균형이 명확한 시스템을 설계하는 기획자로 거듭나겠습니다. 그 외로는 개인 포트폴리오 작업물을 별도로 피드백 받을 수 있을지가 궁금합니다. 감사합니다. | Y23: 김서현 | Z23: 45993 | AA23: 동의함 | AB23: 김서현 | AC23: 45993 | AD23: 동의함
A24: 45990.703 | B24: se7471@naver.com | C24: 김성현 | D24: 남 | E24: 30살(96년생) | F24: 대학교(중퇴) | G24: 비전공자 | H24: 동신대,전기공학과 | I24: 이번 경일아카데미로 공부하게되면서 게임쪽에 관심을 가지고있는 생각을 좀 어느정도 할수있을수도 있겠구나 하게 될것같습니다 감사합니다 | J24: 게임을 경험이 있는 입장이였고 뭔가 게임을 만든다?라는 생각을 접해본게 방송인분들이 여러게임을 하시는거 보면서 관심도 좀 가지게 되었습니다 그래서 한번으로는 게임관련 시스템글을 읽어보던가도 했었던것 같고요 다른쪽으론 이걸 이런식으로 가는건 어떨까?하는 생각도 해보았기도 했고요 그러다 이런 교육을 광고로도 보기도했는데 막상 선택은 못했었는데.. 유튜버 분께서 여기 추천해주는 글을 올리시는거 보고 신청하게 되었습니다 감사합니다 | K24: 따로는 없고..그냥 정보만 대충 흩어만보았습니다 | L24: 게임 개발자,게임 디자인 개발자,게임 기획자,게임 모션 그래픽 디자인?, | M24: 게임쪽에서 한번 일해보는건으로 통해 이런저런 경험을 가지고 좀더 진취적인 앞길을 갈수있으면 어떨까 합니다 | N24: 미보유 | O24: 예 | P24: 우울증이 좀 있고,공황이 좀 있습니다 약먹을 정도까지 갔지만 한 2년전부터는 호전이되는것 같아 먹지 않게되었습니다. | Q24: 대화와 타협을 통한 해결 | R24: 배움과 성장으로 받아들임 | S24: 문제 해결에 필요한 실질적 도움 제공 | T24: 아니요 | V24: 아니요 | W24: 유튜버ㆍ지식백과 | X24: 얼굴보고 하기가 좀 낯설겠지만..수료하게된다면 노력해보겠습니다 | Y24: 김성현 | Z24: 45990 | AA24: 동의함 | AB24: 김성현 | AC24: 45990 | AD24: 동의함
A25: 45952.712 | B25: tarrot00@gmail.com | C25: 김수환 | D25: 남 | E25: 33살(93년생) | F25: 대학교 졸업 | G25: 비전공자 | H25: 한국외국어 대학교 사회과학전공 | I25: 안녕하세요, 저는 2년 정도 게임 QA로 근무하면서 게임의 완성도와 서비스 안정성을 검수하는 일을 해왔습니다. 업무 중에 디자인 업무에도 참여하게 되면서 자연스럽게 게임 시스템 설계나 콘텐츠 구조에 관심이 생기게 되었습니다. 그 경험을 계기로 기획자로 커리어를 전환해보고 싶다는 생각이 들어 이번 부트캠프에 지원하게 되었습니다. AI를 활용한 기획에 대해 배우고, 실제 포트폴리오까지 만들어보면서 제 방향성을 좀 더 구체화하고 싶습니다. 잘 부탁드립니다. | J25: 2년간 게임 QA로 근무하며 개발 전반의 품질 관리와 콘텐츠 구조를 검수하는 과정에서 자연스럽게 기획 업무에 관심을 가지게 되었습니다. 생성형 AI를 활용한 기획 방법을 배우고, 이를 통해 창의적이고 효율적인 게임 기획 역량을 키우기 위해 본 과정에 지원했습니다. | K25: 회사 게임 디자인 업무 진행 | L25: 전투 기획자, 콘텐츠 기획자, 시스템 기획자 | M25: 수료 후에는 배운 기획 지식과 AI 활용 능력을 바탕으로 실제 게임 개발 현장에서 창의적이고 데이터 기반의 기획자로 성장하는 것이 목표입니다. | N25: 보유 | O25: 아니오 | Q25: 대화와 타협을 통한 해결 | R25: 과거의 실수와 연관지어 자신감 상실 | S25: 문제 해결에 필요한 실질적 도움 제공 | T25: 아니요 | V25: 예 | W25: 없음 | X25: 취업준비를 병행하면서 수업에 참여할 예정이어서 그런 부분에 있어서 면접이나 자기소개서 작성 등 취업에 시간을 할애하여야 할 때 교육을 어떻게 참여하면 될지 궁금합니다. | Y25: 김수환 | Z25: 45952 | AA25: 동의함 | AB25: 김수환 | AC25: 45952 | AD25: 동의함
A26: 45977.688 | B26: tldhswls123@gachon.ac.kr | C26: 김시온 | D26: 여 | E26: 24(02년생) | F26: 고등학교 졸업 | G26: 비전공자 | H26: 컴퓨터공학과 | I26: 안녕하세요. 플레이어의 선택과 감정을 설계하는 내러티브 지향 게임 디자이너 지망생 김시온입니다. 대학교 게임 제작 동아리에서 무박 2일 게임잼에 5번 이상 참여했고, 2024년에는 동서대학교에서 진행한 딥다이브 게임잼에도 참가했습니다. 제가 만든 게임을 초면인 사람들이 직접 플레이하면서 재밌다고 말해줄 때 가장 큰 보람을 느꼈고, 그 경험 덕분에 ‘나는 플레이 경험을 설계하는 일을 계속 하고 싶다’는 확신을 갖게 됐습니다. 최근에는 GameAIfy 게임 공모전에 팀을 꾸려 PM 겸 총괄 기획으로 참여했는데, 그 과정에서 데이터 구조나 기획 문서 작성 역량이 아직 많이 부족하다는 걸 느꼈습니다. 이번 부트캠프에서는 이 부분을 체계적으로 보완해서, 팀과 더 잘 소통하고 실제 구현까지 고려하는 게임 디자이너로 성장하고 싶어 지원했습니다. | J26: 최근 GameAIfy에서 주최한 AI 에셋 활용 게임잼에 참여하면서, AI가 게임 기획 작업의 효율을 크게 높일 수 있다는 것을 체감했습니다. 특히 현업 기획자 분께 멘토링을 받으며 GPT-머메이드를 활용해 스크립트 구조도와 관계도를 정리해 보니, 머릿속에서만 고민하던 아이디어를 훨씬 빠르게 시각화하고 검증할 수 있다는 점에서 제 작업 방식의 방향성이 많이 달라졌습니다. 이번 부트캠프에서는 AI를 활용해 효율적으로 기획 문서를 작성하고 아이데이션하는 방법을 체계적으로 배우고, 동시에 AI에게 더 나은 질문을 던지기 위해 필요한 게임 기획 기초 지식을 쌓고자 지원했습니다. | K26: 스나이퍼 팩토리에서 진행한 10주 완성 유니티 프로젝트 과정에 참여하며 C# 기반 유니티 프로그래밍 역량을 키웠습니다. 이 과정에서 웅진의 스마트올 프로젝트 과제에 PM으로 참여해 일정 관리와 커뮤니케이션을 담당했고, 결재용 문서와 발표용 PPT, 스토리 및 퀘스트 스크립트 작성 업무를 수행했습니다. 다만 실제 게임 시스템 설계나 밸런싱과 같은 기획 핵심 영역에 깊게 관여하지 못한 아쉬움이 있었고, 이를 계기로 기획의 기초를 체계적으로 쌓아야겠다고 느꼈습니다. 지난 4년간 학교 게임 제작 동아리 활동을 하면서 여러 스터디와 미니게임 제작에 참여했지만, 역할은 기획자보다는 프로그래머일 때가 더 많았습니다. 덕분에 아이디어를 프로토타입으로 구현하고, 플레이 가능한 형태로 빠르게 옮기는 경험은 많이 쌓을 수 있었습니다. 지금은 기획자의 기초가 충분히 구조화되어 있다고 말하긴 어렵지만, 이번 과정을 통해 기획 기본기를 다진다면, 프로그래밍 역량과 프로젝트 경험을 함께 가진 기획자로 성장할 수 있는 잠재력은 분명하다고 생각합니다. | L26: 시스템 기획자, 레벨 디자이너, PM, PO, PMO, 시나리오 기획자, 퀘스트 기획자, 전투 기획자, UI기획자, AI 기획자, AI 기술 기획자, 컨텐츠 기획자, 클래스 디자이너, 밸런스 기획자, 몬스터 디자이너 | M26: 기획자라고 부를 수 있을 만큼 빠르고 명확한 기획 문서 작성 능력을 갖는 것을 제일 원합니다. 이를 통해 최종적으로 뜻이 맞고 상황이 되는 사람을 모아 3개월 내에 핵심 재미를 검증하고, 1년내에 인디게임을 만들어 스팀에 출시하는 것이 목표입니다. | N26: 보유 | O26: 예 | P26: 목디스트와 손목에 건초염이 발생하여 물리치료를 자주 받아야 함. 알러지성 비염이 있어 환절기에는 비염약을 먹어야함. | Q26: 대화와 타협을 통한 해결 | R26: 배움과 성장으로 받아들임 | S26: 문제 해결에 필요한 실질적 도움 제공 | T26: 아니요 | V26: 예 | W26: 없음 | X26: 공부를 하느라 바쁘긴 하겠지만 개인적으로 기획중이거나 구상중인 게임에 대한 피드백도 받을 수 있는 기회가 있음좋겠습니다. | Y26: 김시온 | Z26: 45977 | AA26: 동의함 | AB26: 김시온 | AC26: 45977 | AD26: 동의함
A27: 45988.622 | B27: rladudeh6055@gmail.com | C27: 김영도 | D27: 남 | E27: 25살(01년생) | F27: 대학 졸업예정자 | G27: 비전공자 | H27: 한신대학교 한중문화콘텐츠학과 | I27: 저는 어릴적부터 다양한 콘텐츠를 좋아해서 그런 콘텐츠를 기획해보고 싶다는 생각을 가지고 살았습니다. 드라마 영화 만화 등 여러가지 콘텐츠를 좋아하고 즐겼지만, 가장 좋아했던건 게임이었습니다. 게임이랑 장르는 재미있고 흥미로운 스토리를 기반으로 나의 선택과 경험이 세계의 모습을 바꿀 수 있다는 점이 저에게 매력적으로 다가왔습니다. 저는 그 때문에 게임을 기획하는 기획자의 길을 가고 싶다는 생각을 했습니다. 게임에 대한 흥미와 열정은 남들보다 더 강하리라는 확신을 가지고 있습니다. | J27: 저는 앞서 말한 것처럼 게임에 대한 애정과 흥미는 깊지만, 당장 게임을 기획하고 그것을 실제로 만들어나가는 기술과 지식이 없다는 것이 저의 단점이라고 생각했습니다. 이런 단점을 보안하고 싶다는 생각이들었고 그렇기 때문에 이번 과정을 참여하고 싶다는 생각이 들었습니다. | K27: 학교에서 콘텐츠 기획에서 게임에 대한 기획을 해본적은 있지만, 명확한 지식과 기술없이 기획만 해본 적은 있습니다. | L27: 게임기획 (콘텐츠 기획자, 레벨 디자이너, 전투디자인, 시스템 기획자) | M27: 제가 이 과정을 수료한 이후에는 이곳에서 배운 지식을 통하여 취업에 대한 목표와 계획에 대해서 더 세부적으로 준비할 생각입니다. | N27: 보유 | O27: 아니오 | Q27: 대화와 타협을 통한 해결 | R27: 배움과 성장으로 받아들임 | S27: 문제 해결에 필요한 실질적 도움 제공 | T27: 아니요 | V27: 아니요 | W27: 없음 | X27: 콘텐츠에 대한 이해와 스토리텔링에 대해서는 전공자이기 때문에 어느정도 이해하고 있지만, 게임업계에 대한 구체적 상황이나 프로그램을 다룬다는 점에서는 조금 걱정됩니다. 하지만 시작한 이상 열심히 참여하고 배운 내용을 통해 취업까지 이어진다면 좋겠다는 생각을 합니다. | Y27: 김영도 | Z27: 45988 | AA27: 동의함 | AB27: 김영도 | AC27: 45988 | AD27: 동의함
A28: 46003.62 | B28: yungjingim@gmail.com | C28: 김용진 | D28: 남 | E28: 32세(93년생) | F28: 대학교 2학년중퇴 | G28: 비전공자 | H28: 극동대학교 만화애니메이션학과 | I28: 원래는 만화와 게임이 좋아서 일러스트작가나 캐릭터디자인으로 꿈꿨지만 개인적인 사정으로 다른 회사에서 8년 일하다가 이제와서 하고싶은 일에 도전해봅니다. 항상 꿈꿔왔던, 하고싶었던것을 할수있는 기회가 왔다고 생각해 다시 도전하고싶습니다. 잘부탁드립니다. | J28: 제가 구독중인 G식백과 김성회님의 영상을 시청중에 협업으로 광고중에 나와서 관심을 갖게 되었고, 하고싶었던 일에 다시 도전하게끔 만드는 계기가 되었습니다. 또한 대학에서는 만화 애니학과에서 기획하고싶었던 게임과 설정 캐릭터들이 있어서 늘 만들고 싶었습니다. | K28: 없음 | L28: 게임기획자(게임 세계관 및 스토리 관련) | M28: 말그대로 수려한 후에는 여기서 배운 지식과 정보를 통해서 제가 예전부터 꿈꿨던 게임을 기획하고싶습니다. | N28: 보유 | O28: 아니오 | Q28: 대화와 타협을 통한 해결 | R28: 배움과 성장으로 받아들임 | S28: 문제 해결에 필요한 실질적 도움 제공 | T28: 아니요 | V28: 예 | W28: 없음 | X28: 열심히하겠습니다아아! | Y28: 김용진 | Z28: 46003 | AA28: 동의함 | AB28: 김용진 | AC28: 46003 | AD28: 동의함
A29: 45967.714 | B29: gimyungyu9@gmail.com | C29: 김윤규 | D29: 남 | E29: 24살(02년생) | F29: 대학교 재학중 | G29: 비전공자 | H29: 광주대학교 경찰행정학과 | I29: 저는 운동을 좋아하고 활발하머 긍정적인 에너지를 가지고 주변 사람들과의 소통을 즐기는 사람입니다. 새로운 환경에서도 빠르게 적응하고 주변 사람들과의 좋은 관계를 유지하는데 장점이 있습니다. 평소 어떤 일이든 완벽하게 해내고자 하는 성향이 강해 맡은 일은 끝까지 책임지고 세심하게 처리하는 편입니다 계획을 세우고 효율적으로 실행하는 것을 선호하고 디테일한 부분까지 놓치지 않기 위해 지속적으로 점검하는 성격을 가지고 있습니다 또한 외국어에 대한 흥미와 강점을 가지고 있습니다. 일본어와 영어를 꾸준히 학습하였으며 언어를 통해 다양한 문화와 사고방식을 이해하려 노력해왔습니다 이러한 경험은 새로운 사람들과의 커뮤니케이션 능력을 키우는 데 큰 도움이 되었습니다 | J29: 어릴 적부터 게임은 제 삶의 큰 부분을 차지해왔습니다. 단순히 즐기는 것을 넘어, 다양한 장르의 게임을 접하면서 ‘이 게임은 왜 재미있을까’, ‘어떤 점이 개선되면 더 좋을까’라는 생각을 자연스럽게 하게 되었습니다. 이러한 경험을 통해 게임의 구조, 밸런스, 스토리 전개 등 세부 요소에 대한 막연하게나마 분석하는 습관을 키울 수 있었습니다. 게임을 단순한 소비자가 아닌 창작자의 시선에서 바라보게 되면서, 게임 기획에 대한 관심이 깊어졌습니다. 좋은 게임은 플레이어에게 재미뿐 아니라 감정적 몰입과 특별한 경험을 선사한다고 생각합니다. 저 역시 그런 경험을 제공하는 기획자가 되고 싶습니다. | K29: 없습니다 | L29: 시스템 기획자, 콘텐츠 기획자, 기술 기획자 | M29: 수료 후 게임기획자로서의 취업을 목표로 열심히 도전할 것입니다. 이 과정을 통해 배운 것을 토대로 목표하고자 하는 기업에 인재상에 도달할 수 있게 게임 기획에 있어서 필요한 지식들을 더 공부하며 포토폴리오 또한 더욱 완벽하게 준비할 수 있도록 노력할 것입니다. 결국 이 과정을 수료하는 것은 취업에 목적을 두고 있기 때문에 수료 후 게임기획자로서의 취직을 위해 디테일 한 부분 놓치지 않고 준비할 것입니다 | N29: 보유 | O29: 아니오 | Q29: 대화와 타협을 통한 해결 | R29: 자신을 비난하고 자책하는 경향 | S29: 문제 해결에 필요한 실질적 도움 제공 | T29: 아니요 | V29: 아니요 | W29: 없음 | X29: 아무래도 온라인이기 때문에 전문적인 수업과 관리에 대한 우려가 조금은 있습니다. 기획자가 되고싶다는 욕심이 크다보니 더욱 열심히 수업의 내용를 배우고 싶고 포토폴리오에 관해서도 더 잘 준비하고 싶은 부분이 있는 것 같습니다. 물론 잘 이끌어주시겠지만 시작의 길에 있다보니 막연한 걱정도 조금은 있는 것 같슴니다..!! | Y29: 김윤규 | Z29: 45967 | AA29: 동의함 | AB29: 김윤규 | AC29: 45967 | AD29: 동의함
A30: 45997.686 | B30: dbsgml430@gmail.com | C30: 김윤희 | D30: 여 | E30: 28 (98년생) | F30: 중졸 | G30: 비전공자 | H30: 없음 | I30: 안녕하세요 28살 김윤희 입니다 취업제대로 해본적도 없고 자기소개도 처음 써보는데 이때까지 살아오면서 뭘 해보자한게 없었습니다 처음으로 해보고자해서 지원했습니다 잘부탁드립니다 | J30: 아직 뭘 한번도 배워본적도 없고 제가 뭘해야할지도 모르는 상황에서 알바생활만 하다가 유튜브광고를 통해 신청하게되었습니다 뽑아만 주신다면 안빠지고 열심히 공부하고 배우겠습니다 정말 모르는게 많지만 잘부탁드리겠습니다 | K30: 아니요 없습니다 | L30: 잘모룹니다! | M30: 수료후엔 관련된 회사들로 취업을 하고싶습니다 취직이 되어 배운것들을 잘 활용해 보고싶니다 | N30: 미보유 | O30: 아니오 | Q30: 분노나 감정을 억누르고 침착함을 유지 | R30: 배움과 성장으로 받아들임 | S30: 문제 해결에 필요한 실질적 도움 제공 | T30: 아니요 | V30: 아니요 | W30: 없음 | X30: 만약에 돈이 너무 없어서 알바를 해야하는 상황이 오면 어쩌나요? | Y30: 김윤희 | Z30: 45997 | AA30: 동의함 | AB30: 김윤희 | AC30: 45997 | AD30: 동의함
A31: 45992.732 | B31: eogks3681@gmail.com | C31: 김재환 | D31: 남 | E31: 28(98년생) | F31: 고등학교 졸업 | G31: 비전공자 | H31: 메카트로닉스 | I31: 평소에 게임에 관심이 많은 상태에서 게임 관련 유튜브에서 소식을 듣게되었습니다 이걸 좋은 기회로 생각하여 게임 업계로 취업하고 싶은 취업준비생 김재환 입니다 | J31: 주말마다 Wixoss라는 오프라인 카드게임을 취미로 즐기고 있었습니다 어느날 Wixoss를 하면서 친해진 사람 중 게임업계에 있는 사람이 많다고 알게되어 게임업계에 흥미가 생겼습니다 그러다 유튜브에서 본 과정을 알게되 신청하였습니다 | K31: 없습니다 | L31: 게임 기획자는 게임의 제작 필요한 작업을 하는 사람입니다 시나리오, 레벨, 컨텐츠, 전투, 밸런스, 시스템 등에 세부 직군이 있다고 알고있습니다 저는 건물이나 몬스터의 위치 및 양으로 게임의 난이도를 조절하는 레벨 디자인에 흥미를 가지고 있습니다 | M31: 수료 후 목표 1위는 당연히 취업 입니다 늦었다고 생각하지만 부모님이 나이가 많으셔서 빠른 자립을 위해서 입니다 | N31: 미보유 | O31: 아니오 | Q31: 대화와 타협을 통한 해결 | R31: 자신을 비난하고 자책하는 경향 | S31: 상황에 대한 이해와 위로 | T31: 아니요 | V31: 예 | W31: 없음 | X31: 12번에서 캠은 없고 마이크만 있은 경우에는 무엇을 선택하면 되나요 본 과정 전부 비대면 온라인 수업입니까? 수업에 늦거나 개인용무로 빠지면 어떻게 됩니까? 녹화본이 있나요? | Y31: 김재환 | Z31: 45992 | AA31: 동의함 | AB31: 김재환 | AC31: 45992 | AD31: 동의함
A32: 45950.552 | B32: oberstmarkts@gmail.com | C32: 김종우 | D32: 남 | E32: 35살(91년생) | F32: 대학원 졸업 | G32: 비전공자 | H32: 부산대학교 경영학 재무관리 | I32: 안녕하세요. 저는 비전공자로서 게임 개발에 첫발을 내딛고자 온라인 게임 기획자 부트캠프 4기에 지원하는 김종우입니다. 경영학을 공부하고 여러 차례 창업을 경험하며 전략·재무·데이터를 다뤄 왔지만, 결국 제가 오래 붙잡고 고민한 것은 ‘사람들이 왜 몰입하고, 무엇에 보상을 느끼는가’였습니다. 그 질문이 저를 게임으로 데려왔고, 이제는 플레이어 심리와 시스템 설계를 결합해 즐거운 경험을 만드는 기획자가 되고자 합니다. 제가 걸어온 길은 다양합니다. 스타트업에서 비즈니스 모델을 설계하고, 제품·웹서비스를 직접 만들며 A/B 테스트와 퍼널을 개선했습니다. 해군 장교 복무로 팀을 이끌고, 위기 상황에서 의사결정과 커뮤니케이션을 단련했습니다. 출판·커머스·소프트웨어 등 여러 현장을 오가며 배운 것은 “가설을 세우고 빠르게 검증하는 루프”와 “유저의 목소리를 데이터로 번역하는 법”이었습니다. 전공은 다르지만, 이 역량은 곧 게임 기획의 기본 역량—코어 루프 정의, 온보딩·난이도·경제 밸런스, 라이브옵스 지표 관리—와 맞닿아 있습니다. 저는 특히 시스템 기획과 경제 밸런싱에 관심이 큽니다. 재화의 생성·소각 사이클, 인플레이션 방지 장치, 보상 곡선과 피로도 관리 같은 이슈를 데이터 기반으로 설계하고 싶습니다. 유저 세그먼트별 동기(경쟁·수집·협동)를 맥락화하여 이벤트를 설계하고, 장기 리텐션을 해치지 않는 과금 UX를 고민하겠습니다. “공정하지만 도전적인 게임”을 만들기 위해 윤리적 수익화 원칙을 지키는 것도 약속드립니다. 비전공자로서의 겸손함도 잊지 않겠습니다. 부트캠프에 합류한다면, 저는 “작게 만들고 자주 검증하는 팀”을 지향하겠습니다. 실패를 숨기지 않고 기록하며, 동료들의 기획 의도를 존중하는 태도로 팀의 속도를 지키겠습니다. 플레이어의 하루를 더 재미있게 만드는 시스템을 설계하고, 팀과 함께 배워 성장하겠습니다. 온라인 게임 기획자 부트캠프 4기에서 저의 첫 걸음을 시작할 수 있도록 기회를 부탁드립니다. 감사합니다. | J32: 1. 데이터 기반 플레이 경험 최적화 플레이어 심리와 지표를 바탕으로 가설→실험→검증 루프를 돌려 몰입을 설계하고 싶습니다. 2. 시스템·경제 밸런싱 역량 전환 재화 생성–소각, 보상 곡선, 피로도·인플레 관리 등 수치 설계를 통해 공정한 재미와 수익을 함께 달성하고자 합니다. 3. 작은 실험의 반복 + 라이브옵스 코어 루프·튜토리얼·이벤트를 작게 빠르게 만들고, 1/7일차 리텐션·ARPDAU로 즉시 개선하는 운영 근육을 기르고 싶습니다. 4. 협업과 커뮤니티 공진화 기획–아트–개발–QA 협업을 통해 완성도를 높이고, 유저 피드백과 메타 변화에 민첩하게 대응하는 문화를 만들고자 합니다. 5. 장기 커리어 비전 시스템 기획→밸런스/라이브 →프로덕션 리드로 성장해, 오래 사랑받는 윤리적 서비스와 IP를 만드는 것이 목표입니다. | K32: 경제학수업-게임이론. 앱개발 4개월 과정(부산_SBS아카데미) 한국표준협회 블록체인 교육과정 그외, 홈페이지 개발이나 웹을 활용한 창업 등 | L32: 1. 경제·밸런스 기획 (Economy Designer) 적합: 재무·수치 감각 → 재화 생성·소각, 보상 곡선 설계에 직결 입문 과제: 코어 루프 가정 후 밸런스 테이블(엑셀)과 시뮬 시트 1종 2. 라이브옵스 기획 (LiveOps) 적합: 운영/그로스 경험 → 이벤트 캘린더·패치 사이클 설계 입문 과제: 4주 라이브 캘린더 + 1/7일차 리텐션 개선 가설·지표판 3. 수익화/과금 기획 (Monetization) 적합: BM 설계·윤리적 수익화 원칙 보유 입문 과제: 배틀패스/번들 2안, A/B 가설표(가격·확률·피로도 가드레일 포함) 4. 게임 PM/프로덕트 매니저 적합: 다프로젝트 리드 경험 → 로드맵·KPI·협업 허브 역할 입문 과제: 미니 MRD/PRD 1세트 + 마일스톤/리스크 로그 5. 데이터 애널리스트(게임) 적합: 퍼널/코호트 분석 경험 풍부 입문 과제: 텔레메트리 이벤트 스키마 초안 + 가짜데이터 리포트(코호트/ARPDAU) | M32: 3년(0–36개월): “입문→핵심 파트 소유” 주니어 경제·밸런스 디자이너 또는 라이브옵스 기획 → 2년차에 미들 레벨 도전 보조 역량: 수익화 문서화, 데이터 분석(기초 SQL), PM 보조 5년(37–60개월): “시니어 코어 소유 → 미니 리드” 시니어 경제/라이브 기획 또는 수익화 리드 후보 소규모 스쿼드(2–4명) 리딩, 주니어 코칭 1–2명 10년(61–120개월): “제품 책임/조직 설계 → IP 확장” 리드 시스템/경제 디자이너, 라이브옵스 책임, 프로덕트 리드 또는 소규모 스튜디오 공동 창업 포트폴리오 IP 1–2개 장기 운영(시즌형·크로스 플랫폼) | N32: 보유 | O32: 아니오 | Q32: 분노나 감정을 억누르고 침착함을 유지 | R32: 배움과 성장으로 받아들임 | S32: 상황에 대한 이해와 위로 | T32: 예 | U32: 신속채무조정과정에 있습니다. | V32: 아니요 | W32: 없음 | X32: 비전공자라서 두 배로 준비했습니다. 저는 ‘작게 만들고 빨리 검증’하는 태도로 코어 루프–튜토리얼–밸런싱을 반복 개선하고, 데이터(리텐션·ARPDAU)와 플레이테스트를 근거로 판단하겠습니다. 화려한 역할보다 필요한 일을 먼저 맡겠습니다—리서치, 로그 정리, 밸런스 시트, 패치 노트까지. 공정한 수익화와 장기 재미를 함께 지키며 팀의 속도를 높이겠습니다. 결과가 틀리면 가설을 바꾸고, 실패는 회고로 남기겠습니다. 3년 내 미들레벨 기획자로 성장해 시즌 운영을 책임지고, 5년 차에는 경제·라이브 영역의 미니 리드를 목표로 하겠습니다. 첫걸음의 무게를 알고 있습니다. 기회를 주신다면 끝까지 책임지겠습니다. | Y32: 김종우 | Z32: 45950 | AA32: 동의함 | AB32: 김종우 | AC32: 45950 | AD32: 동의함
A33: 45989.818 | B33: kjs627480@gmail.com | C33: 김준섭 | D33: 남 | E33: 25살(01년생) | F33: 고등학교 졸업 | G33: 비전공자 | H33: 목원대학교 아트미디어학과(현재는 자퇴) | I33: 안녕하세요!충청남도 당진에 거주 중인 김준섭이라고 합니다!저는 긴장도 많이하고 낯을 많이 가려 도전 정신이 많이 부족했던 사람이었습니다.하지만 아르바이트와 군대를 다녀오며 사회생활을 배워오며 사람들 앞에서 긴장감과 낯을 가리는 것이 많이 줄어들었고 소극적인 태도로는 제 꿈에 다가가기 힘들다고 생각되어 이번 G식백과 김성회님의 게임제작 부트캠프 게시물을 확인하고 이 기회를 무조건 잡고 적극적으로 참여하며 배우며 성장해야한다고 느꼈습니다!이번 부트캠프에 참여해 한 사람의 몫을 하는 사람이 되고싶습니다! | J33: 저는 평소에도 다양한 게임을 해보며 한번쯤은 나도 게임을 제작해보고 싶다고 생각하던 사람이었습니다.그리고 이번에 G식백과 김성회님의 게임제작 부트캠프의 게시물을 보고 꼭 게임업계에서 일하고 싶다고 생각을 하던 저에게 이 기회를 무조건 잡아야 된다고 생각하고 지원하게 되었습니다!현재까지도 관심있는 출시되는 게임을 직접해보고 즐겨보며 오프라인 행사도 참여해보며 유저의 입장에서 어떤 점이 즐겁고 민감한지 배우고 있습니다!많이 부족한 사람이지만 이번 게임제작 부트캠프에 적극적으로 참여해 부족한 저를 선생님들의 배움으로 부족한 부분을 고쳐가며 정말 마지막 기회라고 생각하고 열심히 배우고 노력하며 게임업계에 취업해서 꿈을 향해 달려가고 싶습니다!긴글 읽어주셔서 감사합니다! 현재 하고있는 게임: 리그오브레전드,이터널리턴,림버스컴퍼니,브라운더스트2,스텔라소라,스타세이비어 등이 있습니다! | K33: 게임관련된 학습에 경험이 없지만 이번 부트캠프에서 모든걸 배우며 시작하고 싶습니다! | L33: 제일 배우고 싶은건 게임의 규칙과 스토리,시스템을 설계하고 싶은 게임기획자가 되고 싶고 게임기획자가 꿈인 만큼 이번 부트캠프로 게임업계에 관련된 다양한 분야들을 더 세세히 정확하게 알고싶습니다! | M33: 저는 수료 후 부트캠프에서 배운 모든 것들을 활용하며 게임을 제작해서 저의 꿈의 목표에 가장 가까운 림버스컴퍼니를 만드신 김지훈 디렉터님 처럼 훌륭하고 유저와 소통하며 친화적인 게임 업계인이 되는것이 목표입니다! | N33: 보유 | O33: 아니오 | Q33: 상황을 피하는 경향 | R33: 배움과 성장으로 받아들임 | S33: 상대방이 고칠 수 있도록 충고 | T33: 아니요 | V33: 아니요 | W33: 없음 | X33: 게임제작 부트캠프로 제 인생의 전환점으로 삼아 변하고 노력하는 사람이 되어 부끄럼없이 한 사람의 몫을 하는 사람이 되고 싶습니다! | Y33: 김준섭 | Z33: 45989 | AA33: 동의함 | AB33: 김준섭 | AC33: 45989 | AD33: 동의함
A34: 45966.466 | B34: jhk920707@gmail.com | C34: 김지훈 | D34: 남 | E34: 33살(92년생) | F34: 대학교 중퇴 | G34: 비전공자 | H34: 경희대 한방재료공학과 | I34: 뉴미디어 엔터테인먼트, 주로 유튜브에서 10년 가까이 일했습니다. 최신 경향의 스타트업을 하다보니, 3d 애니메이션도 하게 되었는데 갈수록 현업에서 메타버스의 시대가 오고 있는 것이 느껴졌습니다. 그리고 메타버스의 끝은 결국 게임에 맞닿아있는 것 같아, 게임 교육을 받으려했으나 마음에 드는 과정을 찾지 못 했습니다. 경일아카데미가 커리큘럼이 좋은 건 알고 있었는데, 마음에 드는 과정이 나와 신청하게 되었습니다. | J34: 많은 직무교육을 찾아봤지만 AI시대에 대체되지 않을 내용을 찾기 어려웠습니다. 게임 기획은 아직 인간이 할 수 있는 부분이 많고, 인디게임도 오히려 AI도움을 받아 더 활성화될 거라 생각합니다. 무엇보다 가장 고관여의 콘텐츠를 직접 만들어보고 싶습니다. | K34: 없습니다 | L34: 게임PM, GM, 게임 기획자 | M34: 게임을 만드는 법을 배워 제가 마음에 드는 게임을 만들고 싶습니다. | N34: 보유 | O34: 예 | P34: 허리와 목이 안 좋아 온라인 과정을 신청하게 됐습니다. 우울증 약과 ADHD약도 적지 않게 복용 중입니다. | Q34: 대화와 타협을 통한 해결 | R34: 배움과 성장으로 받아들임 | S34: 문제 해결에 필요한 실질적 도움 제공 | T34: 아니요 | V34: 아니요 | W34: 없음 | X34: 마음에 드는 온라인 과정을 찾기 힘들었는데, 드디어 찾아서 최대한 수료하고 싶습니다. | Y34: 김지훈 | Z34: 45966 | AA34: 동의함 | AB34: 김지훈 | AC34: 45966 | AD34: 동의함
A35: 45990.719 | B35: linon1596@gmail.com | C35: 김태형 | D35: 남 | E35: 28 | F35: 대학교 졸업 | G35: 비전공자 | H35: 서울호서직업전문학교 / 인테리어 디자인 | I35: 안녕하세요 28살 김태형입니다 평소 학교와 취업을 했을때 지각을 해본적이 없었으며 일을 할때도 항상 맡은 일은 열심히 해왔습니다 또한 모르는 일이나 잘 안풀리는 일을 할때에는 사람들에게 물어봐가면서 해결을 하였고 다른 사람들과 잘 지냈습니다 비전공자이지만 새로운 경험을 해보고 싶었으며 게임을 자주하여서 어떻게 게임을 만드는지 궁금하여서 지원을 해보았습니다 | J35: 취업준비중에 친구가 알려주어서 지원을 하게 되었습니다 저 또한 새로운 경험을 시도해보고 싶었으며 게임을 좋아하여 어떻게 만드는 건지 궁금하였고 무언가를 만드는걸 좋아하였는데 게임은 만들어 본적이 없으며 혼자서 만들려고 하여도 경험이 없고 여러 자료를 보아도 무슨 말인지 알수가 없어서 포기하였습니다 하지만 이런 기회가 생겨서 도전해보고 싶어져서 지원을 하게 되었습니다. | K35: 없습니다 | L35: 없습니다 | M35: 게임 회사에 들어가보고 많은 경험을 쌓으면서 여때까지 쌓은 경험으로 저의 실력으로 게임을 제작해 보고 싶습니다 | N35: 미보유 | O35: 아니오 | Q35: 대화와 타협을 통한 해결 | R35: 배움과 성장으로 받아들임 | S35: 문제 해결에 필요한 실질적 도움 제공 | T35: 아니요 | V35: 아니요 | W35: 친구 | X35: 열심히 배워보겠습니다 | Y35: 김태형 | Z35: 45990 | AA35: 동의함 | AB35: 김태형 | AC35: 45990 | AD35: 동의함
A36: 45999.765 | B36: areagate34@gmail.com | C36: 김태환 | D36: 남 | E36: 27살(98년생) | F36: 대학교 졸업 | G36: 전공자 | H36: 건국대학교 컴퓨터공학 | I36: 대학교에서 배운 기본적인 프로그래밍 능력, 그리고 음악 및 글쓰기 활동을 통한 예술지식을 토대로 게임을 만들어가는 개발자, 디자이너 모두와 소통하는 기획자가 되고 싶습니다. | J36: 대학과정에서 프로젝트를 진행할 때 기획 분야에서 큰 흥미를 느꼈습니다. 이후 기획자로 취업을 준비하였지만, 혼자서 과정을 진행하기에는 어려움이 많았습니다. 전문적으로 기획을 배워본 것도 아니며 준비하고 있는 과정이 실무와 얼마나 닿아있는지, 이런 형태의 포트폴리오를 회사에서 원하는 것인지 알기 어려웠습니다. 이런 과정을 여러번 반복하면서 자연스럽게 게임기획이라는 목표에서 멀어지고 말았습니다. 이번 기회를 통해 실제 기획이라는 분야의 전문성을 높이고 실질적인 경험을 토대로 자신만의 게임을 만들고 싶습니다. | K36: 대학교 과정중 진행한 프로젝트 2~3회 | L36: 밸런스 기획, 전투 기획, 시나리오 기획, 동선 및 맵구조 디자인, 시스템 기획, 레벨 디자인 | M36: 볼륨이 크지 않더라도 모두에게 여운을 남길 수 있는 작품을 만들고 싶습니다. | N36: 보유 | O36: 아니오 | Q36: 대화와 타협을 통한 해결 | R36: 배움과 성장으로 받아들임 | S36: 문제 해결에 필요한 실질적 도움 제공 | T36: 아니요 | V36: 예 | W36: 없음 | X36: 모니터의 위치상 카메라의 각도 조절이 어려운 상황입니다. 때에 따라 상반신 전체가 나오지 않을 수 있습니다. | Y36: 김태환 | Z36: 45999 | AA36: 동의함 | AB36: 김태환 | AC36: 45999 | AD36: 동의함
A37: 45996.538 | B37: dpfvpfxmlove@gmail.com | C37: 김태훈 | D37: 남 | E37: 만 24살 (2001년생) | F37: 대학교 졸업 | G37: 비전공자 | H37: 충청대학교 바이오분석학과 | I37: 이번 게임기획자 과정에 참여하게 된 김태훈입니다. 지금까지는 단순히 게임하는 것을 좋아하는 사람이었다면, 이번 기회를 통해 내가 진짜 하고 싶은 직무를 습득해서 덕업일치를 이루고 싶습니다. | J37: 지금까지 게임을 즐기기만 했고, 현생과는 다른 세계라고 생각했었습니다. 우연히 유튜브에서 아카데미를 접하게 되었는데, 내가 배운 전공이랑 거리가 있지만 단순히 전공을 따라가 취업하는 것 보다는 내가 진짜 관심있고, 하고 싶은 업을 배우는 것이 더 중요하다고 생각했고, 이번에 좋은 기회가 왔다고 생각해서 신청하게 되었습니다. | K37: 없습니다. | L37: 프로듀서, 운영자, 게임 디렉터, (시스템, 레벨)디자이너, 아트팀, 음향팀 등 | M37: 아카데미 과정을 잘 수료하여 단순히 직장에 취업한다는 것이 아닌, 내가 즐기면서 일할 수 있고 내가 원하는 게임을 만들고, 이끌어나가는 사람이 되고 싶습니다. | N37: 미보유 | O37: 아니오 | Q37: 논리적인 논쟁으로 해결 | R37: 배움과 성장으로 받아들임 | S37: 문제 해결에 필요한 실질적 도움 제공 | T37: 아니요 | V37: 아니요 | W37: 없음 | X37: 1. 추가 입학하게 되어 진도를 따라갈 수 있을까 다소 걱정되지만, 노력해서 따라갈 수 있도록 하겠습니 다. 2. 마이크는 보유중이지만 캠이 없는데, 문제가 된다면 말씀해주시면 감사하겠습니다. | Y37: 김태훈 | Z37: 45996 | AA37: 동의함 | AB37: 김태훈 | AC37: 45996 | AD37: 동의함
A38: 46008.593 | B38: baoo88000@gmail.com | C38: 김태훈 | D38: 남 | E38: 27살(99년생) | F38: 고등학교 졸업 | G38: 전공자 | H38: 장안대 게임컨텐츠과 | I38: 게임을 좋아하고 재밌는 게임을 만들고 싶어서 지원하였습니다. 다른사람들에게도 게임의 재미를 느낄수 있는 게임을 만들고싶습니다! | J38: 학교에서 어느정도를 배웠지만 게임 기획관련 직무를 더욱더 알고싶어 신청하게 되었습니다. 또한 같은 직군을 준비하는 분들과 함께 팀플등을 하며 의견공유 등을 할 수 있을거라 생각해 신청하게 되었습니다. | K38: 학교에서 기초적인 학습을 하였고 동아리를 들어가 개발을 6개월 정도 해보았습니다. | L38: 게임기획자 중 시스템기획자나 게임 밸런스 디자이너, 레벨 디자이너 정도를 생각하고 있습니다. | M38: 수료후 배운 지식을 바탕으로 게임 기획자로 취업을 성공하는것이 목표입니다! | N38: 미보유 | O38: 아니오 | Q38: 대화와 타협을 통한 해결 | R38: 배움과 성장으로 받아들임 | S38: 문제 해결에 필요한 실질적 도움 제공 | T38: 아니요 | V38: 아니요 | W38: 없음 | X38: 과정에 성실하게 참여하고 많을걸 배워가겠습니다 | Y38: 김태훈 | Z38: 46008 | AA38: 동의함 | AB38: 김태훈 | AC38: 46008 | AD38: 동의함
A39: 45980.597 | B39: youtoo1729@gmail.com | C39: 김현우A | D39: 남 | E39: 26살 | F39: 졸업 예정 | G39: 비전공자 | H39: 시각정보디자인 | I39: 저는 비록 게임이 전공도 아니며 게임업계에 대해서 아는것이 없지만 저의 열정은 누구보다 높다고 자부하며 반드시 게임업계에 취업해서 게임개발자 라는 타이틀을 얻고싶습니다 | J39: 게임업계 취업 희망하며 게임이 현재 자신과 가장 적성에 맞다고 판다하여 본과종에 참여하여 자신의 능력을 향상시켜서 게임업계 진출을 위한 능력을 습득하고 나아가 실제 게임업계에 취업을 희망하여 본 과정에 참여를 신청함 | K39: 전무 | L39: 게임 기획자(벨런스, 경제, 콘텐츠, 스토리), 원화가, 모델가, 개발자 | M39: 게임기확자를 희망하고 있으며 기획자주에서도 가급적 스토리 기획자를 희망하여 실제 게임 기획자로서 취업을 목표로 하고 있음 | N39: 보유 | O39: 아니오 | Q39: 대화와 타협을 통한 해결 | R39: 과거의 실수와 연관지어 자신감 상실 | S39: 상황에 대한 이해와 위로 | T39: 아니요 | V39: 아니요 | W39: 없음 | X39: 성실히 과정에 임할것을 각오합니다 | Y39: 김현우 | Z39: 45980 | AA39: 동의함 | AB39: 김현우 | AC39: 45980 | AD39: 동의함
A40: 45981.723 | B40: gustlrdn3@gmail.com | C40: 김현우B | D40: 남 | E40: 27살(99년생) | F40: 대학교 졸업 | G40: 비전공자 | H40: 하얼빈공업대학교 컴퓨터공학과 | I40: 안녕하세요. 저는 어릴 때부터 게임을 하면서 이건 왜 이렇게 만들어졌을까?, 저건 왜 이런 구조일까? 라는 궁금증을 많이 가졌습니다. 단순히 플레이하는 것을 넘어서, 게임이 만들어지는 과정과 구조를 이해하고 싶다는 생각이 커졌고, 그 호기심이 결국 기획자가 되고 싶은 목표로 이어졌습니다. 이제는 유저로서 느꼈던 의문들을 기획 관점에서 분석하고, 더 나은 경험을 설계하는 기획자가 되고자 노력하고 있습니다. | J40: 여러 부트캠프 후기를 찾아보고 비교했을 때 이 과정이 가장 체계적이고 실무 중심이라는 느낌을 받았습니다. 또한 앞으로는 AI를 활용할 줄 아는 기획자가 더욱 중요해질 것이라 판단해서 생성형 AI를 실제로 활용해보는 커리큘럼에 큰 매력을 느껴 참여하게 되었습니다. | K40: 전문적인 게임 기획 교육을 받은 경험은 아직 없지만, 메이플스토리 등 여러 게임들을 플레이하며 시스템 구조와 유저 경험에 대해 분석해 본 경험이 있습니다. 이번 과정을 통해 실제 실무 중심의 기획 역량을 체계적으로 쌓고 싶습니다. | L40: 시스템 기획자, ux/ui기획자, 밸런스 기획자, 컨텐츠기획자, QA, 시나리오기획자, 게임bm기획자 | M40: 본 과정을 통해 쌓은 개발자와 원활히 소통하며 실무에 적용 가능한 게임기획 역량을 갖추어 취업하는 것입니다. | N40: 미보유 | O40: 예 | P40: 허리디스크가 있습니다. 지금은 호전되어서 약도 안먹고 일상생활에 문제없습니다. | Q40: 대화와 타협을 통한 해결 | R40: 배움과 성장으로 받아들임 | S40: 상황에 대한 이해와 위로 | T40: 아니요 | V40: 아니요 | W40: 없음 | X40: 노트북의 내장된 카메라와 마이크로 화상수업 참여가능한지 궁금합니다. 과정을 충실히 수행하며 기획자로서 성장할 수 있도록 최선을 다하겠습니다 | Y40: 김현우 | Z40: 45981 | AA40: 동의함 | AB40: 김현우 | AC40: 45981 | AD40: 동의함
...

Sheet 면접활용시트
B2: 인터뷰 데이터 | J2: 평가 기준
B4: 기본 정보 | J4: 평가자 | M4: 면접의 증빙 자료로 녹화본, 캡처본, 평가표를 작성해야합니다.
B5: 이름 | C5: {=XLOOKUP($F$5,'설문지 응답 시트1'!$B:$B,'설문지 응답 시트1'!$C:$C,,0,-1)} -> #NAME? | E5: 이메일
M6: 드라이브 | N6: https://drive.google.com/drive/folders/1swEGp9Mvwz3dJC394GfFeoHWFPm-j7By?ths=true | Q6: 모집페이지 | R6: adm.develrocket.com
B7: 최종학력 | C7: {=XLOOKUP($F$5,'설문지 응답 시트1'!$B:$B,'설문지 응답 시트1'!$F:$F,,0,-1) & CHAR(10) & XLOOKUP($F$5,'설문지 응답 시트1'!$B:$B,'설문지 응답 시트1'!$H:$H,,0,-1)} -> #NAME? | E7: 성별 | F7: {=XLOOKUP($F$5,'설문지 응답 시트1'!$B:$B,'설문지 응답 시트1'!$D:$D,,0,-1)} -> #NAME? | G7: 나이 | H7: {=XLOOKUP($F$5,'설문지 응답 시트1'!$B:$B,'설문지 응답 시트1'!$E:$E,,0,-1)} -> #NAME? | J7: 질문/안내 리스트
J8: 지원 동기 | K8: - 왜 기획자가 되고 싶은가. ( 게임을 만든다면, 개발자도 있는데 ) + 기획자는 무엇을 하는 사람이라고 생각하는가
K9: - 기획자로서 달성하고 싶은 목표가 있는가
B10: 캠/마이크 보유 | C10: {=XLOOKUP($F$5,'설문지 응답 시트1'!$B:$B,'설문지 응답 시트1'!$N:$N,,0,-1)} -> #NAME? | D10: 지인 중 업계 종사자 | F10: {=XLOOKUP($F$5,'설문지 응답 시트1'!$B:$B,'설문지 응답 시트1'!$V:$V,,0,-1)} -> #NAME? | G10: 추천인 | H10: {=XLOOKUP($F$5,'설문지 응답 시트1'!$B:$B,'설문지 응답 시트1'!$W:$W,,0,-1)} -> #NAME? | J10: 가능성 | K10: - 기획자에게 가장 중요한 것은 무엇이라고 생각하는가
B11: 기타 정보 | K11: - 게임 기획자에게 게임 경험은 재산이다. 어떤 게임을 플레이 해왔는가? 왜 재미있는가?
B12: 지병 / 질환 | D12: {=XLOOKUP($F$5,'설문지 응답 시트1'!$B:$B,'설문지 응답 시트1'!$O:$O,,0,-1)} -> #NAME? | E12: {=XLOOKUP($F$5,'설문지 응답 시트1'!$B:$B,'설문지 응답 시트1'!$P:$P,,0,-1)} -> #NAME? | K12: - 본인의 강점/약점은? 또는 쌓고 싶은 강점은?
J13: 수업 | K13: - 주5일 9 to 6로 진행되는 과정이며, 자신의 성장을 위해서는 추가 시간도 활용하는 것이 유리하다. 수업 진행에 문제는 없는가
B14: 경제적인 어려움 | D14: {=XLOOKUP($F$5,'설문지 응답 시트1'!$B:$B,'설문지 응답 시트1'!$T:$T,,0,-1)} -> #NAME? | E14: {=XLOOKUP($F$5,'설문지 응답 시트1'!$B:$B,'설문지 응답 시트1'!$U:$U,,0,-1)} -> #NAME? | K14: - 기획자는 여러 파트와 협업하고 다른 사람들 앞에서 자신의 생각을 이야기할 수 있어야 한다. 따라서 팀 작업과 발표가 진행되는데 괜찮은가
K15: - 학원에서 MSOffice(워드, 엑셀, PPT) 사용법은 알려주지 않는다. 스스로 학습해야한다
B16: 게임과 관련 학습/업무 경험 | J16: 과정 중 기관과 타 훈련생에게 어려움을 주지 않을 것으로 판단
B17: {=XLOOKUP($F$5,'설문지 응답 시트1'!$B:$B,'설문지 응답 시트1'!$K:$K,,0,-1)} -> #NAME? | J17: 면접에 임하는 태도 | O17: 면접참여시간 준수
J18: 행동, 자세, 표정, 말투(표현), 의사소통, 질문/답변의 진정성 | O18: 면접 참여 시간 및 연락상태
J20: 우수 | K20: 면접 자세가 우수하고 질문/답변이 우수하다 | N20: FALSE | O20: 우수 | P20: 시간 전에 미리 들어와 설정을 마쳤다 | S20: FALSE
J21: 양호 | K21: 면접 자세는 준수하나 답변의 깊이가 얕다 | N21: FALSE | O21: 양호 | P21: 시간에 맞춰서 들어왔다 | S21: FALSE
B22: 기본 소양 | J22: 보통 | K22: 의사소통은 가능하다 | N22: FALSE | O22: 보통 | P22: 5분 미만 지각 | S22: FALSE
B23: 타인과 갈등 속에서 어떻게 대처하는가 | E23: {=XLOOKUP($F$5,'설문지 응답 시트1'!$B:$B,'설문지 응답 시트1'!$Q:$Q,,0,-1)} -> #NAME? | J23: 미흡 | K23: 소통은 가능하나 표현이 거칠고 불량하다 | N23: FALSE | O23: 미흡 | P23: 5분 이상 지각 | S23: FALSE
J24: 긴급 | K24: 의사소통에 어려움이 있다 | N24: FALSE | O24: 긴급 | P24: 연락 두절 | S24: FALSE
B25: 자신의 실수나 실패에 어떻게 대응하는가 | E25: {=XLOOKUP($F$5,'설문지 응답 시트1'!$B:$B,'설문지 응답 시트1'!$R:$R,,0,-1)} -> #NAME? | J25: 직무에 대한 열정
J26: 자기소개 | O26: 신청 이유
B27: 타인의 부족한 부분이 보였을 때는? | E27: {=XLOOKUP($F$5,'설문지 응답 시트1'!$B:$B,'설문지 응답 시트1'!$S:$S,,0,-1)} -> #NAME? | J27: 기획자를 목표하는 자신을 소개, 서류와 다름이 없는지 확인 | O27: 명확한 이유와 그동안의 행동, 서류와 다름이 없는지 확인
B29: 알고있는 취업 분야 | J29: 우수 | K29: 상황에 맞는 자기소개서를 준비해 왔다 | N29: FALSE | O29: 우수 | P29: 명확한 이유와 사전에 쌓아온 행동들이 있다 | S29: FALSE
B30: {=XLOOKUP($F$5,'설문지 응답 시트1'!$B:$B,'설문지 응답 시트1'!$L:$L,,0,-1)} -> #NAME? | J30: 양호 | K30: 상황에 맞게 자신을 소개할 수 있다 | N30: FALSE | O30: 양호 | P30: 명확한 이유는 있으나 행동은 없었다 | S30: FALSE
J31: 보통 | K31: 미흡하지만 상황에 맞는 소개를 했다 | N31: FALSE | O31: 보통 | P31: 추상적이지만 이유가 있다 | S31: FALSE
J32: 미흡 | K32: 유복한 가정에서 1남 1녀 중 첫째로 태어났다 | N32: FALSE | O32: 미흡 | P32: 그냥 한번 배워보자 | S32: FALSE
B33: 소개 | J33: 긴급 | K33: 자기소개를 거부하거나 거짓이 있다 | N33: FALSE | O33: 긴급 | P33: 답변을 거부하거나 이야기에 거짓이 있다 | S33: FALSE
B34: 자기소개 | J34: 수료 후 목표 | O34: 교육과정 참여와 취업에 대한 각오 및 다짐
B35: {=XLOOKUP($F$5,'설문지 응답 시트1'!$B:$B,'설문지 응답 시트1'!$I:$I,,0,-1)} -> #NAME? | J35: 명확한 목표와 계획, 서류와 다름이 없는지 확인 | O35: 수업(9시~6시), 발표, 팀작업, 프로젝트 밤/주말작업 등 가능한지
J37: 우수 | K37: 구체적인 목표와 앞으로의 로드맵이 있다 | N37: FALSE | O37: 우수 | P37: 도전에 긍정적이고 수업 참여 의사가 강하다 | S37: FALSE
J38: 양호 | K38: 추상적이지만 목표가 있고 계획도 있다 | N38: FALSE | O38: 양호 | P38: 힘들겠지만 열심히 해보겠다 | S38: FALSE
J39: 보통 | K39: 추상적이지만 목표는 있다 | N39: FALSE | O39: 보통 | P39: 여건상 추가로 노력하기 어렵다 | S39: FALSE
J40: 미흡 | K40: 배워보면 어떻게든 되겠지... | N40: FALSE | O40: 미흡 | P40: 힘든건 하기 싫고 편하게 듣고 싶다 | S40: FALSE
J41: 긴급 | K41: 답변을 거부하거나 이야기에 거짓이 있다 | N41: FALSE | O41: 긴급 | P41: 답변을 거부하거나 부정적인 태도를 보인다 | S41: FALSE
J42: 수료까지 참여할 수 있는 상황
J43: 지원자가 교육과정을 수행하기 위해 생각한 계획 및 준비 | O43: 지원자가 교육과정에 집중할 수 있도록 하기 위해 공유하고 싶은 사항
B44: 본 과정에 참여를 신청한 이유 | J44: 공부할 환경을 만들었는가 ( 필요한 것, 위험요소의 인지 ) | O44: 지병/경제적 여건, 타업(알바/대학)병행, 주변 가족들의 지지
B45: {=XLOOKUP($F$5,'설문지 응답 시트1'!$B:$B,'설문지 응답 시트1'!$J:$J,,0,-1)} -> #NAME?
...

Sheet 면접 결과 관리
B2: ▶ 면접 결과 리스트
B4: 점수 | K4: 나이 | T4: 성별 | X4: 학력 | AB4: 상황 | AF4: 결과
B5: A | C5: 91~100 | E5: 우수한 인원 | H5: =COUNTIFS($L$11:$L$210,">90",$M$11:$M$210,"합격") -> 12 | I5: =H5/$AH$7 -> 0.15 | K5: A | L5: 00년생 이하 | N5: 나이가 문제는 안 됨 | Q5: {=SUMPRODUCT(COUNTIFS($F11:$F210, "*0" & {0,1,2,3,4,5,6} & "*",$M$11:$M$210,"합격"))} -> 28 | R5: =Q5/$AH$7 -> 0.35 | T5: 남 | U5: =COUNTIFS($E$11:$E$210,T5,$M$11:$M$210,"합격") -> 68 | V5: =U5/$AH$7 -> 0.85 | X5: 대학 | Y5: =SUMPRODUCT(COUNTIFS($H11:$H210, "*대*",$M$11:$M$210,"합격")) -> 64 | Z5: =Y5/$AH$7 -> 0.8 | AB5: 지병 | AC5: =COUNTIFS($O$11:$O$210,"O",$P$11:$P$210,"X",$M$11:$M$210,"합격") -> 0 | AD5: =AC5/$AH$7 -> 0 | AF5: 총원 | AH5: =COUNTA(M11:M210) -> 112
B6: B | C6: 81~90 | E6: 양호한 인원 | H6: =COUNTIFS($L$11:$L$210,">80",$L$11:$L$210,"<=90",$M$11:$M$210,"합격") -> 32 | I6: =H6/$AH$7 -> 0.4 | K6: B | L6: 97~99년생 | N6: 기본 역량이 있다면 가능 | Q6: {=SUMPRODUCT(COUNTIFS($F11:$F210, "*" & {97,98,99} & "*",$M$11:$M$210,"합격"))} -> 26 | R6: =Q6/$AH$7 -> 0.325 | AB6: 경제 | AC6: =COUNTIFS($O$11:$O$210,"X",$P$11:$P$210,"O",$M$11:$M$210,"합격") -> 0 | AD6: =AC6/$AH$7 -> 0 | AF6: 불합/이탈/보류 | AH6: =AH5-AH7 -> 32
B7: C | C7: 71~80 | E7: 역량도 문제도 없는 인원 | H7: =COUNTIFS($L$11:$L$210,">70",$L$11:$L$210,"<=80",$M$11:$M$210,"합격") -> 19 | I7: =H7/$AH$7 -> 0.2375 | K7: C | L7: 94~96년생 | N7: 반에서 상위권은 찍어야 함 | Q7: {=SUMPRODUCT(COUNTIFS($F11:$F210, "*" & {94,95,96} & "*",$M$11:$M$210,"합격"))} -> 8 | R7: =Q7/$AH$7 -> 0.1 | T7: 여 | U7: =COUNTIFS($E$11:$E$210,T7,$M$11:$M$210,"합격") -> 12 | V7: =U7/$AH$7 -> 0.15 | X7: 고졸 | Y7: =AH7-Y5 -> 16 | Z7: =Y7/$AH$7 -> 0.2 | AB7: 둘다 | AC7: =COUNTIFS($O$11:$O$210,"O",$P$11:$P$210,"O",$M$11:$M$210,"합격") -> 0 | AD7: =AC7/$AH$7 -> 0 | AF7: 합격 | AH7: =COUNTIF(M11:M210,"합격") -> 80
B8: D | C8: 70점 이하 | E8: 주의가 필요한 인원 | H8: =COUNTIFS($L$11:$L$210,"<=70",$M$11:$M$210,"합격") -> 17 | I8: =H8/$AH$7 -> 0.2125 | K8: D | L8: 93년생 이상 | N8: 남들보다 3배는 해야함 | Q8: =AH7-SUM(Q5:Q7) -> 18 | R8: =Q8/$AH$7 -> 0.225 | AB8: 계 | AC8: =SUM(AC5:AC7) -> 0 | AD8: =AC8/$AH$7 -> 0
B10: 번호 | C10: 이름 | E10: 성별 | F10: 나이 | H10: 학력 | L10: 점수 | M10: 결과 | R10: 총평 | AD10: 면접자 | AF10: 면접일 | AH10: 평가지 링크
B11: =IF(B9<201,B9+1,1) -> 1 | C11: 장호윤 | E11: =IFERROR(VLOOKUP(C11,'설문지 응답 시트1'!C:H,2,FALSE),"") -> 남 | F11: =IFERROR(VLOOKUP(C11,'설문지 응답 시트1'!C:H,3,FALSE),"") -> 27살(99년생) | H11: =IFERROR(VLOOKUP(C11,'설문지 응답 시트1'!C:H,6,FALSE),"") -> 상하이교통대 신문방송학과 | L11: 87 | M11: 합격 | R11: RPG 계열의 게임을 좋아하며, 마인크래프트를 좋아한다고 합니다. 모바일 게임은 많이 즐기지는 않으며, 신작이 나오면 해보는 정도라고 합니다. 나중에는 개발도 배워서 1인 개발도 해보고 싶다고 합니다. 모바일 게임 회사에서 1년반 QA(테스터) 업무를 진행한 경험이 있어, 업무 프로세스에 대한 이해는 어느정도 있을 것으로 보입니다. 9-6 수업을 진행하는 것에는 문제될 부분은 없을 것으로 보이며, 팀 실습과 발표에 대한 거부감도 없다고 합니다. QA로서의 강점도 있고 면접 분위기에서도 크게 문제될 부분은 없었습니다. | AD11: 안중재 | AF11: 45943 | AH11: https://docs.google.com/spreadsheets/d/1XbM7ecV-SXzNNru2i-Pxd4qyOSW2Nntm8fq77D0vVaQ/edit
B12: =IF(B11<201,B11+1,1) -> 2 | C12: 강준호 | E12: =IFERROR(VLOOKUP(C12,'설문지 응답 시트1'!C:H,2,FALSE),"") -> 남 | F12: =IFERROR(VLOOKUP(C12,'설문지 응답 시트1'!C:H,3,FALSE),"") -> 25살 (01년생) | H12: =IFERROR(VLOOKUP(C12,'설문지 응답 시트1'!C:H,6,FALSE),"") -> 숭실대학교 심리학과 | L12: 62 | M12: 이탈 | R12: 결벽증이 많이 심하여 사회 활동에 어려움이 있다고 합니다. 청소한 공간에 대하여 가족들을 통제하고 밖에서 사용한 물건은 집에 들여보내지 않는다고 합니다. 어쩔 수 없이 들여보내야하는 핸드폰은 방수 케이스를 사용하여 비누로 씻어서 사용한다고 합니다. 결벽증으로 아르바이트를 해본적이 없으며, 취업도 재택근무나 출근일이 적은 회사를 가고 싶다고 합니다. 게임 기획자로서의 마인드나 게임 경험은 나쁘지 않으며, 소통을 함에 있어서는 문제는 없었습니다. 로드오브히어로즈를 오픈부터 쭉 플레이해오고 있어서 클로버게임즈에 가고 싶다고 합니다. 아침에 잘 일어나지 못하는 부분이 걱정이라고 합니다. | AD12: 안중재 | AF12: 45943 | AH12: https://docs.google.com/spreadsheets/d/1vxEWjXJWW-Zst5wQnpO-gSGUbzGiNOYV_jVX9-0pmkI/edit
B13: =IF(B12<201,B12+1,1) -> 3 | C13: 이형진 | E13: =IFERROR(VLOOKUP(C13,'설문지 응답 시트1'!C:H,2,FALSE),"") -> 남 | F13: =IFERROR(VLOOKUP(C13,'설문지 응답 시트1'!C:H,3,FALSE),"") -> 23(02년생) | H13: =IFERROR(VLOOKUP(C13,'설문지 응답 시트1'!C:H,6,FALSE),"") -> 상지대학교 문화콘텐츠학과 | L13: 88 | M13: 합격 | R13: 독학으로 언리얼,유니티 무료과정 수강 및 쯔꾸르 개발 경험이 있습니다. 게임은 다양하게 즐기며 PC/모바일/콘솔 가리지 않고 다 하는 스타일입니다. 롤모델로는 김용하PD 라고 하며 서브컬쳐에 대한 이해도가 높은 인원입니다. 9-6 수업을 진행하는 것에는 문제될 부분은 없을 것으로 보이며, 팀 실습과 발표에 대한 거부감도 없다고 합니다. 특히 프로그래밍의 중요성을 인지하고 있고 기획을 더 잘하기위해 수료 이후에 시간이 나면 플밍 공부도 진행한다고 합니다. | AD13: 양윤석 | AF13: 45945 | AH13: https://docs.google.com/spreadsheets/d/1q4FYjg9ceV0oVeHjQ-rtCiXI_7Z9lDQueFWpqwZwjTU/edit
B14: =IF(B13<201,B13+1,1) -> 4 | C14: 유해찬 | E14: =IFERROR(VLOOKUP(C14,'설문지 응답 시트1'!C:H,2,FALSE),"") -> 남 | F14: =IFERROR(VLOOKUP(C14,'설문지 응답 시트1'!C:H,3,FALSE),"") -> 27살(99년생) | H14: =IFERROR(VLOOKUP(C14,'설문지 응답 시트1'!C:H,6,FALSE),"") -> 한국방송통신대학교 . 컴퓨터과학과 | L14: 88 | M14: 합격 | R14: [화상 인터뷰 합격] 게임을 만들고 싶은 목적에 개발자를 먼저 시작하게 되었다고 합니다. 이전 회사에서 개발자로서 업무를 진행했으나 기획자(대표)의 요구사항이 명확하지 않아, 기획의 중요성을 깨닫게 되었다고 합니다. 이후 게임을 만들고자 하는 목표에 독학을 해보았으나 기획자 교육을 받아야 겠다고 생각이 들었다고 합니다. ('대표님 고개 못들게 할랍니다'라는 목표는 퇴사 후 대표님이 자신을 험담하는 것을 전해들어, 유명해지고 싶다고 합니다.) 아직 어떤 기획자가 되고 싶다는 명확한 목표는 없어 고민이라고 합니다. 자신의 강점을 살릴 수 있는 부분으로 강화하는 것을 추천해주었습니다. 과정 진행에 문제될 부분은 없어 보이며, 개발적 사고의 강점이 있을 것 같습니다. | AD14: 안중재 | AF14: 45945 | AH14: https://docs.google.com/spreadsheets/d/1hiMmOBWW7mVmAXYVLhpNFbcHWqCPKLsVNZr1EZWrCic/edit
B15: =IF(B14<201,B14+1,1) -> 5 | C15: 신유진 | E15: =IFERROR(VLOOKUP(C15,'설문지 응답 시트1'!C:H,2,FALSE),"") -> 남 | F15: =IFERROR(VLOOKUP(C15,'설문지 응답 시트1'!C:H,3,FALSE),"") -> 만23세 (01년생) | H15: =IFERROR(VLOOKUP(C15,'설문지 응답 시트1'!C:H,6,FALSE),"") -> 경희대/연극영화,디지털콘텐츠학 | L15: 69 | M15: 불합격 | R15: [화상 인터뷰 불합격] 이전 회사에서 2달정도 다니다가 굳이 내가 일 할 이유가 없을 것 같다고 하여 나왔다고 합니다. 공채도 합격했었었고 다니면서 이직 준비를 하는 것이 쉽지 않아서 퇴사를 했다고 합니다. AI를 활용해서 간단하게 게임도 만들어보고 했고 취업 경험도 있어 강점은 있습니다. 하지만 현재 취업 활동을 진행하고 있고, 이번 교육 커리큘럼에서 AI 활용에 목적으로 두고 있어 교육 과정에는 적합하지 않음을 이야기했습니다. 결과적으로 수강을 희망하지 않는 방향으로 이야기를 마무리하였습니다. | AD15: 안중재 | AF15: 45946 | AH15: https://docs.google.com/spreadsheets/d/1NGc_FoIKpAgiz-1WVy0kVuLzM5Z6gAphngIhbLy8-QE/edit
B16: =IF(B15<201,B15+1,1) -> 6 | C16: 오동건 | E16: =IFERROR(VLOOKUP(C16,'설문지 응답 시트1'!C:H,2,FALSE),"") -> 남 | F16: =IFERROR(VLOOKUP(C16,'설문지 응답 시트1'!C:H,3,FALSE),"") -> 24살(01년생) | H16: =IFERROR(VLOOKUP(C16,'설문지 응답 시트1'!C:H,6,FALSE),"") -> 전주대 물리치료학과 | L16: 76 | M16: 합격 | R16: 자기소개중 학과 고민도 있었다길래 전주대에 게임학과 편입 고려해봤는지 질문했는데 학과가 있는지 방금 알았다고합니다(?) 게임 플레이는 다양하게 해보았고 최근 명조를 즐겨하고 있다고 합니다. 태도나 마인드셋은 건전하고 협업에도 문제가 없을것 같습니다. 대출 관련 이야기도 필요시 내용이며 일반적으론 크게 학업에 지장이 가지 않는 내용이라고 합니다. 우려되었던 시나리오는 1지망일뿐이고 신입은 테이블 작업하는걸 알고있다고 합니다. 시나리오가 아니여도 게임 업계에 취업하고자 하는 의지가 강합니다. | AD16: 양윤석 | AF16: 45946 | AH16: https://docs.google.com/spreadsheets/d/1KMXeR-zSPK6rQp9BHqyfVfWmD_1DBwpC4OksiuXRZ6s/edit
B17: =IF(B16<201,B16+1,1) -> 7 | C17: 강나영 | E17: =IFERROR(VLOOKUP(C17,'설문지 응답 시트1'!C:H,2,FALSE),"") -> 여 | F17: =IFERROR(VLOOKUP(C17,'설문지 응답 시트1'!C:H,3,FALSE),"") -> 26살(00년생) | H17: =IFERROR(VLOOKUP(C17,'설문지 응답 시트1'!C:H,6,FALSE),"") -> 한양대학교 경영학과 | L17: 80 | M17: 이탈 | R17: 새로운 아이디어로 게임의 규칙을 만드는 것에 흥미가 생겨서 과정을 신청했다고 합니다. 게임은 PC플랫폼 위주로 RPG(로스트아크) FPS(에이펙스), 생존시뮬레이션(굶지마)를 대표적으로 이야기했습니다. 아직 기획자로서 자신의 목표나 강점은 찾지 못한 상태로 보입니다. 과정 진행하는 것에 있어서 9to6 또는 주말 학습에 대하여 문제될 부분은 없다고 합니다. 팀 작업과 발표에 대해서도 문제는 없다고 합니다. 좋게 이야기하면 차분한 성격으로 보이나, 적극적으로 자신의 생각을 보여주는 부분에 대해서는 걱정이 되기도 합니다. 과정 진행에는 큰 문제는 없을 것으로 판단됩니다. | AD17: 안중재 | AF17: 45947 | AH17: https://docs.google.com/spreadsheets/d/1BzAcjYR0MyH6RMA7mOyhN2rOxDBEwYy7_V4VefG7OWw/edit
B18: =IF(B17<201,B17+1,1) -> 8 | C18: 유수환 | E18: =IFERROR(VLOOKUP(C18,'설문지 응답 시트1'!C:H,2,FALSE),"") -> 남 | F18: =IFERROR(VLOOKUP(C18,'설문지 응답 시트1'!C:H,3,FALSE),"") -> 31살(95년생) | H18: =IFERROR(VLOOKUP(C18,'설문지 응답 시트1'!C:H,6,FALSE),"") -> 건국대학교 경영학과 | L18: 93 | M18: 이탈 | R18: 3년간 마케팅업무를 진행하면서 게임에 대해서 시야를 넓혀왔습니다 콘솔, PC, 모바일 게임의 다양한 플랫폼과 캐주얼장르의 게임도 즐겨했으며, 현재 BM에 대해 살펴보기 위해 리니지M을 해보고 있다고 합니다. 서로 발전적인 관계를 이어가는 것이 부트캠프의 강점이라 생각하고 있어 기대되는 인원입니다. 열심히 하려는 인원으로서 미진자와의 협업에서 어떻게 반응할지 지켜봐야겠으나, 현 시점에서는 강점도 뚜렷하며 목표도 있어 우수하다고 평가됩니다. | AD18: 안중재 | AF18: 45947 | AH18: https://docs.google.com/spreadsheets/d/13Zp2sgUMiByAHJqrDCeftjYOpuhpcl2sHImbJrDR-Ks/edit
B19: =IF(B18<201,B18+1,1) -> 9 | C19: 고승주 | E19: =IFERROR(VLOOKUP(C19,'설문지 응답 시트1'!C:H,2,FALSE),"") -> 남 | F19: =IFERROR(VLOOKUP(C19,'설문지 응답 시트1'!C:H,3,FALSE),"") -> 30살(96년생) | H19: =IFERROR(VLOOKUP(C19,'설문지 응답 시트1'!C:H,6,FALSE),"") -> 서울시립대학교(국어국문학, 도시문화컨텐츠학) | L19: 85 | M19: 합격 | R19: 면접 10분전에 들어와서 준비하고 있었습니다. 2년동안 영업직 업무를 보다가 반복되는 업무에 성장을 느끼지 못했고, 게임을 만들고 싶다는 꿈을 찾아 왔다고 합니다. 기획에 대해서 아직 알고 있는 부분은 없으나, 수업을 들을 수 있는 주변 환경과 개강까지 어떤 것을 준비해야할지 적극적으로 물어보는 부분이 있었습니다. 문화컨텐츠학과와 영업직 경험을 강점으로 살릴 수 있는 방향으로 지도해도 좋을 것 같아 보입니다. 수업을 참여하는 것에는 문제될 부분은 없어보입니다. | AD19: 안중재 | AF19: 45947 | AH19: https://docs.google.com/spreadsheets/d/1wIOl7Z1EMdeHuG7pQ2mFzN0f515zOaS4weqGixOLH40/edit
B20: =IF(B19<201,B19+1,1) -> 10 | C20: 김종우 | E20: =IFERROR(VLOOKUP(C20,'설문지 응답 시트1'!C:H,2,FALSE),"") -> 남 | F20: =IFERROR(VLOOKUP(C20,'설문지 응답 시트1'!C:H,3,FALSE),"") -> 35살(91년생) | H20: =IFERROR(VLOOKUP(C20,'설문지 응답 시트1'!C:H,6,FALSE),"") -> 부산대학교 경영학 재무관리 | L20: 67 | M20: 이탈 | R20: 광고 대행, 출판, 앱 개발(신문을 앱에 띄우는 것)의 창업을 진행했다고 합니다. 현재 창업에 실패하여 부채를 갚아가고 있다고 합니다. 과정 진행에 문제는 없는가에 대하여 해결해야하는 부분이니 문제는 없다고 합니다. 게임은 좋아하나 기획자가 게임 플레이를 많이 해봐야 하는 것에 대한 의문이 있어보이며, 과정의 이탈률, 과정 개설의 연기에 대해서 질문이 있었습니다. 부채를 갚고 있는 상황과 본인의 생각이 견고하고 불신이 있어 보이는 부분이 걱정되나, 면접에서 탈락 사유까지 도달한 사유는 없었습니다. | AD20: 안중재 | AF20: 45950 | AH20: https://docs.google.com/spreadsheets/d/1vac2r6mqga8cy9EcVLbYCSiZ82tNo82KidHSFgIPASo/edit
B21: =IF(B20<201,B20+1,1) -> 11 | C21: 채지형 | E21: =IFERROR(VLOOKUP(C21,'설문지 응답 시트1'!C:H,2,FALSE),"") -> 남 | F21: =IFERROR(VLOOKUP(C21,'설문지 응답 시트1'!C:H,3,FALSE),"") -> 28살(98년생) | H21: =IFERROR(VLOOKUP(C21,'설문지 응답 시트1'!C:H,6,FALSE),"") -> 홍익대학교 게임소프트웨 | L21: 67 | M21: 합격 | R21: 소프트웨어 학 졸업예정생입니다. 기획 배우고 싶은데 마땅히 못찾아서 개발 배우면 뭐라도 알려주겠지 하면서 시작했다고 합니다. 성실하진 않지만 의사소통에 문제는 없습니다. 요즘하는게임은 배그,로아 게임은 다양하게 하려고 노력하는편 모바일은 하지 않습니다. 게임 기획자가 되고싶었던 게임이 블소이며 가고싶은 회사는 시프트업이라고 합니다.(롤모델 김형태) 전형적인 노베이스 인원이라 과정 진행중 잘 주입하면 되지않을까 생각됩니다. | AD21: 양윤석 | AF21: 45950 | AH21: https://docs.google.com/spreadsheets/d/1YHSrraEgKKkcoTV0j9OSgGJYL4viSEsy5KWo-lGuwhg/edit
