Workbook

Sheet 시트3
D2: https://www.ggemguide.com/mobile_list.htm
D3: 게임 추천 목록 | E3: 선정게임 | F3: 사용기기 | G3: 구간 | H3: 맵 | I3: 레벨 | J3: 스토리, 퀘스트 | K3: 등장 몬스터 | L3: 획득 아이템 | M3: 콘텐츠 오픈 | N3: 플레이 타임 | O3: 기타 | P3: 10분 경과
C4: 장윤우 | D4: 운빨 존많겜, 킹샷 | E4: 기어작동 | F4: Android | G4: 7스태이지 | H4: 7스태이지 마지막 보스 | I4: 플레이어 레벨 4 | N4: 전투, 임무, 패스 , vip상점, 기물 뽑기, 기어 뽑기유닛 강화 | O4: 1시간
C6: 김경민 | F6: Iphon | G6: 10스테이지 | I6: 플레이어 레벨 8
C8: 박원우
C10: 이준혁 | D10: 블루 프로토콜 스타 레조넌스 | F10: PC | G10: 7스테이지 | H10: 7스테이지 마지막 보스 | I10: 플레이어 레벨 4
D11: 기어 작동 최후의 요새
C12: 정재용 | D12: 궁수의 전설 2 | F12: IPAD | G12: 7 스테이지 | H12: 7스테이지 보스 직전 | I12: 4
D13: 운빨 디펜스 101 : 메운디
C14: 김서현 | D14: 드래곤플라이트2
D15: 라스트워: 서바이벌
C16: 이석훈

Sheet 개요
B3: 게임 명
B4: 기어 작동: 최후의 요새-Gear Defenders
B6: 조 이름
B7: 한조... 대기중...
B9: 조장
B10: 정재용 님
B12: 영상 공유
B13: https://youtu.be/BWbDnYRmNzk?si=mTDyEoPmjZmprBec

Sheet 합본
B2: 플레이어 | C2: 사용 기기 | G2: 몬스터 명칭 | H2: 일부 인원 획득 아이템 생략
B3: 김경민 | C3: IOS / 아이폰 15 pro max | G3: 보병, 중갑, 원거리, 기병, 보스, 대왕 | H3: 경험치, 골드, 젬
B5: 플레이 타임 | C5: 레벨 | D5: 스테이지 | E5: 차례 | F5: 경민 (광고 1회) | G5: 등장 몬스터 | H5: 획득 아이템 | I5: 콘텐츠 오픈 | J5: 광고 시청 누적수
B6: 10분 | C6: 2 | D6: 3 | E6: 1 | F6: =D6 + (E6 * 0.1) -> 3.1 | G6: 고블린 궁병, 고블린 기병 | H6: 경험치, 골드, 잼 // 골드, 병사 재료, 경기병 기어 | I6: 한정 버프 | J6: 1
B7: 20분 | C7: 3 | D7: 4 | E7: 7 | F7: =D7 + (E7 * 0.1) -> 4.7 | G7: 고블린 궁병, 고블린 보병, 고블린 보스 | H7: 경험치, 골드, 잼 // 골드, 병사 재료 | I7: 임무 | J7: 1
B8: 30분 | C8: 3 | D8: 5 | E8: 7 | F8: =D8 + (E8 * 0.1) -> 5.7 | G8: 고블린 궁병, 고블린 방패병, 고블린 기마병, 고블린 보스 | H8: 경험치, 골드, 잼 // 골드, 병사 재료 | I8: 랭킹 | J8: 1
B9: 40분 | C9: 3 | D9: 6 | E9: 10 | F9: =D9 + (E9 * 0.1) -> 7 | G9: 고블린 궁병, 고블린 방패병, 고블린 도끼병, 고블린 보스 | H9: 경험치, 골드, 잼 // 골드, 병사 재료, 방패병 기어, 코인 기어 | I9: x | J9: 1
B10: 50분 | C10: 4 | D10: 7 | E10: 11 | F10: =D10 + (E10 * 0.1) -> 8.1 | G10: 고블린 궁병, 고블린 도끼병, 고블린 기마병, 고블린 보스 | H10: 경험치, 골드, 잼 // 골드, 병사 재료, 성벽 석재 | I10: x | J10: 1
B12: 플레이어 | C12: 사용 기기 | E12: 영상 공유
B13: 김서현 | C13: iOS / 아이폰 12 mini | E13: https://youtu.be/BWbDnYRmNzk?si=mTDyEoPmjZmprBec | H13: 라이거, 수달, 웜뱃
B15: 플레이 타임 | C15: 레벨 | D15: 스테이지 | E15: 차례 | F15: 서현 ( 광고 12회 ) | G15: 등장 몬스터 | H15: 획득 아이템 | I15: 콘텐츠 오픈 | J15: 광고 시청 누적수
B16: 10분 | C16: 1 | D16: 2 | E16: 2 | F16: =D16 + (E16 * 0.1) -> 2.2 | G16: 보병, 궁수, 보스 | H16: 전사 기어, 궁수 기어 | I16: 진영, 점성술, 기어 강화 | J16: =1+1 -> 2
B17: 20분 | C17: 2 | D17: 3 | E17: 3 | F17: =D17 + (E17 * 0.1) -> 3.3 | G17: 보병, 궁수, 보스 | H17: 창병 기어, 방패 기어 | I17: - | J17: 4
B18: 30분 | C18: 2 | D18: 4 | E18: 4 | F18: =D18 + (E18 * 0.1) -> 4.4 | G18: 보병, 궁수 | H18: 성기사 기어, 경기병 기어 | I18: 한정 버프, 1.5배속 | J18: 6
B19: 40분 | C19: 2 | D19: 5 | E19: 5 | F19: =D19 + (E19 * 0.1) -> 5.5 | G19: 보병, 궁수, 보스 | H19: 성벽 수리 기어 | I19: 그림자 숲 맵, 임무, 첫 충전 보상 | J19: 10
B20: 50분 | C20: 2 | D20: 6 | E20: 6 | F20: =D20 + (E20 * 0.1) -> 6.6 | G20: 기병, 궁수, 대왕 | H20: 강화 기어 | I20: 랭킹 | J20: 12
B22: 플레이어 | C22: 사용 기기
B23: 박원우 | C23: 갤럭시
B25: 플레이 타임 | C25: 레벨 | D25: 스테이지 | E25: 차례 | F25: 원우 (광고 0회) | G25: 등장 몬스터 | H25: 획득 아이템 | I25: 콘텐츠 오픈 | J25: 광고 시청 누적수 | K25: 기타
B26: 10분 | C26: 2 | D26: 2 | E26: 1 | F26: =D26 + (E26 * 0.1) -> 2.1 | G26: 고블린 궁병, 고블린 전사, 고블린 보스 | H26: 경험치, 골드, 젬, 궁수 기어 | I26: 진영, 점성술, 기어강화 | J26: 0
B27: 20분 | C27: 2 | D27: 4 | E27: 2 | F27: =D27 + (E27 * 0.1) -> 4.2 | G27: 고블린 궁병, 고블린 전사, 고블린 기마병, 고블린 보스 | H27: 경험치, 골드, 젬, 경기병기어, 쉴드 기어 | I27: 한정버프, 배속 진영 캐릭터 해금 | J27: 0 | K27: 배속
B28: 30분 | C28: 3 | D28: 5 | E28: 3 | F28: =D28 + (E28 * 0.1) -> 5.3 | G28: 고블린 궁병, 고블린 방패병, 고블린 기마병, 고블린 보스 | H28: 경험치, 골드, 젬 | I28: 랭킹, 상점패키지 | J28: 0 | K28: 클리어 실패시 리스크 확인
B29: 40분 | C29: 4 | D29: 6 | E29: 7 | F29: =D29 + (E29 * 0.1) -> 6.7 | G29: 고블린 궁병, 고블린 방패병, 고블린 도끼병 고블린 기마병, 고블린 보스 | H29: 경험치, 골드, 젬 | I29: 패스, VIP | J29: 0 | K29: 기본적으로 주는 기어만으로 스테이지 도전
B30: 50분 | C30: 4 | D30: 7 | E30: 4 | F30: =D30 + (E30 * 0.1) -> 7.4 | G30: 고블린 궁병, 고블린 방패병, 고블린 도끼병 고블린 기마병, 고블린 보스, 대왕고블린 | H30: 경험치, 골드, 젬 | J30: 0 | K30: 기어 강화후 재도전
B32: 플레이어 | C32: 사용 기기
B33: 장윤우 | C33: Android / 갤럭시 z 플립 3
B35: 플레이 타임 | C35: 레벨 | D35: 스테이지 | E35: 차례 | F35: 윤우 (광고 0회) | G35: 등장 몬스터 | H35: 획득 아이템 | I35: 콘텐츠 오픈 | J35: 광고 시청 누적수 | K35: 기타
B36: 10분 | C36: 2 | D36: 3 | E36: 2 | F36: =D36 + (E36 * 0.1) -> 3.2 | G36: 고블린 궁수, 고블린 전사 | H36: 젬, 골드, 쉴드 기어, 전사 기어, 궁수 기어 | I36: 전투, 진영(기물 강화), 기물 뽑기, 기어뽑기, 상점 | J36: 1
B37: 20분 | C37: 3 | D37: 4 | E37: 8 | F37: =D37 + (E37 * 0.1) -> 4.8 | G37: 고블린 궁수, 고블린 전사, 고블린 기병, 보스 고블린 | H37: 경기병 기어, 쉴드 기어, 동전 기어 ,성벽 수리 | I37: 한정 버프, 1.5배속 | J37: 2 | K37: 첫 충전 보상 팝업 패키지
B38: 30분 | C38: 3 | D38: 5 | E38: 1 | F38: =D38 + (E38 * 0.1) -> 5.1 | G38: 고블린 궁수, 고블린 전사 고블린 기병, 보스 고블린 | I38: 임무 | J38: 4
B39: 40분 | C39: 4 | D39: 5 | E39: 9 | F39: =D39 + (E39 * 0.1) -> 5.9 | G39: 고블린 궁수, 고블린 전사, 고블린 방패병, 고블린 기병, 고블린 도끼병, 보스 고블린 | H39: 방패병 기어 | I39: 랭킹 | J39: 6
B40: 50분 | C40: 4 | D40: 7 | E40: 6 | F40: =D40 + (E40 * 0.1) -> 7.6 | G40: 고블린 궁수, 고블린 전사, 고블린 방패병, 고블린 기병, 고블린 도끼병, 보스 고블린 | I40: 패스 | J40: 7 | K40: 컨텐츠마다 광고시간이 다르다!
B42: 플레이어 | C42: 사용 기기
B43: 이준혁 | C43: PC
B45: 플레이 타임 | C45: 레벨 | D45: 스테이지 | E45: 차례 | F45: 준혁 (광고 7회) | G45: 등장 몬스터 | H45: 획득 아이템 | I45: 콘텐츠 오픈 | J45: 광고 시청 누적수 | K45: 기타
B46: 10분 | C46: 1 | D46: 2 | E46: 1 | F46: =D46 + (E46 * 0.1) -> 2.1 | G46: 보병, 궁병, 중간보스 | H46: 경험치, 골드, 젬, 병사 재료(파랑), 전사 기어, 전사 기어2, 궁수 기어, 일반 기어, 일반 기어2, 성벽 수리 | I46: 전투, 상점, 강화재 가챠, 아군 강화 | J46: 1 | K46: 진행 중, 광고 잘못 걸려서 한참 헤멤
B47: 20분 | C47: 2 | D47: 3 | E47: 7 | F47: =D47 + (E47 * 0.1) -> 3.7 | G47: 보병, 궁병, 기병, 중간보스 | H47: 기어 티켓, 생산 기어(기능 기어) | I47: - | J47: 2 | K47: 스테이지 클리어 후, 광고 잘못걸려서 시간 버림
B48: 30분 | C48: 3 | D48: 5 | E48: 1 | F48: =D48 + (E48 * 0.1) -> 5.1 | G48: 보병, 궁병, 기병, 중간보스 | H48: 경기병 기어, 궁수 기어 2, 병사 재료(노랑), 10포인트 체력, 성벽 수리 기어 | I48: 한정버프(동력 증가, 코인 증가, 성 HP증가), 전투 배속 | J48: 3 | K48: 닭다리 기어, 코인 기어
B49: 40분 | C49: 3 | D49: 5 | E49: 9 | F49: =D49 + (E49 * 0.1) -> 5.9 | G49: 보병, 궁병, 기병, 방패병, 중간보스 | H49: 경기병 기어 2, 궁수 기어 3, 일반 기어 3 | J49: 4 | K49: 광고
B50: 50분 | C50: 4 | D50: 7 | E50: 11 | F50: =D50 + (E50 * 0.1) -> 8.1 | G50: 보스 | H50: 초급 병사 패키지(무료), 궁수 개체 강화, 보병 기어3, 무료 패스, 마법 기어(무료패스 포함 아이템) | I50: 패스, VIP, 랭킹 | J50: 7 | K50: 광고 - 배속 광고 - 성벽 수리 광고 - 노수2 기어
...

Sheet 평균결론
B2: 플레이 타임 | C2: 레벨 | D2: 도달 스테이지 | E2: 광고 시청 누적수 | G2: 스테이지 지표
B3: 10분 | C3: =AVERAGE('합본'!C6,'합본'!C16,'합본'!C26,'합본'!C36,'합본'!C46,'합본'!C56) -> 1.6666667 | D3: =AVERAGE('합본'!D6,'합본'!D16,'합본'!D26,'합본'!D36,'합본'!D46,'합본'!D56) -> 2.5 | E3: =AVERAGE('합본'!J6,'합본'!J16,'합본'!J26,'합본'!J36,'합본'!J56) -> 0.8 | G3: =AVERAGE('합본'!F6,'합본'!F16,'합본'!F26,'합본'!F36,'합본'!F46,'합본'!F56) -> 2.6833333
B4: 20분 | C4: =AVERAGE('합본'!C7,'합본'!C17,'합본'!C27,'합본'!C37,'합본'!C47,'합본'!C57) -> 2.5 | D4: =AVERAGE('합본'!D7,'합본'!D17,'합본'!D27,'합본'!D37,'합본'!D47,'합본'!D57) -> 3.8333333 | E4: =AVERAGE('합본'!J7,'합본'!J17,'합본'!J27,'합본'!J37,'합본'!J57) -> 1.4 | G4: =AVERAGE('합본'!F7,'합본'!F17,'합본'!F27,'합본'!F37,'합본'!F47,'합본'!F57) -> 4.3
B5: 30분 | C5: =AVERAGE('합본'!C8,'합본'!C18,'합본'!C28,'합본'!C38,'합본'!C48,'합본'!C58) -> 2.8333333 | D5: =AVERAGE('합본'!D8,'합본'!D18,'합본'!D28,'합본'!D38,'합본'!D48,'합본'!D58) -> 5 | E5: =AVERAGE('합본'!J8,'합본'!J18,'합본'!J28,'합본'!J38,'합본'!J58) -> 2.2 | G5: =AVERAGE('합본'!F8,'합본'!F18,'합본'!F28,'합본'!F38,'합본'!F48,'합본'!F58) -> 5.3333333
B6: 40분 | C6: =AVERAGE('합본'!C9,'합본'!C19,'합본'!C29,'합본'!C39,'합본'!C49,'합본'!C59) -> 3.3333333 | D6: =AVERAGE('합본'!D9,'합본'!D19,'합본'!D29,'합본'!D39,'합본'!D49,'합본'!D59) -> 5.6666667 | E6: =AVERAGE('합본'!J9,'합본'!J19,'합본'!J29,'합본'!J39,'합본'!J59) -> 3.4 | G6: =AVERAGE('합본'!F9,'합본'!F19,'합본'!F29,'합본'!F39,'합본'!F49,'합본'!F59) -> 6.4166667
B7: 50분 | C7: =AVERAGE('합본'!C10,'합본'!C20,'합본'!C30,'합본'!C40,'합본'!C50,'합본'!C60) -> 3.6666667 | D7: =AVERAGE('합본'!D10,'합본'!D20,'합본'!D30,'합본'!D40,'합본'!D50,'합본'!D60) -> 6.8333333 | E7: =AVERAGE('합본'!J10,'합본'!J20,'합본'!J30,'합본'!J40,'합본'!J60) -> 4 | G7: =AVERAGE('합본'!F10,'합본'!F20,'합본'!F30,'합본'!F40,'합본'!F50,'합본'!F60) -> 7.6166667
B9: 가장 큰 영향 | C9: 결론 | G9: 가장 많이 보인 패턴
B10: 광고 시청 | C10: 평균보다 광고 시청이 많을 수록 진행이 더뎠다. 광고를 통해 레벨디자인을 극복하는 부분또한 존재하였다. | G10: 광고 미시청 | H10: 매 판마다 좋은 캐릭터를 인질로 삼았어요!
B12: 조원 | C12: 후기 | G12: 한조 대기중 총평
B13: 김경민 님 | C13: 흔한 스테이지형 캐주얼에 기어시스템을 가미한 게임. 광고 노출이 너무 잦고 과금 상품들이 비일관적이고 과금 타겟이 플레이 타임이 짧은 플레이어들에 초점이 맞춰져있다. | G13: ● 게임 구성 요소 긍정적 ● 광고를 본 쪽은 난이도가 좀 낮게 느껴지며 보지 않은 사람들은 난이도가 좀 높게 느껴진다 → 무과금은 광고를 자주보게 유도
B14: 김서현 님 | C14: 더 해봐야 알 것 같다. 광고를 선택사항으로 뒀다는 점이 긍정적. 게임 화면 UI가 깔끔했다.
B15: 박원우 님 | C15: 깔끔한 디자인과 자세한 튜토리얼 광고배치로 수익성 까지 챙겼으며 도전욕구와 배치 등 높은 재미를 보장하는 캐주얼 게임.
B16: 장윤우 님 | C16: 괜찮은 게임 방식과 타이트한 레벨 디자인을 광고라는 bm설계를 통해 극복했다. 선택권을 플레이어에게 준 것같은 착각을 설계함으로써 개발사가 돈을 벌 수 있는 설계를 잘해놨다.
B17: 이준혁 님 | C17: 시스템 디자인 - 전통적인 타워디펜스 게임에, 톱니를 넣어 성과에 대한 개인적인 충족감 제공 밸런스, BM 디자인 - 다소 난이도 있는 구간을 초반 구간부터 넣었고, 기물 등장 확률에 랜덤성을 추가해 광고를 시청하도록 유도. 광고를 통해 획득하는 기물의 강함을 체감하도록 유도하여 원활한 스테이지 클리어 유도. 본인이 선택해서 광고를 시청하기 때문에 광고가 필요 없는 구간은 그냥 넘어가도 상관없음. 게임 중간에 강제로 광고를 시청하는 경우가 없어 불쾌함이 줄어듬.
B18: 정재용 님 | C18: 게임성은 나쁘지 않으나 광고시청 유도가 심한 것 같다.
B20: 난이도 자체가 하드해서 어려운 구간은 광고를 보는게 좋을 것 같다
B21: 광고를 유저가 선택하게 하지만, 실질적으로 광고가 필수적으로 유도
B22: 광고가 달린 컨텐츠 마다 광고 시간이 다르다
B23: 광고 BM 모델의 구조 / 개수를 더 살수록 비싸진다
B24: 플레이 환경이 플레이 진행도에 큰 영향을 주지 않았다.
B44: 김서현 | C44: 광고를 본 팀원은 꾸준한 상승 곡선이 보였으나, 광고를 보지 않은 팀원은 후반으로 갈 수록 진행이 더뎌지는 것을 확인. -> 후반으로 갈 수록 광고 시청이 필수 요소로 여겨질 것으로 보임.
B45: 정재용 | C45: 광고를 많이 봐야 클리어가 빠른 것은 아님 -> 클리어 할 수 있을 땐 광고를 보지 않고 진행하는게 더 빠름 하지만 난이도가 어려운 편이라 후반으로 갈수록 광고 시청이 필요할 것으로 예상됨
B46: 이준혁 | C46: 상대적으로 난이도가 있는 반면, 광고 기물로 수월하게 클리어가 가능. 데이터 확인을 통해 기본 컨텐츠에 대해서는 많은 유저들이 평범하게 즐길 수 있다는 점에서, 레벨 디자인이 잘 짜여져있다고 느꼈다.
B47: 장윤우 | C47: 10분 마다 일정한 상승 곡선을 그리는 것으로 보아, 레벨 디자인이 잘 적용 되었다고 볼 수 있음. 다양한 사람들의 평균 값에서도 형태가 튀는 값이 없어서 인상적이다.
B48: 김경민 | C48: 50분 플레이타임 안에서는 플레이 방식에 따른 유의미한 차이가 두드러지게 나기는 어려워 보인다.
B49: 박원우 | C49: 레벨 디자인은 적용이 잘되어있으나 튜토리얼구간과 초반 구간에서 광고를 시청한 사람과 아닌사람의 플레이타임이 큰 변동폭이 존재하진않음.
B51: 다른 분들도 피드백 사항 있으시면 편하게 적어주세요

Sheet 김경민 님
B2: 플레이어 | D2: 사용 기기
B3: 김경민 | D3: IOS / Iphon pro max 15
B5: 플레이 타임 | C5: 레벨 | D5: 스테이지 | E5: 스테이지 | F5: 등장 몬스터 | G5: 획득 아이템 | H5: 콘텐츠 오픈 | I5: 광고 시청 누적수 | J5: 기타
B6: 10분 | C6: 2 | D6: 3 | E6: 1 /10 | F6: 고블린 궁병, 고블린 기병 | G6: 경험치, 골드, 잼 // 골드, 병사 재료, 경기병 // | H6: 한정 버프 | I6: 1 | J6: 광고 스킵권 구매 약 15개 사용
B7: 20분 | C7: 3 | D7: 4 | E7: 7 /10 | F7: 고블린 궁병, 고블린 보병, 고블린 보스 | G7: 경험치, 골드, 잼 // 골드, 병사 재료 | H7: 임무 | I7: 0
B8: 30분 | C8: 3 | D8: 5 | E8: 7 /10 | F8: 고블린 궁병, 고블린 방패병, 고블린 기마병, 고블린 보스 | G8: 경험치, 골드, 잼 // 골드, 병사 재료 | H8: 랭킹 | I8: 0
B9: 40분 | C9: 3 | D9: 6 | E9: 10 /10 | F9: 고블린 궁병, 고블린 방패병, 고블린 도끼병, 고블린 보스 | G9: 경험치, 골드, 잼 // 골드, 병사 재료, 방패병, 코인 기어 | H9: x | I9: 0
B10: 50분 | C10: 4 | D10: 7 | E10: 11 /11 | F10: 고블린 궁병, 고블린 방패병, 고블린 도끼병 고블린 기마병, 고블린 보스 | G10: 경험치, 골드, 잼 // 골드, 병사 재료, 성벽 석재 | H10: x | I10: 0
E15: 서사 | F15: 등급 | G15: HP | H15: ATTACK | I15: TYPE
E16: 창병
E17: 닌자
E18: 성기사
E19: 원시인
E21: 희귀
E22: 야만인
E23: 마법사
E24: 노수
E25: 중장기병
E26: 중장 용사
E28: 우수
E29: 방패병
... E34: 창병

Sheet 김서현 님
B2: 플레이어 | C2: 사용 기기
B3: 김서현 | C3: iOS / 아이폰 12 mini
B5: 플레이 타임 | C5: 레벨 | D5: 스테이지 | E5: 차례 | F5: 등장 몬스터 | G5: 획득 아이템 | H5: 콘텐츠 오픈 | I5: 광고 시청 누적수
B6: 10분 | C6: 1 | D6: 2 | E6: 45692 | F6: 보병, 궁수, 보스 고블린 | G6: 전사 기어, 궁수 기어 | H6: 진영, 점성술, 기어 강화 | I6: =1+1 -> 2
B7: 20분 | C7: 2 | D7: 3 | E7: 45721 | F7: 보병, 궁수, 보스 고블린 | G7: 보병 기어, 방패 기어 | I7: 4
B8: 30분 | C8: 2 | D8: 4 | E8: 45752 | F8: 보병, 궁수 | G8: 성기사 기어, 경기병 기어 | H8: 한정 버프 | I8: 6
B9: 40분 | C9: 2 | D9: 5 | E9: 45780 | F9: 보병, 궁수, 보스 고블린 | G9: 성벽 수리 기어 | H9: 그림자 숲 맵, 임무, 첫 충전 보상 | I9: 10
B10: 50분 | C10: 2 | D10: 6 | E10: 45810 | F10: 기병, 궁수, 대왕 고블린, 방패 고블린 | G10: 강화 기어 | H10: 랭킹 | I10: 12

Sheet 박원우 님
B2: 플레이어 | C2: 사용 기기
B3: 박원우 | C3: 갤럭시
B5: 플레이 타임 | C5: 레벨 | D5: 스테이지 | E5: 차례 | F5: 등장 몬스터 | G5: 획득 아이템 | H5: 콘텐츠 오픈 | I5: 광고 시청 누적수 | J5: 기타
B6: 10분 | C6: 2 | D6: 2 | E6: 1/7 | F6: 고블린 궁병, 고블린 전사, 고블린 보스 | G6: 경험치, 골드, 젬, 궁수 기어 | H6: 진영, 점성술, 기어강화 | I6: x
B7: 20분 | C7: 2 | D7: 4 | E7: 2/8 | F7: 고블린 궁병, 고블린 전사, 고블린 기마병, 고블린 보스 | G7: 경험치, 골드, 젬, 경기병기어, 쉴드 기어 | H7: 한정버프, 배속 진영 캐릭터 해금 | I7: x | J7: 배속
B8: 30분 | C8: 3 | D8: 5 | E8: 3/9 | F8: 고블린 궁병, 고블린 방패병, 고블린 기마병, 고블린 보스 | G8: 경험치, 골드, 젬 | H8: 랭킹, 상점패키지 | I8: x | J8: 클리어 실패시 리스크 확인
B9: 40분 | C9: 4 | D9: 6 | E9: 7/10 | F9: 고블린 궁병, 고블린 방패병, 고블린 도끼병 고블린 기마병, 고블린 보스 | G9: 경험치, 골드, 젬 | H9: 패스, VIP | I9: x | J9: 기본적으로 주는 기어만으로 스테이지 도전
B10: 50분 | C10: 4 | D10: 7 | E10: 4/11 | F10: 고블린 궁병, 고블린 방패병, 고블린 도끼병 고블린 기마병, 고블린 보스, 대왕고블린 | G10: 경험치, 골드, 젬 | I10: x | J10: 기어 강화후 재도전
B12: monster master table | G12: 컬럼명 | H12: 데이터 설명 | I12: 데이터 타입
B13: monster_id | C13: monster_name | D13: monster_type | E13: description | G13: monster_id | H13: 몬스터 고유 ID (PK) | I13: INT
B14: 1 | C14: 고블린 궁병 | D14: 일반 | E14: 원거리 공격을 사용하는 기본 몬스터 | G14: monster_name | H14: 몬스터 이름 | I14: TEXT
B15: 2 | C15: 고블린 전사 | D15: 일반 | E15: 근접 공격 중심의 기본 몬스터 | G15: monster_role | H15: 전투 역할 (근접/원거리/탱커/돌격) | I15: ENUM
B16: 3 | C16: 고블린 방패병 | D16: 일반 | E16: 방어력이 높은 탱커형 몬스터 | G16: monster_type | H16: 일반 / 엘리트 / 보스 | I16: ENUM
B17: 4 | C17: 고블린 기마병 | D17: 일반 | E17: 이동 속도가 빠른 돌격형 몬스터 | G17: attack_range | H17: 공격 범위 (근접/원거리) | I17: ENUM
B18: 5 | C18: 고블린 도끼병 | D18: 일반 | E18: 광역 공격을 사용하는 공격형 몬스터 | G18: move_speed_type | H18: 이동 속도 타입 (느림/보통/빠름) | I18: ENUM
B19: 6 | C19: 고블린 보스 | D19: 보스 | E19: 튜토리얼 구간 보스 몬스터 | G19: ai_behavior | H19: AI 기본 패턴 요약 | I19: TEXT
B20: 7 | C20: 대왕 고블린 | D20: 보스 | E20: 챕터2 라스트 스테이지 강화형 보스 | G20: description | H20: 기획 설명 | I20: TEXT
B22: monster_id | C22: monster_name | D22: monster_role | E22: monster_type | F22: attack_range | G22: move_speed_type | H22: ai_behavior | I22: description
B23: 1 | C23: 고블린 궁병 | D23: 원거리 | E23: 일반 | F23: 원거리 | G23: 보통 | H23: 후방 유지 후 사격 | I23: 원거리 공격을 사용하는 기본 몬스터
B24: 2 | C24: 고블린 전사 | D24: 근접 | E24: 일반 | F24: 근접 | G24: 보통 | H24: 접근 후 근접 공격 | I24: 근접 공격 중심의 기본 몬스터
B25: 3 | C25: 고블린 방패병 | D25: 탱커 | E25: 일반 | F25: 근접 | G25: 보통 | H25: 높은 체력으로 접근 후 근접 공격 | I25: 방어력이 높은 탱커형 몬스터
B26: 4 | C26: 고블린 기마병 | D26: 근접 | E26: 일반 | F26: 근접 | G26: 빠름 | H26: 빠른 돌진 공격 | I26: 이동 속도가 빠른 돌격형 몬스터
B27: 5 | C27: 고블린 도끼병 | D27: 근접 | E27: 일반 | F27: 근접 | G27: 보통 | H27: 점프후 강한 범위 공격 후 근접공격 | I27: 광역 공격을 사용하는 공격형 몬스터
B28: 6 | C28: 고블린 보스 | D28: 근접 | E28: 보스 | F28: 근접 | G28: 보통 | H28: 근접후 강한 범위 공격 | I28: 튜토리얼 구간 보스 몬스터
B29: 7 | C29: 대왕 고블린 | D29: 근접 | E29: 보스 | F29: 근접 | G29: 느림 | I29: 챕터2 라스트 스테이지 강화형 보스

Sheet 이석훈 님
B2: 플레이어 | C2: 사용 기기
B5: 플레이 타임 | C5: 구간 | D5: 맵 | E5: 레벨 | F5: 스토리, 퀘스트 | G5: 등장 몬스터 | H5: 획득 아이템 | I5: 콘텐츠 오픈 | J5: 플레이 타임 | K5: 기타
B6: 10분
B7: 20분
B8: 30분
B9: 40분
B10: 50분

Sheet 장윤우 님
B2: 플레이어 | C2: 사용 기기
B3: 장윤우 | C3: Android / 갤럭시 플립 3
B5: 플레이 타임 | C5: 레벨 | D5: 스테이지 | E5: 차례 | F5: 등장 몬스터 | G5: 획득 아이템 | H5: 콘텐츠 오픈 | I5: 광고 시청 누적수 | J5: 기타
B6: 10분 | C6: 2 | D6: 3 | E6: 45718 | F6: 고블린 궁수, 고블린 전사 | G6: 젬, 골드, 쉴드 기어, 전사 기어, 궁수 기어 | H6: 전투, 진영(기물 강화), 기물 뽑기, 기어뽑기, 상점 | I6: 1
B7: 20분 | C7: 3 | D7: 4 | E7: 45755 | F7: 고블린 궁수, 고블린 전사, 고블린 기병, 보스 고블린 | G7: 경기병 기어, 쉴드 기어, 동전 기어 ,성벽 수리 | H7: 한정 버프, 1.5배속 | I7: 2 | J7: 첫 충전 보상 팝업 패키지
B8: 30분 | C8: 3 | D8: 5 | E8: 45778 | F8: 고블린 궁수, 고블린 전사 고블린 기병, 보스 고블린 | H8: 임무 | I8: 4
B9: 40분 | C9: 4 | D9: 5 | E9: 45786 | F9: 고블린 궁수, 고블린 전사, 고블린 방패병, 고블린 기병, 보스 고블린 | G9: 방패병 기어 | H9: 랭킹 | I9: 6
B10: 50분 | C10: 4 | D10: 7 | E10: 45844 | F10: 고블린 궁수, 고블린 전사, 고블린 방패병, 고블린 기병, 보스 고블린 | H10: 패스 | I10: 7

Sheet 이준혁 님
B2: 플레이어 | C2: 사용 기기
B5: 플레이 타임 | C5: 레벨 | D5: 스테이지 | E5: 차례 | F5: 등장 몬스터 | G5: 획득 아이템 | H5: 콘텐츠 오픈 | I5: 광고 시청 누적수 | J5: 기타
B6: 10분 | C6: 1 | D6: 2 | E6: 45663 | F6: 보병, 궁병, 중간보스 | G6: 경험치, 골드, 젬, 병사 재료(파랑), 전사 기어, 전사 기어2, 궁수 기어, 일반 기어, 일반 기어2, 성벽 수리 | H6: 전투, 상점, 강화재 가챠, 아군 강화 | I6: 2분 21초 | J6: 진행 중, 광고 잘못 걸려서 한참 헤멤
B7: 20분 | C7: 2 | D7: 3 | E7: 45845 | F7: 기병 | G7: 기어 티켓, 생산 기어(기능 기어) | H7: - | I7: 39초 | J7: 스테이지 클리어 후, 광고 잘못걸려서 시간 버림
B8: 30분 | C8: 3 | D8: 5 | E8: 45663 | G8: 경기병 기어, 궁수 기어 2, 병사 재료(노랑), 10포인트 체력, 성벽 수리 기어 | H8: 한정버프(동력 증가, 코인 증가, 성 HP증가), 전투 배속 | I8: 6초 | J8: 닭다리 기어, 코인 기어
B9: 40분 | C9: 3 | D9: 5 | E9: 45909 | F9: 중갑병 | G9: 경기병 기어 2, 궁수 기어 3, 일반 기어 3 | I9: 41초 | J9: 광고 - 성벽수리
B10: 50분 | C10: 4 | D10: 7 | E10: 45668 | F10: 보스 | G10: 초급 병사 패키지(무료), 궁수 개체 강화, 보병 기어3, 무료 패스, 마법 기어(무료패스 포함 아이템) | H10: 패스, VIP | I10: 30초 1분 8초 1분 7초 | J10: 광고 - 배속 광고 - 성벽 수리 광고 - 노수2 기어

Sheet 정재용 님
B1: 플레이어 | C1: 사용 기기
B2: 정재용 | C2: iOS / 아이패드 10
B4: 플레이 타임 | C4: 레벨 | D4: 스테이지 | E4: 차례 | F4: 등장 몬스터 | G4: 획득 아이템 | H4: 콘텐츠 오픈 | I4: 광고 시청 누적수
B5: 10분 | C5: 2 | D5: 3 스테이지 | E5: 4 - 7 | F5: 고블린 보병, 고블린 궁수, 고블린 기마병, 고블린 보스 | G5: 잼, 골드, 성벽 수리권, 생산 기어, 보병, 궁수 | H5: 튜토리얼, 진영(병사 강화, 점성술(병사 뽑기), 궁수 | I5: x
B6: 20분 | C6: 3 | D6: 5 스테이지 | E6: 1 - 9 | F6: 고블린 보병, 고블린 궁수, 고블린 기마병, 고블린 보스 | G6: 잼, 골드, 경기병, 한정 버프 (15분) | H6: 경기병, 새로운 맵(그림자 숲) 오픈 | I6: x
B7: 30분 | C7: 3 | D7: 6 스테이지 | E7: 4 -10 | F7: 강해진 고블린 보병, 고블린 궁수, 고블린 기마병, 고블린 보스 | G7: 방패병 | H7: 방패병 | I7: x
B8: 40분 | C8: 4 | D8: 7 스테이지 | E8: 5 - 11 (클리어 싪패) | F8: 강해진 고블린 보병, 고블린 궁수, 고블린 기마병, 고블린 보스 | G8: X | H8: X | I8: x
B9: 50분 | C9: 4 | D9: 7 스테이지 | E9: 9 - 11 (클리어 실패) | F9: 강해진 고블린 보병, 고블린 궁수, 고블린 기마병, 고블린 보스 | G9: X | H9: X | I9: x
G10: 성벽 수리권 : 지키는 성벽의 일정 이하 체력이 떨어졌을 때 수리를 해줄 수 있는 아이템 생산 기어 : 화살표가 가르키는 방향에 HP 30%에 해당하는 방패(쉴드)를 가지고 소환

Sheet 대본_데이터 분석
B2: 안녕하세요. 1조 : 한조.. 대기중..의 조장이자 발표자인 정재용이라고 합니다. 저희가 해본 게임은 기어 작동: 최후의 요새 - Gear Defenders 라는 게임입니다. 이 게임을 선택한 이유는 플레이스토어의 캐주얼 부분 3위를 차지하고 있어서 입니다. 우선 영상을 보시죠! (영상 대충 30초~1분 ) 이런식의 게임인데요 어디서 많이 보지 않았나요? ( 3조 삼겹살팀의 냥냥시노비랑 많이 비슷하죠? -> 이건 3조가 먼저 발표하면 사용 ) 옛날에 플래시 게임중 전쟁시대나 궁수의 전설이랑 많이 비슷하죠? 저희 팀 내부 평가에서 게임성에 대해서는 꽤 고평가를 받았습니다. 영상에서 보셨다 싶이 밑에 보시면 타워 디펜스 게임에 톱니바퀴를 넣어 성과에 대한 개인적인 충족감을 제공했고요 깔끔한 디자인과 적당히 난이도가 어려운 레벨 디자인 등 호평이 자자했습니다. 저희 팀은 각각 10분, 20분, 30분 ... 50분 이런식으로 시간으로 통계를 내서 10분차엔 몇스테이지에 몇차례까지 왔는지 평균을 내보았는데요 평균 통계를 냈을때 플레이 타임이 비슷한 분들도 계시지만 크게 차이나는 경우도 있습니다. 그 이유는 아까 말씀드렸던 '적당히 난이도가 어려운' 이라는 것입니다. 적당히 어렵다는건 사실 어렵다는 뜻과 같다고 저는 생각합니다. 과금하기는 싫고.. 클리어는 하고싶고.. 그래서 그런 사람들을 위해 내놓은 이 게임의 방향성은 밑에 보시면 저 TV에 재생표시 보이시나요? 어디서 많이 본 표시죠? 저건 광고 표시입니다. 광고를 보게한 후 저 아이템을 제공하는 것 입니다. 물론 광고를 볼지 안볼지 선택을 하게 해주는 것은 괜찮은 시스템 이라고 생각합니다. 다른 게임들 보면 게임 한두판 끝날때마다 한번씩 광고를 강제로 틀어서 불편하게 하잖아요? 그 불편함을 제거했다는건 괜찮다고 생각합니다. 그리고 BM도 재밌는점이 있습니다. 보통 이렇게 광고를 하는 게임은 광고를 영구 제거하는 BM이 있는데 이 게임엔 없고 대신 광고 건 별로 광고 제거를 유료 재화 이게임에선 잼 이라고 합니다. 심지어 보통 양이 많으면 할인을 해줄텐데 여긴 그렇지 않습니다 가격이 오히려 높아집니다. 광고 1회 제거시 60잼 5개는 300잼 10개는 900잼 이라고 합니다. 뭔가 마지막 가격이 이상하지 않나요? 10번이면 .. 600 이어야 하지 않을까요? 그럼 그냥 광고를 보면 안됐냐? 하고 물어보실 수 있는데요 광고 길이 1분~2분에 스킵이 없다고 하네요 재밌었던건 성벽 수리도 광고를 봐야 되니... 당황했습니다. 물론 50분이라는 짧은 시간 내에 이 게임에 대해서 느껴봤어야 했어서 혹시 이 게임을 더 했었어야 했으면 저는 광고를 봤을겁니다.. 하하.. 결론적으로! 저희 한조 대기중에서 이 게임에 총평을 내리자면 게임의 구성 요소는 좋았지만 광고를 보지 않으면 조금 난이도가 있어 무과금은 광고를 자주보게 유도를 하며 BM이 조금 아쉽다! 입니다.
B4: 추천한 신작 게임중'이라는 워딩보다 '플레이스토어의 캐주얼 부분 3위'라서 했다고 하는 편이 더 좋지 않을까요?! 다른 부분은 다 좋은 것 같아요! -> 왜 3위나 했지??! 라는 의문에서 시작했다고 하면 더 좋은 뉘앙스를 주지 않을까 싶습니다 -김서현
B5: 영상에서 보셨다 싶이 밑에 보시면 타워 디펜스 게임에 톱니바퀴를 넣어 성과에 대한 개인적인 충족감을 제공했고요 -> 이 부분을 영상에서 보셨다 싶이 밑에 보시면 타워 디펜스 게임에 톱니바퀴를 활용하여 유닛을 생산하는 플레이 과정이 직관성이 높고 추후 활용성이 높다고 평가했습니다. -> 로 바꾸는게 어떨까요 - 10번째 줄 입니다

Sheet ID 기준
B3: ChrData | C3: 1000
B4: MosterData | C4: 2000
B5: StageData | C5: 3000
B6: StoreData | C6: 4000
B7: ItemData | C7: 5000
B10: 캐릭터 / 몬스터 / 스테이지 / 스토어

Sheet Chr
B2: Character list
F3: 증가 스탯
B4: ID | C4: Dev_Name | D4: Rarity | E4: Name | F4: hp | G4: att
B5: 1001 | C5: warrior | D5: 우수 | E5: 전사 | F5: 6 | G5: 2
B6: 1002 | C6: Archer | D6: 우수 | E6: 궁수 | F6: 2 | G6: 1
B7: 1003 | C7: hussar | D7: 우수 | E7: 경기병 | F7: 6 | G7: 2
B8: 1004 | C8: spearman | D8: 우수 | E8: 창병 | F8: 11 | G8: 2
B9: 1005 | C9: shielder | D9: 우수 | E9: 방패병 | F9: 11 | G9: 2
B10: 1006 | C10: Alchemist | D10: 우수 | E10: 연금술사 | F10: 8 | G10: 3
B11: 1007 | C11: Barbarian | D11: 희귀 | E11: 야만인 | F11: 8 | G11: 3
B12: 1008 | C12: Wizard | D12: 희귀 | E12: 마법사 | F12: - | G12: -
B13: 1009 | C13: Crossbowman | D13: 희귀 | E13: 노수 | F13: 4 | G13: 2
B14: 1010 | C14: heavycavalry | D14: 희귀 | E14: 중장기병 | F14: 8 | G14: 2
B15: 1011 | C15: heavywarrior | D15: 희귀 | E15: 중장 용사 | F15: 20 | G15: 4
B16: 1012 | C16: epic_spearman | D16: 서사 | E16: 창병 | F16: 12 | G16: 4
B17: 1013 | C17: ninja | D17: 서사 | E17: 닌자 | F17: - | G17: -
B18: 1014 | C18: paladin | D18: 서사 | E18: 성기사 | F18: - | G18: -
B19: 1015 | C19: prinitiveman | D19: 서사 | E19: 원시인 | F19: - | G19: -

Sheet Chr_Stat
B2: Stat
B3: 코드 | C3: 영문 | D3: 등급 | E3: 이름 | F3: 병종 | G3: 승급 | H3: 체력 | I3: 공격력 | J3: 치명타확률 | K3: 리스폰 타임
B4: ID | C4: Dev_Name | D4: Rarity | E4: Name | F4: type | G4: Grade | H4: MaxHP | I4: Attack | J4: Critical | K4: spawn_time (s)
B5: 1001 | C5: warrior | D5: 우수 | E5: 전사 | F5: 보병 | G5: 0 | H5: 64 | I5: 22 | J5: 0.12 | K5: 0.14
G6: 1 | H6: 146 | I6: 50 | J6: 0.12
G7: 2 | J7: 0.12
G8: 3 | J8: 0.12
G9: 4 | J9: 0.12
B10: 1002 | C10: {=XLOOKUP(B10, Chr!$B$5:$B$19, Chr!$C$5:$E$19)} -> Archer | D10: 우수 | E10: 궁수 | F10: 원거리 | G10: 0 | H10: 26 | I10: 10 | J10: 0.1 | K10: 0.14
G11: 1 | H11: 57 | I11: 19 | J11: 0.13
G12: 2 | J12: 0.13
G13: 3 | J13: 0.13
G14: 4 | J14: 0.13
B15: 1003 | C15: {=XLOOKUP(B15, Chr!$B$5:$B$19, Chr!$C$5:$E$19)} -> hussar | D15: 우수 | E15: 경기병 | F15: 기병 | G15: 0 | H15: 55 | I15: 17 | J15: 0.08 | K15: 0.14
G16: 1 | H16: 125 | I16: 39 | J16: 0.08
G17: 2 | J17: 0.08
G18: 3 | J18: 0.08
G19: 4 | J19: 0.08
B20: 1004 | C20: {=XLOOKUP(B20, Chr!$B$5:$B$19, Chr!$C$5:$E$19)} -> spearman | D20: 우수 | E20: 창병 | F20: 보병 | G20: 0 | H20: 110 | I20: 26 | J20: 0.14 | K20: 0.8
G21: 1 | H21: 285 | I21: 61 | J21: 0.14
G22: 2 | J22: 0.14
G23: 3 | J23: 0.14
G24: 4 | J24: 0.14
B25: 1005 | C25: {=XLOOKUP(B25, Chr!$B$5:$B$19, Chr!$C$5:$E$19)} -> shielder | D25: 우수 | E25: 방패병 | F25: 중갑 | G25: 0 | H25: 108 | I25: 25 | J25: 0 | K25: 0.14
G26: 1 | J26: 0
G27: 2 | J27: 0
G28: 3 | J28: 0
G29: 4 | J29: 0
B30: 1006 | C30: {=XLOOKUP(B30, Chr!$B$5:$B$19, Chr!$C$5:$E$19)} -> Alchemist | D30: 우수 | E30: 연금술사 | F30: 원거리 | G30: 0 | H30: 74 | I30: 29 | J30: 0.05 | K30: 0.06
G31: 1 | H31: 53 | I31: 171 | J31: 0.05
G32: 2 | J32: 0.05
G33: 3 | J33: 0.05
G34: 4 | J34: 0.05
B35: 1007 | C35: {=XLOOKUP(B35, Chr!$B$5:$B$19, Chr!$C$5:$E$19)} -> Barbarian | D35: 희귀 | E35: 야만인 | F35: 보병 | G35: 0 | H35: 80 | I35: 27 | J35: 0.28 | K35: 0.13
G36: 1 | H36: 182 | I36: 53 | J36: 0.28
G37: 2 | J37: 0.28
G38: 3 | J38: 0.28
G39: 4 | J39: 0.28
B40: 1008 | C40: {=XLOOKUP(B40, Chr!$B$5:$B$19, Chr!$C$5:$E$19)} -> Wizard | D40: 희귀 | E40: 마법사 | F40: 원거리 | G40: 0 | H40: 40 | I40: 30 | J40: 0.2 | K40: 0.13
G41: 1 | J41: 0.2
...

Sheet ChrData
B2: Lv Upgrade
B3: 코드 | C3: 이름 | D3: 승급 | E3: 레벨 | F3: 성장 체력치 | G3: 체력 | H3: 성장 공격력 | I3: 공격력 | J3: 내용
B4: ID | C4: Name | D4: grade | E4: LV | F4: HP_growth | G4: HP | H4: Attck_growth | I4: Attack | J4: skill
B5: 1001 | C5: {=XLOOKUP(B5, Chr!$B$5:$B$19, Chr!$E$5:$E$19, "")} -> 전사 | D5: 0 | E5: 1 | F5: 6 | G5: 64 | H5: 2 | I5: 22
C6: {=XLOOKUP(B6, Chr!$B$5:$B$19, Chr!$E$5:$E$19, "")} | E6: 2 | F6: 6 | G6: 70 | H6: 2 | I6: 24
C7: {=XLOOKUP(B7, Chr!$B$5:$B$19, Chr!$E$5:$E$19, "")} | E7: 3 | F7: 7 | G7: 77 | H7: 2 | I7: 26
C8: {=XLOOKUP(B8, Chr!$B$5:$B$19, Chr!$E$5:$E$19, "")} | E8: 4 | F8: 6 | G8: 83 | H8: 3 | I8: 29
C9: {=XLOOKUP(B9, Chr!$B$5:$B$19, Chr!$E$5:$E$19, "")} | E9: 5 | F9: 7 | G9: 90 | H9: 2 | I9: 31 | J9: 일반 형태, 스트라이커 착용됩니다! / 치명타 확률 +3%
C10: {=XLOOKUP(B10, Chr!$B$5:$B$19, Chr!$E$5:$E$19, "")} | E10: 6 | F10: 6 | G10: 96 | H10: 2 | I10: 33
C11: {=XLOOKUP(B11, Chr!$B$5:$B$19, Chr!$E$5:$E$19, "")} | E11: 7 | F11: 6 | G11: 102 | H11: 2 | I11: 35
C12: {=XLOOKUP(B12, Chr!$B$5:$B$19, Chr!$E$5:$E$19, "")} | E12: 8 | F12: 7 | G12: 109 | H12: 2 | I12: 37
C13: {=XLOOKUP(B13, Chr!$B$5:$B$19, Chr!$E$5:$E$19, "")} | E13: 9 | F13: 6 | G13: 115 | H13: 3 | I13: 40
C14: {=XLOOKUP(B14, Chr!$B$5:$B$19, Chr!$E$5:$E$19, "")} | E14: 10 | F14: 7 | G14: 122 | H14: 2 | I14: 42
C15: {=XLOOKUP(B15, Chr!$B$5:$B$19, Chr!$E$5:$E$19, "")} | D15: 1 | E15: 승급 | F15: 6 | G15: 146 | H15: 2 | I15: 50 | J15: 2번째 공격은 30% 축력 단칼을 발동하며, 3배의 피해를 입힐 것입니다.
C16: {=XLOOKUP(B16, Chr!$B$5:$B$19, Chr!$E$5:$E$19, "")} | E16: 11 | F16: 6 | G16: 130 | H16: 2 | I16: 44
C17: {=XLOOKUP(B17, Chr!$B$5:$B$19, Chr!$E$5:$E$19, "")} | E17: 12 | F17: 6 | G17: =F17+G16 -> 136 | H17: 2 | I17: 46
C18: {=XLOOKUP(B18, Chr!$B$5:$B$19, Chr!$E$5:$E$19, "")} | E18: 13 | F18: 6 | G18: =F18+G17 -> 142 | H18: 2 | I18: 48
C19: {=XLOOKUP(B19, Chr!$B$5:$B$19, Chr!$E$5:$E$19, "")} | E19: 14 | F19: 6 | G19: =F19+G18 -> 148 | H19: 2 | I19: 50
C20: {=XLOOKUP(B20, Chr!$B$5:$B$19, Chr!$E$5:$E$19, "")} | E20: 15 | F20: 6 | G20: =F20+G19 -> 154 | H20: 2 | I20: 52 | J20: 일반 형태, 가죽 세트 착용됩니다! / 치명타 확률 +%
C21: {=XLOOKUP(B21, Chr!$B$5:$B$19, Chr!$E$5:$E$19, "")} | E21: 16 | F21: 6 | G21: =F21+G20 -> 160 | H21: 2 | I21: 54
C22: {=XLOOKUP(B22, Chr!$B$5:$B$19, Chr!$E$5:$E$19, "")} | E22: 17 | F22: 6 | G22: =F22+G21 -> 166 | H22: 2 | I22: 56
C23: {=XLOOKUP(B23, Chr!$B$5:$B$19, Chr!$E$5:$E$19, "")} | E23: 18 | F23: 6 | G23: =F23+G22 -> 172 | H23: 2 | I23: 58
C24: {=XLOOKUP(B24, Chr!$B$5:$B$19, Chr!$E$5:$E$19, "")} | E24: 19 | F24: 6 | G24: =F24+G23 -> 178 | H24: 2 | I24: 60
C25: {=XLOOKUP(B25, Chr!$B$5:$B$19, Chr!$E$5:$E$19, "")} | E25: 20 | F25: 6 | G25: =F25+G24 -> 184 | H25: 2 | I25: 62
C26: {=XLOOKUP(B26, Chr!$B$5:$B$19, Chr!$E$5:$E$19, "")} | D26: 2 | E26: 승급 | F26: 6 | G26: 190 | H26: 2 | I26: 64 | J26: 궁극 형태, 투구 업그레이드 되며, 병사 세트 착용됩니다! / 치명타 확률 +3%
C27: {=XLOOKUP(B27, Chr!$B$5:$B$19, Chr!$E$5:$E$19, "")} | E27: 21 | F27: 6 | G27: 196 | H27: 2 | I27: 66
C28: {=XLOOKUP(B28, Chr!$B$5:$B$19, Chr!$E$5:$E$19, "")} | E28: 22 | F28: 6 | G28: 202 | H28: 2 | I28: 68
C29: {=XLOOKUP(B29, Chr!$B$5:$B$19, Chr!$E$5:$E$19, "")} | E29: 23 | F29: 6 | G29: 208 | H29: 2 | I29: 70
C30: {=XLOOKUP(B30, Chr!$B$5:$B$19, Chr!$E$5:$E$19, "")} | E30: 24 | F30: 6 | G30: 214 | H30: 2 | I30: 72
C31: {=XLOOKUP(B31, Chr!$B$5:$B$19, Chr!$E$5:$E$19, "")} | E31: 25 | F31: 6 | G31: 220 | H31: 2 | I31: 74 | J31: 세 번째 공격은 반드시 축력 단칼을 발동하여 대량의 피해를 입힐 것입니다!
C32: {=XLOOKUP(B32, Chr!$B$5:$B$19, Chr!$E$5:$E$19, "")} | E32: 26 | F32: 6 | G32: 226 | H32: 2 | I32: 76
C33: {=XLOOKUP(B33, Chr!$B$5:$B$19, Chr!$E$5:$E$19, "")} | E33: 27 | F33: 6 | G33: 232 | H33: 2 | I33: 78
C34: {=XLOOKUP(B34, Chr!$B$5:$B$19, Chr!$E$5:$E$19, "")} | E34: 28 | F34: 6 | G34: 238 | H34: 2 | I34: 80
C35: {=XLOOKUP(B35, Chr!$B$5:$B$19, Chr!$E$5:$E$19, "")} | E35: 29 | F35: 6 | G35: 244 | H35: 2 | I35: 82
C36: {=XLOOKUP(B36, Chr!$B$5:$B$19, Chr!$E$5:$E$19, "")} | E36: 30 | F36: 6 | G36: 250 | H36: 2 | I36: 84
C37: {=XLOOKUP(B37, Chr!$B$5:$B$19, Chr!$E$5:$E$19, "")} | D37: 3 | E37: 승급 | F37: 6 | G37: 256 | H37: 2 | I37: 86 | J37: 궁극 형태, 황금 병사 세트로 업그레이드 됩니다! / 치명타 확률 +3%
C38: {=XLOOKUP(B38, Chr!$B$5:$B$19, Chr!$E$5:$E$19, "")} | E38: 31 | F38: 6 | G38: 262 | H38: 2 | I38: 88
C39: {=XLOOKUP(B39, Chr!$B$5:$B$19, Chr!$E$5:$E$19, "")} | E39: 32 | F39: 6 | G39: 268 | H39: 2 | I39: 90
C40: {=XLOOKUP(B40, Chr!$B$5:$B$19, Chr!$E$5:$E$19, "")} | E40: 33 | F40: 6 | G40: 274 | H40: 2 | I40: 92
C41: {=XLOOKUP(B41, Chr!$B$5:$B$19, Chr!$E$5:$E$19, "")} | E41: 34 | F41: 6 | G41: 280 | H41: 2 | I41: 94
...

Sheet Monster table
B1: monster master table
B2: monster_id | C2: monster_name | D2: monster_type | E2: description | G2: 컬럼명 | H2: 데이터 설명 | I2: 데이터 타입
B3: 2001 | C3: 고블린 궁병 | D3: 일반 | E3: 원거리 공격을 사용하는 기본 몬스터 | G3: monster_id | H3: 몬스터 고유 ID (PK) | I3: INT
B4: 2002 | C4: 고블린 전사 | D4: 일반 | E4: 근접 공격 중심의 기본 몬스터 | G4: monster_name | H4: 몬스터 이름 | I4: TEXT
B5: 2003 | C5: 고블린 방패병 | D5: 일반 | E5: 방어력이 높은 탱커형 몬스터 | G5: monster_type | H5: 일반 / 엘리트 / 보스 | I5: ENUM
B6: 2004 | C6: 고블린 기마병 | D6: 일반 | E6: 이동 속도가 빠른 돌격형 몬스터 | G6: attack_range | H6: 공격 범위 (근접/원거리) | I6: ENUM
B7: 2005 | C7: 고블린 도끼병 | D7: 일반 | E7: 광역 공격을 사용하는 공격형 몬스터 | G7: move_speed_type | H7: 이동 속도 타입 (느림/보통/빠름) | I7: ENUM
B8: 2006 | C8: 고블린 보스 | D8: 보스 | E8: 튜토리얼 구간 보스 몬스터 | G8: ai_behavior | H8: AI 기본 패턴 요약 | I8: TEXT
B9: 2007 | C9: 대왕 고블린 | D9: 보스 | E9: 챕터2 라스트 스테이지 강화형 보스 | G9: description | H9: 기획 설명 | I9: TEXT
B12: monster_id | C12: monster_name | D12: monster_type | E12: attack_range | F12: move_speed_type | G12: ai_behavior | H12: description
B13: 2001 | C13: 고블린 궁병 | D13: 일반 | E13: 원거리 | F13: 보통 | G13: 후방 유지 후 사격 | H13: 원거리 공격을 사용하는 기본 몬스터
B14: 2002 | C14: 고블린 전사 | D14: 일반 | E14: 근접 | F14: 보통 | G14: 접근 후 근접 공격 | H14: 근접 공격 중심의 기본 몬스터
B15: 2003 | C15: 고블린 방패병 | D15: 일반 | E15: 근접 | F15: 보통 | G15: 높은 체력으로 접근 후 근접 공격 | H15: 방어력이 높은 탱커형 몬스터
B16: 2004 | C16: 고블린 기마병 | D16: 일반 | E16: 근접 | F16: 빠름 | G16: 빠른 돌진 공격 | H16: 이동 속도가 빠른 돌격형 몬스터
B17: 2005 | C17: 고블린 도끼병 | D17: 일반 | E17: 근접 | F17: 보통 | G17: 점프후 강한 범위 공격 후 근접공격 | H17: 광역 공격을 사용하는 공격형 몬스터
B18: 2006 | C18: 고블린 보스 | D18: 보스 | E18: 근접 | F18: 보통 | G18: 근접후 강한 범위 공격 | H18: 튜토리얼 구간 보스 몬스터
B19: 2007 | C19: 대왕 고블린 | D19: 보스 | E19: 근접 | F19: 느림 | G19: 느리게 접근후 강한 범위 공격 | H19: 챕터2 라스트 스테이지 강화형 보스
B20: 2008 | C20: 고블린 마법사 | D20: 일반 | E20: 원거리 | F20: 보통 | G20: 후방 유지 후 마법공격 | H20: 원거리 공격을 사용하는 마법 몬스터
B22: 컬럼명 | C22: 데이터 설명 | D22: 데이터 타입 | E22: 필요 여부 | G22: 컬럼명 | H22: 데이터 설명 | I22: 데이터 타입 | J22: 필요 여부
B23: stage_id | C23: 스테이지 ID (FK) | D23: INT | E23: 필수 | G23: stage_id | H23: 스테이지 ID (FK) | I23: INT | J23: 필수
B24: monster_id | C24: 몬스터 ID (FK) | D24: INT | E24: 필수 | G24: monster_id | H24: 몬스터 ID (FK) | I24: INT | J24: 필수
G25: spawn_count | H25: 등장 수 | I25: INT | J25: 필수
G26: spawn_wave | H26: 등장 웨이브 | I26: INT | J26: 선택
G27: is_boss | H27: 보스 여부 | I27: BOOLEAN | J27: 필수

Sheet Store_ItemData
B2: 패키지 | H2: 상점
B3: 일일 번들 | H3: 잼
B4: ID | C4: Name | D4: Item | E4: Number | F4: Price | H4: ID | I4: Name | J4: Gem | K4: Price
B5: 4000 | C5: 초급 병사 패키지 - 1 | D5: 방패병(우수) | E5: 1 | F5: 3300 | H5: 4100 | I5: 소량잼 | J5: 70 | K5: 1100
D6: 병사 업그레이드 재료(우수) | E6: 5 | H6: 4101 | I6: 적당한 양의 젬 | J6: 350 | K6: 6600
D7: 젬 | E7: 200 | H7: 4102 | I7: 많은 젬 | J7: 1050 | K7: 22000
B8: 4001 | C8: 초급 병사 패키지 - 2 | D8: 창병 | E8: 1 | F8: 3300 | H8: 4103 | I8: 작은 주머니 젬 | J8: 2100 | K8: 44000
D9: 병사 업그레이드 재료(우수) | E9: 5 | H9: 4104 | I9: 한 통 젬 | J9: 3500 | K9: 66000
D10: 젬 | E10: 200 | H10: 4105 | I10: 큰 상자 젬 | J10: 7000 | K10: 149000
B11: 4002 | C11: 초급 병사 패키지 - 3 | D11: 궁수(우수) | E11: 1 | F11: 3300
D12: 병사 업그레이드 재료(우수) | E12: 5
D13: 젬 | E13: 200 | H13: 골드
B14: 4003 | C14: 초급 병사 패키지 - 4 | D14: 연금술사 | E14: 1 | F14: 3300 | H14: ID | I14: Name | J14: Number | K14: Number of Purchases | L14: Price
D15: 병사 업그레이드 재료(우수) | E15: 5 | H15: 4150 | I15: 골드 묶음 | J15: 500 | K15: 10 | L15: 10젬
D16: 젬 | E16: 200 | H16: 4151 | I16: 골드 더미 | J16: 5000 | K16: 10 | L16: 100젬
B17: 4004 | C17: 초급 기어 패키지 | D17: 기어(우수) | E17: 10 | F17: 3300 | H17: 4152 | I17: 골드 상자 | J17: 50000 | K17: 10 | L17: 1000젬
D18: 젬 | E18: 200
B19: 4005 | C19: 초급 강화 패키지 | D19: 병사 업그레이드 재료(우수) | E19: 18 | F19: 3300
D20: 골드 | E20: 5000 | H20: 체력
D21: 젬 | E21: 200 | H21: ID | I21: Name | J21: Number | K21: Number of Purchases | L21: Price
H22: 4170 | I22: 10 포인트 무료 체력 회복 | J22: 10 | K22: 1 | L22: 무료
H23: 4171 | I23: 40포인트 체력 회복 | J23: 40 | K23: 10 | L23: 30젬
B24: 주간 번들 | H24: 4172 | I24: 75포인트 체력 회복 | J24: 75 | K24: 10 | L24: 50젬
B25: ID | C25: Name | D25: Item | E25: Number | F25: Price
B26: 4020 | C26: 중급 병사 패키지 -1 | D26: 중장 용사(희귀) | E26: 2 | F26: 14000
D27: 병사 업그레이드 재료(희귀) | E27: 20 | H27: 광고 스킵 티켓
D28: 젬 | E28: 1000 | H28: ID | I28: Name | J28: Number | K28: Number of Purchases | L28: Price
B29: 4021 | C29: 중급 병사 패키지 - 2 | D29: 마법사(희귀) | E29: 2 | F29: 14000 | H29: 4200 | I29: 소량 광고 스킵 티켓 | J29: 1 | K29: 3 | L29: 60젬
D30: 병사 업그레이드 재료(희귀) | E30: 20 | H30: 4201 | I30: 중량 광고 스킵 티켓 | J30: 5 | K30: 3 | L30: 300젬
D31: 젬 | E31: 1000 | H31: 4202 | I31: 대량 광고 스킵 티켓 | J31: 10 | K31: 3 | L31: 900젬
B32: 4022 | C32: 중급 병사 패키지 - 3 | D32: 중장기병(희귀) | E32: 2 | F32: 14000
D33: 병사 업그레이드 재료(희귀) | E33: 20
D34: 젬 | E34: 1000
B35: 4023 | C35: 중급 병사 패키지 - 4 | D35: 노수(희귀) | E35: 2 | F35: 14000
D36: 병사 업그레이드 재료(희귀) | E36: 20
D37: 젬 | E37: 1000
B38: 4024 | C38: 중급 강화 패키지 | D38: 병사 업그레이드 재료(희귀) | E38: 20 | F38: 6600
D39: 골드 | E39: 10000
D40: 젬 | E40: 500
B41: 4025 | C41: 중급 기어 패키지 | D41: 희귀 기어 | E41: 25 | F41: 6600
...

Sheet 대본_데이터 테이블
B4: 게임 개요 설명 + 데이터 기준 (정하는 과정) + 기준으로 하여금 어떤 데이터를 수집해서 작성했는지 + 결론

Sheet Chr_Ability
B2: Ability
B3: ID | C3: Dev_Name | E3: Name | F3: LV | G3: Ability

Sheet QuestData
F14: ? | G14: ?
